Workbook

Sheet 4月部门分发
A1: 打卡地点 | B1: 姓名 | C1: 工号 | D1: 一级部门 | E1: 二级部门 | F1: 46113 | H1: 小时数 | I1: 天数 | J1: 46114 | L1: 小时数 | M1: 天数 | N1: 46115 | P1: 小时数 | Q1: 天数 | R1: 46116 | T1: 小时数 | U1: 天数 | V1: 46117 | X1: 小时数 | Y1: 天数 | Z1: 46118 | AB1: 小时数 | AC1: 天数 | AD1: 46119 | AF1: 小时数 | AG1: 天数 | AH1: 46120 | AJ1: 小时数 | AK1: 天数 | AL1: 46121 | AN1: 小时数 | AO1: 天数 | AP1: 46122 | AR1: 小时数 | AS1: 天数 | AT1: 46123 | AV1: 小时数 | AW1: 天数 | AX1: 46124 | AZ1: 小时数 | BA1: 天数 | BB1: 46125 | BD1: 小时数 | BE1: 天数 | BF1: 46126 | BH1: 小时数 | BI1: 天数 | BJ1: 46127 | BL1: 小时数 | BM1: 天数 | BN1: 46128 | BP1: 小时数 | BQ1: 天数 | BR1: 46129 | BT1: 小时数 | BU1: 天数 | BV1: 46130 | BX1: 小时数 | BY1: 天数 | BZ1: 46131 | CB1: 小时数 | CC1: 天数 | CD1: 46132 | CF1: 小时数 | CG1: 天数 | CH1: 46133 | CJ1: 小时数 | CK1: 天数 | CL1: 46134 | CN1: 小时数 | CO1: 天数 | CP1: 46135 | CR1: 小时数 | CS1: 天数 | CT1: 46136 | CV1: 小时数 | CW1: 天数 | CX1: 46137 | CZ1: 小时数 | DA1: 天数 | DB1: 46138 | DD1: 小时数 | DE1: 天数 | DF1: 46139 | DH1: 小时数 | DI1: 天数 | DJ1: 46140 | DL1: 小时数 | DM1: 天数 | DN1: 46141 | DP1: 小时数 | DQ1: 天数 | DR1: 46142 | DT1: 小时数 | DU1: 天数 | DZ1: 总小时数 | EA1: 总天数 | EB1: 1日异常 | EC1: 2日异常 | ED1: 3日异常 | EE1: 4日异常 | EF1: 5日异常 | EG1: 6日异常 | EH1: 7日异常 | EI1: 8日异常 | EJ1: 9日异常 | EK1: 10日异常 | EL1: 11日异常 | EM1: 12日异常 | EN1: 13日异常 | EO1: 14日异常 | EP1: 15日异常 | EQ1: 16日异常 | ER1: 17日异常 | ES1: 18日异常 | ET1: 19日异常 | EU1: 20日异常 | EV1: 21日异常 | EW1: 22日异常 | EX1: 23日异常 | EY1: 24日异常 | EZ1: 25日异常 | FA1: 26日异常 | FB1: 27日异常 | FC1: 28日异常 | FD1: 29日异常 | FE1: 30日异常
A2: 五楼 | B2: 高淑文 | C2: 2 | F2: 0.35347222 | G2: 0.73611111 | H2: =MOD(G2-F2,1)*24 | I2: 1 | J2: 0.34513889 | M2: 0.5 | N2: 0.34652778 | O2: 0.73611111 | P2: =MOD(O2-N2,1)*24 | Q2: 1 | Z2: 0.35069444 | AA2: 0.73611111 | AB2: =MOD(AA2-Z2,1)*24 | AC2: 1 | AD2: 0.34444444 | AE2: 0.73611111 | AF2: =MOD(AE2-AD2,1)*24 | AG2: 1 | AH2: 0.34166667 | AI2: 0.73611111 | AJ2: =MOD(AI2-AH2,1)*24 | AK2: 1 | AL2: 0.34166667 | AM2: 0.73611111 | AN2: =MOD(AM2-AL2,1)*24 | AO2: 1 | AP2: 0.34375 | AQ2: 0.73611111 | AR2: =MOD(AQ2-AP2,1)*24 | AS2: 1 | AT2: 0.34722222 | AU2: 0.73611111 | AV2: =MOD(AU2-AT2,1)*24 | AW2: 1 | BB2: 0.34930556 | BC2: 0.73680556 | BD2: =MOD(BC2-BB2,1)*24 | BE2: 1 | BF2: 0.34722222 | BG2: 0.73611111 | BH2: =MOD(BG2-BF2,1)*24 | BI2: 1 | BJ2: 0.34513889 | BK2: 0.73680556 | BL2: =MOD(BK2-BJ2,1)*24 | BM2: 1 | BN2: 0.34652778 | BO2: 0.73611111 | BP2: =MOD(BO2-BN2,1)*24 | BQ2: 1 | BR2: 0.34375 | BS2: 0.73680556 | BT2: =MOD(BS2-BR2,1)*24 | BU2: 1 | BV2: 0.34791667 | BW2: 0.73680556 | BX2: =MOD(BW2-BV2,1)*24 | BY2: 1 | CD2: 0.34305556 | CE2: 0.73611111 | CF2: =MOD(CE2-CD2,1)*24 | CG2: 1 | CH2: 0.34652778 | CI2: 0.73680556 | CJ2: =MOD(CI2-CH2,1)*24 | CK2: 1 | CL2: 0.34236111 | CM2: 0.73611111 | CN2: =MOD(CM2-CL2,1)*24 | CO2: 1 | CP2: 0.34375 | CQ2: 0.73611111 | CR2: =MOD(CQ2-CP2,1)*24 | CS2: 1 | CT2: 0.34930556 | CU2: 0.73611111 | CV2: =MOD(CU2-CT2,1)*24 | CW2: 1 | CX2: 0.33958333 | CY2: 0.73611111 | CZ2: =MOD(CY2-CX2,1)*24 | DA2: 1 | DF2: 0.34444444 | DG2: 0.73611111 | DH2: =MOD(DG2-DF2,1)*24 | DI2: 1 | DJ2: 0.34722222 | DK2: 0.73680556 | DL2: =MOD(DK2-DJ2,1)*24 | DM2: 1 | DN2: 0.34097222 | DO2: 0.73680556 | DP2: =MOD(DO2-DN2,1)*24 | DQ2: 1 | DR2: 0.34583333 | DS2: 0.73611111 | DT2: =MOD(DS2-DR2,1)*24 | DU2: 1 | DV2: =SUM(H2,L2,P2,T2,X2,AB2,AF2,AJ2,AN2,AR2,AV2,AZ2,BD2,BH2,BL2,BP2,BT2,BX2,CB2,CF2,CJ2,CN2,CR2,CV2,CZ2,DD2,DH2,DL2,DP2,DT2) | DW2: =SUM(I2,M2,Q2,U2,Y2,AC2,AG2,AK2,AO2,AS2,AW2,BA2,BE2,BI2,BM2,BQ2,BU2,BY2,CC2,CG2,CK2,CO2,CS2,CW2,DA2,DE2,DI2,DM2,DQ2,DU2) | EC2: 只打一次卡
A3: 五楼 | B3: 伍小雪 | C3: 3 | F3: 0.35347222 | G3: 0.75 | H3: =MOD(G3-F3,1)*24 | I3: 1 | J3: 0.35277778 | K3: 0.73819444 | L3: =MOD(K3-J3,1)*24 | M3: 1 | N3: 0.34930556 | O3: 0.74027778 | P3: =MOD(O3-N3,1)*24 | Q3: 1 | Z3: 0.35 | AA3: 0.73958333 | AB3: =MOD(AA3-Z3,1)*24 | AC3: 1 | AD3: 0.35347222 | AE3: 0.75833333 | AF3: =MOD(AE3-AD3,1)*24 | AG3: 1 | AH3: 0.35 | AI3: 0.74097222 | AJ3: =MOD(AI3-AH3,1)*24 | AK3: 1 | AL3: 0.35208333 | AM3: 0.7375 | AN3: =MOD(AM3-AL3,1)*24 | AO3: 1 | AP3: 0.35 | AQ3: 0.74375 | AR3: =MOD(AQ3-AP3,1)*24 | AS3: 1 | AT3: 0.34930556 | AU3: 0.73958333 | AV3: =MOD(AU3-AT3,1)*24 | AW3: 1 | BB3: 0.35208333 | BC3: 0.73680556 | BD3: =MOD(BC3-BB3,1)*24 | BE3: 1 | BF3: 0.35069444 | BG3: 0.83888889 | BH3: =MOD(BG3-BF3,1)*24 | BI3: 1 | BJ3: 0.35069444 | BK3: 0.73819444 | BL3: =MOD(BK3-BJ3,1)*24 | BM3: 1 | BN3: 0.35138889 | BO3: 0.73819444 | BP3: =MOD(BO3-BN3,1)*24 | BQ3: 1 | BR3: 0.35138889 | BS3: 0.74305556 | BT3: =MOD(BS3-BR3,1)*24 | BU3: 1 | BV3: 0.34652778 | BW3: 0.74513889 | BX3: =MOD(BW3-BV3,1)*24 | BY3: 1 | CD3: 0.35277778 | CE3: 0.74166667 | CF3: =MOD(CE3-CD3,1)*24 | CG3: 1 | CH3: 0.34861111 | CI3: 0.73819444 | CJ3: =MOD(CI3-CH3,1)*24 | CK3: 1 | CL3: 0.35208333 | CM3: 0.74097222 | CN3: =MOD(CM3-CL3,1)*24 | CO3: 1 | CP3: 0.35138889 | CQ3: 0.74236111 | CR3: =MOD(CQ3-CP3,1)*24 | CS3: 1 | CT3: 0.34513889 | CU3: 0.73958333 | CV3: =MOD(CU3-CT3,1)*24 | CW3: 1 | CX3: 0.34791667 | CY3: 0.74513889 | CZ3: =MOD(CY3-CX3,1)*24 | DA3: 1 | DF3: 0.35 | DG3: 0.74236111 | DH3: =MOD(DG3-DF3,1)*24 | DI3: 1 | DJ3: 0.34791667 | DK3: 0.73958333 | DL3: =MOD(DK3-DJ3,1)*24 | DM3: 1 | DN3: 0.34791667 | DO3: 0.74097222 | DP3: =MOD(DO3-DN3,1)*24 | DQ3: 1 | DR3: 0.35138889 | DS3: 0.74236111 | DT3: =MOD(DS3-DR3,1)*24 | DU3: 1 | DV3: =SUM(H3,L3,P3,T3,X3,AB3,AF3,AJ3,AN3,AR3,AV3,AZ3,BD3,BH3,BL3,BP3,BT3,BX3,CB3,CF3,CJ3,CN3,CR3,CV3,CZ3,DD3,DH3,DL3,DP3,DT3) | DW3: =SUM(I3,M3,Q3,U3,Y3,AC3,AG3,AK3,AO3,AS3,AW3,BA3,BE3,BI3,BM3,BQ3,BU3,BY3,CC3,CG3,CK3,CO3,CS3,CW3,DA3,DE3,DI3,DM3,DQ3,DU3)
A4: 五楼 | B4: 邱霞 | C4: 4 | F4: 0.35138889 | G4: 0.75 | H4: =MOD(G4-F4,1)*24 | I4: 1 | J4: 0.35 | K4: 0.73888889 | L4: =MOD(K4-J4,1)*24 | M4: 1 | N4: 0.35069444 | O4: 0.74097222 | P4: =MOD(O4-N4,1)*24 | Q4: 1 | Z4: 0.35277778 | AA4: 0.73958333 | AB4: =MOD(AA4-Z4,1)*24 | AC4: 1 | AD4: 0.35138889 | AE4: 0.7375 | AF4: =MOD(AE4-AD4,1)*24 | AG4: 1 | AH4: 0.34791667 | AI4: 0.74027778 | AJ4: =MOD(AI4-AH4,1)*24 | AK4: 1 | AL4: 0.34930556 | AM4: 0.73819444 | AN4: =MOD(AM4-AL4,1)*24 | AO4: 1 | AP4: 0.35069444 | AQ4: 0.73958333 | AR4: =MOD(AQ4-AP4,1)*24 | AS4: 1 | AT4: 0.35069444 | AU4: 0.74097222 | AV4: =MOD(AU4-AT4,1)*24 | AW4: 1 | BB4: 0.35 | BC4: 0.73819444 | BD4: =MOD(BC4-BB4,1)*24 | BE4: 1 | BF4: 0.35069444 | BG4: 0.73958333 | BH4: =MOD(BG4-BF4,1)*24 | BI4: 1 | BJ4: 0.34930556 | BK4: 0.73819444 | BL4: =MOD(BK4-BJ4,1)*24 | BM4: 1 | BN4: 0.34861111 | BO4: 0.73958333 | BP4: =MOD(BO4-BN4,1)*24 | BQ4: 1 | BR4: 0.34791667 | BS4: 0.73819444 | BT4: =MOD(BS4-BR4,1)*24 | BU4: 1 | BZ4: 0.34791667 | CA4: 0.73680556 | CB4: =MOD(CA4-BZ4,1)*24 | CC4: 1 | CD4: 0.34930556 | CE4: 0.74097222 | CF4: =MOD(CE4-CD4,1)*24 | CG4: 1 | CH4: 0.34861111 | CI4: 0.73819444 | CJ4: =MOD(CI4-CH4,1)*24 | CK4: 1 | CL4: 0.35069444 | CM4: 0.74027778 | CN4: =MOD(CM4-CL4,1)*24 | CO4: 1 | CP4: 0.35 | CQ4: 0.74236111 | CR4: =MOD(CQ4-CP4,1)*24 | CS4: 1 | CT4: 0.34930556 | CU4: 0.73888889 | CV4: =MOD(CU4-CT4,1)*24 | CW4: 1 | CX4: 0.35208333 | CY4: 0.74027778 | CZ4: =MOD(CY4-CX4,1)*24 | DA4: 1 | DF4: 0.34930556 | DG4: 0.73958333 | DH4: =MOD(DG4-DF4,1)*24 | DI4: 1 | DJ4: 0.35138889 | DK4: 0.73819444 | DL4: =MOD(DK4-DJ4,1)*24 | DM4: 1 | DN4: 0.35069444 | DO4: 0.73819444 | DP4: =MOD(DO4-DN4,1)*24 | DQ4: 1 | DR4: 0.34930556 | DS4: 0.74236111 | DT4: =MOD(DS4-DR4,1)*24 | DU4: 1 | DV4: =SUM(H4,L4,P4,T4,X4,AB4,AF4,AJ4,AN4,AR4,AV4,AZ4,BD4,BH4,BL4,BP4,BT4,BX4,CB4,CF4,CJ4,CN4,CR4,CV4,CZ4,DD4,DH4,DL4,DP4,DT4) | DW4: =SUM(I4,M4,Q4,U4,Y4,AC4,AG4,AK4,AO4,AS4,AW4,BA4,BE4,BI4,BM4,BQ4,BU4,BY4,CC4,CG4,CK4,CO4,CS4,CW4,DA4,DE4,DI4,DM4,DQ4,DU4)
A5: 五楼 | B5: 黄晓云 | C5: 6 | F5: 0.35347222 | G5: 0.73611111 | H5: =MOD(G5-F5,1)*24 | I5: 1 | J5: 0.35138889 | K5: 0.73611111 | L5: =MOD(K5-J5,1)*24 | M5: 1 | N5: 0.35277778 | O5: 0.73680556 | P5: =MOD(O5-N5,1)*24 | Q5: 1 | AD5: 0.35277778 | AE5: 0.74305556 | AF5: =MOD(AE5-AD5,1)*24 | AG5: 1 | AH5: 0.35416667 | AI5: 0.7375 | AJ5: =MOD(AI5-AH5,1)*24 | AK5: 1 | AL5: 0.35277778 | AM5: 0.73611111 | AN5: =MOD(AM5-AL5,1)*24 | AO5: 1 | AP5: 0.35277778 | AQ5: 0.7375 | AR5: =MOD(AQ5-AP5,1)*24 | AS5: 1 | AT5: 0.35277778 | AU5: 0.74236111 | AV5: =MOD(AU5-AT5,1)*24 | AW5: 1 | AX5: 0.35416667 | AY5: 0.73680556 | AZ5: =MOD(AY5-AX5,1)*24 | BA5: 1 | BB5: 0.35208333 | BC5: 0.73611111 | BD5: =MOD(BC5-BB5,1)*24 | BE5: 1 | BF5: 0.35138889 | BG5: 0.73680556 | BH5: =MOD(BG5-BF5,1)*24 | BI5: 1 | BJ5: 0.35277778 | BK5: 0.73680556 | BL5: =MOD(BK5-BJ5,1)*24 | BM5: 1 | BN5: 0.35208333 | BO5: 0.74444444 | BP5: =MOD(BO5-BN5,1)*24 | BQ5: 1 | BR5: 0.35138889 | BS5: 0.73611111 | BT5: =MOD(BS5-BR5,1)*24 | BU5: 1 | BV5: 0.34375 | BW5: 0.76597222 | BX5: =MOD(BW5-BV5,1)*24 | BY5: 0.5 | CH5: 0.35138889 | CI5: 0.73888889 | CJ5: =MOD(CI5-CH5,1)*24 | CK5: 1 | CL5: 0.35416667 | CM5: 0.7375 | CN5: =MOD(CM5-CL5,1)*24 | CO5: 1 | CP5: 0.27847222 | CQ5: 0.34305556 | CR5: =MOD(CQ5-CP5,1)*24 | CS5: 0.5 | CT5: 0.35347222 | CU5: 0.74166667 | CV5: =MOD(CU5-CT5,1)*24 | CW5: 1 | CX5: 0.35347222 | CY5: 0.73680556 | CZ5: =MOD(CY5-CX5,1)*24 | DA5: 1 | DB5: 0.35416667 | DC5: 0.73680556 | DD5: =MOD(DC5-DB5,1)*24 | DE5: 1 | DF5: 0.35277778 | DG5: 0.74305556 | DH5: =MOD(DG5-DF5,1)*24 | DI5: 1 | DJ5: 0.35555556 | DM5: 0.5 | DN5: 0.35416667 | DO5: 0.74166667 | DP5: =MOD(DO5-DN5,1)*24 | DQ5: 1 | DR5: 0.33958333 | DU5: 0.5 | DV5: =SUM(H5,L5,P5,T5,X5,AB5,AF5,AJ5,AN5,AR5,AV5,AZ5,BD5,BH5,BL5,BP5,BT5,BX5,CB5,CF5,CJ5,CN5,CR5,CV5,CZ5,DD5,DH5,DL5,DP5,DT5) | DW5: =SUM(I5,M5,Q5,U5,Y5,AC5,AG5,AK5,AO5,AS5,AW5,BA5,BE5,BI5,BM5,BQ5,BU5,BY5,CC5,CG5,CK5,CO5,CS5,CW5,DA5,DE5,DI5,DM5,DQ5,DU5) | EX5: 早退 | FC5: 只打一次卡 | FE5: 只打一次卡
A6: 五楼 | B6: 黄晓云 | C6: 6 | BV6: 0.76875 | BY6: 0.5 | DV6: =SUM(H6,L6,P6,T6,X6,AB6,AF6,AJ6,AN6,AR6,AV6,AZ6,BD6,BH6,BL6,BP6,BT6,BX6,CB6,CF6,CJ6,CN6,CR6,CV6,CZ6,DD6,DH6,DL6,DP6,DT6) | DW6: =SUM(I6,M6,Q6,U6,Y6,AC6,AG6,AK6,AO6,AS6,AW6,BA6,BE6,BI6,BM6,BQ6,BU6,BY6,CC6,CG6,CK6,CO6,CS6,CW6,DA6,DE6,DI6,DM6,DQ6,DU6)
A7: 五楼 | B7: 陈小红 | C7: 7 | F7: 0.35 | G7: 0.74236111 | H7: =MOD(G7-F7,1)*24 | I7: 1 | J7: 0.35 | K7: 0.74791667 | L7: =MOD(K7-J7,1)*24 | M7: 1 | N7: 0.35138889 | O7: 0.81944444 | P7: =MOD(O7-N7,1)*24 | Q7: 1 | R7: 0.34861111 | S7: 0.73611111 | T7: =MOD(S7-R7,1)*24 | U7: 1 | Z7: 0.35486111 | AA7: 0.74027778 | AB7: =MOD(AA7-Z7,1)*24 | AC7: 1 | AD7: 0.34305556 | AE7: 0.74027778 | AF7: =MOD(AE7-AD7,1)*24 | AG7: 1 | AH7: 0.34305556 | AI7: 0.73611111 | AJ7: =MOD(AI7-AH7,1)*24 | AK7: 1 | AL7: 0.34166667 | AM7: 0.74236111 | AN7: =MOD(AM7-AL7,1)*24 | AO7: 1 | AP7: 0.35277778 | AQ7: 0.74444444 | AR7: =MOD(AQ7-AP7,1)*24 | AS7: 1 | AT7: 0.35555556 | AU7: 0.74930556 | AV7: =MOD(AU7-AT7,1)*24 | AW7: 1 | BB7: 0.35069444 | BC7: 0.74930556 | BD7: =MOD(BC7-BB7,1)*24 | BE7: 1 | BF7: 0.34305556 | BG7: 0.74166667 | BH7: =MOD(BG7-BF7,1)*24 | BI7: 1 | BJ7: 0.35069444 | BK7: 0.74305556 | BL7: =MOD(BK7-BJ7,1)*24 | BM7: 1 | BN7: 0.35069444 | BO7: 0.74513889 | BP7: =MOD(BO7-BN7,1)*24 | BQ7: 1 | BR7: 0.35069444 | BS7: 0.74305556 | BT7: =MOD(BS7-BR7,1)*24 | BU7: 1 | BV7: 0.35625 | BW7: 0.74513889 | BX7: =MOD(BW7-BV7,1)*24 | BY7: 1 | CD7: 0.35208333 | CE7: 0.74791667 | CF7: =MOD(CE7-CD7,1)*24 | CG7: 1 | CH7: 0.34236111 | CI7: 0.82916667 | CJ7: =MOD(CI7-CH7,1)*24 | CK7: 1 | CL7: 0.34375 | CM7: 0.78263889 | CN7: =MOD(CM7-CL7,1)*24 | CO7: 1 | CP7: 0.33888889 | CQ7: 0.76319444 | CR7: =MOD(CQ7-CP7,1)*24 | CS7: 0.5 | CT7: 0.35069444 | CU7: 0.74722222 | CV7: =MOD(CU7-CT7,1)*24 | CW7: 1 | CX7: 0.33958333 | CY7: 0.77013889 | CZ7: =MOD(CY7-CX7,1)*24 | DA7: 1 | DB7: 0.35069444 | DC7: 0.7375 | DD7: =MOD(DC7-DB7,1)*24 | DE7: 1 | DF7: 0.33819444 | DG7: 0.78888889 | DH7: =MOD(DG7-DF7,1)*24 | DI7: 1 | DJ7: 0.34305556 | DK7: 0.85902778 | DL7: =MOD(DK7-DJ7,1)*24 | DM7: 1 | DN7: 0.33611111 | DO7: 0.88611111 | DP7: =MOD(DO7-DN7,1)*24 | DQ7: 1 | DR7: 0.33958333 | DS7: 0.78958333 | DT7: =MOD(DS7-DR7,1)*24 | DU7: 1 | DV7: =SUM(H7,L7,P7,T7,X7,AB7,AF7,AJ7,AN7,AR7,AV7,AZ7,BD7,BH7,BL7,BP7,BT7,BX7,CB7,CF7,CJ7,CN7,CR7,CV7,CZ7,DD7,DH7,DL7,DP7,DT7) | DW7: =SUM(I7,M7,Q7,U7,Y7,AC7,AG7,AK7,AO7,AS7,AW7,BA7,BE7,BI7,BM7,BQ7,BU7,BY7,CC7,CG7,CK7,CO7,CS7,CW7,DA7,DE7,DI7,DM7,DQ7,DU7) | EG7: 迟到 | EL7: 迟到 | ES7: 迟到
A8: 五楼 | B8: 陈小红 | C8: 7 | CP8: 0.81805556 | CS8: 0.5 | DV8: =SUM(H8,L8,P8,T8,X8,AB8,AF8,AJ8,AN8,AR8,AV8,AZ8,BD8,BH8,BL8,BP8,BT8,BX8,CB8,CF8,CJ8,CN8,CR8,CV8,CZ8,DD8,DH8,DL8,DP8,DT8) | DW8: =SUM(I8,M8,Q8,U8,Y8,AC8,AG8,AK8,AO8,AS8,AW8,BA8,BE8,BI8,BM8,BQ8,BU8,BY8,CC8,CG8,CK8,CO8,CS8,CW8,DA8,DE8,DI8,DM8,DQ8,DU8)
A9: 五楼 | B9: 胡娅 | C9: 9 | J9: 0.34583333 | K9: 0.7375 | L9: =MOD(K9-J9,1)*24 | M9: 1 | N9: 0.34791667 | O9: 0.73888889 | P9: =MOD(O9-N9,1)*24 | Q9: 1 | R9: 0.34027778 | S9: 0.73611111 | T9: =MOD(S9-R9,1)*24 | U9: 1 | Z9: 0.34513889 | AA9: 0.73611111 | AB9: =MOD(AA9-Z9,1)*24 | AC9: 1 | AD9: 0.34513889 | AE9: 0.73611111 | AF9: =MOD(AE9-AD9,1)*24 | AG9: 1 | AH9: 0.34652778 | AI9: 0.73680556 | AJ9: =MOD(AI9-AH9,1)*24 | AK9: 1 | AL9: 0.73680556 | AO9: 0.5 | AP9: 0.34583333 | AS9: 0.5 | AT9: 0.34444444 | AU9: 0.73611111 | AV9: =MOD(AU9-AT9,1)*24 | AW9: 1 | BB9: 0.34583333 | BC9: 0.73611111 | BD9: =MOD(BC9-BB9,1)*24 | BE9: 1 | BF9: 0.34583333 | BG9: 0.73680556 | BH9: =MOD(BG9-BF9,1)*24 | BI9: 1 | BJ9: 0.34444444 | BK9: 0.73611111 | BL9: =MOD(BK9-BJ9,1)*24 | BM9: 1 | BN9: 0.34791667 | BO9: 0.73680556 | BP9: =MOD(BO9-BN9,1)*24 | BQ9: 1 | BR9: 0.34652778 | BS9: 0.73611111 | BT9: =MOD(BS9-BR9,1)*24 | BU9: 1 | BV9: 0.34583333 | BW9: 0.7375 | BX9: =MOD(BW9-BV9,1)*24 | BY9: 1 | CD9: 0.34652778 | CE9: 0.73680556 | CF9: =MOD(CE9-CD9,1)*24 | CG9: 1 | CH9: 0.34791667 | CI9: 0.73680556 | CJ9: =MOD(CI9-CH9,1)*24 | CK9: 1 | CL9: 0.34166667 | CM9: 0.7375 | CN9: =MOD(CM9-CL9,1)*24 | CO9: 1 | CP9: 0.27847222 | CQ9: 0.33819444 | CR9: =MOD(CQ9-CP9,1)*24 | CS9: 0.5 | CT9: 0.3375 | CU9: 0.7375 | CV9: =MOD(CU9-CT9,1)*24 | CW9: 1 | CX9: 0.34375 | CY9: 0.73680556 | CZ9: =MOD(CY9-CX9,1)*24 | DA9: 1 | DF9: 0.34791667 | DG9: 0.73680556 | DH9: =MOD(DG9-DF9,1)*24 | DI9: 1 | DJ9: 0.35138889 | DK9: 0.73819444 | DL9: =MOD(DK9-DJ9,1)*24 | DM9: 1 | DN9: 0.34375 | DO9: 0.73611111 | DP9: =MOD(DO9-DN9,1)*24 | DQ9: 1 | DR9: 0.34652778 | DS9: 0.74166667 | DT9: =MOD(DS9-DR9,1)*24 | DU9: 1 | DV9: =SUM(H9,L9,P9,T9,X9,AB9,AF9,AJ9,AN9,AR9,AV9,AZ9,BD9,BH9,BL9,BP9,BT9,BX9,CB9,CF9,CJ9,CN9,CR9,CV9,CZ9,DD9,DH9,DL9,DP9,DT9) | DW9: =SUM(I9,M9,Q9,U9,Y9,AC9,AG9,AK9,AO9,AS9,AW9,BA9,BE9,BI9,BM9,BQ9,BU9,BY9,CC9,CG9,CK9,CO9,CS9,CW9,DA9,DE9,DI9,DM9,DQ9,DU9) | EJ9: 只打一次卡 | EK9: 只打一次卡 | EX9: 早退
A10: 五楼 | B10: 杨青青 | C10: 10 | F10: 0.34097222 | G10: 0.7375 | H10: =MOD(G10-F10,1)*24 | I10: 1 | J10: 0.33611111 | K10: 0.74791667 | L10: =MOD(K10-J10,1)*24 | M10: 1 | N10: 0.34097222 | O10: 0.73888889 | P10: =MOD(O10-N10,1)*24 | Q10: 1 | Z10: 0.32847222 | AA10: 0.7375 | AB10: =MOD(AA10-Z10,1)*24 | AC10: 1 | AH10: 0.35069444 | AI10: 0.74027778 | AJ10: =MOD(AI10-AH10,1)*24 | AK10: 1 | AL10: 0.34930556 | AM10: 0.73680556 | AN10: =MOD(AM10-AL10,1)*24 | AO10: 1 | AP10: 0.35138889 | AQ10: 0.73958333 | AR10: =MOD(AQ10-AP10,1)*24 | AS10: 1 | AT10: 0.34861111 | AU10: 0.73888889 | AV10: =MOD(AU10-AT10,1)*24 | AW10: 1 | AX10: 0.35208333 | AY10: 0.73680556 | AZ10: =MOD(AY10-AX10,1)*24 | BA10: 1 | BB10: 0.34791667 | BC10: 0.73888889 | BD10: =MOD(BC10-BB10,1)*24 | BE10: 1 | BF10: 0.35 | BG10: 0.74027778 | BH10: =MOD(BG10-BF10,1)*24 | BI10: 1 | BJ10: 0.35069444 | BK10: 0.73958333 | BL10: =MOD(BK10-BJ10,1)*24 | BM10: 1 | BN10: 0.35069444 | BO10: 0.73958333 | BP10: =MOD(BO10-BN10,1)*24 | BQ10: 1 | BR10: 0.35347222 | BS10: 0.73888889 | BT10: =MOD(BS10-BR10,1)*24 | BU10: 1 | BV10: 0.35069444 | BW10: 0.73888889 | BX10: =MOD(BW10-BV10,1)*24 | BY10: 1 | CD10: 0.35277778 | CE10: 0.74097222 | CF10: =MOD(CE10-CD10,1)*24 | CG10: 1 | CH10: 0.35138889 | CI10: 0.7375 | CJ10: =MOD(CI10-CH10,1)*24 | CK10: 1 | CL10: 0.35486111 | CM10: 0.73680556 | CN10: =MOD(CM10-CL10,1)*24 | CO10: 1 | CP10: 0.34722222 | CQ10: 0.74236111 | CR10: =MOD(CQ10-CP10,1)*24 | CS10: 1 | CT10: 0.35347222 | CU10: 0.7375 | CV10: =MOD(CU10-CT10,1)*24 | CW10: 1 | DB10: 0.35277778 | DC10: 0.73611111 | DD10: =MOD(DC10-DB10,1)*24 | DE10: 1 | DF10: 0.34444444 | DG10: 0.74166667 | DH10: =MOD(DG10-DF10,1)*24 | DI10: 1 | DJ10: 0.34861111 | DK10: 0.73819444 | DL10: =MOD(DK10-DJ10,1)*24 | DM10: 1 | DN10: 0.34791667 | DO10: 0.73680556 | DP10: =MOD(DO10-DN10,1)*24 | DQ10: 1 | DR10: 0.34722222 | DS10: 0.74027778 | DT10: =MOD(DS10-DR10,1)*24 | DU10: 1 | DV10: =SUM(H10,L10,P10,T10,X10,AB10,AF10,AJ10,AN10,AR10,AV10,AZ10,BD10,BH10,BL10,BP10,BT10,BX10,CB10,CF10,CJ10,CN10,CR10,CV10,CZ10,DD10,DH10,DL10,DP10,DT10) | DW10: =SUM(I10,M10,Q10,U10,Y10,AC10,AG10,AK10,AO10,AS10,AW10,BA10,BE10,BI10,BM10,BQ10,BU10,BY10,CC10,CG10,CK10,CO10,CS10,CW10,DA10,DE10,DI10,DM10,DQ10,DU10) | EW10: 迟到
A11: 五楼 | B11: 向锋 | C11: 12 | F11: 0.35138889 | G11: 0.75 | H11: =MOD(G11-F11,1)*24 | I11: 1 | J11: 0.35069444 | K11: 0.74027778 | L11: =MOD(K11-J11,1)*24 | M11: 1 | N11: 0.35 | O11: 0.83125 | P11: =MOD(O11-N11,1)*24 | Q11: 1 | R11: 0.34930556 | S11: 0.7375 | T11: =MOD(S11-R11,1)*24 | U11: 1 | Z11: 0.97222222 | AC11: 0.5 | AD11: 0.35208333 | AE11: 0.77291667 | AF11: =MOD(AE11-AD11,1)*24 | AG11: 1 | AH11: 0.35138889 | AI11: 0.83263889 | AJ11: =MOD(AI11-AH11,1)*24 | AK11: 1 | AL11: 0.35069444 | AM11: 0.76319444 | AN11: =MOD(AM11-AL11,1)*24 | AO11: 1 | AP11: 0.35 | AQ11: 0.80763889 | AR11: =MOD(AQ11-AP11,1)*24 | AS11: 1 | AT11: 0.35 | AU11: 0.75138889 | AV11: =MOD(AU11-AT11,1)*24 | AW11: 1 | AX11: 0.26597222 | AY11: 0.79652778 | AZ11: =MOD(AY11-AX11,1)*24 | BA11: 1 | BB11: 0.35138889 | BC11: 0.73888889 | BD11: =MOD(BC11-BB11,1)*24 | BE11: 1 | BJ11: 0.34583333 | BK11: 0.74930556 | BL11: =MOD(BK11-BJ11,1)*24 | BM11: 1 | CD11: 0.35069444 | CE11: 0.76666667 | CF11: =MOD(CE11-CD11,1)*24 | CG11: 1 | CH11: 0.35208333 | CI11: 0.74791667 | CJ11: =MOD(CI11-CH11,1)*24 | CK11: 1 | CL11: 0.83541667 | CO11: 0.5 | CP11: 0.35 | CQ11: 0.85625 | CR11: =MOD(CQ11-CP11,1)*24 | CS11: 1 | CT11: 0.35069444 | CU11: 0.88541667 | CV11: =MOD(CU11-CT11,1)*24 | CW11: 1 | CX11: 0.35 | CY11: 0.74097222 | CZ11: =MOD(CY11-CX11,1)*24 | DA11: 1 | DF11: 0.34722222 | DG11: 0.84027778 | DH11: =MOD(DG11-DF11,1)*24 | DI11: 1 | DJ11: 0.35138889 | DK11: 0.77083333 | DL11: =MOD(DK11-DJ11,1)*24 | DM11: 1 | DN11: 0.35208333 | DO11: 0.84930556 | DP11: =MOD(DO11-DN11,1)*24 | DQ11: 1 | DR11: 0.35 | DS11: 0.75347222 | DT11: =MOD(DS11-DR11,1)*24 | DU11: 1 | DV11: =SUM(H11,L11,P11,T11,X11,AB11,AF11,AJ11,AN11,AR11,AV11,AZ11,BD11,BH11,BL11,BP11,BT11,BX11,CB11,CF11,CJ11,CN11,CR11,CV11,CZ11,DD11,DH11,DL11,DP11,DT11) | DW11: =SUM(I11,M11,Q11,U11,Y11,AC11,AG11,AK11,AO11,AS11,AW11,BA11,BE11,BI11,BM11,BQ11,BU11,BY11,CC11,CG11,CK11,CO11,CS11,CW11,DA11,DE11,DI11,DM11,DQ11,DU11) | EG11: 只打一次卡 | EW11: 只打一次卡
A12: 五楼 | B12: 雷松儒 | C12: 13 | F12: 0.36527778 | G12: 0.75069444 | H12: =MOD(G12-F12,1)*24 | I12: 1 | J12: 0.34375 | K12: 0.81180556 | L12: =MOD(K12-J12,1)*24 | M12: 1 | N12: 0.34375 | O12: 0.74861111 | P12: =MOD(O12-N12,1)*24 | Q12: 1 | R12: 0.34513889 | S12: 0.7375 | T12: =MOD(S12-R12,1)*24 | U12: 1 | Z12: 0.85 | AC12: 0.5 | AD12: 0.35208333 | AE12: 0.77430556 | AF12: =MOD(AE12-AD12,1)*24 | AG12: 1 | AH12: 0.35138889 | AI12: 0.75347222 | AJ12: =MOD(AI12-AH12,1)*24 | AK12: 1 | AL12: 0.34444444 | AM12: 0.82361111 | AN12: =MOD(AM12-AL12,1)*24 | AO12: 1 | AP12: 0.34652778 | AQ12: 0.79027778 | AR12: =MOD(AQ12-AP12,1)*24 | AS12: 1 | AT12: 0.34791667 | AW12: 0.5 | AX12: 0.79791667 | BA12: 0.5 | BB12: 0.34513889 | BC12: 0.74652778 | BD12: =MOD(BC12-BB12,1)*24 | BE12: 1 | BF12: 0.35 | BG12: 0.78958333 | BH12: =MOD(BG12-BF12,1)*24 | BI12: 1 | BJ12: 0.34166667 | BK12: 0.75833333 | BL12: =MOD(BK12-BJ12,1)*24 | BM12: 1 | BN12: 0.34583333 | BO12: 0.74444444 | BP12: =MOD(BO12-BN12,1)*24 | BQ12: 1 | BR12: 0.34444444 | BS12: 0.74791667 | BT12: =MOD(BS12-BR12,1)*24 | BU12: 1 | BV12: 0.34305556 | BW12: 0.74444444 | BX12: =MOD(BW12-BV12,1)*24 | BY12: 1 | BZ12: 0.34652778 | CA12: 0.84027778 | CB12: =MOD(CA12-BZ12,1)*24 | CC12: 1 | CD12: 0.35069444 | CE12: 0.74027778 | CF12: =MOD(CE12-CD12,1)*24 | CG12: 1 | CH12: 0.34652778 | CI12: 0.74791667 | CJ12: =MOD(CI12-CH12,1)*24 | CK12: 1 | CL12: 0.33819444 | CM12: 0.74930556 | CN12: =MOD(CM12-CL12,1)*24 | CO12: 1 | CP12: 0.34791667 | CQ12: 0.77013889 | CR12: =MOD(CQ12-CP12,1)*24 | CS12: 1 | CT12: 0.34652778 | CU12: 0.82291667 | CV12: =MOD(CU12-CT12,1)*24 | CW12: 1 | CX12: 0.34236111 | CY12: 0.73680556 | CZ12: =MOD(CY12-CX12,1)*24 | DA12: 1 | DF12: 0.82152778 | DI12: 0.5 | DJ12: 0.35555556 | DK12: 0.80138889 | DL12: =MOD(DK12-DJ12,1)*24 | DM12: 1 | DN12: 0.34236111 | DO12: 0.77361111 | DP12: =MOD(DO12-DN12,1)*24 | DQ12: 1 | DR12: 0.34583333 | DS12: 0.75069444 | DT12: =MOD(DS12-DR12,1)*24 | DU12: 1 | DV12: =SUM(H12,L12,P12,T12,X12,AB12,AF12,AJ12,AN12,AR12,AV12,AZ12,BD12,BH12,BL12,BP12,BT12,BX12,CB12,CF12,CJ12,CN12,CR12,CV12,CZ12,DD12,DH12,DL12,DP12,DT12) | DW12: =SUM(I12,M12,Q12,U12,Y12,AC12,AG12,AK12,AO12,AS12,AW12,BA12,BE12,BI12,BM12,BQ12,BU12,BY12,CC12,CG12,CK12,CO12,CS12,CW12,DA12,DE12,DI12,DM12,DQ12,DU12) | EB12: 迟到 | EG12: 只打一次卡 | EL12: 只打一次卡 | EM12: 只打一次卡 | FB12: 只打一次卡 | FC12: 迟到
A13: 五楼 | B13: 杨首琴 | C13: 14 | F13: 0.35347222 | G13: 0.75902778 | H13: =MOD(G13-F13,1)*24 | I13: 1 | J13: 0.34791667 | K13: 0.7625 | L13: =MOD(K13-J13,1)*24 | M13: 1 | N13: 0.35138889 | O13: 0.74652778 | P13: =MOD(O13-N13,1)*24 | Q13: 1 | Z13: 0.35069444 | AA13: 0.74166667 | AB13: =MOD(AA13-Z13,1)*24 | AC13: 1 | AD13: 0.35208333 | AE13: 0.73958333 | AF13: =MOD(AE13-AD13,1)*24 | AG13: 1 | AH13: 0.35138889 | AI13: 0.74791667 | AJ13: =MOD(AI13-AH13,1)*24 | AK13: 1 | AL13: 0.35138889 | AM13: 0.73888889 | AN13: =MOD(AM13-AL13,1)*24 | AO13: 1 | AP13: 0.35347222 | AQ13: 0.73888889 | AR13: =MOD(AQ13-AP13,1)*24 | AS13: 1 | AT13: 0.35069444 | AU13: 0.73958333 | AV13: =MOD(AU13-AT13,1)*24 | AW13: 1 | BB13: 0.35138889 | BC13: 0.73819444 | BD13: =MOD(BC13-BB13,1)*24 | BE13: 1 | BF13: 0.35347222 | BG13: 0.73680556 | BH13: =MOD(BG13-BF13,1)*24 | BI13: 1 | BJ13: 0.35069444 | BK13: 0.73958333 | BL13: =MOD(BK13-BJ13,1)*24 | BM13: 1 | BN13: 0.35069444 | BO13: 0.73611111 | BP13: =MOD(BO13-BN13,1)*24 | BQ13: 1 | BR13: 0.35069444 | BS13: 0.73888889 | BT13: =MOD(BS13-BR13,1)*24 | BU13: 1 | BV13: 0.34305556 | BW13: 0.74097222 | BX13: =MOD(BW13-BV13,1)*24 | BY13: 1 | CD13: 0.35208333 | CE13: 0.73958333 | CF13: =MOD(CE13-CD13,1)*24 | CG13: 0.5 | CH13: 0.35208333 | CI13: 0.74791667 | CJ13: =MOD(CI13-CH13,1)*24 | CK13: 0.5 | CL13: 0.35 | CM13: 0.74583333 | CN13: =MOD(CM13-CL13,1)*24 | CO13: 1 | CP13: 0.35138889 | CQ13: 0.74236111 | CR13: =MOD(CQ13-CP13,1)*24 | CS13: 1 | CT13: 0.35069444 | CU13: 0.74236111 | CV13: =MOD(CU13-CT13,1)*24 | CW13: 1 | CX13: 0.34444444 | CY13: 0.74027778 | CZ13: =MOD(CY13-CX13,1)*24 | DA13: 1 | DB13: 0.34930556 | DC13: 0.50069444 | DD13: =MOD(DC13-DB13,1)*24 | DE13: 0.5 | DF13: 0.34930556 | DG13: 0.74791667 | DH13: =MOD(DG13-DF13,1)*24 | DI13: 1 | DJ13: 0.35069444 | DK13: 0.76111111 | DL13: =MOD(DK13-DJ13,1)*24 | DM13: 0.5 | DN13: 0.54305556 | DO13: 0.74166667 | DP13: =MOD(DO13-DN13,1)*24 | DQ13: 0.5 | DR13: 0.34583333 | DS13: 0.74652778 | DT13: =MOD(DS13-DR13,1)*24 | DU13: 0.5 | DV13: =SUM(H13,L13,P13,T13,X13,AB13,AF13,AJ13,AN13,AR13,AV13,AZ13,BD13,BH13,BL13,BP13,BT13,BX13,CB13,CF13,CJ13,CN13,CR13,CV13,CZ13,DD13,DH13,DL13,DP13,DT13) | DW13: =SUM(I13,M13,Q13,U13,Y13,AC13,AG13,AK13,AO13,AS13,AW13,BA13,BE13,BI13,BM13,BQ13,BU13,BY13,CC13,CG13,CK13,CO13,CS13,CW13,DA13,DE13,DI13,DM13,DQ13,DU13) | FA13: 早退 | FD13: 迟到
A14: 五楼 | B14: 杨首琴 | C14: 14 | CD14: 0.74027778 | CG14: 0.5 | CH14: 0.74930556 | CK14: 0.5 | DJ14: 0.76319444 | DM14: 0.5 | DR14: 0.74791667 | DU14: 0.5 | DV14: =SUM(H14,L14,P14,T14,X14,AB14,AF14,AJ14,AN14,AR14,AV14,AZ14,BD14,BH14,BL14,BP14,BT14,BX14,CB14,CF14,CJ14,CN14,CR14,CV14,CZ14,DD14,DH14,DL14,DP14,DT14) | DW14: =SUM(I14,M14,Q14,U14,Y14,AC14,AG14,AK14,AO14,AS14,AW14,BA14,BE14,BI14,BM14,BQ14,BU14,BY14,CC14,CG14,CK14,CO14,CS14,CW14,DA14,DE14,DI14,DM14,DQ14,DU14)
A15: 五楼 | B15: 王晓兰 | C15: 15 | F15: 0.35138889 | G15: 0.74027778 | H15: =MOD(G15-F15,1)*24 | I15: 1 | J15: 0.35069444 | K15: 0.7375 | L15: =MOD(K15-J15,1)*24 | M15: 1 | R15: 0.34930556 | S15: 0.74097222 | T15: =MOD(S15-R15,1)*24 | U15: 1 | Z15: 0.35277778 | AA15: 0.74027778 | AB15: =MOD(AA15-Z15,1)*24 | AC15: 1 | AD15: 0.34652778 | AE15: 0.73958333 | AF15: =MOD(AE15-AD15,1)*24 | AG15: 1 | AH15: 0.34236111 | AI15: 0.74236111 | AJ15: =MOD(AI15-AH15,1)*24 | AK15: 1 | AL15: 0.34791667 | AM15: 0.73958333 | AN15: =MOD(AM15-AL15,1)*24 | AO15: 1 | AP15: 0.33680556 | AQ15: 0.73888889 | AR15: =MOD(AQ15-AP15,1)*24 | AS15: 1 | AT15: 0.35208333 | AU15: 0.7375 | AV15: =MOD(AU15-AT15,1)*24 | AW15: 1 | BB15: 0.34791667 | BC15: 0.73819444 | BD15: =MOD(BC15-BB15,1)*24 | BE15: 1 | BF15: 0.34166667 | BG15: 0.73680556 | BH15: =MOD(BG15-BF15,1)*24 | BI15: 1 | BJ15: 0.34861111 | BK15: 0.73958333 | BL15: =MOD(BK15-BJ15,1)*24 | BM15: 1 | BN15: 0.34513889 | BO15: 0.73888889 | BP15: =MOD(BO15-BN15,1)*24 | BQ15: 1 | BR15: 0.34513889 | BS15: 0.73819444 | BT15: =MOD(BS15-BR15,1)*24 | BU15: 1 | BV15: 0.35 | BW15: 0.73888889 | BX15: =MOD(BW15-BV15,1)*24 | BY15: 1 | CD15: 0.34444444 | CE15: 0.74027778 | CF15: =MOD(CE15-CD15,1)*24 | CG15: 1 | CH15: 0.35 | CI15: 0.74444444 | CJ15: =MOD(CI15-CH15,1)*24 | CK15: 1 | CL15: 0.33680556 | CM15: 0.73888889 | CN15: =MOD(CM15-CL15,1)*24 | CO15: 1 | CP15: 0.33958333 | CQ15: 0.74027778 | CR15: =MOD(CQ15-CP15,1)*24 | CS15: 1 | CT15: 0.35138889 | CU15: 0.74027778 | CV15: =MOD(CU15-CT15,1)*24 | CW15: 1 | CX15: 0.54513889 | CY15: 0.73888889 | CZ15: =MOD(CY15-CX15,1)*24 | DA15: 0.5 | DB15: 0.35069444 | DC15: 0.53333333 | DD15: =MOD(DC15-DB15,1)*24 | DE15: 0.5 | DF15: 0.34166667 | DG15: 0.74305556 | DH15: =MOD(DG15-DF15,1)*24 | DI15: 1 | DJ15: 0.35277778 | DK15: 0.73819444 | DL15: =MOD(DK15-DJ15,1)*24 | DM15: 1 | DN15: 0.34236111 | DO15: 0.73680556 | DP15: =MOD(DO15-DN15,1)*24 | DQ15: 1 | DR15: 0.33819444 | DS15: 0.73819444 | DT15: =MOD(DS15-DR15,1)*24 | DU15: 1 | DV15: =SUM(H15,L15,P15,T15,X15,AB15,AF15,AJ15,AN15,AR15,AV15,AZ15,BD15,BH15,BL15,BP15,BT15,BX15,CB15,CF15,CJ15,CN15,CR15,CV15,CZ15,DD15,DH15,DL15,DP15,DT15) | DW15: =SUM(I15,M15,Q15,U15,Y15,AC15,AG15,AK15,AO15,AS15,AW15,BA15,BE15,BI15,BM15,BQ15,BU15,BY15,CC15,CG15,CK15,CO15,CS15,CW15,DA15,DE15,DI15,DM15,DQ15,DU15) | EZ15: 迟到 | FA15: 早退
A16: 五楼 | B16: 杨益琴 | C16: 16 | F16: 0.34513889 | G16: 0.73680556 | H16: =MOD(G16-F16,1)*24 | I16: 1 | J16: 0.35 | K16: 0.73680556 | L16: =MOD(K16-J16,1)*24 | M16: 1 | N16: 0.34652778 | O16: 0.7375 | P16: =MOD(O16-N16,1)*24 | Q16: 1 | Z16: 0.34652778 | AA16: 0.73680556 | AB16: =MOD(AA16-Z16,1)*24 | AC16: 1 | AD16: 0.34861111 | AE16: 0.7375 | AF16: =MOD(AE16-AD16,1)*24 | AG16: 1 | AH16: 0.34652778 | AI16: 0.7375 | AJ16: =MOD(AI16-AH16,1)*24 | AK16: 1 | AL16: 0.34305556 | AM16: 0.7375 | AN16: =MOD(AM16-AL16,1)*24 | AO16: 1 | AP16: 0.34236111 | AQ16: 0.7375 | AR16: =MOD(AQ16-AP16,1)*24 | AS16: 1 | AX16: 0.34722222 | AY16: 0.73680556 | AZ16: =MOD(AY16-AX16,1)*24 | BA16: 1 | BB16: 0.34722222 | BC16: 0.7375 | BD16: =MOD(BC16-BB16,1)*24 | BE16: 1 | BF16: 0.35 | BG16: 0.7375 | BH16: =MOD(BG16-BF16,1)*24 | BI16: 1 | BJ16: 0.34791667 | BK16: 0.7375 | BL16: =MOD(BK16-BJ16,1)*24 | BM16: 1 | BN16: 0.34930556 | BO16: 0.7375 | BP16: =MOD(BO16-BN16,1)*24 | BQ16: 1 | BR16: 0.34166667 | BS16: 0.73888889 | BT16: =MOD(BS16-BR16,1)*24 | BU16: 1 | BV16: 0.34305556 | BW16: 0.73819444 | BX16: =MOD(BW16-BV16,1)*24 | BY16: 1 | CD16: 0.34791667 | CE16: 0.7375 | CF16: =MOD(CE16-CD16,1)*24 | CG16: 1 | CH16: 0.34930556 | CI16: 0.7375 | CJ16: =MOD(CI16-CH16,1)*24 | CK16: 1 | CL16: 0.34513889 | CM16: 0.7375 | CN16: =MOD(CM16-CL16,1)*24 | CO16: 1 | CP16: 0.27847222 | CQ16: 0.34791667 | CR16: =MOD(CQ16-CP16,1)*24 | CS16: 0.5 | CT16: 0.34375 | CU16: 0.73680556 | CV16: =MOD(CU16-CT16,1)*24 | CW16: 1 | CX16: 0.35 | CY16: 0.73680556 | CZ16: =MOD(CY16-CX16,1)*24 | DA16: 1 | DB16: 0.35 | DC16: 0.73680556 | DD16: =MOD(DC16-DB16,1)*24 | DE16: 1 | DJ16: 0.34722222 | DK16: 0.81041667 | DL16: =MOD(DK16-DJ16,1)*24 | DM16: 1 | DN16: 0.34652778 | DO16: 0.73888889 | DP16: =MOD(DO16-DN16,1)*24 | DQ16: 1 | DR16: 0.34861111 | DS16: 0.96527778 | DT16: =MOD(DS16-DR16,1)*24 | DU16: 1 | DV16: =SUM(H16,L16,P16,T16,X16,AB16,AF16,AJ16,AN16,AR16,AV16,AZ16,BD16,BH16,BL16,BP16,BT16,BX16,CB16,CF16,CJ16,CN16,CR16,CV16,CZ16,DD16,DH16,DL16,DP16,DT16) | DW16: =SUM(I16,M16,Q16,U16,Y16,AC16,AG16,AK16,AO16,AS16,AW16,BA16,BE16,BI16,BM16,BQ16,BU16,BY16,CC16,CG16,CK16,CO16,CS16,CW16,DA16,DE16,DI16,DM16,DQ16,DU16) | EX16: 早退
A17: 五楼 | B17: 刘琴 | C17: 17 | F17: 0.35138889 | G17: 0.87569444 | H17: =MOD(G17-F17,1)*24 | I17: 1 | J17: 0.35138889 | K17: 0.80555556 | L17: =MOD(K17-J17,1)*24 | M17: 1 | N17: 0.35277778 | O17: 0.75555556 | P17: =MOD(O17-N17,1)*24 | Q17: 0.5 | R17: 0.34861111 | S17: 0.50277778 | T17: =MOD(S17-R17,1)*24 | U17: 0.5 | Z17: 0.35208333 | AA17: 0.74166667 | AB17: =MOD(AA17-Z17,1)*24 | AC17: 1 | AD17: 0.34930556 | AE17: 0.87569444 | AF17: =MOD(AE17-AD17,1)*24 | AG17: 1 | AH17: 0.35138889 | AI17: 0.75069444 | AJ17: =MOD(AI17-AH17,1)*24 | AK17: 1 | AL17: 0.35208333 | AM17: 0.76527778 | AN17: =MOD(AM17-AL17,1)*24 | AO17: 1 | AP17: 0.35069444 | AQ17: 0.79930556 | AR17: =MOD(AQ17-AP17,1)*24 | AS17: 1 | AT17: 0.35347222 | AU17: 0.75763889 | AV17: =MOD(AU17-AT17,1)*24 | AW17: 0.5 | BB17: 0.35277778 | BC17: 0.73819444 | BD17: =MOD(BC17-BB17,1)*24 | BE17: 1 | BF17: 0.35069444 | BG17: 0.82986111 | BH17: =MOD(BG17-BF17,1)*24 | BI17: 0.5 | BJ17: 0.35069444 | BK17: 0.7375 | BL17: =MOD(BK17-BJ17,1)*24 | BM17: 1 | BR17: 0.74722222 | BU17: 0.5 | BV17: 0.34791667 | BW17: 0.74027778 | BX17: =MOD(BW17-BV17,1)*24 | BY17: 1 | CT17: 0.35 | CU17: 0.75 | CV17: =MOD(CU17-CT17,1)*24 | CW17: 1 | CX17: 0.35 | CY17: 0.75347222 | CZ17: =MOD(CY17-CX17,1)*24 | DA17: 1 | DF17: 0.34930556 | DG17: 0.76736111 | DH17: =MOD(DG17-DF17,1)*24 | DI17: 1 | DJ17: 0.34861111 | DK17: 0.75833333 | DL17: =MOD(DK17-DJ17,1)*24 | DM17: 1 | DN17: 0.35 | DO17: 0.77222222 | DP17: =MOD(DO17-DN17,1)*24 | DQ17: 1 | DR17: 0.34930556 | DS17: 0.76111111 | DT17: =MOD(DS17-DR17,1)*24 | DU17: 1 | DV17: =SUM(H17,L17,P17,T17,X17,AB17,AF17,AJ17,AN17,AR17,AV17,AZ17,BD17,BH17,BL17,BP17,BT17,BX17,CB17,CF17,CJ17,CN17,CR17,CV17,CZ17,DD17,DH17,DL17,DP17,DT17) | DW17: =SUM(I17,M17,Q17,U17,Y17,AC17,AG17,AK17,AO17,AS17,AW17,BA17,BE17,BI17,BM17,BQ17,BU17,BY17,CC17,CG17,CK17,CO17,CS17,CW17,DA17,DE17,DI17,DM17,DQ17,DU17) | EE17: 早退 | ER17: 只打一次卡
A18: 五楼 | B18: 刘琴 | C18: 17 | N18: 0.75694444 | Q18: 0.5 | AT18: 0.76319444 | AW18: 0.5 | BF18: 0.83402778 | BI18: 0.5 | DV18: =SUM(H18,L18,P18,T18,X18,AB18,AF18,AJ18,AN18,AR18,AV18,AZ18,BD18,BH18,BL18,BP18,BT18,BX18,CB18,CF18,CJ18,CN18,CR18,CV18,CZ18,DD18,DH18,DL18,DP18,DT18) | DW18: =SUM(I18,M18,Q18,U18,Y18,AC18,AG18,AK18,AO18,AS18,AW18,BA18,BE18,BI18,BM18,BQ18,BU18,BY18,CC18,CG18,CK18,CO18,CS18,CW18,DA18,DE18,DI18,DM18,DQ18,DU18)
A19: 五楼 | B19: 刘文旦 | C19: 18 | J19: 0.34652778 | K19: 0.81527778 | L19: =MOD(K19-J19,1)*24 | M19: 1 | N19: 0.35277778 | O19: 0.77847222 | P19: =MOD(O19-N19,1)*24 | Q19: 1 | R19: 0.35486111 | S19: 0.77777778 | T19: =MOD(S19-R19,1)*24 | U19: 1 | V19: 0.35069444 | Y19: 0.5 | Z19: 0.35208333 | AA19: 0.93680556 | AB19: =MOD(AA19-Z19,1)*24 | AC19: 1 | AD19: 0.35416667 | AE19: 0.77708333 | AF19: =MOD(AE19-AD19,1)*24 | AG19: 1 | AH19: 0.34305556 | AI19: 0.81041667 | AJ19: =MOD(AI19-AH19,1)*24 | AK19: 1 | AL19: 0.35625 | AM19: 0.81388889 | AN19: =MOD(AM19-AL19,1)*24 | AO19: 1 | AP19: 0.35486111 | AQ19: 0.82152778 | AR19: =MOD(AQ19-AP19,1)*24 | AS19: 1 | AT19: 0.79930556 | AW19: 0.5 | BJ19: 0.75069444 | BM19: 0.5 | BN19: 0.35347222 | BO19: 0.79583333 | BP19: =MOD(BO19-BN19,1)*24 | BQ19: 1 | BR19: 0.35486111 | BS19: 0.79166667 | BT19: =MOD(BS19-BR19,1)*24 | BU19: 1 | BV19: 0.775 | BY19: 0.5 | BZ19: 0.78680556 | CC19: 0.5 | CD19: 0.35902778 | CE19: 0.86666667 | CF19: =MOD(CE19-CD19,1)*24 | CG19: 1 | CH19: 0.80763889 | CK19: 0.5 | CL19: 0.34930556 | CM19: 0.80277778 | CN19: =MOD(CM19-CL19,1)*24 | CO19: 1 | CP19: 0.35277778 | CQ19: 0.80625 | CR19: =MOD(CQ19-CP19,1)*24 | CS19: 1 | CT19: 0.84166667 | CW19: 0.5 | CX19: 0.35069444 | CY19: 0.82083333 | CZ19: =MOD(CY19-CX19,1)*24 | DA19: 1 | DB19: 0.75 | DE19: 0.5 | DF19: 0.35069444 | DG19: 0.83263889 | DH19: =MOD(DG19-DF19,1)*24 | DI19: 1 | DJ19: 0.35694444 | DK19: 0.92222222 | DL19: =MOD(DK19-DJ19,1)*24 | DM19: 1 | DN19: 0.35347222 | DO19: 0.83055556 | DP19: =MOD(DO19-DN19,1)*24 | DQ19: 1 | DR19: 0.35555556 | DS19: 0.88263889 | DT19: =MOD(DS19-DR19,1)*24 | DU19: 1 | DV19: =SUM(H19,L19,P19,T19,X19,AB19,AF19,AJ19,AN19,AR19,AV19,AZ19,BD19,BH19,BL19,BP19,BT19,BX19,CB19,CF19,CJ19,CN19,CR19,CV19,CZ19,DD19,DH19,DL19,DP19,DT19) | DW19: =SUM(I19,M19,Q19,U19,Y19,AC19,AG19,AK19,AO19,AS19,AW19,BA19,BE19,BI19,BM19,BQ19,BU19,BY19,CC19,CG19,CK19,CO19,CS19,CW19,DA19,DE19,DI19,DM19,DQ19,DU19) | EE19: 迟到 | EF19: 只打一次卡 | EJ19: 迟到 | EK19: 迟到 | EL19: 只打一次卡 | EP19: 只打一次卡 | ER19: 迟到 | ES19: 只打一次卡 | ET19: 只打一次卡 | EU19: 迟到 | EV19: 只打一次卡 | EY19: 只打一次卡 | FA19: 只打一次卡 | FC19: 迟到 | FE19: 迟到
A20: 五楼 | B20: 王一程 | C20: 19 | F20: 0.35347222 | G20: 0.73819444 | H20: =MOD(G20-F20,1)*24 | I20: 1 | J20: 0.35277778 | K20: 0.74791667 | L20: =MOD(K20-J20,1)*24 | M20: 1 | N20: 0.34930556 | O20: 0.9125 | P20: =MOD(O20-N20,1)*24 | Q20: 1 | R20: 0.34861111 | S20: 0.73611111 | T20: =MOD(S20-R20,1)*24 | U20: 1 | Z20: 0.35069444 | AA20: 0.75486111 | AB20: =MOD(AA20-Z20,1)*24 | AC20: 1 | AD20: 0.35347222 | AE20: 0.75277778 | AF20: =MOD(AE20-AD20,1)*24 | AG20: 0.5 | AH20: 0.35 | AI20: 0.73819444 | AJ20: =MOD(AI20-AH20,1)*24 | AK20: 1 | AL20: 0.35208333 | AM20: 0.73680556 | AN20: =MOD(AM20-AL20,1)*24 | AO20: 1 | AT20: 0.34930556 | AU20: 0.7375 | AV20: =MOD(AU20-AT20,1)*24 | AW20: 1 | BB20: 0.35208333 | BC20: 0.7375 | BD20: =MOD(BC20-BB20,1)*24 | BE20: 1 | BF20: 0.35277778 | BG20: 0.7375 | BH20: =MOD(BG20-BF20,1)*24 | BI20: 1 | BJ20: 0.35069444 | BK20: 0.7375 | BL20: =MOD(BK20-BJ20,1)*24 | BM20: 1 | BN20: 0.35138889 | BO20: 0.73680556 | BP20: =MOD(BO20-BN20,1)*24 | BQ20: 1 | BR20: 0.35138889 | BS20: 0.73680556 | BT20: =MOD(BS20-BR20,1)*24 | BU20: 1 | BV20: 0.34652778 | BW20: 0.7375 | BX20: =MOD(BW20-BV20,1)*24 | BY20: 1 | CD20: 0.35277778 | CE20: 0.73819444 | CF20: =MOD(CE20-CD20,1)*24 | CG20: 1 | CH20: 0.34861111 | CI20: 0.7375 | CJ20: =MOD(CI20-CH20,1)*24 | CK20: 1 | CL20: 0.35208333 | CM20: 0.7375 | CN20: =MOD(CM20-CL20,1)*24 | CO20: 1 | CP20: 0.35138889 | CQ20: 0.74166667 | CR20: =MOD(CQ20-CP20,1)*24 | CS20: 1 | CT20: 0.34513889 | CU20: 0.73680556 | CV20: =MOD(CU20-CT20,1)*24 | CW20: 1 | CX20: 0.34791667 | CY20: 0.73680556 | CZ20: =MOD(CY20-CX20,1)*24 | DA20: 1 | DF20: 0.35 | DG20: 0.74375 | DH20: =MOD(DG20-DF20,1)*24 | DI20: 0.5 | DJ20: 0.34652778 | DK20: 0.73958333 | DL20: =MOD(DK20-DJ20,1)*24 | DM20: 1 | DN20: 0.34861111 | DO20: 0.88888889 | DP20: =MOD(DO20-DN20,1)*24 | DQ20: 1 | DR20: 0.35069444 | DS20: 0.73958333 | DT20: =MOD(DS20-DR20,1)*24 | DU20: 1 | DV20: =SUM(H20,L20,P20,T20,X20,AB20,AF20,AJ20,AN20,AR20,AV20,AZ20,BD20,BH20,BL20,BP20,BT20,BX20,CB20,CF20,CJ20,CN20,CR20,CV20,CZ20,DD20,DH20,DL20,DP20,DT20) | DW20: =SUM(I20,M20,Q20,U20,Y20,AC20,AG20,AK20,AO20,AS20,AW20,BA20,BE20,BI20,BM20,BQ20,BU20,BY20,CC20,CG20,CK20,CO20,CS20,CW20,DA20,DE20,DI20,DM20,DQ20,DU20)
A21: 五楼 | B21: 王一程 | C21: 19 | AD21: 0.75833333 | AG21: 0.5 | DF21: 0.81041667 | DI21: 0.5 | DV21: =SUM(H21,L21,P21,T21,X21,AB21,AF21,AJ21,AN21,AR21,AV21,AZ21,BD21,BH21,BL21,BP21,BT21,BX21,CB21,CF21,CJ21,CN21,CR21,CV21,CZ21,DD21,DH21,DL21,DP21,DT21) | DW21: =SUM(I21,M21,Q21,U21,Y21,AC21,AG21,AK21,AO21,AS21,AW21,BA21,BE21,BI21,BM21,BQ21,BU21,BY21,CC21,CG21,CK21,CO21,CS21,CW21,DA21,DE21,DI21,DM21,DQ21,DU21)
A22: 五楼 | B22: 段绍红 | C22: 20 | F22: 0.34513889 | G22: 0.73680556 | H22: =MOD(G22-F22,1)*24 | I22: 1 | J22: 0.34513889 | K22: 0.7375 | L22: =MOD(K22-J22,1)*24 | M22: 1 | Z22: 0.33958333 | AA22: 0.73680556 | AB22: =MOD(AA22-Z22,1)*24 | AC22: 1 | AD22: 0.34861111 | AE22: 0.73611111 | AF22: =MOD(AE22-AD22,1)*24 | AG22: 1 | AH22: 0.34722222 | AI22: 0.73680556 | AJ22: =MOD(AI22-AH22,1)*24 | AK22: 1 | AL22: 0.34027778 | AM22: 0.73680556 | AN22: =MOD(AM22-AL22,1)*24 | AO22: 1 | AP22: 0.34722222 | AQ22: 0.73611111 | AR22: =MOD(AQ22-AP22,1)*24 | AS22: 1 | AT22: 0.34930556 | AU22: 0.73958333 | AV22: =MOD(AU22-AT22,1)*24 | AW22: 0.5 | BB22: 0.33888889 | BE22: 0.5 | BF22: 0.34791667 | BG22: 0.7375 | BH22: =MOD(BG22-BF22,1)*24 | BI22: 1 | BJ22: 0.34652778 | BK22: 0.73680556 | BL22: =MOD(BK22-BJ22,1)*24 | BM22: 0.5 | BN22: 0.34444444 | BO22: 0.73611111 | BP22: =MOD(BO22-BN22,1)*24 | BQ22: 1 | BR22: 0.33472222 | BS22: 0.7375 | BT22: =MOD(BS22-BR22,1)*24 | BU22: 1 | BV22: 0.34444444 | BY22: 0.5 | BZ22: 0.3125 | CA22: 0.74375 | CB22: =MOD(CA22-BZ22,1)*24 | CC22: 1 | CD22: 0.34236111 | CE22: 0.74097222 | CF22: =MOD(CE22-CD22,1)*24 | CG22: 1 | CH22: 0.34097222 | CI22: 0.73680556 | CJ22: =MOD(CI22-CH22,1)*24 | CK22: 1 | CL22: 0.33958333 | CM22: 0.73680556 | CN22: =MOD(CM22-CL22,1)*24 | CO22: 1 | CP22: 0.27847222 | CQ22: 0.33958333 | CR22: =MOD(CQ22-CP22,1)*24 | CS22: 0.5 | DV22: =SUM(H22,L22,P22,T22,X22,AB22,AF22,AJ22,AN22,AR22,AV22,AZ22,BD22,BH22,BL22,BP22,BT22,BX22,CB22,CF22,CJ22,CN22,CR22,CV22,CZ22,DD22,DH22,DL22,DP22,DT22) | DW22: =SUM(I22,M22,Q22,U22,Y22,AC22,AG22,AK22,AO22,AS22,AW22,BA22,BE22,BI22,BM22,BQ22,BU22,BY22,CC22,CG22,CK22,CO22,CS22,CW22,DA22,DE22,DI22,DM22,DQ22,DU22) | EN22: 只打一次卡 | ES22: 只打一次卡 | EX22: 早退
A23: 五楼 | B23: 段绍红 | C23: 20 | AT23: 0.74166667 | AW23: 0.5 | BJ23: 0.74305556 | BM23: 0.5 | DV23: =SUM(H23,L23,P23,T23,X23,AB23,AF23,AJ23,AN23,AR23,AV23,AZ23,BD23,BH23,BL23,BP23,BT23,BX23,CB23,CF23,CJ23,CN23,CR23,CV23,CZ23,DD23,DH23,DL23,DP23,DT23) | DW23: =SUM(I23,M23,Q23,U23,Y23,AC23,AG23,AK23,AO23,AS23,AW23,BA23,BE23,BI23,BM23,BQ23,BU23,BY23,CC23,CG23,CK23,CO23,CS23,CW23,DA23,DE23,DI23,DM23,DQ23,DU23)
A24: 五楼 | B24: 龙训东 | C24: 21 | F24: 0.34444444 | G24: 0.74305556 | H24: =MOD(G24-F24,1)*24 | I24: 1 | J24: 0.34375 | K24: 0.74097222 | L24: =MOD(K24-J24,1)*24 | M24: 1 | N24: 0.33819444 | O24: 0.74097222 | P24: =MOD(O24-N24,1)*24 | Q24: 1 | R24: 0.34236111 | S24: 0.73680556 | T24: =MOD(S24-R24,1)*24 | U24: 1 | AD24: 0.34375 | AE24: 0.74027778 | AF24: =MOD(AE24-AD24,1)*24 | AG24: 1 | AH24: 0.33888889 | AI24: 0.73958333 | AJ24: =MOD(AI24-AH24,1)*24 | AK24: 1 | AL24: 0.34513889 | AM24: 0.74236111 | AN24: =MOD(AM24-AL24,1)*24 | AO24: 1 | AP24: 0.34305556 | AQ24: 0.73819444 | AR24: =MOD(AQ24-AP24,1)*24 | AS24: 1 | AX24: 0.34513889 | AY24: 0.73819444 | AZ24: =MOD(AY24-AX24,1)*24 | BA24: 1 | BB24: 0.34444444 | BC24: 0.73958333 | BD24: =MOD(BC24-BB24,1)*24 | BE24: 1 | BF24: 0.35138889 | BG24: 0.74027778 | BH24: =MOD(BG24-BF24,1)*24 | BI24: 1 | BJ24: 0.34930556 | BK24: 0.73819444 | BL24: =MOD(BK24-BJ24,1)*24 | BM24: 1 | BN24: 0.35138889 | BO24: 0.73819444 | BP24: =MOD(BO24-BN24,1)*24 | BQ24: 1 | BR24: 0.34652778 | BS24: 0.7375 | BT24: =MOD(BS24-BR24,1)*24 | BU24: 1 | BZ24: 0.35069444 | CA24: 0.7375 | CB24: =MOD(CA24-BZ24,1)*24 | CC24: 1 | CD24: 0.33333333 | CE24: 0.73958333 | CF24: =MOD(CE24-CD24,1)*24 | CG24: 1 | CH24: 0.34236111 | CI24: 0.74027778 | CJ24: =MOD(CI24-CH24,1)*24 | CK24: 1 | CL24: 0.33541667 | CM24: 0.7375 | CN24: =MOD(CM24-CL24,1)*24 | CO24: 1 | CT24: 0.33541667 | CU24: 0.74097222 | CV24: =MOD(CU24-CT24,1)*24 | CW24: 1 | CX24: 0.33333333 | CY24: 0.74166667 | CZ24: =MOD(CY24-CX24,1)*24 | DA24: 1 | DB24: 0.33263889 | DC24: 0.73819444 | DD24: =MOD(DC24-DB24,1)*24 | DE24: 1 | DF24: 0.34027778 | DG24: 0.79097222 | DH24: =MOD(DG24-DF24,1)*24 | DI24: 1 | DJ24: 0.33541667 | DK24: 0.79236111 | DL24: =MOD(DK24-DJ24,1)*24 | DM24: 1 | DN24: 0.34375 | DO24: 0.87986111 | DP24: =MOD(DO24-DN24,1)*24 | DQ24: 1 | DR24: 0.35 | DS24: 0.86597222 | DT24: =MOD(DS24-DR24,1)*24 | DU24: 1 | DV24: =SUM(H24,L24,P24,T24,X24,AB24,AF24,AJ24,AN24,AR24,AV24,AZ24,BD24,BH24,BL24,BP24,BT24,BX24,CB24,CF24,CJ24,CN24,CR24,CV24,CZ24,DD24,DH24,DL24,DP24,DT24) | DW24: =SUM(I24,M24,Q24,U24,Y24,AC24,AG24,AK24,AO24,AS24,AW24,BA24,BE24,BI24,BM24,BQ24,BU24,BY24,CC24,CG24,CK24,CO24,CS24,CW24,DA24,DE24,DI24,DM24,DQ24,DU24)
A25: 五楼 | B25: 李荧 | C25: 22 | F25: 0.35069444 | G25: 0.74305556 | H25: =MOD(G25-F25,1)*24 | I25: 1 | J25: 0.34652778 | K25: 0.73888889 | L25: =MOD(K25-J25,1)*24 | M25: 1 | N25: 0.34722222 | O25: 0.74375 | P25: =MOD(O25-N25,1)*24 | Q25: 1 | Z25: 0.34930556 | AA25: 0.74097222 | AB25: =MOD(AA25-Z25,1)*24 | AC25: 1 | AD25: 0.34375 | AE25: 0.74444444 | AF25: =MOD(AE25-AD25,1)*24 | AG25: 1 | AH25: 0.34652778 | AI25: 0.74305556 | AJ25: =MOD(AI25-AH25,1)*24 | AK25: 1 | AL25: 0.34027778 | AM25: 0.73680556 | AN25: =MOD(AM25-AL25,1)*24 | AO25: 1 | AP25: 0.34513889 | AQ25: 0.73680556 | AR25: =MOD(AQ25-AP25,1)*24 | AS25: 1 | AT25: 0.34236111 | AU25: 0.73819444 | AV25: =MOD(AU25-AT25,1)*24 | AW25: 1 | AX25: 0.34097222 | AY25: 0.73680556 | AZ25: =MOD(AY25-AX25,1)*24 | BA25: 1 | BB25: 0.34236111 | BC25: 0.73680556 | BD25: =MOD(BC25-BB25,1)*24 | BE25: 1 | BF25: 0.34375 | BG25: 0.7375 | BH25: =MOD(BG25-BF25,1)*24 | BI25: 1 | BJ25: 0.35 | BK25: 0.73611111 | BL25: =MOD(BK25-BJ25,1)*24 | BM25: 1 | BN25: 0.34583333 | BO25: 0.73680556 | BP25: =MOD(BO25-BN25,1)*24 | BQ25: 1 | BR25: 0.34652778 | BS25: 0.73888889 | BT25: =MOD(BS25-BR25,1)*24 | BU25: 1 | CD25: 0.34236111 | CE25: 0.7375 | CF25: =MOD(CE25-CD25,1)*24 | CG25: 1 | CH25: 0.34722222 | CI25: 0.73819444 | CJ25: =MOD(CI25-CH25,1)*24 | CK25: 1 | CL25: 0.34166667 | CM25: 0.73888889 | CN25: =MOD(CM25-CL25,1)*24 | CO25: 1 | CP25: 0.33958333 | CQ25: 0.74027778 | CR25: =MOD(CQ25-CP25,1)*24 | CS25: 1 | CT25: 0.34930556 | CU25: 0.73958333 | CV25: =MOD(CU25-CT25,1)*24 | CW25: 1 | CX25: 0.34513889 | CY25: 0.75208333 | CZ25: =MOD(CY25-CX25,1)*24 | DA25: 1 | DB25: 0.35 | DC25: 0.7375 | DD25: =MOD(DC25-DB25,1)*24 | DE25: 1 | DF25: 0.33819444 | DG25: 0.73958333 | DH25: =MOD(DG25-DF25,1)*24 | DI25: 1 | DJ25: 0.34652778 | DK25: 0.775 | DL25: =MOD(DK25-DJ25,1)*24 | DM25: 1 | DN25: 0.34722222 | DO25: 0.88055556 | DP25: =MOD(DO25-DN25,1)*24 | DQ25: 1 | DR25: 0.34861111 | DS25: 0.78541667 | DT25: =MOD(DS25-DR25,1)*24 | DU25: 1 | DV25: =SUM(H25,L25,P25,T25,X25,AB25,AF25,AJ25,AN25,AR25,AV25,AZ25,BD25,BH25,BL25,BP25,BT25,BX25,CB25,CF25,CJ25,CN25,CR25,CV25,CZ25,DD25,DH25,DL25,DP25,DT25) | DW25: =SUM(I25,M25,Q25,U25,Y25,AC25,AG25,AK25,AO25,AS25,AW25,BA25,BE25,BI25,BM25,BQ25,BU25,BY25,CC25,CG25,CK25,CO25,CS25,CW25,DA25,DE25,DI25,DM25,DQ25,DU25)
A26: 五楼 | B26: 贺悦 | C26: 23 | F26: 0.35208333 | G26: 0.73958333 | H26: =MOD(G26-F26,1)*24 | I26: 1 | J26: 0.35 | K26: 0.74236111 | L26: =MOD(K26-J26,1)*24 | M26: 1 | N26: 0.34652778 | O26: 0.73819444 | P26: =MOD(O26-N26,1)*24 | Q26: 1 | Z26: 0.35 | AA26: 0.73888889 | AB26: =MOD(AA26-Z26,1)*24 | AC26: 1 | AD26: 0.35138889 | AE26: 0.7375 | AF26: =MOD(AE26-AD26,1)*24 | AG26: 1 | AH26: 0.35 | AI26: 0.73888889 | AJ26: =MOD(AI26-AH26,1)*24 | AK26: 1 | AL26: 0.35138889 | AM26: 0.73888889 | AN26: =MOD(AM26-AL26,1)*24 | AO26: 1 | AP26: 0.35 | AQ26: 0.73888889 | AR26: =MOD(AQ26-AP26,1)*24 | AS26: 1 | AT26: 0.35208333 | AU26: 0.74097222 | AV26: =MOD(AU26-AT26,1)*24 | AW26: 0.5 | BB26: 0.35138889 | BC26: 0.74166667 | BD26: =MOD(BC26-BB26,1)*24 | BE26: 1 | BF26: 0.35208333 | BG26: 0.74375 | BH26: =MOD(BG26-BF26,1)*24 | BI26: 1 | BJ26: 0.35138889 | BK26: 0.73680556 | BL26: =MOD(BK26-BJ26,1)*24 | BM26: 1 | BR26: 0.35138889 | BS26: 0.7375 | BT26: =MOD(BS26-BR26,1)*24 | BU26: 1 | BV26: 0.35138889 | BW26: 0.74444444 | BX26: =MOD(BW26-BV26,1)*24 | BY26: 1 | BZ26: 0.34652778 | CC26: 0.5 | CD26: 0.35 | CE26: 0.7375 | CF26: =MOD(CE26-CD26,1)*24 | CG26: 1 | CH26: 0.35208333 | CI26: 0.7375 | CJ26: =MOD(CI26-CH26,1)*24 | CK26: 1 | CL26: 0.34861111 | CM26: 0.73819444 | CN26: =MOD(CM26-CL26,1)*24 | CO26: 1 | CP26: 0.35138889 | CQ26: 0.73819444 | CR26: =MOD(CQ26-CP26,1)*24 | CS26: 1 | CT26: 0.35069444 | CU26: 0.74305556 | CV26: =MOD(CU26-CT26,1)*24 | CW26: 1 | CX26: 0.35208333 | CY26: 0.7375 | CZ26: =MOD(CY26-CX26,1)*24 | DA26: 1 | DF26: 0.35 | DG26: 0.74097222 | DH26: =MOD(DG26-DF26,1)*24 | DI26: 1 | DJ26: 0.35069444 | DK26: 0.73888889 | DL26: =MOD(DK26-DJ26,1)*24 | DM26: 1 | DN26: 0.34930556 | DO26: 0.74166667 | DP26: =MOD(DO26-DN26,1)*24 | DQ26: 0.5 | DR26: 0.35 | DS26: 0.74375 | DT26: =MOD(DS26-DR26,1)*24 | DU26: 1 | DV26: =SUM(H26,L26,P26,T26,X26,AB26,AF26,AJ26,AN26,AR26,AV26,AZ26,BD26,BH26,BL26,BP26,BT26,BX26,CB26,CF26,CJ26,CN26,CR26,CV26,CZ26,DD26,DH26,DL26,DP26,DT26) | DW26: =SUM(I26,M26,Q26,U26,Y26,AC26,AG26,AK26,AO26,AS26,AW26,BA26,BE26,BI26,BM26,BQ26,BU26,BY26,CC26,CG26,CK26,CO26,CS26,CW26,DA26,DE26,DI26,DM26,DQ26,DU26) | ET26: 只打一次卡
A27: 五楼 | B27: 贺悦 | C27: 23 | AT27: 0.74236111 | AW27: 0.5 | DN27: 0.74305556 | DQ27: 0.5 | DV27: =SUM(H27,L27,P27,T27,X27,AB27,AF27,AJ27,AN27,AR27,AV27,AZ27,BD27,BH27,BL27,BP27,BT27,BX27,CB27,CF27,CJ27,CN27,CR27,CV27,CZ27,DD27,DH27,DL27,DP27,DT27) | DW27: =SUM(I27,M27,Q27,U27,Y27,AC27,AG27,AK27,AO27,AS27,AW27,BA27,BE27,BI27,BM27,BQ27,BU27,BY27,CC27,CG27,CK27,CO27,CS27,CW27,DA27,DE27,DI27,DM27,DQ27,DU27)
A28: 五楼 | B28: 莫娇 | C28: 24 | F28: 0.34930556 | G28: 0.73611111 | H28: =MOD(G28-F28,1)*24 | I28: 1 | J28: 0.34652778 | K28: 0.73680556 | L28: =MOD(K28-J28,1)*24 | M28: 1 | N28: 0.34722222 | O28: 0.74444444 | P28: =MOD(O28-N28,1)*24 | Q28: 1 | Z28: 0.34861111 | AA28: 0.73680556 | AB28: =MOD(AA28-Z28,1)*24 | AC28: 1 | AD28: 0.35 | AE28: 0.73680556 | AF28: =MOD(AE28-AD28,1)*24 | AG28: 1 | AH28: 0.34861111 | AI28: 0.73888889 | AJ28: =MOD(AI28-AH28,1)*24 | AK28: 1 | AL28: 0.34375 | AM28: 0.7375 | AN28: =MOD(AM28-AL28,1)*24 | AO28: 1 | AP28: 0.35 | AQ28: 0.73680556 | AR28: =MOD(AQ28-AP28,1)*24 | AS28: 1 | AT28: 0.34513889 | AU28: 0.74097222 | AV28: =MOD(AU28-AT28,1)*24 | AW28: 1 | BB28: 0.35069444 | BC28: 0.73680556 | BD28: =MOD(BC28-BB28,1)*24 | BE28: 1 | BF28: 0.34930556 | BG28: 0.73680556 | BH28: =MOD(BG28-BF28,1)*24 | BI28: 1 | BJ28: 0.34375 | BK28: 0.7375 | BL28: =MOD(BK28-BJ28,1)*24 | BM28: 1 | BN28: 0.34652778 | BO28: 0.7375 | BP28: =MOD(BO28-BN28,1)*24 | BQ28: 1 | BR28: 0.34652778 | BS28: 0.7375 | BT28: =MOD(BS28-BR28,1)*24 | BU28: 1 | BV28: 0.34722222 | BW28: 0.73680556 | BX28: =MOD(BW28-BV28,1)*24 | BY28: 1 | BZ28: 0.34236111 | CA28: 0.50069444 | CB28: =MOD(CA28-BZ28,1)*24 | CC28: 0.5 | CD28: 0.34861111 | CE28: 0.73680556 | CF28: =MOD(CE28-CD28,1)*24 | CG28: 1 | CH28: 0.35 | CI28: 0.51041667 | CJ28: =MOD(CI28-CH28,1)*24 | CK28: 0.5 | CL28: 0.34861111 | CM28: 0.7375 | CN28: =MOD(CM28-CL28,1)*24 | CO28: 1 | CP28: 0.27847222 | CQ28: 0.34861111 | CR28: =MOD(CQ28-CP28,1)*24 | CS28: 0.5 | CT28: 0.34513889 | CU28: 0.73680556 | CV28: =MOD(CU28-CT28,1)*24 | CW28: 1 | CX28: 0.34861111 | CY28: 0.7375 | CZ28: =MOD(CY28-CX28,1)*24 | DA28: 1 | DF28: 0.35 | DG28: 0.73819444 | DH28: =MOD(DG28-DF28,1)*24 | DI28: 1 | DJ28: 0.35138889 | DK28: 0.73680556 | DL28: =MOD(DK28-DJ28,1)*24 | DM28: 1 | DN28: 0.34791667 | DO28: 0.7375 | DP28: =MOD(DO28-DN28,1)*24 | DQ28: 1 | DR28: 0.34513889 | DS28: 0.92361111 | DT28: =MOD(DS28-DR28,1)*24 | DU28: 1 | DV28: =SUM(H28,L28,P28,T28,X28,AB28,AF28,AJ28,AN28,AR28,AV28,AZ28,BD28,BH28,BL28,BP28,BT28,BX28,CB28,CF28,CJ28,CN28,CR28,CV28,CZ28,DD28,DH28,DL28,DP28,DT28) | DW28: =SUM(I28,M28,Q28,U28,Y28,AC28,AG28,AK28,AO28,AS28,AW28,BA28,BE28,BI28,BM28,BQ28,BU28,BY28,CC28,CG28,CK28,CO28,CS28,CW28,DA28,DE28,DI28,DM28,DQ28,DU28) | ET28: 早退 | EV28: 早退 | EX28: 早退
A29: 五楼 | B29: 蒋年冬 | C29: 25 | F29: 0.34513889 | G29: 0.73888889 | H29: =MOD(G29-F29,1)*24 | I29: 1 | J29: 0.35069444 | K29: 0.73680556 | L29: =MOD(K29-J29,1)*24 | M29: 1 | N29: 0.35069444 | O29: 0.74513889 | P29: =MOD(O29-N29,1)*24 | Q29: 1 | Z29: 0.34861111 | AA29: 0.73680556 | AB29: =MOD(AA29-Z29,1)*24 | AC29: 1 | AD29: 0.34583333 | AE29: 0.73611111 | AF29: =MOD(AE29-AD29,1)*24 | AG29: 1 | AH29: 0.34513889 | AI29: 0.73680556 | AJ29: =MOD(AI29-AH29,1)*24 | AK29: 1 | AL29: 0.34513889 | AM29: 0.73680556 | AN29: =MOD(AM29-AL29,1)*24 | AO29: 1 | AP29: 0.34236111 | AQ29: 0.73680556 | AR29: =MOD(AQ29-AP29,1)*24 | AS29: 1 | AT29: 0.34930556 | AU29: 0.73680556 | AV29: =MOD(AU29-AT29,1)*24 | AW29: 1 | BB29: 0.34166667 | BC29: 0.73680556 | BD29: =MOD(BC29-BB29,1)*24 | BE29: 1 | BF29: 0.34930556 | BG29: 0.73680556 | BH29: =MOD(BG29-BF29,1)*24 | BI29: 1 | BJ29: 0.34027778 | BK29: 0.73680556 | BL29: =MOD(BK29-BJ29,1)*24 | BM29: 1 | BN29: 0.34513889 | BO29: 0.73680556 | BP29: =MOD(BO29-BN29,1)*24 | BQ29: 1 | BR29: 0.35069444 | BS29: 0.73680556 | BT29: =MOD(BS29-BR29,1)*24 | BU29: 1 | BV29: 0.35069444 | BW29: 0.73680556 | BX29: =MOD(BW29-BV29,1)*24 | BY29: 1 | CD29: 0.35347222 | CE29: 0.73888889 | CF29: =MOD(CE29-CD29,1)*24 | CG29: 1 | CH29: 0.34236111 | CI29: 0.73680556 | CJ29: =MOD(CI29-CH29,1)*24 | CK29: 1 | CL29: 0.34166667 | CM29: 0.7375 | CN29: =MOD(CM29-CL29,1)*24 | CO29: 1 | CP29: 0.27847222 | CQ29: 0.34236111 | CR29: =MOD(CQ29-CP29,1)*24 | CS29: 0.5 | CT29: 0.3375 | CU29: 0.73680556 | CV29: =MOD(CU29-CT29,1)*24 | CW29: 1 | DV29: =SUM(H29,L29,P29,T29,X29,AB29,AF29,AJ29,AN29,AR29,AV29,AZ29,BD29,BH29,BL29,BP29,BT29,BX29,CB29,CF29,CJ29,CN29,CR29,CV29,CZ29,DD29,DH29,DL29,DP29,DT29) | DW29: =SUM(I29,M29,Q29,U29,Y29,AC29,AG29,AK29,AO29,AS29,AW29,BA29,BE29,BI29,BM29,BQ29,BU29,BY29,CC29,CG29,CK29,CO29,CS29,CW29,DA29,DE29,DI29,DM29,DQ29,DU29) | EX29: 早退
A30: 五楼 | B30: 田建锋 | C30: 26 | F30: 0.34166667 | G30: 0.73680556 | H30: =MOD(G30-F30,1)*24 | I30: 1 | J30: 0.34375 | K30: 0.73680556 | L30: =MOD(K30-J30,1)*24 | M30: 1 | N30: 0.34444444 | O30: 0.73680556 | P30: =MOD(O30-N30,1)*24 | Q30: 1 | R30: 0.34166667 | S30: 0.73958333 | T30: =MOD(S30-R30,1)*24 | U30: 1 | Z30: 0.34791667 | AA30: 0.7375 | AB30: =MOD(AA30-Z30,1)*24 | AC30: 1 | AD30: 0.34375 | AE30: 0.74097222 | AF30: =MOD(AE30-AD30,1)*24 | AG30: 1 | AH30: 0.34861111 | AI30: 0.7375 | AJ30: =MOD(AI30-AH30,1)*24 | AK30: 1 | AL30: 0.34375 | AM30: 0.73680556 | AN30: =MOD(AM30-AL30,1)*24 | AO30: 1 | AP30: 0.34444444 | AQ30: 0.7375 | AR30: =MOD(AQ30-AP30,1)*24 | AS30: 1 | AT30: 0.34236111 | AU30: 0.7375 | AV30: =MOD(AU30-AT30,1)*24 | AW30: 1 | BB30: 0.34513889 | BC30: 0.7375 | BD30: =MOD(BC30-BB30,1)*24 | BE30: 1 | BF30: 0.34305556 | BG30: 0.73680556 | BH30: =MOD(BG30-BF30,1)*24 | BI30: 1 | BJ30: 0.33888889 | BK30: 0.5 | BL30: =MOD(BK30-BJ30,1)*24 | BM30: 0.5 | BN30: 0.34097222 | BO30: 0.73611111 | BP30: =MOD(BO30-BN30,1)*24 | BQ30: 1 | BV30: 0.34027778 | BW30: 0.74513889 | BX30: =MOD(BW30-BV30,1)*24 | BY30: 1 | BZ30: 0.34930556 | CA30: 0.73680556 | CB30: =MOD(CA30-BZ30,1)*24 | CC30: 1 | CD30: 0.34236111 | CE30: 0.73888889 | CF30: =MOD(CE30-CD30,1)*24 | CG30: 1 | CH30: 0.34236111 | CI30: 0.73680556 | CJ30: =MOD(CI30-CH30,1)*24 | CK30: 1 | CL30: 0.34444444 | CM30: 0.73611111 | CN30: =MOD(CM30-CL30,1)*24 | CO30: 1 | CP30: 0.34444444 | CQ30: 0.5 | CR30: =MOD(CQ30-CP30,1)*24 | CS30: 0.5 | CT30: 0.34305556 | CU30: 0.73888889 | CV30: =MOD(CU30-CT30,1)*24 | CW30: 1 | CX30: 0.34861111 | CY30: 0.75972222 | CZ30: =MOD(CY30-CX30,1)*24 | DA30: 1 | DB30: 0.34722222 | DC30: 0.73611111 | DD30: =MOD(DC30-DB30,1)*24 | DE30: 1 | DF30: 0.34166667 | DG30: 0.74583333 | DH30: =MOD(DG30-DF30,1)*24 | DI30: 1 | DJ30: 0.34305556 | DK30: 0.80138889 | DL30: =MOD(DK30-DJ30,1)*24 | DM30: 1 | DN30: 0.34444444 | DO30: 0.88611111 | DP30: =MOD(DO30-DN30,1)*24 | DQ30: 1 | DR30: 0.34097222 | DS30: 0.95347222 | DT30: =MOD(DS30-DR30,1)*24 | DU30: 1 | DV30: =SUM(H30,L30,P30,T30,X30,AB30,AF30,AJ30,AN30,AR30,AV30,AZ30,BD30,BH30,BL30,BP30,BT30,BX30,CB30,CF30,CJ30,CN30,CR30,CV30,CZ30,DD30,DH30,DL30,DP30,DT30) | DW30: =SUM(I30,M30,Q30,U30,Y30,AC30,AG30,AK30,AO30,AS30,AW30,BA30,BE30,BI30,BM30,BQ30,BU30,BY30,CC30,CG30,CK30,CO30,CS30,CW30,DA30,DE30,DI30,DM30,DQ30,DU30) | EP30: 早退 | EX30: 早退
A31: 五楼 | B31: 李红波 | C31: 27 | F31: 0.34722222 | G31: 0.73611111 | H31: =MOD(G31-F31,1)*24 | I31: 1 | J31: 0.34791667 | K31: 0.73680556 | L31: =MOD(K31-J31,1)*24 | M31: 1 | N31: 0.34513889 | O31: 0.73680556 | P31: =MOD(O31-N31,1)*24 | Q31: 1 | R31: 0.34375 | S31: 0.73680556 | T31: =MOD(S31-R31,1)*24 | U31: 1 | Z31: 0.34375 | AA31: 0.7375 | AB31: =MOD(AA31-Z31,1)*24 | AC31: 1 | AD31: 0.34861111 | AE31: 0.73819444 | AF31: =MOD(AE31-AD31,1)*24 | AG31: 1 | AH31: 0.34861111 | AI31: 0.7375 | AJ31: =MOD(AI31-AH31,1)*24 | AK31: 1 | AP31: 0.34305556 | AQ31: 0.73611111 | AR31: =MOD(AQ31-AP31,1)*24 | AS31: 1 | AT31: 0.34444444 | AU31: 0.7375 | AV31: =MOD(AU31-AT31,1)*24 | AW31: 1 | AX31: 0.34097222 | AY31: 0.73611111 | AZ31: =MOD(AY31-AX31,1)*24 | BA31: 1 | BB31: 0.34444444 | BC31: 0.73680556 | BD31: =MOD(BC31-BB31,1)*24 | BE31: 1 | BF31: 0.34236111 | BG31: 0.73680556 | BH31: =MOD(BG31-BF31,1)*24 | BI31: 1 | BN31: 0.34791667 | BO31: 0.73680556 | BP31: =MOD(BO31-BN31,1)*24 | BQ31: 1 | BR31: 0.34791667 | BS31: 0.73680556 | BT31: =MOD(BS31-BR31,1)*24 | BU31: 1 | BV31: 0.34861111 | BW31: 0.73680556 | BX31: =MOD(BW31-BV31,1)*24 | BY31: 1 | BZ31: 0.34861111 | CA31: 0.73680556 | CB31: =MOD(CA31-BZ31,1)*24 | CC31: 1 | CH31: 0.34236111 | CI31: 0.7375 | CJ31: =MOD(CI31-CH31,1)*24 | CK31: 1 | CL31: 0.34583333 | CM31: 0.7375 | CN31: =MOD(CM31-CL31,1)*24 | CO31: 1 | CP31: 0.27847222 | CQ31: 0.34513889 | CR31: =MOD(CQ31-CP31,1)*24 | CS31: 0.5 | CT31: 0.34930556 | CU31: 0.74027778 | CV31: =MOD(CU31-CT31,1)*24 | CW31: 1 | CX31: 0.34930556 | CY31: 0.75972222 | CZ31: =MOD(CY31-CX31,1)*24 | DA31: 1 | DB31: 0.34513889 | DC31: 0.50069444 | DD31: =MOD(DC31-DB31,1)*24 | DE31: 0.5 | DF31: 0.35 | DG31: 0.73819444 | DH31: =MOD(DG31-DF31,1)*24 | DI31: 1 | DJ31: 0.34583333 | DK31: 0.78055556 | DL31: =MOD(DK31-DJ31,1)*24 | DM31: 1 | DN31: 0.34930556 | DO31: 0.77569444 | DP31: =MOD(DO31-DN31,1)*24 | DQ31: 1 | DR31: 0.34861111 | DS31: 0.81319444 | DT31: =MOD(DS31-DR31,1)*24 | DU31: 1 | DV31: =SUM(H31,L31,P31,T31,X31,AB31,AF31,AJ31,AN31,AR31,AV31,AZ31,BD31,BH31,BL31,BP31,BT31,BX31,CB31,CF31,CJ31,CN31,CR31,CV31,CZ31,DD31,DH31,DL31,DP31,DT31) | DW31: =SUM(I31,M31,Q31,U31,Y31,AC31,AG31,AK31,AO31,AS31,AW31,BA31,BE31,BI31,BM31,BQ31,BU31,BY31,CC31,CG31,CK31,CO31,CS31,CW31,DA31,DE31,DI31,DM31,DQ31,DU31) | EX31: 早退 | FA31: 早退
A32: 五楼 | B32: 陈明会 | C32: 28 | F32: 0.33888889 | G32: 0.74027778 | H32: =MOD(G32-F32,1)*24 | I32: 1 | J32: 0.33958333 | K32: 0.73680556 | L32: =MOD(K32-J32,1)*24 | M32: 1 | N32: 0.34305556 | O32: 0.75555556 | P32: =MOD(O32-N32,1)*24 | Q32: 1 | Z32: 0.34375 | AA32: 0.73888889 | AB32: =MOD(AA32-Z32,1)*24 | AC32: 1 | AD32: 0.32291667 | AE32: 0.74027778 | AF32: =MOD(AE32-AD32,1)*24 | AG32: 1 | AH32: 0.33472222 | AI32: 0.7375 | AJ32: =MOD(AI32-AH32,1)*24 | AK32: 1 | AL32: 0.33958333 | AM32: 0.73819444 | AN32: =MOD(AM32-AL32,1)*24 | AO32: 1 | AP32: 0.33958333 | AQ32: 0.73819444 | AR32: =MOD(AQ32-AP32,1)*24 | AS32: 1 | AT32: 0.33333333 | AU32: 0.75069444 | AV32: =MOD(AU32-AT32,1)*24 | AW32: 1 | BB32: 0.33472222 | BC32: 0.7375 | BD32: =MOD(BC32-BB32,1)*24 | BE32: 1 | BF32: 0.33819444 | BG32: 0.74166667 | BH32: =MOD(BG32-BF32,1)*24 | BI32: 1 | BJ32: 0.33611111 | BK32: 0.7375 | BL32: =MOD(BK32-BJ32,1)*24 | BM32: 1 | BN32: 0.33819444 | BO32: 0.74027778 | BP32: =MOD(BO32-BN32,1)*24 | BQ32: 1 | BV32: 0.3375 | BW32: 0.73819444 | BX32: =MOD(BW32-BV32,1)*24 | BY32: 1 | BZ32: 0.33402778 | CA32: 0.7375 | CB32: =MOD(CA32-BZ32,1)*24 | CC32: 1 | CD32: 0.3375 | CE32: 0.73888889 | CF32: =MOD(CE32-CD32,1)*24 | CG32: 1 | CH32: 0.33541667 | CI32: 0.7375 | CJ32: =MOD(CI32-CH32,1)*24 | CK32: 1 | CL32: 0.32222222 | CM32: 0.74097222 | CN32: =MOD(CM32-CL32,1)*24 | CO32: 1 | CP32: 0.34027778 | CQ32: 0.7375 | CR32: =MOD(CQ32-CP32,1)*24 | CS32: 1 | CT32: 0.34166667 | CU32: 0.73680556 | CV32: =MOD(CU32-CT32,1)*24 | CW32: 1 | CX32: 0.33819444 | CY32: 0.74027778 | CZ32: =MOD(CY32-CX32,1)*24 | DA32: 1 | DF32: 0.3375 | DG32: 0.34930556 | DH32: =MOD(DG32-DF32,1)*24 | DI32: 0.5 | DJ32: 0.33819444 | DK32: 0.73680556 | DL32: =MOD(DK32-DJ32,1)*24 | DM32: 1 | DN32: 0.32916667 | DO32: 0.73888889 | DP32: =MOD(DO32-DN32,1)*24 | DQ32: 1 | DR32: 0.33541667 | DS32: 0.87430556 | DT32: =MOD(DS32-DR32,1)*24 | DU32: 1 | DV32: =SUM(H32,L32,P32,T32,X32,AB32,AF32,AJ32,AN32,AR32,AV32,AZ32,BD32,BH32,BL32,BP32,BT32,BX32,CB32,CF32,CJ32,CN32,CR32,CV32,CZ32,DD32,DH32,DL32,DP32,DT32) | DW32: =SUM(I32,M32,Q32,U32,Y32,AC32,AG32,AK32,AO32,AS32,AW32,BA32,BE32,BI32,BM32,BQ32,BU32,BY32,CC32,CG32,CK32,CO32,CS32,CW32,DA32,DE32,DI32,DM32,DQ32,DU32)
A33: 五楼 | B33: 陈明会 | C33: 28 | DF33: 0.74791667 | DI33: 0.5 | DV33: =SUM(H33,L33,P33,T33,X33,AB33,AF33,AJ33,AN33,AR33,AV33,AZ33,BD33,BH33,BL33,BP33,BT33,BX33,CB33,CF33,CJ33,CN33,CR33,CV33,CZ33,DD33,DH33,DL33,DP33,DT33) | DW33: =SUM(I33,M33,Q33,U33,Y33,AC33,AG33,AK33,AO33,AS33,AW33,BA33,BE33,BI33,BM33,BQ33,BU33,BY33,CC33,CG33,CK33,CO33,CS33,CW33,DA33,DE33,DI33,DM33,DQ33,DU33)
A34: 五楼 | B34: 张金彬 | C34: 29 | F34: 0.35 | G34: 0.74097222 | H34: =MOD(G34-F34,1)*24 | I34: 1 | J34: 0.35 | K34: 0.73680556 | L34: =MOD(K34-J34,1)*24 | M34: 1 | N34: 0.34791667 | O34: 0.74375 | P34: =MOD(O34-N34,1)*24 | Q34: 1 | Z34: 0.35277778 | AA34: 0.74236111 | AB34: =MOD(AA34-Z34,1)*24 | AC34: 1 | AD34: 0.35069444 | AE34: 0.73888889 | AF34: =MOD(AE34-AD34,1)*24 | AG34: 1 | AH34: 0.35138889 | AI34: 0.75277778 | AJ34: =MOD(AI34-AH34,1)*24 | AK34: 1 | AL34: 0.34791667 | AM34: 0.75138889 | AN34: =MOD(AM34-AL34,1)*24 | AO34: 1 | AP34: 0.34930556 | AQ34: 0.74444444 | AR34: =MOD(AQ34-AP34,1)*24 | AS34: 1 | AT34: 0.35069444 | AU34: 0.74027778 | AV34: =MOD(AU34-AT34,1)*24 | AW34: 1 | BB34: 0.35208333 | BE34: 0.5 | BF34: 0.34930556 | BG34: 0.74166667 | BH34: =MOD(BG34-BF34,1)*24 | BI34: 1 | BJ34: 0.34652778 | BK34: 0.74305556 | BL34: =MOD(BK34-BJ34,1)*24 | BM34: 1 | BN34: 0.34791667 | BO34: 0.7375 | BP34: =MOD(BO34-BN34,1)*24 | BQ34: 1 | BR34: 0.35069444 | BS34: 0.77291667 | BT34: =MOD(BS34-BR34,1)*24 | BU34: 1 | BV34: 0.34791667 | BW34: 0.73888889 | BX34: =MOD(BW34-BV34,1)*24 | BY34: 1 | BZ34: 0.34583333 | CA34: 0.48888889 | CB34: =MOD(CA34-BZ34,1)*24 | CC34: 0.5 | CD34: 0.34861111 | CE34: 0.73680556 | CF34: =MOD(CE34-CD34,1)*24 | CG34: 1 | CH34: 0.34861111 | CI34: 0.75138889 | CJ34: =MOD(CI34-CH34,1)*24 | CK34: 1 | CL34: 0.35 | CM34: 0.73888889 | CN34: =MOD(CM34-CL34,1)*24 | CO34: 1 | CP34: 0.34791667 | CQ34: 0.76388889 | CR34: =MOD(CQ34-CP34,1)*24 | CS34: 1 | CT34: 0.34513889 | CU34: 0.85486111 | CV34: =MOD(CU34-CT34,1)*24 | CW34: 1 | CX34: 0.34791667 | CY34: 0.85486111 | CZ34: =MOD(CY34-CX34,1)*24 | DA34: 1 | DF34: 0.35069444 | DG34: 0.84722222 | DH34: =MOD(DG34-DF34,1)*24 | DI34: 1 | DJ34: 0.35 | DK34: 0.74027778 | DL34: =MOD(DK34-DJ34,1)*24 | DM34: 1 | DN34: 0.34861111 | DO34: 0.73958333 | DP34: =MOD(DO34-DN34,1)*24 | DQ34: 1 | DR34: 0.34583333 | DS34: 0.74513889 | DT34: =MOD(DS34-DR34,1)*24 | DU34: 1 | DV34: =SUM(H34,L34,P34,T34,X34,AB34,AF34,AJ34,AN34,AR34,AV34,AZ34,BD34,BH34,BL34,BP34,BT34,BX34,CB34,CF34,CJ34,CN34,CR34,CV34,CZ34,DD34,DH34,DL34,DP34,DT34) | DW34: =SUM(I34,M34,Q34,U34,Y34,AC34,AG34,AK34,AO34,AS34,AW34,BA34,BE34,BI34,BM34,BQ34,BU34,BY34,CC34,CG34,CK34,CO34,CS34,CW34,DA34,DE34,DI34,DM34,DQ34,DU34) | EN34: 只打一次卡 | ET34: 早退
