Workbook

Sheet 6月部门分发
A1: 打卡地点 | B1: 姓名 | C1: 工号 | D1: 一级部门 | E1: 二级部门 | F1: 1 | H1: 小时数 | I1: 天数 | J1: 2 | L1: 小时数 | M1: 天数 | N1: 3 | P1: 小时数 | Q1: 天数 | R1: 4 | T1: 小时数 | U1: 天数 | V1: 5 | X1: 小时数 | Y1: 天数 | Z1: 6 | AB1: 小时数 | AC1: 天数 | AD1: 7 | AF1: 小时数 | AG1: 天数 | AH1: 8 | AJ1: 小时数 | AK1: 天数 | AL1: 9 | AN1: 小时数 | AO1: 天数 | AP1: 10 | AR1: 小时数 | AS1: 天数 | AT1: 11 | AV1: 小时数 | AW1: 天数 | AX1: 12 | AZ1: 小时数 | BA1: 天数 | BB1: 13 | BD1: 小时数 | BE1: 天数 | BF1: 14 | BH1: 小时数 | BI1: 天数 | BJ1: 15 | BL1: 小时数 | BM1: 天数 | BN1: 16 | BP1: 小时数 | BQ1: 天数 | BR1: 17 | BT1: 小时数 | BU1: 天数 | BV1: 18 | BX1: 小时数 | BY1: 天数 | BZ1: 19 | CB1: 小时数 | CC1: 天数 | CD1: 20 | CF1: 小时数 | CG1: 天数 | CH1: 21 | CJ1: 小时数 | CK1: 天数 | CL1: 22 | CN1: 小时数 | CO1: 天数 | CP1: 23 | CR1: 小时数 | CS1: 天数 | CT1: 24 | CV1: 小时数 | CW1: 天数 | CX1: 25 | CZ1: 小时数 | DA1: 天数 | DB1: 26 | DD1: 小时数 | DE1: 天数 | DF1: 27 | DH1: 小时数 | DI1: 天数 | DJ1: 28 | DL1: 小时数 | DM1: 天数 | DN1: 29 | DP1: 小时数 | DQ1: 天数 | DR1: 30 | DT1: 小时数 | DU1: 天数 | DX1: 小时数 | DY1: 天数 | DZ1: 总小时数 | EA1: 总天数
A2: 五楼 | B2: 伍小雪 | C2: 3 | D2: 订单部 | E2: 计划物控组 | F2: 08:25 | G2: 0.78055556 | H2: =MOD(G2-F2,1)*24 | I2: 1 | J2: 0.35069444 | K2: 0.85763889 | L2: =MOD(K2-J2,1)*24 | M2: 1 | N2: 0.35208333 | O2: 0.78194444 | P2: =MOD(O2-N2,1)*24 | Q2: 1 | R2: 0.35069444 | S2: 0.75555556 | T2: =MOD(S2-R2,1)*24 | U2: 1 | V2: 0.34722222 | W2: 0.75555556 | X2: =MOD(W2-V2,1)*24 | Y2: 1 | Z2: 0.35277778 | AA2: 0.75972222 | AB2: =MOD(AA2-Z2,1)*24 | AC2: 1 | AH2: 0.35347222 | AI2: 0.76111111 | AJ2: =MOD(AI2-AH2,1)*24 | AK2: 1 | AL2: 0.35069444 | AM2: 0.87638889 | AN2: =MOD(AM2-AL2,1)*24 | AO2: 1 | AP2: 0.35208333 | AQ2: 0.76041667 | AR2: =MOD(AQ2-AP2,1)*24 | AS2: 1 | AT2: 0.35138889 | AU2: 0.76666667 | AV2: =MOD(AU2-AT2,1)*24 | AW2: 1 | AX2: 0.35138889 | AY2: 0.76111111 | AZ2: =MOD(AY2-AX2,1)*24 | BA2: 1 | BB2: 0.35208333 | BC2: 0.75763889 | BD2: =MOD(BC2-BB2,1)*24 | BE2: 1 | BJ2: 0.35069444 | BK2: 0.76388889 | BL2: =MOD(BK2-BJ2,1)*24 | BM2: 1 | BN2: 0.35208333 | BO2: 0.75555556 | BP2: =MOD(BO2-BN2,1)*24 | BQ2: 1 | BR2: 0.35208333 | BS2: 0.75277778 | BT2: =MOD(BS2-BR2,1)*24 | BU2: 1 | BV2: 0.35208333 | BW2: 0.76041667 | BX2: =MOD(BW2-BV2,1)*24 | BY2: 1 | CH2: 0.35208333 | CI2: 0.75208333 | CJ2: =MOD(CI2-CH2,1)*24 | CK2: 1 | CL2: 0.35277778 | CM2: 0.75972222 | CN2: =MOD(CM2-CL2,1)*24 | CO2: 1 | CP2: 0.35069444 | CQ2: 0.87638889 | CR2: =MOD(CQ2-CP2,1)*24 | CS2: 1 | CT2: 0.35069444 | CU2: 0.75277778 | CV2: =MOD(CU2-CT2,1)*24 | CW2: 1 | CX2: 0.34861111 | CY2: 0.75694444 | CZ2: =MOD(CY2-CX2,1)*24 | DA2: 1 | DB2: 0.34930556 | DC2: 0.75208333 | DD2: =MOD(DC2-DB2,1)*24 | DE2: 1 | DF2: 0.35138889 | DG2: 0.7625 | DH2: =MOD(DG2-DF2,1)*24 | DI2: 1 | DN2: 0.34930556 | DO2: 0.75902778 | DP2: =MOD(DO2-DN2,1)*24 | DQ2: 1 | DR2: 0.35069444 | DS2: 0.75277778 | DT2: =MOD(DS2-DR2,1)*24 | DU2: 1 | DZ2: =H2+L2+P2+T2+X2+AB2+AF2+AJ2+AN2+AR2+AV2+AZ2+BD2+BH2+BL2+BP2+BT2+BX2+CB2+CF2+CJ2+CN2+CR2+CV2+CZ2+DD2+DH2+DL2+DP2+DT2 | EA2: =I2+M2+Q2+U2+Y2+AC2+AG2+AK2+AO2+AS2+AW2+BA2+BE2+BI2+BM2+BQ2+BU2+BY2+CC2+CG2+CK2+CO2+CS2+CW2+DA2+DE2+DI2+DM2+DQ2+DU2
A3: 五楼 | B3: 伍小雪 | C3: 3 | D3: 订单部 | E3: 计划物控组 | BT3: =MOD(BS3-BR3,1)*24
A4: 五楼 | B4: 邱霞 | C4: 4 | D4: 订单部 | E4: 计划物控组 | F4: 08:24 | G4: 0.75208333 | H4: =MOD(G4-F4,1)*24 | I4: 1 | J4: 0.35 | K4: 0.75486111 | L4: =MOD(K4-J4,1)*24 | M4: 1 | N4: 0.35069444 | O4: 0.75208333 | P4: =MOD(O4-N4,1)*24 | Q4: 1 | R4: 0.35 | S4: 0.75277778 | T4: =MOD(S4-R4,1)*24 | U4: 1 | V4: 0.35277778 | W4: 0.75208333 | X4: =MOD(W4-V4,1)*24 | Y4: 1 | Z4: 0.35208333 | AA4: 0.75416667 | AB4: =MOD(AA4-Z4,1)*24 | AC4: 1 | AH4: 0.35208333 | AI4: 0.75208333 | AJ4: =MOD(AI4-AH4,1)*24 | AK4: 1 | AL4: 0.35069444 | AM4: 0.75208333 | AN4: =MOD(AM4-AL4,1)*24 | AO4: 1 | AP4: 0.35208333 | AQ4: 0.75694444 | AR4: =MOD(AQ4-AP4,1)*24 | AS4: 1 | AT4: 0.35138889 | AU4: 0.75277778 | AV4: =MOD(AU4-AT4,1)*24 | AW4: 1 | AX4: 0.35138889 | AY4: 0.75069444 | AZ4: =MOD(AY4-AX4,1)*24 | BA4: 1 | BB4: 0.35069444 | BC4: 0.75208333 | BD4: =MOD(BC4-BB4,1)*24 | BE4: 1 | BJ4: 0.35069444 | BK4: 0.75625 | BL4: =MOD(BK4-BJ4,1)*24 | BM4: 1 | BN4: 0.34930556 | BO4: 0.75208333 | BP4: =MOD(BO4-BN4,1)*24 | BQ4: 1 | BR4: 0.35 | BS4: 0.75138889 | BT4: =MOD(BS4-BR4,1)*24 | BU4: 1 | BV4: 0.35277778 | BW4: 0.75416667 | BX4: =MOD(BW4-BV4,1)*24 | BY4: 1 | CH4: 0.35277778 | CI4: 0.75277778 | CJ4: =MOD(CI4-CH4,1)*24 | CK4: 1 | CL4: 0.35138889 | CM4: 0.75138889 | CN4: =MOD(CM4-CL4,1)*24 | CO4: 1 | CP4: 0.35069444 | CQ4: 0.75347222 | CR4: =MOD(CQ4-CP4,1)*24 | CS4: 1 | CT4: 0.35138889 | CU4: 0.75138889 | CV4: =MOD(CU4-CT4,1)*24 | CW4: 1 | CX4: 0.35138889 | CY4: 0.75138889 | CZ4: =MOD(CY4-CX4,1)*24 | DA4: 1 | DB4: 0.35138889 | DC4: 0.75208333 | DD4: =MOD(DC4-DB4,1)*24 | DE4: 1 | DF4: 0.35069444 | DG4: 0.75277778 | DH4: =MOD(DG4-DF4,1)*24 | DI4: 1 | DN4: 0.35277778 | DO4: 0.75208333 | DP4: =MOD(DO4-DN4,1)*24 | DQ4: 1 | DR4: 0.35069444 | DS4: 0.75208333 | DT4: =MOD(DS4-DR4,1)*24 | DU4: 1 | DZ4: =H4+L4+P4+T4+X4+AB4+AF4+AJ4+AN4+AR4+AV4+AZ4+BD4+BH4+BL4+BP4+BT4+BX4+CB4+CF4+CJ4+CN4+CR4+CV4+CZ4+DD4+DH4+DL4+DP4+DT4 | EA4: =I4+M4+Q4+U4+Y4+AC4+AG4+AK4+AO4+AS4+AW4+BA4+BE4+BI4+BM4+BQ4+BU4+BY4+CC4+CG4+CK4+CO4+CS4+CW4+DA4+DE4+DI4+DM4+DQ4+DU4
A5: 五楼 | B5: 陈小红 | C5: 7 | D5: 设计部 | E5: 设计组 | F5: 08:20 | G5: 0.79930556 | H5: =MOD(G5-F5,1)*24 | I5: 1 | J5: 0.34652778 | K5: 0.85833333 | L5: =MOD(K5-J5,1)*24 | M5: 1 | N5: 0.33888889 | Q5: 0.5 | R5: 0.33819444 | S5: 0.80138889 | T5: =MOD(S5-R5,1)*24 | U5: 1 | V5: 0.35069444 | W5: 0.85902778 | X5: =MOD(W5-V5,1)*24 | Y5: 1 | Z5: 0.35208333 | AA5: 0.77708333 | AB5: =MOD(AA5-Z5,1)*24 | AC5: 1 | AD5: 0.75138889 | AG5: 0.5 | AH5: 0.34652778 | AI5: 0.77708333 | AJ5: =MOD(AI5-AH5,1)*24 | AK5: 1 | AL5: 0.34027778 | AM5: 0.75763889 | AN5: =MOD(AM5-AL5,1)*24 | AO5: 1 | AP5: 0.34583333 | AQ5: 0.75555556 | AR5: =MOD(AQ5-AP5,1)*24 | AS5: 1 | AT5: 0.34930556 | AU5: 0.79166667 | AV5: =MOD(AU5-AT5,1)*24 | AW5: 1 | AX5: 0.34236111 | AY5: 0.81875 | AZ5: =MOD(AY5-AX5,1)*24 | BA5: 1 | BB5: 0.35 | BC5: 0.76527778 | BD5: =MOD(BC5-BB5,1)*24 | BE5: 1 | BJ5: 0.33402778 | BK5: 0.84652778 | BL5: =MOD(BK5-BJ5,1)*24 | BM5: 1 | BN5: 0.34652778 | BO5: 0.83958333 | BP5: =MOD(BO5-BN5,1)*24 | BQ5: 1 | BR5: 0.34166667 | BS5: 0.80486111 | BT5: =MOD(BS5-BR5,1)*24 | BU5: 1 | BV5: 0.33402778 | BW5: 0.80416667 | BX5: =MOD(BW5-BV5,1)*24 | BY5: 1 | CD5: 0.35416667 | CG5: 0.5 | CH5: 0.35138889 | CI5: 0.76319444 | CJ5: =MOD(CI5-CH5,1)*24 | CK5: 1 | CL5: 0.34236111 | CM5: 0.75555556 | CN5: =MOD(CM5-CL5,1)*24 | CO5: 1 | CP5: 0.34652778 | CQ5: 0.82708333 | CR5: =MOD(CQ5-CP5,1)*24 | CS5: 1 | CT5: 0.34583333 | CU5: 0.79166667 | CV5: =MOD(CU5-CT5,1)*24 | CW5: 1 | CX5: 0.34375 | CY5: 0.75208333 | CZ5: =MOD(CY5-CX5,1)*24 | DA5: 1 | DB5: 0.76180556 | DD5: =MOD(DC5-DB5,1)*24 | DE5: 0.5 | DF5: 0.34166667 | DG5: 0.75555556 | DH5: =MOD(DG5-DF5,1)*24 | DI5: 1 | DJ5: 0.35277778 | DK5: 0.75972222 | DL5: =MOD(DK5-DJ5,1)*24 | DM5: 1 | DN5: 0.34652778 | DO5: 0.77638889 | DP5: =MOD(DO5-DN5,1)*24 | DQ5: 1 | DR5: 0.35486111 | DS5: 0.75902778 | DT5: =MOD(DS5-DR5,1)*24 | DU5: 1 | DZ5: =H5+L5+P5+T5+X5+AB5+AF5+AJ5+AN5+AR5+AV5+AZ5+BD5+BH5+BL5+BP5+BT5+BX5+CB5+CF5+CJ5+CN5+CR5+CV5+CZ5+DD5+DH5+DL5+DP5+DT5 | EA5: =I5+M5+Q5+U5+Y5+AC5+AG5+AK5+AO5+AS5+AW5+BA5+BE5+BI5+BM5+BQ5+BU5+BY5+CC5+CG5+CK5+CO5+CS5+CW5+DA5+DE5+DI5+DM5+DQ5+DU5
A6: 五楼 | B6: 陈小红 | C6: 7 | D6: 设计部 | E6: 设计组 | BT6: =MOD(BS6-BR6,1)*24
A7: 五楼 | B7: 胡娅 | C7: 9 | D7: 订单部 | E7: 计划物控组 | F7: 08:19 | G7: 0.75833333 | H7: =MOD(G7-F7,1)*24 | I7: 1 | J7: 0.34236111 | K7: 0.75 | L7: =MOD(K7-J7,1)*24 | M7: 1 | N7: 0.34652778 | O7: 0.75069444 | P7: =MOD(O7-N7,1)*24 | Q7: 1 | R7: 0.34375 | S7: 0.75347222 | T7: =MOD(S7-R7,1)*24 | U7: 1 | V7: 0.34722222 | W7: 0.75138889 | X7: =MOD(W7-V7,1)*24 | Y7: 1 | Z7: 0.34652778 | AA7: 0.75833333 | AB7: =MOD(AA7-Z7,1)*24 | AC7: 1 | AH7: 0.34583333 | AI7: 0.75138889 | AJ7: =MOD(AI7-AH7,1)*24 | AK7: 1 | AL7: 0.33611111 | AM7: 0.75069444 | AN7: =MOD(AM7-AL7,1)*24 | AO7: 1 | AP7: 0.34027778 | AQ7: 0.75763889 | AR7: =MOD(AQ7-AP7,1)*24 | AS7: 1 | AT7: 0.34513889 | AU7: 0.75069444 | AV7: =MOD(AU7-AT7,1)*24 | AW7: 1 | AX7: 0.34375 | AY7: 0.75069444 | AZ7: =MOD(AY7-AX7,1)*24 | BA7: 1 | BB7: 0.33819444 | BC7: 0.75069444 | BD7: =MOD(BC7-BB7,1)*24 | BE7: 1 | BJ7: 0.33541667 | BK7: 0.75069444 | BL7: =MOD(BK7-BJ7,1)*24 | BM7: 1 | BN7: 0.3375 | BO7: 0.75069444 | BP7: =MOD(BO7-BN7,1)*24 | BQ7: 1 | BR7: 0.3375 | BS7: 0.75138889 | BT7: =MOD(BS7-BR7,1)*24 | BU7: 1 | BV7: 0.34513889 | BW7: 0.75069444 | BX7: =MOD(BW7-BV7,1)*24 | BY7: 1 | CH7: 0.34513889 | CI7: 0.75069444 | CJ7: =MOD(CI7-CH7,1)*24 | CK7: 1 | CL7: 0.34513889 | CM7: 0.75069444 | CN7: =MOD(CM7-CL7,1)*24 | CO7: 1 | CP7: 0.34861111 | CQ7: 0.75069444 | CR7: =MOD(CQ7-CP7,1)*24 | CS7: 1 | CT7: 0.34305556 | CU7: 0.75069444 | CV7: =MOD(CU7-CT7,1)*24 | CW7: 1 | CX7: 0.34513889 | CY7: 0.75069444 | CZ7: =MOD(CY7-CX7,1)*24 | DA7: 1 | DB7: 0.34652778 | DC7: 0.75069444 | DD7: =MOD(DC7-DB7,1)*24 | DE7: 1 | DF7: 0.34583333 | DG7: 0.75 | DH7: =MOD(DG7-DF7,1)*24 | DI7: 1 | DN7: 0.34513889 | DO7: 0.75069444 | DP7: =MOD(DO7-DN7,1)*24 | DQ7: 1 | DR7: 0.34513889 | DS7: 0.75069444 | DT7: =MOD(DS7-DR7,1)*24 | DU7: 1 | DZ7: =H7+L7+P7+T7+X7+AB7+AF7+AJ7+AN7+AR7+AV7+AZ7+BD7+BH7+BL7+BP7+BT7+BX7+CB7+CF7+CJ7+CN7+CR7+CV7+CZ7+DD7+DH7+DL7+DP7+DT7 | EA7: =I7+M7+Q7+U7+Y7+AC7+AG7+AK7+AO7+AS7+AW7+BA7+BE7+BI7+BM7+BQ7+BU7+BY7+CC7+CG7+CK7+CO7+CS7+CW7+DA7+DE7+DI7+DM7+DQ7+DU7
A8: 五楼 | B8: 杨青青 | C8: 10 | D8: 订单部 | E8: 计划物控组 | F8: 08:24 | G8: 0.77152778 | H8: =MOD(G8-F8,1)*24 | I8: 1 | J8: 0.35069444 | K8: 0.75694444 | L8: =MOD(K8-J8,1)*24 | M8: 1 | N8: 0.35347222 | O8: 0.75208333 | P8: =MOD(O8-N8,1)*24 | Q8: 1 | R8: 0.34791667 | S8: 0.75277778 | T8: =MOD(S8-R8,1)*24 | U8: 1 | V8: 0.34722222 | W8: 0.75138889 | X8: =MOD(W8-V8,1)*24 | Y8: 1 | Z8: 0.34444444 | AA8: 0.75972222 | AB8: =MOD(AA8-Z8,1)*24 | AC8: 1 | AH8: 0.34930556 | AI8: 0.75277778 | AJ8: =MOD(AI8-AH8,1)*24 | AK8: 1 | AL8: 0.34236111 | AM8: 0.75208333 | AN8: =MOD(AM8-AL8,1)*24 | AO8: 1 | AP8: 0.34027778 | AQ8: 0.75486111 | AR8: =MOD(AQ8-AP8,1)*24 | AS8: 1 | AT8: 0.35208333 | AU8: 0.75555556 | AV8: =MOD(AU8-AT8,1)*24 | AW8: 1 | AX8: 0.35 | AY8: 0.75486111 | AZ8: =MOD(AY8-AX8,1)*24 | BA8: 1 | BB8: 0.35069444 | BC8: 0.75208333 | BD8: =MOD(BC8-BB8,1)*24 | BE8: 1 | BJ8: 0.35486111 | BK8: 0.75694444 | BL8: =MOD(BK8-BJ8,1)*24 | BM8: 1 | BN8: 0.34583333 | BO8: 0.75138889 | BP8: =MOD(BO8-BN8,1)*24 | BQ8: 1 | BR8: 0.35416667 | BS8: 0.75 | BT8: =MOD(BS8-BR8,1)*24 | BU8: 1 | BV8: 0.35069444 | BW8: 0.75486111 | BX8: =MOD(BW8-BV8,1)*24 | BY8: 1 | CH8: 0.35069444 | CI8: 0.75208333 | CJ8: =MOD(CI8-CH8,1)*24 | CK8: 1 | CL8: 0.34513889 | CM8: 0.75902778 | CN8: =MOD(CM8-CL8,1)*24 | CO8: 1 | CP8: 0.34305556 | CQ8: 0.75902778 | CR8: =MOD(CQ8-CP8,1)*24 | CS8: 1 | CT8: 0.35347222 | CU8: 0.75277778 | CV8: =MOD(CU8-CT8,1)*24 | CW8: 1 | CX8: 0.34444444 | CY8: 0.75208333 | CZ8: =MOD(CY8-CX8,1)*24 | DA8: 1 | DB8: 0.35208333 | DC8: 0.75208333 | DD8: =MOD(DC8-DB8,1)*24 | DE8: 1 | DF8: 0.34583333 | DG8: 0.7625 | DH8: =MOD(DG8-DF8,1)*24 | DI8: 1 | DN8: 0.75902778 | DQ8: 0.5 | DR8: 0.35069444 | DS8: 0.75208333 | DT8: =MOD(DS8-DR8,1)*24 | DU8: 1 | DZ8: =H8+L8+P8+T8+X8+AB8+AF8+AJ8+AN8+AR8+AV8+AZ8+BD8+BH8+BL8+BP8+BT8+BX8+CB8+CF8+CJ8+CN8+CR8+CV8+CZ8+DD8+DH8+DL8+DP8+DT8 | EA8: =I8+M8+Q8+U8+Y8+AC8+AG8+AK8+AO8+AS8+AW8+BA8+BE8+BI8+BM8+BQ8+BU8+BY8+CC8+CG8+CK8+CO8+CS8+CW8+DA8+DE8+DI8+DM8+DQ8+DU8
A9: 五楼 | B9: 向锋 | C9: 12 | D9: 设计部 | E9: 设计组 | F9: 08:14 | G9: 0.8375 | H9: =MOD(G9-F9,1)*24 | I9: 1 | J9: 0.35069444 | K9: 0.76111111 | L9: =MOD(K9-J9,1)*24 | M9: 1 | R9: 0.34791667 | S9: 0.91736111 | T9: =MOD(S9-R9,1)*24 | U9: 1 | V9: 0.35069444 | W9: 0.84444444 | X9: =MOD(W9-V9,1)*24 | Y9: 1 | Z9: 0.35069444 | AA9: 0.75347222 | AB9: =MOD(AA9-Z9,1)*24 | AC9: 1 | AH9: 0.36875 | AI9: 0.84930556 | AJ9: =MOD(AI9-AH9,1)*24 | AK9: 1 | AL9: 0.35277778 | AM9: 0.83819444 | AN9: =MOD(AM9-AL9,1)*24 | AO9: 1 | AP9: 0.35208333 | AQ9: 0.75972222 | AR9: =MOD(AQ9-AP9,1)*24 | AS9: 1 | AT9: 0.34930556 | AU9: 0.82638889 | AV9: =MOD(AU9-AT9,1)*24 | AW9: 1 | AX9: 0.35138889 | AY9: 0.83958333 | AZ9: =MOD(AY9-AX9,1)*24 | BA9: 1 | BB9: 0.35138889 | BC9: 0.75208333 | BD9: =MOD(BC9-BB9,1)*24 | BE9: 1 | BJ9: 0.35069444 | BK9: 0.83819444 | BL9: =MOD(BK9-BJ9,1)*24 | BM9: 1 | BN9: 0.35 | BO9: 0.82013889 | BP9: =MOD(BO9-BN9,1)*24 | BQ9: 1 | BR9: 0.34930556 | BS9: 0.84652778 | BT9: =MOD(BS9-BR9,1)*24 | BU9: 1 | BV9: 0.34583333 | BW9: 0.75 | BX9: =MOD(BW9-BV9,1)*24 | BY9: 1 | CH9: 0.34513889 | CI9: 0.80833333 | CJ9: =MOD(CI9-CH9,1)*24 | CK9: 1 | CL9: 0.35069444 | CM9: 0.82847222 | CN9: =MOD(CM9-CL9,1)*24 | CO9: 1 | CP9: 0.34861111 | CQ9: 0.82916667 | CR9: =MOD(CQ9-CP9,1)*24 | CS9: 1 | CT9: 0.35138889 | CU9: 0.88680556 | CV9: =MOD(CU9-CT9,1)*24 | CW9: 1 | CX9: 0.33611111 | CY9: 0.82986111 | CZ9: =MOD(CY9-CX9,1)*24 | DA9: 1 | DB9: 0.32986111 | DD9: =MOD(DC9-DB9,1)*24 | DE9: 1 | DF9: 0.34652778 | DG9: 0.75277778 | DH9: =MOD(DG9-DF9,1)*24 | DI9: 1 | DN9: 0.35138889 | DO9: 0.8375 | DP9: =MOD(DO9-DN9,1)*24 | DQ9: 1 | DR9: 0.34652778 | DS9: 0.83472222 | DT9: =MOD(DS9-DR9,1)*24 | DU9: 1 | DZ9: =H9+L9+P9+T9+X9+AB9+AF9+AJ9+AN9+AR9+AV9+AZ9+BD9+BH9+BL9+BP9+BT9+BX9+CB9+CF9+CJ9+CN9+CR9+CV9+CZ9+DD9+DH9+DL9+DP9+DT9 | EA9: =I9+M9+Q9+U9+Y9+AC9+AG9+AK9+AO9+AS9+AW9+BA9+BE9+BI9+BM9+BQ9+BU9+BY9+CC9+CG9+CK9+CO9+CS9+CW9+DA9+DE9+DI9+DM9+DQ9+DU9
A10: 五楼 | B10: 向锋 | C10: 12 | D10: 设计部 | E10: 设计组
A11: 五楼 | B11: 杨首琴 | C11: 14 | D11: 采购部 | E11: 采购部 | F11: 08:28 | G11: 0.75069444 | H11: =MOD(G11-F11,1)*24 | I11: 1 | J11: 0.34791667 | K11: 0.75694444 | L11: =MOD(K11-J11,1)*24 | M11: 1 | N11: 0.35 | O11: 0.75277778 | P11: =MOD(O11-N11,1)*24 | Q11: 1 | R11: 0.35 | S11: 0.75208333 | T11: =MOD(S11-R11,1)*24 | U11: 1 | V11: 0.35208333 | W11: 0.75069444 | X11: =MOD(W11-V11,1)*24 | Y11: 1 | Z11: 0.35208333 | AA11: 0.75416667 | AB11: =MOD(AA11-Z11,1)*24 | AC11: 1 | AH11: 0.35208333 | AI11: 0.75694444 | AJ11: =MOD(AI11-AH11,1)*24 | AK11: 1 | AP11: 0.34791667 | AQ11: 0.75416667 | AR11: =MOD(AQ11-AP11,1)*24 | AS11: 1 | AT11: 0.34652778 | AU11: 0.75277778 | AV11: =MOD(AU11-AT11,1)*24 | AW11: 1 | AX11: 0.34861111 | AY11: 0.75208333 | AZ11: =MOD(AY11-AX11,1)*24 | BA11: 1 | BB11: 0.35069444 | BC11: 0.75277778 | BD11: =MOD(BC11-BB11,1)*24 | BE11: 1 | BJ11: 0.35138889 | BK11: 0.7625 | BL11: =MOD(BK11-BJ11,1)*24 | BM11: 1 | BN11: 0.35 | BO11: 0.75069444 | BP11: =MOD(BO11-BN11,1)*24 | BQ11: 1 | BR11: 0.75486111 | BT11: =MOD(BS11-BR11,1)*24 | BU11: 0.5 | BV11: 0.35347222 | BW11: 0.75555556 | BX11: =MOD(BW11-BV11,1)*24 | BY11: 1 | CH11: 0.34722222 | CI11: 0.75 | CJ11: =MOD(CI11-CH11,1)*24 | CK11: 1 | CL11: 0.34444444 | CM11: 0.75138889 | CN11: =MOD(CM11-CL11,1)*24 | CO11: 1 | CP11: 0.34861111 | CQ11: 0.75208333 | CR11: =MOD(CQ11-CP11,1)*24 | CS11: 1 | CT11: 0.34513889 | CU11: 0.75 | CV11: =MOD(CU11-CT11,1)*24 | CW11: 1 | CX11: 0.35069444 | CY11: 0.75208333 | CZ11: =MOD(CY11-CX11,1)*24 | DA11: 1 | DB11: 0.34791667 | DC11: 0.75555556 | DD11: =MOD(DC11-DB11,1)*24 | DE11: 1 | DF11: 0.34791667 | DG11: 0.75138889 | DH11: =MOD(DG11-DF11,1)*24 | DI11: 1 | DJ11: 0.35069444 | DK11: 0.75208333 | DL11: =MOD(DK11-DJ11,1)*24 | DM11: 1 | DN11: 0.35 | DO11: 0.75486111 | DP11: =MOD(DO11-DN11,1)*24 | DQ11: 1 | DR11: 0.34791667 | DS11: 0.75347222 | DT11: =MOD(DS11-DR11,1)*24 | DU11: 1 | DZ11: =H11+L11+P11+T11+X11+AB11+AF11+AJ11+AN11+AR11+AV11+AZ11+BD11+BH11+BL11+BP11+BT11+BX11+CB11+CF11+CJ11+CN11+CR11+CV11+CZ11+DD11+DH11+DL11+DP11+DT11 | EA11: =I11+M11+Q11+U11+Y11+AC11+AG11+AK11+AO11+AS11+AW11+BA11+BE11+BI11+BM11+BQ11+BU11+BY11+CC11+CG11+CK11+CO11+CS11+CW11+DA11+DE11+DI11+DM11+DQ11+DU11
A12: 五楼 | B12: 杨首琴 | C12: 14 | D12: 采购部 | E12: 采购部
A13: 五楼 | B13: 王晓兰 | C13: 15 | E13: 财务部 | J13: 0.34513889 | K13: 0.75416667 | L13: =MOD(K13-J13,1)*24 | M13: 1 | N13: 0.34513889 | O13: 0.75208333 | P13: =MOD(O13-N13,1)*24 | Q13: 1 | R13: 0.34375 | S13: 0.75138889 | T13: =MOD(S13-R13,1)*24 | U13: 1 | V13: 0.34583333 | W13: 0.75138889 | X13: =MOD(W13-V13,1)*24 | Y13: 1 | Z13: 0.35277778 | AA13: 0.75347222 | AB13: =MOD(AA13-Z13,1)*24 | AC13: 1 | AD13: 0.35347222 | AE13: 0.52777778 | AF13: =MOD(AE13-AD13,1)*24 | AG13: 0.5 | AH13: 0.35208333 | AI13: 0.75902778 | AJ13: =MOD(AI13-AH13,1)*24 | AK13: 1 | AL13: 0.34444444 | AM13: 0.75277778 | AN13: =MOD(AM13-AL13,1)*24 | AO13: 1 | AP13: 0.34166667 | AQ13: 0.75625 | AR13: =MOD(AQ13-AP13,1)*24 | AS13: 1 | AT13: 0.34583333 | AU13: 0.75277778 | AV13: =MOD(AU13-AT13,1)*24 | AW13: 1 | AX13: 0.34166667 | AY13: 0.75069444 | AZ13: =MOD(AY13-AX13,1)*24 | BA13: 1 | BB13: 0.35 | BC13: 0.75347222 | BD13: =MOD(BC13-BB13,1)*24 | BE13: 1 | BF13: 0.35277778 | BG13: 0.54097222 | BH13: =MOD(BG13-BF13,1)*24 | BI13: 0.5 | BJ13: 0.35138889 | BK13: 0.75277778 | BL13: =MOD(BK13-BJ13,1)*24 | BM13: 1 | BN13: 0.34444444 | BO13: 0.75069444 | BP13: =MOD(BO13-BN13,1)*24 | BQ13: 1 | BR13: 0.35138889 | BS13: 0.75486111 | BT13: =MOD(BS13-BR13,1)*24 | BU13: 1 | BV13: 0.34444444 | BW13: 0.75416667 | BX13: =MOD(BW13-BV13,1)*24 | BY13: 1 | CH13: 0.35138889 | CI13: 0.75347222 | CJ13: =MOD(CI13-CH13,1)*24 | CK13: 1 | CL13: 0.34722222 | CM13: 0.75277778 | CN13: =MOD(CM13-CL13,1)*24 | CO13: 1 | CP13: 0.34861111 | CQ13: 0.75138889 | CR13: =MOD(CQ13-CP13,1)*24 | CS13: 1 | CT13: 0.34027778 | CU13: 0.75763889 | CV13: =MOD(CU13-CT13,1)*24 | CW13: 1 | CX13: 0.35069444 | CY13: 0.75138889 | CZ13: =MOD(CY13-CX13,1)*24 | DA13: 1 | DB13: 0.34166667 | DC13: 0.75208333 | DD13: =MOD(DC13-DB13,1)*24 | DE13: 1 | DF13: 0.54513889 | DG13: 0.75138889 | DH13: =MOD(DG13-DF13,1)*24 | DI13: 0.5 | DJ13: 0.35069444 | DK13: 0.50138889 | DL13: =MOD(DK13-DJ13,1)*24 | DM13: 0.5 | DN13: 0.35 | DO13: 0.75416667 | DP13: =MOD(DO13-DN13,1)*24 | DQ13: 1 | DR13: 0.35138889 | DS13: 0.75416667 | DT13: =MOD(DS13-DR13,1)*24 | DU13: 1 | DZ13: =H13+L13+P13+T13+X13+AB13+AF13+AJ13+AN13+AR13+AV13+AZ13+BD13+BH13+BL13+BP13+BT13+BX13+CB13+CF13+CJ13+CN13+CR13+CV13+CZ13+DD13+DH13+DL13+DP13+DT13 | EA13: =I13+M13+Q13+U13+Y13+AC13+AG13+AK13+AO13+AS13+AW13+BA13+BE13+BI13+BM13+BQ13+BU13+BY13+CC13+CG13+CK13+CO13+CS13+CW13+DA13+DE13+DI13+DM13+DQ13+DU13
A14: 五楼 | B14: 杨益琴 | C14: 16 | D14: 综合部 | E14: 财务核价 | F14: 18:03 | H14: =MOD(G14-F14,1)*24 | I14: 0.5 | J14: 0.35 | K14: 0.75208333 | L14: =MOD(K14-J14,1)*24 | M14: 1 | N14: 0.34930556 | O14: 0.75069444 | P14: =MOD(O14-N14,1)*24 | Q14: 1 | R14: 0.35 | S14: 0.75555556 | T14: =MOD(S14-R14,1)*24 | U14: 1 | V14: 0.75069444 | Y14: 0.5 | Z14: 0.35 | AA14: 0.75138889 | AB14: =MOD(AA14-Z14,1)*24 | AC14: 1 | AH14: 0.35 | AI14: 0.75069444 | AJ14: =MOD(AI14-AH14,1)*24 | AK14: 1 | AL14: 0.35 | AM14: 0.75138889 | AN14: =MOD(AM14-AL14,1)*24 | AO14: 1 | AP14: 0.35 | AQ14: 0.75138889 | AR14: =MOD(AQ14-AP14,1)*24 | AS14: 1 | AT14: 0.34861111 | AU14: 0.75138889 | AV14: =MOD(AU14-AT14,1)*24 | AW14: 1 | AX14: 0.35 | AY14: 0.75277778 | AZ14: =MOD(AY14-AX14,1)*24 | BA14: 1 | BB14: 0.34861111 | BC14: 0.75208333 | BD14: =MOD(BC14-BB14,1)*24 | BE14: 1 | BJ14: 0.34861111 | BK14: 0.75138889 | BL14: =MOD(BK14-BJ14,1)*24 | BM14: 1 | BN14: 0.34930556 | BO14: 0.75138889 | BP14: =MOD(BO14-BN14,1)*24 | BQ14: 1 | BR14: 0.35 | BS14: 0.75902778 | BT14: =MOD(BS14-BR14,1)*24 | BU14: 1 | BV14: 0.34930556 | BW14: 0.75138889 | BX14: =MOD(BW14-BV14,1)*24 | BY14: 1 | CH14: 0.34791667 | CI14: 0.75138889 | CJ14: =MOD(CI14-CH14,1)*24 | CK14: 1 | CL14: 0.34791667 | CM14: 0.75208333 | CN14: =MOD(CM14-CL14,1)*24 | CO14: 1 | CP14: 0.34652778 | CQ14: 0.75277778 | CR14: =MOD(CQ14-CP14,1)*24 | CS14: 1 | CT14: 0.34930556 | CU14: 0.75138889 | CV14: =MOD(CU14-CT14,1)*24 | CW14: 1 | CX14: 0.34930556 | CY14: 0.75208333 | CZ14: =MOD(CY14-CX14,1)*24 | DA14: 1 | DF14: 0.35 | DG14: 0.75208333 | DH14: =MOD(DG14-DF14,1)*24 | DI14: 1 | DJ14: 0.35069444 | DK14: 0.75069444 | DL14: =MOD(DK14-DJ14,1)*24 | DM14: 1 | DN14: 0.34930556 | DO14: 0.76111111 | DP14: =MOD(DO14-DN14,1)*24 | DQ14: 1 | DR14: 0.35 | DS14: 0.96666667 | DT14: =MOD(DS14-DR14,1)*24 | DU14: 1 | DZ14: =H14+L14+P14+T14+X14+AB14+AF14+AJ14+AN14+AR14+AV14+AZ14+BD14+BH14+BL14+BP14+BT14+BX14+CB14+CF14+CJ14+CN14+CR14+CV14+CZ14+DD14+DH14+DL14+DP14+DT14 | EA14: =I14+M14+Q14+U14+Y14+AC14+AG14+AK14+AO14+AS14+AW14+BA14+BE14+BI14+BM14+BQ14+BU14+BY14+CC14+CG14+CK14+CO14+CS14+CW14+DA14+DE14+DI14+DM14+DQ14+DU14
A15: 五楼 | B15: 刘琴 | C15: 17 | D15: 采购部 | E15: 采购部 | J15: 0.35277778 | K15: 0.85902778 | L15: =MOD(K15-J15,1)*24 | M15: 1 | N15: 0.35 | O15: 0.82430556 | P15: =MOD(O15-N15,1)*24 | Q15: 1 | R15: 0.35208333 | S15: 0.75277778 | T15: =MOD(S15-R15,1)*24 | U15: 1 | V15: 0.34791667 | W15: 0.85277778 | X15: =MOD(W15-V15,1)*24 | Y15: 1 | Z15: 0.35208333 | AA15: 0.82222222 | AB15: =MOD(AA15-Z15,1)*24 | AC15: 1 | AD15: 0.35069444 | AE15: 0.87708333 | AF15: =MOD(AE15-AD15,1)*24 | AG15: 1 | AH15: 0.35069444 | AI15: 0.93055556 | AJ15: =MOD(AI15-AH15,1)*24 | AK15: 1 | AL15: 0.35208333 | AM15: 0.87777778 | AN15: =MOD(AM15-AL15,1)*24 | AO15: 1 | AP15: 0.35138889 | AQ15: 0.75277778 | AR15: =MOD(AQ15-AP15,1)*24 | AS15: 1 | AT15: 0.35347222 | AU15: 0.75138889 | AV15: =MOD(AU15-AT15,1)*24 | AW15: 1 | AX15: 0.35277778 | AY15: 0.85833333 | AZ15: =MOD(AY15-AX15,1)*24 | BA15: 1 | BB15: 0.35347222 | BC15: 0.77708333 | BD15: =MOD(BC15-BB15,1)*24 | BE15: 1 | BJ15: 0.35138889 | BK15: 0.775 | BL15: =MOD(BK15-BJ15,1)*24 | BM15: 1 | BN15: 0.35277778 | BP15: =MOD(BO15-BN15,1)*24 | BQ15: 1 | BT15: =MOD(BS15-BR15,1)*24 | BV15: 0.75138889 | BY15: 0.5 | CH15: 0.35277778 | CI15: 0.75208333 | CJ15: =MOD(CI15-CH15,1)*24 | CK15: 1 | CL15: 0.35 | CM15: 0.75208333 | CN15: =MOD(CM15-CL15,1)*24 | CO15: 1 | CT15: 0.35069444 | CU15: 0.77222222 | CV15: =MOD(CU15-CT15,1)*24 | CW15: 1 | CX15: 0.34930556 | CY15: 0.76875 | CZ15: =MOD(CY15-CX15,1)*24 | DA15: 1 | DB15: 0.35 | DC15: 0.8875 | DD15: =MOD(DC15-DB15,1)*24 | DE15: 1 | DF15: 0.35347222 | DG15: 0.84166667 | DH15: =MOD(DG15-DF15,1)*24 | DI15: 1 | DN15: 0.35277778 | DO15: 0.75416667 | DP15: =MOD(DO15-DN15,1)*24 | DQ15: 1 | DR15: 0.35277778 | DS15: 0.75277778 | DT15: =MOD(DS15-DR15,1)*24 | DU15: 1 | DZ15: =H15+L15+P15+T15+X15+AB15+AF15+AJ15+AN15+AR15+AV15+AZ15+BD15+BH15+BL15+BP15+BT15+BX15+CB15+CF15+CJ15+CN15+CR15+CV15+CZ15+DD15+DH15+DL15+DP15+DT15 | EA15: =I15+M15+Q15+U15+Y15+AC15+AG15+AK15+AO15+AS15+AW15+BA15+BE15+BI15+BM15+BQ15+BU15+BY15+CC15+CG15+CK15+CO15+CS15+CW15+DA15+DE15+DI15+DM15+DQ15+DU15
A16: 五楼 | B16: 刘琴 | C16: 17 | D16: 采购部 | E16: 采购部 | BT16: =MOD(BS16-BR16,1)*24
A17: 五楼 | B17: 刘文旦 | C17: 18 | D17: 设计部 | E17: 设计组 | F17: 18:06 | H17: =MOD(G17-F17,1)*24 | I17: 0.5 | J17: 0.35208333 | K17: 0.76458333 | L17: =MOD(K17-J17,1)*24 | M17: 1 | N17: 0.79861111 | O17: 0.93888889 | P17: =MOD(O17-N17,1)*24 | Q17: 0.5 | R17: 0.35208333 | S17: 0.82708333 | T17: =MOD(S17-R17,1)*24 | U17: 1 | AH17: 0.78055556 | AK17: 0.5 | AL17: 0.35138889 | AM17: 0.8125 | AN17: =MOD(AM17-AL17,1)*24 | AO17: 1 | AP17: 0.36041667 | AQ17: 0.80694444 | AR17: =MOD(AQ17-AP17,1)*24 | AS17: 1 | AT17: 0.35625 | AU17: 0.76458333 | AV17: =MOD(AU17-AT17,1)*24 | AW17: 1 | BB17: 0.82222222 | BC17: 0.97777778 | BD17: =MOD(BC17-BB17,1)*24 | BE17: 0.5 | BF17: 0.45833333 | BG17: 0.79166667 | BH17: =MOD(BG17-BF17,1)*24 | BI17: 1 | BJ17: 0.79375 | BK17: 0.98611111 | BL17: =MOD(BK17-BJ17,1)*24 | BM17: 0.5 | BN17: 0.78125 | BP17: =MOD(BO17-BN17,1)*24 | BQ17: 0.5 | BR17: 0.34652778 | BS17: 0.75416667 | BT17: =MOD(BS17-BR17,1)*24 | BU17: 1 | BV17: 0.35555556 | BW17: 0.75138889 | BX17: =MOD(BW17-BV17,1)*24 | BY17: 1 | CH17: 0.34722222 | CK17: 0.5 | CL17: 0.34444444 | CM17: 0.78541667 | CN17: =MOD(CM17-CL17,1)*24 | CO17: 1 | CP17: 0.35277778 | CQ17: 0.81111111 | CR17: =MOD(CQ17-CP17,1)*24 | CS17: 1 | CT17: 0.35555556 | CU17: 0.80972222 | CV17: =MOD(CU17-CT17,1)*24 | CW17: 1 | CX17: 0.35625 | CY17: 0.75625 | CZ17: =MOD(CY17-CX17,1)*24 | DA17: 1 | DB17: 0.35486111 | DE17: 0.5 | DF17: 0.35069444 | DG17: 0.75625 | DH17: =MOD(DG17-DF17,1)*24 | DI17: 1 | DJ17: 0.35486111 | DK17: 0.80277778 | DL17: =MOD(DK17-DJ17,1)*24 | DM17: 1 | DN17: 0.35625 | DO17: 0.75625 | DP17: =MOD(DO17-DN17,1)*24 | DQ17: 1 | DR17: 0.35277778 | DS17: 0.76597222 | DT17: =MOD(DS17-DR17,1)*24 | DU17: 1 | DZ17: =H17+L17+P17+T17+X17+AB17+AF17+AJ17+AN17+AR17+AV17+AZ17+BD17+BH17+BL17+BP17+BT17+BX17+CB17+CF17+CJ17+CN17+CR17+CV17+CZ17+DD17+DH17+DL17+DP17+DT17 | EA17: =I17+M17+Q17+U17+Y17+AC17+AG17+AK17+AO17+AS17+AW17+BA17+BE17+BI17+BM17+BQ17+BU17+BY17+CC17+CG17+CK17+CO17+CS17+CW17+DA17+DE17+DI17+DM17+DQ17+DU17
A18: 五楼 | B18: 刘文旦 | C18: 18 | D18: 设计部 | E18: 设计组
A19: 五楼 | B19: 王一程 | C19: 19 | D19: 设计部 | E19: 设计组 | F19: 08:26 | G19: 0.75138889 | H19: =MOD(G19-F19,1)*24 | I19: 1 | J19: 0.35069444 | K19: 0.75138889 | L19: =MOD(K19-J19,1)*24 | M19: 1 | N19: 0.35208333 | O19: 0.75277778 | P19: =MOD(O19-N19,1)*24 | Q19: 1 | R19: 0.35069444 | S19: 0.75347222 | T19: =MOD(S19-R19,1)*24 | U19: 1 | V19: 0.34722222 | W19: 0.75138889 | X19: =MOD(W19-V19,1)*24 | Y19: 1 | Z19: 0.35277778 | AA19: 0.75486111 | AB19: =MOD(AA19-Z19,1)*24 | AC19: 1 | AH19: 0.35277778 | AI19: 0.75138889 | AJ19: =MOD(AI19-AH19,1)*24 | AK19: 1 | AL19: 0.35069444 | AM19: 0.75138889 | AN19: =MOD(AM19-AL19,1)*24 | AO19: 1 | AP19: 0.35208333 | AQ19: 0.75138889 | AR19: =MOD(AQ19-AP19,1)*24 | AS19: 1 | AT19: 0.34236111 | AU19: 0.75208333 | AV19: =MOD(AU19-AT19,1)*24 | AW19: 1 | AX19: 0.35138889 | AY19: 0.75208333 | AZ19: =MOD(AY19-AX19,1)*24 | BA19: 1 | BB19: 0.75138889 | BE19: 0.5 | BJ19: 0.35069444 | BK19: 0.75069444 | BL19: =MOD(BK19-BJ19,1)*24 | BM19: 1 | BN19: 0.35208333 | BO19: 0.75069444 | BP19: =MOD(BO19-BN19,1)*24 | BQ19: 1 | BR19: 0.35277778 | BS19: 0.75069444 | BT19: =MOD(BS19-BR19,1)*24 | BU19: 1 | BV19: 0.35208333 | BW19: 0.75138889 | BX19: =MOD(BW19-BV19,1)*24 | BY19: 1 | CH19: 0.35208333 | CI19: 0.75069444 | CJ19: =MOD(CI19-CH19,1)*24 | CK19: 1 | CL19: 0.35277778 | CM19: 0.75416667 | CN19: =MOD(CM19-CL19,1)*24 | CO19: 1 | CP19: 0.35069444 | CQ19: 0.75138889 | CR19: =MOD(CQ19-CP19,1)*24 | CS19: 1 | CT19: 0.35069444 | CU19: 0.75138889 | CV19: =MOD(CU19-CT19,1)*24 | CW19: 1 | CX19: 0.34791667 | CY19: 0.75555556 | CZ19: =MOD(CY19-CX19,1)*24 | DA19: 1 | DB19: 0.34930556 | DC19: 0.75208333 | DD19: =MOD(DC19-DB19,1)*24 | DE19: 1 | DF19: 0.35138889 | DG19: 0.75138889 | DH19: =MOD(DG19-DF19,1)*24 | DI19: 1 | DN19: 0.34930556 | DO19: 0.78402778 | DP19: =MOD(DO19-DN19,1)*24 | DQ19: 1 | DR19: 0.35069444 | DS19: 0.75138889 | DT19: =MOD(DS19-DR19,1)*24 | DU19: 1 | DZ19: =H19+L19+P19+T19+X19+AB19+AF19+AJ19+AN19+AR19+AV19+AZ19+BD19+BH19+BL19+BP19+BT19+BX19+CB19+CF19+CJ19+CN19+CR19+CV19+CZ19+DD19+DH19+DL19+DP19+DT19 | EA19: =I19+M19+Q19+U19+Y19+AC19+AG19+AK19+AO19+AS19+AW19+BA19+BE19+BI19+BM19+BQ19+BU19+BY19+CC19+CG19+CK19+CO19+CS19+CW19+DA19+DE19+DI19+DM19+DQ19+DU19
A20: 五楼 | B20: 龙训东 | C20: 21 | D20: 订单部 | E20: 审单组 | F20: 08:21 | G20: 0.75277778 | H20: =MOD(G20-F20,1)*24 | I20: 1 | J20: 0.34236111 | K20: 0.75902778 | L20: =MOD(K20-J20,1)*24 | M20: 1 | N20: 0.34652778 | O20: 0.75208333 | P20: =MOD(O20-N20,1)*24 | Q20: 1 | V20: 0.33333333 | W20: 0.75208333 | X20: =MOD(W20-V20,1)*24 | Y20: 1 | Z20: 0.33125 | AA20: 0.75138889 | AB20: =MOD(AA20-Z20,1)*24 | AC20: 1 | AD20: 0.34305556 | AE20: 0.75416667 | AF20: =MOD(AE20-AD20,1)*24 | AG20: 1 | AH20: 0.34444444 | AI20: 0.75138889 | AJ20: =MOD(AI20-AH20,1)*24 | AK20: 1 | AL20: 0.34930556 | AM20: 0.75138889 | AN20: =MOD(AM20-AL20,1)*24 | AO20: 1 | AT20: 0.33263889 | AU20: 0.75138889 | AV20: =MOD(AU20-AT20,1)*24 | AW20: 1 | AX20: 0.34722222 | AY20: 0.75902778 | AZ20: =MOD(AY20-AX20,1)*24 | BA20: 1 | BB20: 0.34861111 | BC20: 0.75416667 | BD20: =MOD(BC20-BB20,1)*24 | BE20: 1 | BF20: 0.34236111 | BG20: 0.75069444 | BH20: =MOD(BG20-BF20,1)*24 | BI20: 1 | BJ20: 0.33402778 | BK20: 0.75208333 | BL20: =MOD(BK20-BJ20,1)*24 | BM20: 1 | BN20: 0.34444444 | BO20: 0.75277778 | BP20: =MOD(BO20-BN20,1)*24 | BQ20: 1 | BR20: 0.35 | BS20: 0.75486111 | BT20: =MOD(BS20-BR20,1)*24 | BU20: 1 | BV20: 0.34583333 | BW20: 0.75208333 | BX20: =MOD(BW20-BV20,1)*24 | BY20: 1 | CH20: 0.33958333 | CI20: 0.75208333 | CJ20: =MOD(CI20-CH20,1)*24 | CK20: 1 | CL20: 0.34583333 | CM20: 0.75277778 | CN20: =MOD(CM20-CL20,1)*24 | CO20: 1 | CP20: 0.33680556 | CQ20: 0.75069444 | CR20: =MOD(CQ20-CP20,1)*24 | CS20: 1 | CT20: 0.34444444 | CU20: 0.75347222 | CV20: =MOD(CU20-CT20,1)*24 | CW20: 1 | DB20: 0.33541667 | DC20: 0.75347222 | DD20: =MOD(DC20-DB20,1)*24 | DE20: 1 | DF20: 0.34722222 | DG20: 0.76805556 | DH20: =MOD(DG20-DF20,1)*24 | DI20: 1 | DJ20: 0.34027778 | DK20: 0.80902778 | DL20: =MOD(DK20-DJ20,1)*24 | DM20: 1 | DN20: 0.34791667 | DO20: 0.92638889 | DP20: =MOD(DO20-DN20,1)*24 | DQ20: 1 | DR20: 0.34791667 | DS20: 0.98055556 | DT20: =MOD(DS20-DR20,1)*24 | DU20: 1 | DZ20: =H20+L20+P20+T20+X20+AB20+AF20+AJ20+AN20+AR20+AV20+AZ20+BD20+BH20+BL20+BP20+BT20+BX20+CB20+CF20+CJ20+CN20+CR20+CV20+CZ20+DD20+DH20+DL20+DP20+DT20 | EA20: =I20+M20+Q20+U20+Y20+AC20+AG20+AK20+AO20+AS20+AW20+BA20+BE20+BI20+BM20+BQ20+BU20+BY20+CC20+CG20+CK20+CO20+CS20+CW20+DA20+DE20+DI20+DM20+DQ20+DU20
A21: 五楼 | B21: 李荧 | C21: 22 | D21: 订单部 | E21: 审单组 | F21: 08:20 | G21: 0.75625 | H21: =MOD(G21-F21,1)*24 | I21: 1 | J21: 0.33888889 | K21: 0.75069444 | L21: =MOD(K21-J21,1)*24 | M21: 1 | N21: 0.34722222 | O21: 0.75138889 | P21: =MOD(O21-N21,1)*24 | Q21: 1 | R21: 0.34375 | S21: 0.76388889 | T21: =MOD(S21-R21,1)*24 | U21: 1 | V21: 0.33819444 | W21: 0.75833333 | X21: =MOD(W21-V21,1)*24 | Y21: 1 | Z21: 0.33263889 | AA21: 0.77361111 | AB21: =MOD(AA21-Z21,1)*24 | AC21: 1 | AH21: 0.34305556 | AI21: 0.75833333 | AJ21: =MOD(AI21-AH21,1)*24 | AK21: 1 | AL21: 0.34375 | AM21: 0.75277778 | AN21: =MOD(AM21-AL21,1)*24 | AO21: 1 | AP21: 0.34513889 | AQ21: 0.75 | AR21: =MOD(AQ21-AP21,1)*24 | AS21: 1 | AT21: 0.34166667 | AU21: 0.75833333 | AV21: =MOD(AU21-AT21,1)*24 | AW21: 1 | AX21: 0.34652778 | AY21: 0.75763889 | AZ21: =MOD(AY21-AX21,1)*24 | BA21: 1 | BB21: 0.35 | BC21: 0.75555556 | BD21: =MOD(BC21-BB21,1)*24 | BE21: 1 | BJ21: 0.35069444 | BK21: 0.75138889 | BL21: =MOD(BK21-BJ21,1)*24 | BM21: 1 | BN21: 0.34513889 | BO21: 0.75277778 | BP21: =MOD(BO21-BN21,1)*24 | BQ21: 1 | BR21: 0.34097222 | BS21: 0.75208333 | BT21: =MOD(BS21-BR21,1)*24 | BU21: 1 | BV21: 0.34027778 | BW21: 0.75138889 | BX21: =MOD(BW21-BV21,1)*24 | BY21: 1 | CH21: 0.34652778 | CI21: 0.75833333 | CJ21: =MOD(CI21-CH21,1)*24 | CK21: 1 | CL21: 0.34722222 | CM21: 0.77569444 | CN21: =MOD(CM21-CL21,1)*24 | CO21: 1 | CP21: 0.34375 | CQ21: 0.75069444 | CR21: =MOD(CQ21-CP21,1)*24 | CS21: 1 | CT21: 0.34166667 | CU21: 0.75208333 | CV21: =MOD(CU21-CT21,1)*24 | CW21: 1 | DB21: 0.34166667 | DC21: 0.76666667 | DD21: =MOD(DC21-DB21,1)*24 | DE21: 1 | DF21: 0.34097222 | DG21: 0.76597222 | DH21: =MOD(DG21-DF21,1)*24 | DI21: 1 | DJ21: 0.35 | DK21: 0.76597222 | DL21: =MOD(DK21-DJ21,1)*24 | DM21: 1 | DN21: 0.34652778 | DO21: 0.92777778 | DP21: =MOD(DO21-DN21,1)*24 | DQ21: 1 | DR21: 0.98402778 | DU21: 0.5 | DZ21: =H21+L21+P21+T21+X21+AB21+AF21+AJ21+AN21+AR21+AV21+AZ21+BD21+BH21+BL21+BP21+BT21+BX21+CB21+CF21+CJ21+CN21+CR21+CV21+CZ21+DD21+DH21+DL21+DP21+DT21 | EA21: =I21+M21+Q21+U21+Y21+AC21+AG21+AK21+AO21+AS21+AW21+BA21+BE21+BI21+BM21+BQ21+BU21+BY21+CC21+CG21+CK21+CO21+CS21+CW21+DA21+DE21+DI21+DM21+DQ21+DU21
A22: 五楼 | B22: 贺悦 | C22: 23 | D22: 信息部 | E22: 信息部 | F22: 08:24 | G22: 0.75138889 | H22: =MOD(G22-F22,1)*24 | I22: 1 | J22: 0.35138889 | K22: 0.75625 | L22: =MOD(K22-J22,1)*24 | M22: 1 | N22: 0.34652778 | O22: 0.75208333 | P22: =MOD(O22-N22,1)*24 | Q22: 1 | R22: 0.35069444 | S22: 0.75486111 | T22: =MOD(S22-R22,1)*24 | U22: 1 | V22: 0.35 | W22: 0.7625 | X22: =MOD(W22-V22,1)*24 | Y22: 1 | Z22: 0.35069444 | AA22: 0.75138889 | AB22: =MOD(AA22-Z22,1)*24 | AC22: 1 | AH22: 0.34930556 | AI22: 0.75069444 | AJ22: =MOD(AI22-AH22,1)*24 | AK22: 1 | AL22: 0.34861111 | AM22: 0.75138889 | AN22: =MOD(AM22-AL22,1)*24 | AO22: 1 | AP22: 0.35069444 | AQ22: 0.75069444 | AR22: =MOD(AQ22-AP22,1)*24 | AS22: 1 | AT22: 0.35138889 | AU22: 0.75208333 | AV22: =MOD(AU22-AT22,1)*24 | AW22: 1 | AX22: 0.35 | AY22: 0.7625 | AZ22: =MOD(AY22-AX22,1)*24 | BA22: 1 | BB22: 0.35208333 | BC22: 0.75 | BD22: =MOD(BC22-BB22,1)*24 | BE22: 1 | BJ22: 0.34930556 | BK22: 0.76041667 | BL22: =MOD(BK22-BJ22,1)*24 | BM22: 1 | BN22: 0.35 | BO22: 0.75416667 | BP22: =MOD(BO22-BN22,1)*24 | BQ22: 1 | BR22: 0.35138889 | BS22: 0.75138889 | BT22: =MOD(BS22-BR22,1)*24 | BU22: 1 | BV22: 0.35277778 | BW22: 0.75138889 | BX22: =MOD(BW22-BV22,1)*24 | BY22: 1 | CH22: 0.35208333 | CI22: 0.75347222 | CJ22: =MOD(CI22-CH22,1)*24 | CK22: 1 | CL22: 0.35 | CM22: 0.75486111 | CN22: =MOD(CM22-CL22,1)*24 | CO22: 1 | CP22: 0.35277778 | CQ22: 0.79861111 | CR22: =MOD(CQ22-CP22,1)*24 | CS22: 1 | CT22: 0.35347222 | CU22: 0.79861111 | CV22: =MOD(CU22-CT22,1)*24 | CW22: 1 | CX22: 0.35 | CZ22: =MOD(CY22-CX22,1)*24 | DA22: 0.5 | DB22: 0.35277778 | DC22: 0.78958333 | DD22: =MOD(DC22-DB22,1)*24 | DE22: 1 | DF22: 0.35208333 | DG22: 0.75138889 | DH22: =MOD(DG22-DF22,1)*24 | DI22: 1 | DN22: 0.35 | DO22: 0.75972222 | DP22: =MOD(DO22-DN22,1)*24 | DQ22: 1 | DR22: 0.35208333 | DS22: 0.75555556 | DT22: =MOD(DS22-DR22,1)*24 | DU22: 1 | DZ22: =H22+L22+P22+T22+X22+AB22+AF22+AJ22+AN22+AR22+AV22+AZ22+BD22+BH22+BL22+BP22+BT22+BX22+CB22+CF22+CJ22+CN22+CR22+CV22+CZ22+DD22+DH22+DL22+DP22+DT22 | EA22: =I22+M22+Q22+U22+Y22+AC22+AG22+AK22+AO22+AS22+AW22+BA22+BE22+BI22+BM22+BQ22+BU22+BY22+CC22+CG22+CK22+CO22+CS22+CW22+DA22+DE22+DI22+DM22+DQ22+DU22
A23: 五楼 | B23: 莫娇 | C23: 24 | D23: 订单部 | E23: 接单报价组 | F23: 08:25 | G23: 0.75069444 | H23: =MOD(G23-F23,1)*24 | I23: 1 | J23: 0.35138889 | K23: 0.75069444 | L23: =MOD(K23-J23,1)*24 | M23: 1 | R23: 0.34791667 | S23: 0.75069444 | T23: =MOD(S23-R23,1)*24 | U23: 1 | V23: 0.34861111 | W23: 0.75069444 | X23: =MOD(W23-V23,1)*24 | Y23: 1 | Z23: 0.34930556 | AA23: 0.75069444 | AB23: =MOD(AA23-Z23,1)*24 | AC23: 1 | AD23: 0.35 | AE23: 0.75069444 | AF23: =MOD(AE23-AD23,1)*24 | AG23: 1 | AH23: 0.35277778 | AI23: 0.75138889 | AJ23: =MOD(AI23-AH23,1)*24 | AK23: 1 | AL23: 0.34930556 | AM23: 0.75069444 | AN23: =MOD(AM23-AL23,1)*24 | AO23: 1 | AP23: 0.35 | AQ23: 0.75069444 | AR23: =MOD(AQ23-AP23,1)*24 | AS23: 1 | AT23: 0.34861111 | AU23: 0.75069444 | AV23: =MOD(AU23-AT23,1)*24 | AW23: 1 | AX23: 0.34861111 | AY23: 0.75138889 | AZ23: =MOD(AY23-AX23,1)*24 | BA23: 1 | BB23: 0.34930556 | BC23: 0.75069444 | BD23: =MOD(BC23-BB23,1)*24 | BE23: 1 | BJ23: 0.34722222 | BK23: 0.75138889 | BL23: =MOD(BK23-BJ23,1)*24 | BM23: 1 | BN23: 0.34791667 | BO23: 0.75069444 | BP23: =MOD(BO23-BN23,1)*24 | BQ23: 1 | BR23: 0.35069444 | BS23: 0.75069444 | BT23: =MOD(BS23-BR23,1)*24 | BU23: 1 | BV23: 0.34930556 | BW23: 0.75069444 | BX23: =MOD(BW23-BV23,1)*24 | BY23: 1 | CH23: 0.34861111 | CI23: 0.75069444 | CJ23: =MOD(CI23-CH23,1)*24 | CK23: 1 | CL23: 0.35 | CM23: 0.75138889 | CN23: =MOD(CM23-CL23,1)*24 | CO23: 1 | CP23: 0.34722222 | CQ23: 0.75069444 | CR23: =MOD(CQ23-CP23,1)*24 | CS23: 1 | CT23: 0.34583333 | CU23: 0.75069444 | CV23: =MOD(CU23-CT23,1)*24 | CW23: 1 | CX23: 0.35 | CY23: 0.75069444 | CZ23: =MOD(CY23-CX23,1)*24 | DA23: 1 | DF23: 0.34652778 | DG23: 0.75069444 | DH23: =MOD(DG23-DF23,1)*24 | DI23: 1 | DJ23: 0.34097222 | DK23: 0.75069444 | DL23: =MOD(DK23-DJ23,1)*24 | DM23: 1 | DN23: 0.35069444 | DO23: 0.75069444 | DP23: =MOD(DO23-DN23,1)*24 | DQ23: 1 | DR23: 0.34722222 | DS23: 0.96736111 | DT23: =MOD(DS23-DR23,1)*24 | DU23: 1 | DZ23: =H23+L23+P23+T23+X23+AB23+AF23+AJ23+AN23+AR23+AV23+AZ23+BD23+BH23+BL23+BP23+BT23+BX23+CB23+CF23+CJ23+CN23+CR23+CV23+CZ23+DD23+DH23+DL23+DP23+DT23 | EA23: =I23+M23+Q23+U23+Y23+AC23+AG23+AK23+AO23+AS23+AW23+BA23+BE23+BI23+BM23+BQ23+BU23+BY23+CC23+CG23+CK23+CO23+CS23+CW23+DA23+DE23+DI23+DM23+DQ23+DU23
A24: 五楼 | B24: 田建锋 | C24: 26 | D24: 订单部 | E24: 审单组 | F24: 08:13 | G24: 0.79583333 | H24: =MOD(G24-F24,1)*24 | I24: 1 | J24: 0.34652778 | K24: 0.5 | L24: =MOD(K24-J24,1)*24 | M24: 0.5 | N24: 0.34791667 | O24: 0.75138889 | P24: =MOD(O24-N24,1)*24 | Q24: 1 | R24: 0.34861111 | S24: 0.81111111 | T24: =MOD(S24-R24,1)*24 | U24: 1 | V24: 0.34027778 | W24: 0.76111111 | X24: =MOD(W24-V24,1)*24 | Y24: 1 | Z24: 0.75694444 | AC24: 0.5 | AD24: 0.34722222 | AE24: 0.75 | AF24: =MOD(AE24-AD24,1)*24 | AG24: 1 | AH24: 0.34583333 | AI24: 0.75138889 | AJ24: =MOD(AI24-AH24,1)*24 | AK24: 1 | AL24: 0.34652778 | AM24: 0.5 | AN24: =MOD(AM24-AL24,1)*24 | AO24: 0.5 | AP24: 0.34583333 | AQ24: 0.78055556 | AR24: =MOD(AQ24-AP24,1)*24 | AS24: 1 | AT24: 0.34027778 | AU24: 0.75833333 | AV24: =MOD(AU24-AT24,1)*24 | AW24: 1 | AX24: 0.34444444 | AY24: 0.75763889 | AZ24: =MOD(AY24-AX24,1)*24 | BA24: 1 | BB24: 0.34513889 | BC24: 0.76458333 | BD24: =MOD(BC24-BB24,1)*24 | BE24: 1 | BJ24: 0.34305556 | BK24: 0.75138889 | BL24: =MOD(BK24-BJ24,1)*24 | BM24: 1 | BN24: 0.34513889 | BO24: 0.75416667 | BP24: =MOD(BO24-BN24,1)*24 | BQ24: 1 | BR24: 0.35069444 | BS24: 0.75208333 | BT24: =MOD(BS24-BR24,1)*24 | BU24: 1 | BV24: 0.34513889 | BW24: 0.75069444 | BX24: =MOD(BW24-BV24,1)*24 | BY24: 1 | CD24: 0.34097222 | CE24: 0.75069444 | CF24: =MOD(CE24-CD24,1)*24 | CG24: 1 | CH24: 0.34652778 | CI24: 0.75555556 | CJ24: =MOD(CI24-CH24,1)*24 | CK24: 1 | CL24: 0.34583333 | CM24: 0.50069444 | CN24: =MOD(CM24-CL24,1)*24 | CO24: 0.5 | CP24: 0.34583333 | CQ24: 0.75069444 | CR24: =MOD(CQ24-CP24,1)*24 | CS24: 1 | CT24: 0.34375 | CU24: 0.75833333 | CV24: =MOD(CU24-CT24,1)*24 | CW24: 1 | CX24: 0.34930556 | CY24: 0.75069444 | CZ24: =MOD(CY24-CX24,1)*24 | DA24: 1 | DF24: 0.34583333 | DG24: 0.75625 | DH24: =MOD(DG24-DF24,1)*24 | DI24: 1 | DJ24: 0.34375 | DK24: 0.76597222 | DL24: =MOD(DK24-DJ24,1)*24 | DM24: 1 | DN24: 0.34236111 | DO24: 0.92361111 | DP24: =MOD(DO24-DN24,1)*24 | DQ24: 1 | DR24: 0.34305556 | DS24: 0.94097222 | DT24: =MOD(DS24-DR24,1)*24 | DU24: 1 | DZ24: =H24+L24+P24+T24+X24+AB24+AF24+AJ24+AN24+AR24+AV24+AZ24+BD24+BH24+BL24+BP24+BT24+BX24+CB24+CF24+CJ24+CN24+CR24+CV24+CZ24+DD24+DH24+DL24+DP24+DT24 | EA24: =I24+M24+Q24+U24+Y24+AC24+AG24+AK24+AO24+AS24+AW24+BA24+BE24+BI24+BM24+BQ24+BU24+BY24+CC24+CG24+CK24+CO24+CS24+CW24+DA24+DE24+DI24+DM24+DQ24+DU24
A25: 五楼 | B25: 李红波 | C25: 27 | D25: 订单部 | E25: 审单组 | F25: 08:23 | G25: 0.75208333 | H25: =MOD(G25-F25,1)*24 | I25: 1 | J25: 0.35 | K25: 0.75138889 | L25: =MOD(K25-J25,1)*24 | M25: 1 | N25: 0.34444444 | O25: 0.75138889 | P25: =MOD(O25-N25,1)*24 | Q25: 1 | R25: 0.34375 | S25: 0.75347222 | T25: =MOD(S25-R25,1)*24 | U25: 1 | V25: 0.34305556 | W25: 0.75555556 | X25: =MOD(W25-V25,1)*24 | Y25: 1 | Z25: 0.34444444 | AA25: 0.75138889 | AB25: =MOD(AA25-Z25,1)*24 | AC25: 1 | AH25: 0.33888889 | AI25: 0.75416667 | AJ25: =MOD(AI25-AH25,1)*24 | AK25: 1 | AL25: 0.34722222 | AM25: 0.75555556 | AN25: =MOD(AM25-AL25,1)*24 | AO25: 1 | AP25: 0.34930556 | AQ25: 0.75347222 | AR25: =MOD(AQ25-AP25,1)*24 | AS25: 1 | AT25: 0.34375 | AU25: 0.75902778 | AV25: =MOD(AU25-AT25,1)*24 | AW25: 1 | AX25: 0.34722222 | AY25: 0.75277778 | AZ25: =MOD(AY25-AX25,1)*24 | BA25: 1 | BB25: 0.34444444 | BC25: 0.75277778 | BD25: =MOD(BC25-BB25,1)*24 | BE25: 1 | BJ25: 0.34305556 | BK25: 0.75208333 | BL25: =MOD(BK25-BJ25,1)*24 | BM25: 1 | BN25: 0.34652778 | BO25: 0.75138889 | BP25: =MOD(BO25-BN25,1)*24 | BQ25: 1 | BR25: 0.34652778 | BS25: 0.76805556 | BT25: =MOD(BS25-BR25,1)*24 | BU25: 1 | BV25: 0.34166667 | BW25: 0.75138889 | BX25: =MOD(BW25-BV25,1)*24 | BY25: 1 | CH25: 0.34236111 | CI25: 0.75833333 | CJ25: =MOD(CI25-CH25,1)*24 | CK25: 1 | CL25: 0.35 | CM25: 0.75486111 | CN25: =MOD(CM25-CL25,1)*24 | CO25: 1 | CP25: 0.34236111 | CQ25: 0.75069444 | CR25: =MOD(CQ25-CP25,1)*24 | CS25: 1 | CT25: 0.34652778 | CU25: 0.75069444 | CV25: =MOD(CU25-CT25,1)*24 | CW25: 1 | CX25: 0.34236111 | CY25: 0.75694444 | CZ25: =MOD(CY25-CX25,1)*24 | DA25: 1 | DB25: 0.34513889 | DC25: 0.75277778 | DD25: =MOD(DC25-DB25,1)*24 | DE25: 1 | DF25: 0.34513889 | DH25: =MOD(DG25-DF25,1)*24 | DI25: 1 | DN25: 0.34583333 | DO25: 0.75625 | DP25: =MOD(DO25-DN25,1)*24 | DQ25: 1 | DR25: 0.34722222 | DS25: 0.78055556 | DT25: =MOD(DS25-DR25,1)*24 | DU25: 1 | DZ25: =H25+L25+P25+T25+X25+AB25+AF25+AJ25+AN25+AR25+AV25+AZ25+BD25+BH25+BL25+BP25+BT25+BX25+CB25+CF25+CJ25+CN25+CR25+CV25+CZ25+DD25+DH25+DL25+DP25+DT25 | EA25: =I25+M25+Q25+U25+Y25+AC25+AG25+AK25+AO25+AS25+AW25+BA25+BE25+BI25+BM25+BQ25+BU25+BY25+CC25+CG25+CK25+CO25+CS25+CW25+DA25+DE25+DI25+DM25+DQ25+DU25
A26: 五楼 | B26: 陈明会 | C26: 28 | D26: 综合部 | E26: 财务核价 | F26: 08:16 | G26: 0.75416667 | H26: =MOD(G26-F26,1)*24 | I26: 1 | J26: 0.32777778 | K26: 0.75138889 | L26: =MOD(K26-J26,1)*24 | M26: 1 | N26: 0.34305556 | O26: 0.75902778 | P26: =MOD(O26-N26,1)*24 | Q26: 1 | R26: 0.32638889 | S26: 0.8 | T26: =MOD(S26-R26,1)*24 | U26: 1 | V26: 0.34583333 | W26: 0.75763889 | X26: =MOD(W26-V26,1)*24 | Y26: 1 | Z26: 0.34236111 | AA26: 0.75138889 | AB26: =MOD(AA26-Z26,1)*24 | AC26: 1 | AH26: 0.34583333 | AI26: 0.76597222 | AJ26: =MOD(AI26-AH26,1)*24 | AK26: 1 | AL26: 0.34444444 | AM26: 0.75763889 | AN26: =MOD(AM26-AL26,1)*24 | AO26: 1 | AP26: 0.34097222 | AQ26: 0.75625 | AR26: =MOD(AQ26-AP26,1)*24 | AS26: 1 | AT26: 0.32430556 | AU26: 0.75208333 | AV26: =MOD(AU26-AT26,1)*24 | AW26: 1 | AX26: 0.33888889 | AY26: 0.75277778 | AZ26: =MOD(AY26-AX26,1)*24 | BA26: 1 | BB26: 0.34444444 | BC26: 0.75208333 | BD26: =MOD(BC26-BB26,1)*24 | BE26: 1 | BJ26: 0.34375 | BK26: 0.75277778 | BL26: =MOD(BK26-BJ26,1)*24 | BM26: 1 | BN26: 0.33472222 | BO26: 0.75208333 | BP26: =MOD(BO26-BN26,1)*24 | BQ26: 1 | BR26: 0.32777778 | BS26: 0.75138889 | BT26: =MOD(BS26-BR26,1)*24 | BU26: 1 | BV26: 0.33472222 | BW26: 0.75347222 | BX26: =MOD(BW26-BV26,1)*24 | BY26: 1 | CH26: 0.33680556 | CI26: 0.75 | CJ26: =MOD(CI26-CH26,1)*24 | CK26: 1 | CL26: 0.34097222 | CM26: 0.75208333 | CN26: =MOD(CM26-CL26,1)*24 | CO26: 1 | CP26: 0.32638889 | CQ26: 0.75555556 | CR26: =MOD(CQ26-CP26,1)*24 | CS26: 1 | CT26: 0.33402778 | CU26: 0.75208333 | CV26: =MOD(CU26-CT26,1)*24 | CW26: 1 | CX26: 0.34513889 | CY26: 0.76875 | CZ26: =MOD(CY26-CX26,1)*24 | DA26: 1 | DB26: 0.33402778 | DC26: 0.75833333 | DD26: =MOD(DC26-DB26,1)*24 | DE26: 1 | DF26: 0.34236111 | DG26: 0.75694444 | DH26: =MOD(DG26-DF26,1)*24 | DI26: 1 | DN26: 0.34375 | DO26: 0.80277778 | DP26: =MOD(DO26-DN26,1)*24 | DQ26: 1 | DR26: 0.34583333 | DS26: 0.87361111 | DT26: =MOD(DS26-DR26,1)*24 | DU26: 1 | DZ26: =H26+L26+P26+T26+X26+AB26+AF26+AJ26+AN26+AR26+AV26+AZ26+BD26+BH26+BL26+BP26+BT26+BX26+CB26+CF26+CJ26+CN26+CR26+CV26+CZ26+DD26+DH26+DL26+DP26+DT26 | EA26: =I26+M26+Q26+U26+Y26+AC26+AG26+AK26+AO26+AS26+AW26+BA26+BE26+BI26+BM26+BQ26+BU26+BY26+CC26+CG26+CK26+CO26+CS26+CW26+DA26+DE26+DI26+DM26+DQ26+DU26
A27: 五楼 | B27: 张金彬 | C27: 29 | D27: 设计部 | E27: 设计组 | F27: 08:20 | G27: 0.75694444 | H27: =MOD(G27-F27,1)*24 | I27: 1 | J27: 0.35208333 | K27: 0.75486111 | L27: =MOD(K27-J27,1)*24 | M27: 1 | N27: 0.34791667 | O27: 0.75694444 | P27: =MOD(O27-N27,1)*24 | Q27: 1 | R27: 0.34791667 | S27: 0.81944444 | T27: =MOD(S27-R27,1)*24 | U27: 1 | V27: 0.34722222 | W27: 0.75972222 | X27: =MOD(W27-V27,1)*24 | Y27: 1 | Z27: 0.34791667 | AA27: 0.75833333 | AB27: =MOD(AA27-Z27,1)*24 | AC27: 1 | AH27: 0.75208333 | AK27: 0.5 | AL27: 0.35208333 | AM27: 0.75277778 | AN27: =MOD(AM27-AL27,1)*24 | AO27: 1 | AP27: 0.35 | AQ27: 0.90694444 | AR27: =MOD(AQ27-AP27,1)*24 | AS27: 1 | AT27: 0.35277778 | AU27: 0.75416667 | AV27: =MOD(AU27-AT27,1)*24 | AW27: 1 | AX27: 0.34722222 | AY27: 0.75208333 | AZ27: =MOD(AY27-AX27,1)*24 | BA27: 1 | BB27: 0.34652778 | BC27: 0.75069444 | BD27: =MOD(BC27-BB27,1)*24 | BE27: 1 | BJ27: 0.35347222 | BK27: 0.75208333 | BL27: =MOD(BK27-BJ27,1)*24 | BM27: 1 | BN27: 0.34930556 | BO27: 0.75208333 | BP27: =MOD(BO27-BN27,1)*24 | BQ27: 1 | BR27: 0.34930556 | BS27: 0.75277778 | BT27: =MOD(BS27-BR27,1)*24 | BU27: 1 | BV27: 0.34930556 | BW27: 0.75555556 | BX27: =MOD(BW27-BV27,1)*24 | BY27: 1 | CH27: 0.35 | CI27: 0.75694444 | CJ27: =MOD(CI27-CH27,1)*24 | CK27: 1 | CL27: 0.34930556 | CM27: 0.75416667 | CN27: =MOD(CM27-CL27,1)*24 | CO27: 1 | CP27: 0.34930556 | CQ27: 0.75972222 | CR27: =MOD(CQ27-CP27,1)*24 | CS27: 1 | CT27: 0.35 | CU27: 0.75138889 | CV27: =MOD(CU27-CT27,1)*24 | CW27: 1 | CX27: 0.34930556 | CY27: 0.76180556 | CZ27: =MOD(CY27-CX27,1)*24 | DA27: 1 | DB27: 0.35 | DC27: 0.75694444 | DD27: =MOD(DC27-DB27,1)*24 | DE27: 1 | DF27: 0.34513889 | DG27: 0.75208333 | DH27: =MOD(DG27-DF27,1)*24 | DI27: 1 | DN27: 0.34861111 | DO27: 0.75416667 | DP27: =MOD(DO27-DN27,1)*24 | DQ27: 1 | DR27: 0.34722222 | DS27: 0.77013889 | DT27: =MOD(DS27-DR27,1)*24 | DU27: 1 | DZ27: =H27+L27+P27+T27+X27+AB27+AF27+AJ27+AN27+AR27+AV27+AZ27+BD27+BH27+BL27+BP27+BT27+BX27+CB27+CF27+CJ27+CN27+CR27+CV27+CZ27+DD27+DH27+DL27+DP27+DT27 | EA27: =I27+M27+Q27+U27+Y27+AC27+AG27+AK27+AO27+AS27+AW27+BA27+BE27+BI27+BM27+BQ27+BU27+BY27+CC27+CG27+CK27+CO27+CS27+CW27+DA27+DE27+DI27+DM27+DQ27+DU27
A28: 五楼 | B28: 吕丹丹 | C28: 31 | D28: 订单部 | E28: 接单报价组 | F28: 08:26 | G28: 0.75069444 | H28: =MOD(G28-F28,1)*24 | I28: 1 | J28: 0.35138889 | K28: 0.75069444 | L28: =MOD(K28-J28,1)*24 | M28: 1 | R28: 0.34791667 | S28: 0.75069444 | T28: =MOD(S28-R28,1)*24 | U28: 1 | V28: 0.34861111 | W28: 0.75 | X28: =MOD(W28-V28,1)*24 | Y28: 1 | Z28: 0.34930556 | AA28: 0.75069444 | AB28: =MOD(AA28-Z28,1)*24 | AC28: 1 | AD28: 0.35 | AE28: 0.75069444 | AF28: =MOD(AE28-AD28,1)*24 | AG28: 1 | AH28: 0.35277778 | AI28: 0.75069444 | AJ28: =MOD(AI28-AH28,1)*24 | AK28: 1 | AL28: 0.34930556 | AM28: 0.75069444 | AN28: =MOD(AM28-AL28,1)*24 | AO28: 1 | AP28: 0.35 | AQ28: 0.75069444 | AR28: =MOD(AQ28-AP28,1)*24 | AS28: 1 | AT28: 0.34861111 | AU28: 0.75138889 | AV28: =MOD(AU28-AT28,1)*24 | AW28: 1 | AX28: 0.34861111 | AY28: 0.75069444 | AZ28: =MOD(AY28-AX28,1)*24 | BA28: 1 | BB28: 0.34930556 | BC28: 0.75069444 | BD28: =MOD(BC28-BB28,1)*24 | BE28: 1 | BJ28: 0.34791667 | BK28: 0.75069444 | BL28: =MOD(BK28-BJ28,1)*24 | BM28: 1 | BN28: 0.34791667 | BO28: 0.75069444 | BP28: =MOD(BO28-BN28,1)*24 | BQ28: 1 | BR28: 0.35069444 | BS28: 0.75138889 | BT28: =MOD(BS28-BR28,1)*24 | BU28: 1 | BV28: 0.34930556 | BW28: 0.75069444 | BX28: =MOD(BW28-BV28,1)*24 | BY28: 1 | CH28: 0.34861111 | CI28: 0.75069444 | CJ28: =MOD(CI28-CH28,1)*24 | CK28: 1 | CL28: 0.35 | CM28: 0.75138889 | CN28: =MOD(CM28-CL28,1)*24 | CO28: 1 | CP28: 0.34791667 | CQ28: 0.75069444 | CR28: =MOD(CQ28-CP28,1)*24 | CS28: 1 | CT28: 0.34583333 | CU28: 0.75138889 | CV28: =MOD(CU28-CT28,1)*24 | CW28: 1 | CX28: 0.35 | CY28: 0.75069444 | CZ28: =MOD(CY28-CX28,1)*24 | DA28: 1 | DB28: 0.35277778 | DC28: 0.75069444 | DD28: =MOD(DC28-DB28,1)*24 | DE28: 1 | DF28: 0.34652778 | DG28: 0.75069444 | DH28: =MOD(DG28-DF28,1)*24 | DI28: 1 | DN28: 0.35069444 | DO28: 0.75277778 | DP28: =MOD(DO28-DN28,1)*24 | DQ28: 1 | DR28: 0.34722222 | DS28: 0.76666667 | DT28: =MOD(DS28-DR28,1)*24 | DU28: 1 | DZ28: =H28+L28+P28+T28+X28+AB28+AF28+AJ28+AN28+AR28+AV28+AZ28+BD28+BH28+BL28+BP28+BT28+BX28+CB28+CF28+CJ28+CN28+CR28+CV28+CZ28+DD28+DH28+DL28+DP28+DT28 | EA28: =I28+M28+Q28+U28+Y28+AC28+AG28+AK28+AO28+AS28+AW28+BA28+BE28+BI28+BM28+BQ28+BU28+BY28+CC28+CG28+CK28+CO28+CS28+CW28+DA28+DE28+DI28+DM28+DQ28+DU28
A29: 五楼 | B29: 李光义 | C29: 32 | D29: 综合部 | E29: 固豪售后 | F29: 08:29 | G29: 0.75138889 | H29: =MOD(G29-F29,1)*24 | I29: 1 | J29: 0.35069444 | K29: 0.75069444 | L29: =MOD(K29-J29,1)*24 | M29: 1 | N29: 0.35208333 | O29: 0.75069444 | P29: =MOD(O29-N29,1)*24 | Q29: 1 | R29: 0.325 | S29: 0.75972222 | T29: =MOD(S29-R29,1)*24 | U29: 1 | V29: 0.33402778 | W29: 0.84930556 | X29: =MOD(W29-V29,1)*24 | Y29: 1 | Z29: 0.35069444 | AA29: 0.75486111 | AB29: =MOD(AA29-Z29,1)*24 | AC29: 1 | AH29: 0.33958333 | AI29: 0.75208333 | AJ29: =MOD(AI29-AH29,1)*24 | AK29: 1 | AL29: 0.34791667 | AM29: 0.75069444 | AN29: =MOD(AM29-AL29,1)*24 | AO29: 1 | AP29: 0.35 | AQ29: 0.75069444 | AR29: =MOD(AQ29-AP29,1)*24 | AS29: 1 | AT29: 0.3375 | AU29: 0.77013889 | AV29: =MOD(AU29-AT29,1)*24 | AW29: 1 | AX29: 0.33402778 | AY29: 0.86111111 | AZ29: =MOD(AY29-AX29,1)*24 | BA29: 1 | BB29: 0.33472222 | BC29: 0.75 | BD29: =MOD(BC29-BB29,1)*24 | BE29: 1 | BJ29: 0.33680556 | BK29: 0.75069444 | BL29: =MOD(BK29-BJ29,1)*24 | BM29: 1 | BN29: 0.3375 | BO29: 0.75138889 | BP29: =MOD(BO29-BN29,1)*24 | BQ29: 1 | BR29: 0.33888889 | BS29: 0.76111111 | BT29: =MOD(BS29-BR29,1)*24 | BU29: 1 | BV29: 0.33125 | BW29: 0.75208333 | BX29: =MOD(BW29-BV29,1)*24 | BY29: 1 | CH29: 0.35277778 | CI29: 0.75138889 | CJ29: =MOD(CI29-CH29,1)*24 | CK29: 1 | CL29: 0.33611111 | CM29: 0.75347222 | CN29: =MOD(CM29-CL29,1)*24 | CO29: 1 | CP29: 0.35138889 | CQ29: 0.88541667 | CR29: =MOD(CQ29-CP29,1)*24 | CS29: 1 | CT29: 0.33888889 | CU29: 0.75347222 | CV29: =MOD(CU29-CT29,1)*24 | CW29: 1 | CX29: 0.33402778 | CY29: 0.78402778 | CZ29: =MOD(CY29-CX29,1)*24 | DA29: 1 | DB29: 0.35277778 | DC29: 0.89027778 | DD29: =MOD(DC29-DB29,1)*24 | DE29: 1 | DF29: 0.35208333 | DG29: 0.75138889 | DH29: =MOD(DG29-DF29,1)*24 | DI29: 1 | DN29: 0.35208333 | DO29: 0.75138889 | DP29: =MOD(DO29-DN29,1)*24 | DQ29: 1 | DR29: 0.32569444 | DS29: 0.75138889 | DT29: =MOD(DS29-DR29,1)*24 | DU29: 1 | DZ29: =H29+L29+P29+T29+X29+AB29+AF29+AJ29+AN29+AR29+AV29+AZ29+BD29+BH29+BL29+BP29+BT29+BX29+CB29+CF29+CJ29+CN29+CR29+CV29+CZ29+DD29+DH29+DL29+DP29+DT29 | EA29: =I29+M29+Q29+U29+Y29+AC29+AG29+AK29+AO29+AS29+AW29+BA29+BE29+BI29+BM29+BQ29+BU29+BY29+CC29+CG29+CK29+CO29+CS29+CW29+DA29+DE29+DI29+DM29+DQ29+DU29
A30: 五楼 | B30: 李光义 | C30: 32 | D30: 综合部 | E30: 固豪售后
A31: 五楼 | B31: 匡启素 | C31: 33 | D31: 综合部 | E31: 综合部 | F31: 08:16 | G31: 0.76597222 | H31: =MOD(G31-F31,1)*24 | I31: 1 | J31: 0.34166667 | K31: 0.86319444 | L31: =MOD(K31-J31,1)*24 | M31: 1 | N31: 0.33680556 | O31: 0.78541667 | P31: =MOD(O31-N31,1)*24 | Q31: 1 | R31: 0.33888889 | S31: 0.8 | T31: =MOD(S31-R31,1)*24 | U31: 1 | V31: 0.32569444 | W31: 0.87083333 | X31: =MOD(W31-V31,1)*24 | Y31: 1 | Z31: 0.33958333 | AA31: 0.79652778 | AB31: =MOD(AA31-Z31,1)*24 | AC31: 1 | AH31: 0.33055556 | AI31: 0.78611111 | AJ31: =MOD(AI31-AH31,1)*24 | AK31: 1 | AL31: 0.3375 | AM31: 0.87986111 | AN31: =MOD(AM31-AL31,1)*24 | AO31: 1 | AP31: 0.34583333 | AQ31: 0.75625 | AR31: =MOD(AQ31-AP31,1)*24 | AS31: 1 | AT31: 0.34444444 | AU31: 0.78611111 | AV31: =MOD(AU31-AT31,1)*24 | AW31: 1 | AX31: 0.32777778 | AY31: 0.86805556 | AZ31: =MOD(AY31-AX31,1)*24 | BA31: 1 | BB31: 0.33125 | BC31: 0.76041667 | BD31: =MOD(BC31-BB31,1)*24 | BE31: 1 | BJ31: 0.33472222 | BK31: 0.78472222 | BL31: =MOD(BK31-BJ31,1)*24 | BM31: 1 | BN31: 0.34097222 | BQ31: 0.5 | BR31: 0.33958333 | BS31: 0.76041667 | BT31: =MOD(BS31-BR31,1)*24 | BU31: 1 | BV31: 0.34375 | BW31: 0.75625 | BX31: =MOD(BW31-BV31,1)*24 | BY31: 1 | CH31: 0.33402778 | CI31: 0.75763889 | CJ31: =MOD(CI31-CH31,1)*24 | CK31: 1 | CL31: 0.31944444 | CM31: 0.76458333 | CN31: =MOD(CM31-CL31,1)*24 | CO31: 1 | CP31: 0.33125 | CQ31: 0.89097222 | CR31: =MOD(CQ31-CP31,1)*24 | CS31: 1 | CT31: 0.33402778 | CU31: 0.78194444 | CV31: =MOD(CU31-CT31,1)*24 | CW31: 1 | CX31: 0.34305556 | CY31: 0.79097222 | CZ31: =MOD(CY31-CX31,1)*24 | DA31: 1 | DB31: 0.33611111 | DC31: 0.90555556 | DD31: =MOD(DC31-DB31,1)*24 | DE31: 1 | DF31: 0.34652778 | DG31: 0.77222222 | DH31: =MOD(DG31-DF31,1)*24 | DI31: 1 | DN31: 0.31944444 | DO31: 0.86388889 | DP31: =MOD(DO31-DN31,1)*24 | DQ31: 1 | DR31: 0.34097222 | DS31: 0.92777778 | DT31: =MOD(DS31-DR31,1)*24 | DU31: 1 | DZ31: =H31+L31+P31+T31+X31+AB31+AF31+AJ31+AN31+AR31+AV31+AZ31+BD31+BH31+BL31+BP31+BT31+BX31+CB31+CF31+CJ31+CN31+CR31+CV31+CZ31+DD31+DH31+DL31+DP31+DT31 | EA31: =I31+M31+Q31+U31+Y31+AC31+AG31+AK31+AO31+AS31+AW31+BA31+BE31+BI31+BM31+BQ31+BU31+BY31+CC31+CG31+CK31+CO31+CS31+CW31+DA31+DE31+DI31+DM31+DQ31+DU31
A32: 五楼 | B32: 兰媛 | C32: 35 | D32: 综合部 | E32: 财务核价 | F32: 08:25 | G32: 0.75138889 | H32: =MOD(G32-F32,1)*24 | I32: 1 | J32: 0.35069444 | K32: 0.75208333 | L32: =MOD(K32-J32,1)*24 | M32: 1 | N32: 0.35 | O32: 0.75902778 | P32: =MOD(O32-N32,1)*24 | Q32: 1 | R32: 0.35 | S32: 0.75555556 | T32: =MOD(S32-R32,1)*24 | U32: 1 | V32: 0.35 | W32: 0.75069444 | X32: =MOD(W32-V32,1)*24 | Y32: 1 | Z32: 0.35 | AA32: 0.75208333 | AB32: =MOD(AA32-Z32,1)*24 | AC32: 1 | AH32: 0.34861111 | AI32: 0.75138889 | AJ32: =MOD(AI32-AH32,1)*24 | AK32: 1 | AL32: 0.34930556 | AM32: 0.75138889 | AN32: =MOD(AM32-AL32,1)*24 | AO32: 1 | AP32: 0.35 | AQ32: 0.75138889 | AR32: =MOD(AQ32-AP32,1)*24 | AS32: 1 | AT32: 0.34583333 | AU32: 0.75138889 | AV32: =MOD(AU32-AT32,1)*24 | AW32: 1 | AX32: 0.34791667 | AY32: 0.75277778 | AZ32: =MOD(AY32-AX32,1)*24 | BA32: 1 | BF32: 0.35069444 | BG32: 0.75138889 | BH32: =MOD(BG32-BF32,1)*24 | BI32: 1 | BJ32: 0.34861111 | BK32: 0.75138889 | BL32: =MOD(BK32-BJ32,1)*24 | BM32: 1 | BN32: 0.34930556 | BO32: 0.75208333 | BP32: =MOD(BO32-BN32,1)*24 | BQ32: 1 | BR32: 0.34930556 | BS32: 0.75138889 | BT32: =MOD(BS32-BR32,1)*24 | BU32: 1 | BV32: 0.35 | BW32: 0.75138889 | BX32: =MOD(BW32-BV32,1)*24 | BY32: 1 | CH32: 0.34930556 | CI32: 0.75138889 | CJ32: =MOD(CI32-CH32,1)*24 | CK32: 1 | CL32: 0.34930556 | CM32: 0.75208333 | CN32: =MOD(CM32-CL32,1)*24 | CO32: 1 | CP32: 0.34791667 | CQ32: 0.75277778 | CR32: =MOD(CQ32-CP32,1)*24 | CS32: 1 | CT32: 0.34930556 | CU32: 0.75138889 | CV32: =MOD(CU32-CT32,1)*24 | CW32: 1 | CX32: 0.34930556 | CY32: 0.75347222 | CZ32: =MOD(CY32-CX32,1)*24 | DA32: 1 | DB32: 0.34722222 | DC32: 0.75972222 | DD32: =MOD(DC32-DB32,1)*24 | DE32: 1 | DF32: 0.35 | DG32: 0.76597222 | DH32: =MOD(DG32-DF32,1)*24 | DI32: 1 | DN32: 0.34861111 | DO32: 0.77916667 | DP32: =MOD(DO32-DN32,1)*24 | DQ32: 1 | DR32: 0.35 | DS32: 0.76944444 | DT32: =MOD(DS32-DR32,1)*24 | DU32: 1 | DZ32: =H32+L32+P32+T32+X32+AB32+AF32+AJ32+AN32+AR32+AV32+AZ32+BD32+BH32+BL32+BP32+BT32+BX32+CB32+CF32+CJ32+CN32+CR32+CV32+CZ32+DD32+DH32+DL32+DP32+DT32 | EA32: =I32+M32+Q32+U32+Y32+AC32+AG32+AK32+AO32+AS32+AW32+BA32+BE32+BI32+BM32+BQ32+BU32+BY32+CC32+CG32+CK32+CO32+CS32+CW32+DA32+DE32+DI32+DM32+DQ32+DU32
A33: 五楼 | B33: 兰媛 | C33: 35 | D33: 综合部 | E33: 财务核价
A34: 五楼 | B34: 方宇 | C34: 36 | D34: 订单部 | E34: 接单报价组 | F34: 08:11 | G34: 0.75069444 | H34: =MOD(G34-F34,1)*24 | I34: 1 | J34: 0.34236111 | K34: 0.75 | L34: =MOD(K34-J34,1)*24 | M34: 1 | N34: 0.34236111 | O34: 0.75069444 | P34: =MOD(O34-N34,1)*24 | Q34: 1 | R34: 0.34375 | S34: 0.75277778 | T34: =MOD(S34-R34,1)*24 | U34: 1 | V34: 0.34444444 | W34: 0.75 | X34: =MOD(W34-V34,1)*24 | Y34: 1 | Z34: 0.34513889 | AA34: 0.75069444 | AB34: =MOD(AA34-Z34,1)*24 | AC34: 1 | AH34: 0.34791667 | AI34: 0.75 | AJ34: =MOD(AI34-AH34,1)*24 | AK34: 1 | AL34: 0.34930556 | AM34: 0.75 | AN34: =MOD(AM34-AL34,1)*24 | AO34: 1 | AP34: 0.34444444 | AQ34: 0.75069444 | AR34: =MOD(AQ34-AP34,1)*24 | AS34: 1 | AT34: 0.34513889 | AU34: 0.75 | AV34: =MOD(AU34-AT34,1)*24 | AW34: 1 | AX34: 0.34097222 | AY34: 0.75 | AZ34: =MOD(AY34-AX34,1)*24 | BA34: 1 | BB34: 0.34652778 | BC34: 0.75347222 | BD34: =MOD(BC34-BB34,1)*24 | BE34: 1 | BJ34: 0.34305556 | BK34: 0.75 | BL34: =MOD(BK34-BJ34,1)*24 | BM34: 1 | BN34: 0.34722222 | BO34: 0.75 | BP34: =MOD(BO34-BN34,1)*24 | BQ34: 1 | BR34: 0.34513889 | BS34: 0.75 | BT34: =MOD(BS34-BR34,1)*24 | BU34: 1 | BV34: 0.34513889 | BW34: 0.75069444 | BX34: =MOD(BW34-BV34,1)*24 | BY34: 1 | CH34: 0.34513889 | CI34: 0.75 | CJ34: =MOD(CI34-CH34,1)*24 | CK34: 1 | CL34: 0.34236111 | CM34: 0.75 | CN34: =MOD(CM34-CL34,1)*24 | CO34: 1 | CP34: 0.33819444 | CQ34: 0.82152778 | CR34: =MOD(CQ34-CP34,1)*24 | CS34: 1 | CX34: 0.34166667 | CY34: 0.75069444 | CZ34: =MOD(CY34-CX34,1)*24 | DA34: 1 | DB34: 0.34513889 | DC34: 0.75069444 | DD34: =MOD(DC34-DB34,1)*24 | DE34: 1 | DF34: 0.35138889 | DG34: 0.75069444 | DH34: =MOD(DG34-DF34,1)*24 | DI34: 1 | DJ34: 0.35 | DK34: 0.75 | DL34: =MOD(DK34-DJ34,1)*24 | DM34: 1 | DN34: 0.34513889 | DO34: 0.75069444 | DP34: =MOD(DO34-DN34,1)*24 | DQ34: 1 | DR34: 0.34097222 | DS34: 0.75069444 | DT34: =MOD(DS34-DR34,1)*24 | DU34: 1 | DZ34: =H34+L34+P34+T34+X34+AB34+AF34+AJ34+AN34+AR34+AV34+AZ34+BD34+BH34+BL34+BP34+BT34+BX34+CB34+CF34+CJ34+CN34+CR34+CV34+CZ34+DD34+DH34+DL34+DP34+DT34 | EA34: =I34+M34+Q34+U34+Y34+AC34+AG34+AK34+AO34+AS34+AW34+BA34+BE34+BI34+BM34+BQ34+BU34+BY34+CC34+CG34+CK34+CO34+CS34+CW34+DA34+DE34+DI34+DM34+DQ34+DU34
A35: 五楼 | B35: 莫永兵 | C35: 37 | D35: 板式车间 | E35: 板式车间 | F35: 08:14 | G35: 0.99166667 | H35: =MOD(G35-F35,1)*24 | I35: 1 | J35: 0.34722222 | K35: 0.99305556 | L35: =MOD(K35-J35,1)*24 | M35: 1 | N35: 0.99861111 | Q35: 0.5 | R35: 0.34791667 | S35: 0.99097222 | T35: =MOD(S35-R35,1)*24 | U35: 1 | V35: 0.34652778 | W35: 0.95694444 | X35: =MOD(W35-V35,1)*24 | Y35: 1 | Z35: 0.34444444 | AA35: 0.92986111 | AB35: =MOD(AA35-Z35,1)*24 | AC35: 1 | AD35: 0.81597222 | AG35: 0.5 | AH35: 0.34305556 | AI35: 0.95416667 | AJ35: =MOD(AI35-AH35,1)*24 | AK35: 1 | AL35: 0.34791667 | AM35: 0.94375 | AN35: =MOD(AM35-AL35,1)*24 | AO35: 1 | AP35: 0.34722222 | AQ35: 0.95555556 | AR35: =MOD(AQ35-AP35,1)*24 | AS35: 1 | AT35: 0.34375 | AW35: 0.5 | AX35: 0.2625 | AY35: 0.91666667 | AZ35: =MOD(AY35-AX35,1)*24 | BA35: 1 | BB35: 0.35 | BC35: 0.84652778 | BD35: =MOD(BC35-BB35,1)*24 | BE35: 1 | BF35: 0.79513889 | BI35: 0.5 | BJ35: 0.34305556 | BK35: 0.94652778 | BL35: =MOD(BK35-BJ35,1)*24 | BM35: 1 | BN35: 0.35069444 | BO35: 0.89027778 | BP35: =MOD(BO35-BN35,1)*24 | BQ35: 1 | BR35: 0.34722222 | BS35: 0.90486111 | BT35: =MOD(BS35-BR35,1)*24 | BU35: 1 | BV35: 0.80763889 | BY35: 0.5 | BZ35: 0.83125 | CC35: 0.5 | CD35: 0.35277778 | CE35: 0.78819444 | CF35: =MOD(CE35-CD35,1)*24 | CG35: 1 | CH35: 0.34722222 | CI35: 0.81875 | CJ35: =MOD(CI35-CH35,1)*24 | CK35: 1 | CL35: 0.34722222 | CM35: 0.86527778 | CN35: =MOD(CM35-CL35,1)*24 | CO35: 1 | CP35: 0.34305556 | CQ35: 0.89513889 | CR35: =MOD(CQ35-CP35,1)*24 | CS35: 1 | CT35: 0.33958333 | CU35: 0.85555556 | CV35: =MOD(CU35-CT35,1)*24 | CW35: 1 | CX35: 0.33958333 | CY35: 0.89861111 | CZ35: =MOD(CY35-CX35,1)*24 | DA35: 1 | DB35: 0.34444444 | DC35: 0.9375 | DD35: =MOD(DC35-DB35,1)*24 | DE35: 1 | DF35: 0.34375 | DG35: 0.81666667 | DH35: =MOD(DG35-DF35,1)*24 | DI35: 1 | DJ35: 0.34583333 | DK35: 0.81527778 | DL35: =MOD(DK35-DJ35,1)*24 | DM35: 1 | DN35: 0.34444444 | DO35: 0.93541667 | DP35: =MOD(DO35-DN35,1)*24 | DQ35: 1 | DR35: 0.35 | DS35: 0.98680556 | DT35: =MOD(DS35-DR35,1)*24 | DU35: 1 | DZ35: =H35+L35+P35+T35+X35+AB35+AF35+AJ35+AN35+AR35+AV35+AZ35+BD35+BH35+BL35+BP35+BT35+BX35+CB35+CF35+CJ35+CN35+CR35+CV35+CZ35+DD35+DH35+DL35+DP35+DT35 | EA35: =I35+M35+Q35+U35+Y35+AC35+AG35+AK35+AO35+AS35+AW35+BA35+BE35+BI35+BM35+BQ35+BU35+BY35+CC35+CG35+CK35+CO35+CS35+CW35+DA35+DE35+DI35+DM35+DQ35+DU35
A36: 五楼 | B36: 冯钰超 | C36: 38 | D36: 设计部 | E36: 设计组 | F36: 08:24 | G36: 0.75555556 | H36: =MOD(G36-F36,1)*24 | I36: 1 | J36: 0.34722222 | K36: 0.75625 | L36: =MOD(K36-J36,1)*24 | M36: 1 | N36: 0.34930556 | O36: 0.75625 | P36: =MOD(O36-N36,1)*24 | Q36: 1 | R36: 0.34861111 | S36: 0.75208333 | T36: =MOD(S36-R36,1)*24 | U36: 1 | V36: 0.34930556 | W36: 0.75069444 | X36: =MOD(W36-V36,1)*24 | Y36: 1 | Z36: 0.34930556 | AA36: 0.75069444 | AB36: =MOD(AA36-Z36,1)*24 | AC36: 1 | AH36: 0.34791667 | AI36: 0.75208333 | AJ36: =MOD(AI36-AH36,1)*24 | AK36: 1 | AL36: 0.34930556 | AM36: 0.75208333 | AN36: =MOD(AM36-AL36,1)*24 | AO36: 1 | AP36: 0.35069444 | AQ36: 0.77361111 | AR36: =MOD(AQ36-AP36,1)*24 | AS36: 1 | AT36: 0.34791667 | AU36: 0.76597222 | AV36: =MOD(AU36-AT36,1)*24 | AW36: 1 | AX36: 0.34791667 | AY36: 0.75763889 | AZ36: =MOD(AY36-AX36,1)*24 | BA36: 1 | BB36: 0.35 | BC36: 0.75069444 | BD36: =MOD(BC36-BB36,1)*24 | BE36: 1 | BF36: 0.34930556 | BG36: 0.75 | BH36: =MOD(BG36-BF36,1)*24 | BI36: 1 | BJ36: 0.34861111 | BK36: 0.75138889 | BL36: =MOD(BK36-BJ36,1)*24 | BM36: 1 | BN36: 0.34930556 | BO36: 0.79513889 | BP36: =MOD(BO36-BN36,1)*24 | BQ36: 1 | BR36: 0.34513889 | BS36: 0.75208333 | BT36: =MOD(BS36-BR36,1)*24 | BU36: 1 | BV36: 0.34861111 | BW36: 0.75 | BX36: =MOD(BW36-BV36,1)*24 | BY36: 1 | CH36: 0.35 | CI36: 0.75486111 | CJ36: =MOD(CI36-CH36,1)*24 | CK36: 1 | CL36: 0.35 | CM36: 0.77569444 | CN36: =MOD(CM36-CL36,1)*24 | CO36: 1 | CP36: 0.34861111 | CQ36: 0.77361111 | CR36: =MOD(CQ36-CP36,1)*24 | CS36: 1 | CT36: 0.35 | CU36: 0.75069444 | CV36: =MOD(CU36-CT36,1)*24 | CW36: 1 | CX36: 0.34930556 | CY36: 0.75208333 | CZ36: =MOD(CY36-CX36,1)*24 | DA36: 1 | DB36: 0.35069444 | DC36: 0.77013889 | DD36: =MOD(DC36-DB36,1)*24 | DE36: 1 | DF36: 0.35 | DG36: 0.78125 | DH36: =MOD(DG36-DF36,1)*24 | DI36: 1 | DN36: 0.34861111 | DO36: 0.83611111 | DP36: =MOD(DO36-DN36,1)*24 | DQ36: 1 | DR36: 0.34861111 | DS36: 0.77430556 | DT36: =MOD(DS36-DR36,1)*24 | DU36: 1 | DZ36: =H36+L36+P36+T36+X36+AB36+AF36+AJ36+AN36+AR36+AV36+AZ36+BD36+BH36+BL36+BP36+BT36+BX36+CB36+CF36+CJ36+CN36+CR36+CV36+CZ36+DD36+DH36+DL36+DP36+DT36 | EA36: =I36+M36+Q36+U36+Y36+AC36+AG36+AK36+AO36+AS36+AW36+BA36+BE36+BI36+BM36+BQ36+BU36+BY36+CC36+CG36+CK36+CO36+CS36+CW36+DA36+DE36+DI36+DM36+DQ36+DU36
