Workbook

Sheet 汇总
A1: 订单金额汇总表
A2: 单号 | B2: 序号 | C2: 板材金额 | D2: 五金金额 | E2: 铝框门
A3: ='1'!Q2 -> 0 | B3: -1 | C3: ='1'!L27 -> 0 | D3: ='五金-1'!R26 -> 0 | E3: =铝框门!M26 -> 0
A4: =A3 -> 0 | B4: -2 | C4: ='2'!L25 -> 0 | D4: ='五金-2'!R26 -> 0
A5: =A4 -> 0 | B5: -3 | C5: ='3'!L25 -> 0
A6: =A5 -> 0 | B6: -4 | C6: ='4'!L25 -> 0
A7: =A6 -> 0 | B7: -5 | C7: ='5'!L25 -> 0
A8: =A7 -> 0 | B8: -6 | C8: ='6'!L25 -> 0
A9: =A8 -> 0 | B9: -7 | C9: ='7'!L25 -> 0
A10: =A9 -> 0 | B10: -8 | C10: ='8'!L25 -> 0
A11: =A10 -> 0 | B11: -9 | C11: ='9'!L25 -> 0
A12: =A11 -> 0 | B12: -10 | C12: ='10'!L25 -> 0
A13: =A12 -> 0 | B13: -11 | C13: ='11'!L25 -> 0
A14: =A13 -> 0 | B14: -12 | C14: ='12'!L25 -> 0
A15: =A14 -> 0 | B15: -13 | C15: ='13'!L25 -> 0
A16: =A15 -> 0 | B16: -14 | C16: ='14'!L25 -> 0
A17: =A16 -> 0 | B17: -15 | C17: ='15'!L25 -> 0
A18: =A17 -> 0 | B18: -16 | C18: ='16'!L25 -> 0
A19: =A18 -> 0 | B19: -17 | C19: ='17'!L25 -> 0
A20: =A19 -> 0 | B20: -18 | C20: ='18'!L25 -> 0
A21: =A20 -> 0 | B21: -19 | C21: ='19'!L25 -> 0
A22: =A21 -> 0 | B22: -20 | C22: ='20'!L25 -> 0
A23: =A22 -> 0 | B23: -21 | C23: ='21'!L25 -> 0
A24: =A23 -> 0 | B24: -22 | C24: ='22'!L25 -> 0
A25: =A24 -> 0 | B25: -23 | C25: ='23'!L25 -> 0
A26: =A25 -> 0 | B26: -24 | C26: ='24'!L25 -> 0
A27: =A26 -> 0 | B27: -25 | C27: ='25'!L25 -> 0
A28: =A27 -> 0 | B28: -26 | C28: ='26'!L25 -> 0
A29: =A28 -> 0 | B29: -27 | C29: ='27'!L25 -> 0
A30: =A29 -> 0 | B30: -28 | C30: ='28'!L25 -> 0
A31: =A30 -> 0 | B31: -29 | C31: ='29'!L25 -> 0
A32: =A31 -> 0 | B32: -30 | C32: ='30'!L25 -> 0
A33: 小计 | C33: =SUM(C3:C32) -> 0 | D33: =SUM(D3:D32) -> 0 | E33: =SUM(E3:E32) -> 0
A34: 总合计 | C34: =C33+D33+E33 -> 0

Sheet 1
A1: 奢匠 | C1: 整装产品报价生产清单 | P1: 销售经理
C2: 经销商地址 | E2: 经销商名 | L2: 接单日期 | P2: 订单编号
C3: 终端客户及地址
A4: =A1 -> 奢匠 | C4: 整装作业单 | P4: 销售经理 | Q4: =+Q1 -> 0
C5: 省份 | D5: =+D2 -> 0 | E5: 姓名 | F5: =+F2 -> 0 | J5: 生产单号 | O5: =+R2 -> 0 | P5: 订单编号 | Q5: =+Q2 -> 0 | R5: -1
C6: 终端客户及地址 | E6: =E3 -> 0
A7: 序号 | B7: 区域 | C7: 产品名称 | D7: 款式 | E7: 高 | F7: 宽 | G7: 厚 | H7: 数量 | I7: 米数 | J7: 平方 | K7: 单价（元） | L7: 小计（元） | M7: 工分 | N7: 颜色 | P7: 材质 | Q7: 备注
A8: 1 | J8: =E8/1000*F8/1000*H8 -> 0 | L8: =J8*K8 -> 0 | M8: =L8/100 -> 0 | N8: （请车间多配一瓶油漆，随货一起）
A9: 2 | M9: =L9/100 -> 0
A10: 3 | M10: =L10/100 -> 0
A11: 4 | M11: =L11/100 -> 0
A12: 5 | M12: =L12/100 -> 0
A13: 6 | M13: =L13/100 -> 0
A14: 7 | M14: =L14/100 -> 0
A15: 8 | M15: =L15/100 -> 0
A16: 9 | M16: =L16/100 -> 0
A17: 10 | M17: =L17/100 -> 0
A18: 11 | M18: =L18/100 -> 0
A19: 12 | M19: =L19/100 -> 0
A20: 13 | M20: =L20/100 -> 0
... A24: 17 | M24: =L24/100 -> 0
A25: 18 | C25: 木箱包装 | D25: 此单共打个木箱包装
A26: 合计 | H26: =SUM(H8:H24) -> 0 | I26: =SUM(I8:I24) -> 0 | J26: =SUM(J8:J24) -> 0 | M26: =SUM(M8:M24) -> 0
A27: 图文说明: | L27: =+SUM(L8:L25) -> 0 | N27: 元
D28: 共计页 | E28: 合计 | F28: =+L28+O28 -> 0 | H28: 元 | K28: 板材 | L28: =+L27+'2'!L25+'3'!L25+'4'!L25+'5'!L25+'6'!L25+'7'!L25+'8'!L25+'9'!L25+'10'!L25+'11'!L25+'12'!L25+'13'!L25+'14'!L25+'15'!L25+'16'!L25+'17'!L25+'18'!L25+'19'!L25+'20'!L25+'21'!L25+'22'!L25+'23'!L25+'24'!L25+'25'!L25+'26'!L25+'27'!L25+'28'!L25+'29'!L25+'30'!L25 -> 0 | N28: 五金 | O28: ='五金-1'!R26+'五金-2'!R26+铝框门!M26 -> 0
L30: 经销商确认:
A31: 制表人： | C31: 陈昌容 | D31: 项目设计师： | H31: 绘图员： | L31: 拆单：
A32: =+A27 -> 图文说明: | I32: 木工预计交货日期： | P32: 木工实际交货日期：
I33: 包装预计交货日期： | P33: 包装实际交货日期：
A34: 1、开料 | C34: 2、实木备料 | E34: 3、柜体开料 | G34: 4、封边 | I34: 5、打孔 | N34: 6、门扇 | P34: 7、附件
A35: 责任人 | B35: 完成时间 | C35: 责任人 | D35: 完成时间 | E35: 责任人 | F35: 完成时间 | G35: 责任人 | H35: 完成时间 | I35: 责任人 | J35: 完成时间 | N35: 责任人 | O35: 完成时间 | P35: 责任人 | Q35: 完成时间
A37: 8、贴皮 | C37: 9、雕刻 | E37: 10、木工配套 | G37: 11、木磨 | I37: 12、灰工 | N37: 13、底漆 | P37: 14、油磨
A38: 责任人 | B38: 完成时间 | C38: 责任人 | D38: 完成时间 | E38: 责任人 | F38: 完成时间 | G38: 责任人 | H38: 完成时间 | I38: 责任人 | J38: 完成时间 | N38: 责任人 | O38: 完成时间 | P38: 责任人 | Q38: 完成时间
A40: 15、油磨检验 | C40: 16、擦色 | E40: 17、面漆 | G40: 18、全检 | I40: 19、包装
A41: 责任人 | B41: 完成时间 | C41: 责任人 | D41: 完成时间 | E41: 责任人 | F41: 完成时间 | G41: 责任人 | H41: 完成时间 | I41: 责任人 | J41: 完成时间
A43: 预计交货日期： | C43: =N33 -> 0 | E43: 下单日期: | N43: 生产单号 | P43: =Q2 -> 0 | R43: =R2 -> 0
A44: 制表人： | C44: =C31 -> 陈昌容 | D44: 项目设计师： | F44: =F31 -> 0 | H44: 绘图员： | J44: =J31 -> 0 | L44: 拆单： | N44: =N31 -> 0

Sheet 2
A1: =+'1'!A1 -> 奢匠 | C1: 整装产品报价生产清单 | P1: 销售经理 | Q1: =+'1'!Q1 -> 0
C2: 经销商地址 | D2: =+'1'!D2 -> 0 | E2: 经销商名 | F2: =+'1'!F2 -> 0 | L2: 接单日期 | M2: ='1'!M2 -> 0 | P2: 订单编号 | Q2: =+'1'!Q2 -> 0 | R2: -2
C3: 终端客户及地址 | E3: ='1'!E3 -> 0
A4: =+A1 -> 奢匠 | C4: 整装作业单 | P4: 销售经理 | Q4: =+Q1 -> 0
C5: 省份 | D5: =+D2 -> 0 | E5: 姓名 | F5: =+F2 -> 0 | J5: 生产单号 | N5: =+'1'!N5 -> 0 | O5: =+R2 -> -2 | P5: 订单编号 | Q5: =+Q2 -> 0 | R5: =+R2 -> -2
C6: 终端客户及地址 | E6: =E3 -> 0
A7: 序号 | B7: 区域 | C7: 产品名称 | D7: 款式 | E7: 高 | F7: 宽 | G7: 厚 | H7: 数量 | I7: 米数 | J7: 平方 | K7: 单价（元） | L7: 小计（元） | M7: 工分 | N7: 颜色 | P7: 材质 | Q7: 备注
A8: 1 | J8: =E8/1000*F8/1000*H8 -> 0 | L8: =J8*K8 -> 0 | M8: =L8/100 -> 0 | N8: ='1'!N8 -> （请车间多配一瓶油漆，随货一起）
A9: 2 | M9: =L9/100 -> 0
A10: 3 | M10: =L10/100 -> 0
A11: 4 | M11: =L11/100 -> 0
A12: 5 | M12: =L12/100 -> 0
A13: 6 | M13: =L13/100 -> 0
A14: 7 | M14: =L14/100 -> 0
A15: 8 | M15: =L15/100 -> 0
A16: 9 | M16: =L16/100 -> 0
A17: 10 | M17: =L17/100 -> 0
A18: 11 | M18: =L18/100 -> 0
A19: 12 | M19: =L19/100 -> 0
A20: 13 | M20: =L20/100 -> 0
... A22: 15 | M22: =L22/100 -> 0
A23: 16 | C23: 木箱包装 | D23: 此单共打个木箱包装
A24: 合计 | H24: =SUM(H6:H22) -> 0 | I24: =SUM(I6:I22) -> 0 | J24: =SUM(J6:J22) -> 0 | M24: =SUM(M6:M22) -> 0
A25: ='1'!A27 -> 图文说明: | L25: =+SUM(L8:L23) -> 0 | N25: 元
D27: ='1'!D29 -> 0
L28: 经销商确认:
A29: 制表人： | C29: ='1'!C31 -> 陈昌容 | D29: 项目设计师： | F29: ='1'!F31 -> 0 | H29: 绘图员： | J29: ='1'!J31 -> 0 | L29: 拆单： | N29: ='1'!N31 -> 0
A30: =+A25 -> 图文说明: | I30: 木工预计交货日期： | P30: 木工实际交货日期：
I31: 包装预计交货日期： | N31: =+'1'!N33 -> 0 | P31: 包装实际交货日期：
A32: 1、开料 | C32: 2、实木备料 | E32: 3、柜体开料 | G32: 4、封边 | I32: 5、打孔 | N32: 6、门扇 | P32: 7、附件
A33: 责任人 | B33: 完成时间 | C33: 责任人 | D33: 完成时间 | E33: 责任人 | F33: 完成时间 | G33: 责任人 | H33: 完成时间 | I33: 责任人 | J33: 完成时间 | N33: 责任人 | O33: 完成时间 | P33: 责任人 | Q33: 完成时间
A35: 8、贴皮 | C35: 9、雕刻 | E35: 10、木工配套 | G35: 11、木磨 | I35: 12、灰工 | N35: 13、底漆 | P35: 14、油磨
A36: 责任人 | B36: 完成时间 | C36: 责任人 | D36: 完成时间 | E36: 责任人 | F36: 完成时间 | G36: 责任人 | H36: 完成时间 | I36: 责任人 | J36: 完成时间 | N36: 责任人 | O36: 完成时间 | P36: 责任人 | Q36: 完成时间
A38: 15、油磨检验 | C38: 16、擦色 | E38: 17、面漆 | G38: 18、全检 | I38: 19、包装
A39: 责任人 | B39: 完成时间 | C39: 责任人 | D39: 完成时间 | E39: 责任人 | F39: 完成时间 | G39: 责任人 | H39: 完成时间 | I39: 责任人 | J39: 完成时间
A41: 预计交货日期： | C41: =N31 -> 0 | E41: 下单日期: | N41: 生产单号 | P41: =Q2 -> 0 | R41: =R2 -> -2
A42: 制表人： | C42: =C29 -> 陈昌容 | D42: 项目设计师： | F42: =F29 -> 0 | H42: 绘图员： | J42: =J29 -> 0 | L42: 拆单： | N42: =N29 -> 0

Sheet 3
A1: =+'1'!A1 -> 奢匠 | C1: 整装产品报价生产清单 | P1: 销售经理 | Q1: =+'1'!Q1 -> 0
C2: 经销商地址 | D2: =+'1'!D2 -> 0 | E2: 经销商名 | F2: =+'1'!F2 -> 0 | L2: 接单日期 | M2: ='1'!M2 -> 0 | P2: 订单编号 | Q2: =+'1'!Q2 -> 0 | R2: -3
C3: 终端客户及地址 | E3: ='1'!E3 -> 0
A4: =+A1 -> 奢匠 | C4: 整装作业单 | P4: 销售经理 | Q4: =+Q1 -> 0
C5: 省份 | D5: =+D2 -> 0 | E5: 姓名 | F5: =+F2 -> 0 | J5: 生产单号 | N5: =+'1'!N5 -> 0 | O5: =+R2 -> -3 | P5: 订单编号 | Q5: =+Q2 -> 0 | R5: =+R2 -> -3
C6: 终端客户及地址 | E6: =E3 -> 0
A7: 序号 | B7: 区域 | C7: 产品名称 | D7: 款式 | E7: 高 | F7: 宽 | G7: 厚 | H7: 数量 | I7: 米数 | J7: 平方 | K7: 单价（元） | L7: 小计（元） | M7: 工分 | N7: 颜色 | P7: 材质 | Q7: 备注
A8: 1 | J8: =E8/1000*F8/1000*H8 -> 0 | L8: =J8*K8 -> 0 | M8: =L8/100 -> 0 | N8: ='1'!N8 -> （请车间多配一瓶油漆，随货一起）
A9: 2 | M9: =L9/100 -> 0
A10: 3 | M10: =L10/100 -> 0
A11: 4 | M11: =L11/100 -> 0
A12: 5 | M12: =L12/100 -> 0
A13: 6 | M13: =L13/100 -> 0
A14: 7 | M14: =L14/100 -> 0
A15: 8 | M15: =L15/100 -> 0
A16: 9 | M16: =L16/100 -> 0
A17: 10 | M17: =L17/100 -> 0
A18: 11 | M18: =L18/100 -> 0
A19: 12 | M19: =L19/100 -> 0
A20: 13 | M20: =L20/100 -> 0
... A22: 15 | M22: =L22/100 -> 0
A23: 16 | C23: 木箱包装 | D23: 此单共打个木箱包装
A24: 合计 | H24: =SUM(H6:H22) -> 0 | I24: =SUM(I6:I22) -> 0 | J24: =SUM(J6:J22) -> 0 | M24: =SUM(M6:M22) -> 0
A25: ='1'!A27 -> 图文说明: | L25: =+SUM(L8:L23) -> 0 | N25: 元
D27: ='1'!D29 -> 0
L28: 经销商确认:
A29: 制表人： | C29: ='1'!C31 -> 陈昌容 | D29: 项目设计师： | F29: ='1'!F31 -> 0 | H29: 绘图员： | J29: ='1'!J31 -> 0 | L29: 拆单： | N29: ='1'!N31 -> 0
A30: =+A25 -> 图文说明: | I30: 木工预计交货日期： | P30: 木工实际交货日期：
I31: 包装预计交货日期： | N31: =+'1'!N33 -> 0 | P31: 包装实际交货日期：
A32: 1、开料 | C32: 2、实木备料 | E32: 3、柜体开料 | G32: 4、封边 | I32: 5、打孔 | N32: 6、门扇 | P32: 7、附件
A33: 责任人 | B33: 完成时间 | C33: 责任人 | D33: 完成时间 | E33: 责任人 | F33: 完成时间 | G33: 责任人 | H33: 完成时间 | I33: 责任人 | J33: 完成时间 | N33: 责任人 | O33: 完成时间 | P33: 责任人 | Q33: 完成时间
A35: 8、贴皮 | C35: 9、雕刻 | E35: 10、木工配套 | G35: 11、木磨 | I35: 12、灰工 | N35: 13、底漆 | P35: 14、油磨
A36: 责任人 | B36: 完成时间 | C36: 责任人 | D36: 完成时间 | E36: 责任人 | F36: 完成时间 | G36: 责任人 | H36: 完成时间 | I36: 责任人 | J36: 完成时间 | N36: 责任人 | O36: 完成时间 | P36: 责任人 | Q36: 完成时间
A38: 15、油磨检验 | C38: 16、擦色 | E38: 17、面漆 | G38: 18、全检 | I38: 19、包装
A39: 责任人 | B39: 完成时间 | C39: 责任人 | D39: 完成时间 | E39: 责任人 | F39: 完成时间 | G39: 责任人 | H39: 完成时间 | I39: 责任人 | J39: 完成时间
A41: 预计交货日期： | C41: =N31 -> 0 | E41: 下单日期: | N41: 生产单号 | P41: =Q2 -> 0 | R41: =R2 -> -3
A42: 制表人： | C42: =C29 -> 陈昌容 | D42: 项目设计师： | F42: =F29 -> 0 | H42: 绘图员： | J42: =J29 -> 0 | L42: 拆单： | N42: =N29 -> 0

Sheet 4
A1: =+'1'!A1 -> 奢匠 | C1: 整装产品报价生产清单 | P1: 销售经理 | Q1: =+'1'!Q1 -> 0
C2: 经销商地址 | D2: =+'1'!D2 -> 0 | E2: 经销商名 | F2: =+'1'!F2 -> 0 | L2: 接单日期 | M2: ='1'!M2 -> 0 | P2: 订单编号 | Q2: =+'1'!Q2 -> 0 | R2: -4
C3: 终端客户及地址 | E3: ='1'!E3 -> 0
A4: =+A1 -> 奢匠 | C4: 整装作业单 | P4: 销售经理 | Q4: =+Q1 -> 0
C5: 省份 | D5: =+D2 -> 0 | E5: 姓名 | F5: =+F2 -> 0 | J5: 生产单号 | N5: =+'1'!N5 -> 0 | O5: =+R2 -> -4 | P5: 订单编号 | Q5: =+Q2 -> 0 | R5: =+R2 -> -4
C6: 终端客户及地址 | E6: =E3 -> 0
A7: 序号 | B7: 区域 | C7: 产品名称 | D7: 款式 | E7: 高 | F7: 宽 | G7: 厚 | H7: 数量 | I7: 米数 | J7: 平方 | K7: 单价（元） | L7: 小计（元） | M7: 工分 | N7: 颜色 | P7: 材质 | Q7: 备注
A8: 1 | M8: =L8/100 -> 0 | N8: ='1'!N8 -> （请车间多配一瓶油漆，随货一起）
A9: 2 | M9: =L9/100 -> 0
A10: 3 | J10: =E10/1000*F10/1000*H10 -> 0 | L10: =J10*K10 -> 0 | M10: =L10/100 -> 0
A11: 4 | M11: =L11/100 -> 0
A12: 5 | M12: =L12/100 -> 0
A13: 6 | M13: =L13/100 -> 0
A14: 7 | M14: =L14/100 -> 0
A15: 8 | M15: =L15/100 -> 0
A16: 9 | M16: =L16/100 -> 0
A17: 10 | M17: =L17/100 -> 0
A18: 11 | M18: =L18/100 -> 0
A19: 12 | M19: =L19/100 -> 0
A20: 13 | M20: =L20/100 -> 0
A21: 14 | M21: =L21/100 -> 0
A22: 15 | M22: =L22/100 -> 0
A23: 16 | C23: 木箱包装 | D23: 此单共打个木箱包装
A24: 合计 | H24: =SUM(H6:H22) -> 0 | I24: =SUM(I6:I22) -> 0 | J24: =SUM(J6:J22) -> 0 | M24: =SUM(M6:M22) -> 0
A25: ='1'!A27 -> 图文说明: | L25: =+SUM(L8:L23) -> 0 | N25: 元
D27: ='1'!D29 -> 0
L28: 经销商确认:
A29: 制表人： | C29: ='1'!C31 -> 陈昌容 | D29: 项目设计师： | F29: ='1'!F31 -> 0 | H29: 绘图员： | J29: ='1'!J31 -> 0 | L29: 拆单： | N29: ='1'!N31 -> 0
A30: =+A25 -> 图文说明: | I30: 木工预计交货日期： | P30: 木工实际交货日期：
I31: 包装预计交货日期： | N31: =+'1'!N33 -> 0 | P31: 包装实际交货日期：
A32: 1、开料 | C32: 2、实木备料 | E32: 3、柜体开料 | G32: 4、封边 | I32: 5、打孔 | N32: 6、门扇 | P32: 7、附件
A33: 责任人 | B33: 完成时间 | C33: 责任人 | D33: 完成时间 | E33: 责任人 | F33: 完成时间 | G33: 责任人 | H33: 完成时间 | I33: 责任人 | J33: 完成时间 | N33: 责任人 | O33: 完成时间 | P33: 责任人 | Q33: 完成时间
A35: 8、贴皮 | C35: 9、雕刻 | E35: 10、木工配套 | G35: 11、木磨 | I35: 12、灰工 | N35: 13、底漆 | P35: 14、油磨
A36: 责任人 | B36: 完成时间 | C36: 责任人 | D36: 完成时间 | E36: 责任人 | F36: 完成时间 | G36: 责任人 | H36: 完成时间 | I36: 责任人 | J36: 完成时间 | N36: 责任人 | O36: 完成时间 | P36: 责任人 | Q36: 完成时间
A38: 15、油磨检验 | C38: 16、擦色 | E38: 17、面漆 | G38: 18、全检 | I38: 19、包装
A39: 责任人 | B39: 完成时间 | C39: 责任人 | D39: 完成时间 | E39: 责任人 | F39: 完成时间 | G39: 责任人 | H39: 完成时间 | I39: 责任人 | J39: 完成时间
A41: 预计交货日期： | C41: =N31 -> 0 | E41: 下单日期: | N41: 生产单号 | P41: =Q2 -> 0 | R41: =R2 -> -4
A42: 制表人： | C42: =C29 -> 陈昌容 | D42: 项目设计师： | F42: =F29 -> 0 | H42: 绘图员： | J42: =J29 -> 0 | L42: 拆单： | N42: =N29 -> 0

Sheet 5
A1: =+'1'!A1 -> 奢匠 | C1: 整装产品报价生产清单 | P1: 销售经理 | Q1: =+'1'!Q1 -> 0
C2: 经销商地址 | D2: =+'1'!D2 -> 0 | E2: 经销商名 | F2: =+'1'!F2 -> 0 | L2: 接单日期 | M2: ='1'!M2 -> 0 | P2: 订单编号 | Q2: =+'1'!Q2 -> 0 | R2: -5
C3: 终端客户及地址 | E3: ='1'!E3 -> 0
A4: =+A1 -> 奢匠 | C4: 整装作业单 | P4: 销售经理 | Q4: =+Q1 -> 0
C5: 省份 | D5: =+D2 -> 0 | E5: 姓名 | F5: =+F2 -> 0 | J5: 生产单号 | N5: =+'1'!N5 -> 0 | O5: =+R2 -> -5 | P5: 订单编号 | Q5: =+Q2 -> 0 | R5: =+R2 -> -5
C6: 终端客户及地址 | E6: =E3 -> 0
A7: 序号 | B7: 区域 | C7: 产品名称 | D7: 款式 | E7: 高 | F7: 宽 | G7: 厚 | H7: 数量 | I7: 米数 | J7: 平方 | K7: 单价（元） | L7: 小计（元） | M7: 工分 | N7: 颜色 | P7: 材质 | Q7: 备注
A8: 1 | J8: =E8/1000*F8/1000*H8 -> 0 | L8: =J8*K8 -> 0 | M8: =L8/100 -> 0 | N8: ='1'!N8 -> （请车间多配一瓶油漆，随货一起）
A9: 2 | M9: =L9/100 -> 0
A10: 3 | M10: =L10/100 -> 0
A11: 4 | M11: =L11/100 -> 0
A12: 5 | M12: =L12/100 -> 0
A13: 6 | M13: =L13/100 -> 0
A14: 7 | M14: =L14/100 -> 0
A15: 8 | M15: =L15/100 -> 0
A16: 9 | M16: =L16/100 -> 0
A17: 10 | M17: =L17/100 -> 0
A18: 11 | M18: =L18/100 -> 0
A19: 12 | M19: =L19/100 -> 0
A20: 13 | M20: =L20/100 -> 0
... A22: 15 | M22: =L22/100 -> 0
A23: 16 | C23: 木箱包装 | D23: 此单共打个木箱包装
A24: 合计 | H24: =SUM(H6:H22) -> 0 | I24: =SUM(I6:I22) -> 0 | J24: =SUM(J6:J22) -> 0 | M24: =SUM(M6:M22) -> 0
A25: ='1'!A27 -> 图文说明: | L25: =+SUM(L8:L23) -> 0 | N25: 元
D27: ='1'!D29 -> 0
L28: 经销商确认:
A29: 制表人： | C29: ='1'!C31 -> 陈昌容 | D29: 项目设计师： | F29: ='1'!F31 -> 0 | H29: 绘图员： | J29: ='1'!J31 -> 0 | L29: 拆单： | N29: ='1'!N31 -> 0
A30: =+A25 -> 图文说明: | I30: 木工预计交货日期： | P30: 木工实际交货日期：
I31: 包装预计交货日期： | N31: =+'1'!N33 -> 0 | P31: 包装实际交货日期：
A32: 1、开料 | C32: 2、实木备料 | E32: 3、柜体开料 | G32: 4、封边 | I32: 5、打孔 | N32: 6、门扇 | P32: 7、附件
A33: 责任人 | B33: 完成时间 | C33: 责任人 | D33: 完成时间 | E33: 责任人 | F33: 完成时间 | G33: 责任人 | H33: 完成时间 | I33: 责任人 | J33: 完成时间 | N33: 责任人 | O33: 完成时间 | P33: 责任人 | Q33: 完成时间
A35: 8、贴皮 | C35: 9、雕刻 | E35: 10、木工配套 | G35: 11、木磨 | I35: 12、灰工 | N35: 13、底漆 | P35: 14、油磨
A36: 责任人 | B36: 完成时间 | C36: 责任人 | D36: 完成时间 | E36: 责任人 | F36: 完成时间 | G36: 责任人 | H36: 完成时间 | I36: 责任人 | J36: 完成时间 | N36: 责任人 | O36: 完成时间 | P36: 责任人 | Q36: 完成时间
A38: 15、油磨检验 | C38: 16、擦色 | E38: 17、面漆 | G38: 18、全检 | I38: 19、包装
A39: 责任人 | B39: 完成时间 | C39: 责任人 | D39: 完成时间 | E39: 责任人 | F39: 完成时间 | G39: 责任人 | H39: 完成时间 | I39: 责任人 | J39: 完成时间
A41: 预计交货日期： | C41: =N31 -> 0 | E41: 下单日期: | N41: 生产单号 | P41: =Q2 -> 0 | R41: =R2 -> -5
A42: 制表人： | C42: =C29 -> 陈昌容 | D42: 项目设计师： | F42: =F29 -> 0 | H42: 绘图员： | J42: =J29 -> 0 | L42: 拆单： | N42: =N29 -> 0

Sheet 6
A1: =+'1'!A1 -> 奢匠 | C1: 整装产品报价生产清单 | P1: 销售经理 | Q1: =+'1'!Q1 -> 0
C2: 经销商地址 | D2: =+'1'!D2 -> 0 | E2: 经销商名 | F2: =+'1'!F2 -> 0 | L2: 接单日期 | M2: ='1'!M2 -> 0 | P2: 订单编号 | Q2: =+'1'!Q2 -> 0 | R2: -6
C3: 终端客户及地址 | E3: ='1'!E3 -> 0
A4: =+A1 -> 奢匠 | C4: 整装作业单 | P4: 销售经理 | Q4: =+Q1 -> 0
C5: 省份 | D5: =+D2 -> 0 | E5: 姓名 | F5: =+F2 -> 0 | J5: 生产单号 | N5: =+'1'!N5 -> 0 | O5: =+R2 -> -6 | P5: 订单编号 | Q5: =+Q2 -> 0 | R5: =+R2 -> -6
C6: 终端客户及地址 | E6: =E3 -> 0
A7: 序号 | B7: 区域 | C7: 产品名称 | D7: 款式 | E7: 高 | F7: 宽 | G7: 厚 | H7: 数量 | I7: 米数 | J7: 平方 | K7: 单价（元） | L7: 小计（元） | M7: 工分 | N7: 颜色 | P7: 材质 | Q7: 备注
A8: 1 | J8: =E8/1000*F8/1000*H8 -> 0 | L8: =J8*K8 -> 0 | M8: =L8/100 -> 0 | N8: ='1'!N8 -> （请车间多配一瓶油漆，随货一起）
A9: 2 | M9: =L9/100 -> 0
A10: 3 | M10: =L10/100 -> 0
A11: 4 | M11: =L11/100 -> 0
A12: 5 | M12: =L12/100 -> 0
A13: 6 | M13: =L13/100 -> 0
A14: 7 | M14: =L14/100 -> 0
A15: 8 | M15: =L15/100 -> 0
A16: 9 | M16: =L16/100 -> 0
A17: 10 | M17: =L17/100 -> 0
A18: 11 | M18: =L18/100 -> 0
A19: 12 | M19: =L19/100 -> 0
A20: 13 | M20: =L20/100 -> 0
... A22: 15 | M22: =L22/100 -> 0
A23: 16 | C23: 木箱包装 | D23: 此单共打个木箱包装
A24: 合计 | H24: =SUM(H6:H22) -> 0 | I24: =SUM(I6:I22) -> 0 | J24: =SUM(J6:J22) -> 0 | M24: =SUM(M6:M22) -> 0
A25: ='1'!A27 -> 图文说明: | L25: =+SUM(L8:L23) -> 0 | N25: 元
D27: ='1'!D29 -> 0
L28: 经销商确认:
A29: 制表人： | C29: ='1'!C31 -> 陈昌容 | D29: 项目设计师： | F29: ='1'!F31 -> 0 | H29: 绘图员： | J29: ='1'!J31 -> 0 | L29: 拆单： | N29: ='1'!N31 -> 0
A30: =+A25 -> 图文说明: | I30: 木工预计交货日期： | P30: 木工实际交货日期：
I31: 包装预计交货日期： | N31: =+'1'!N33 -> 0 | P31: 包装实际交货日期：
A32: 1、开料 | C32: 2、实木备料 | E32: 3、柜体开料 | G32: 4、封边 | I32: 5、打孔 | N32: 6、门扇 | P32: 7、附件
A33: 责任人 | B33: 完成时间 | C33: 责任人 | D33: 完成时间 | E33: 责任人 | F33: 完成时间 | G33: 责任人 | H33: 完成时间 | I33: 责任人 | J33: 完成时间 | N33: 责任人 | O33: 完成时间 | P33: 责任人 | Q33: 完成时间
A35: 8、贴皮 | C35: 9、雕刻 | E35: 10、木工配套 | G35: 11、木磨 | I35: 12、灰工 | N35: 13、底漆 | P35: 14、油磨
A36: 责任人 | B36: 完成时间 | C36: 责任人 | D36: 完成时间 | E36: 责任人 | F36: 完成时间 | G36: 责任人 | H36: 完成时间 | I36: 责任人 | J36: 完成时间 | N36: 责任人 | O36: 完成时间 | P36: 责任人 | Q36: 完成时间
A38: 15、油磨检验 | C38: 16、擦色 | E38: 17、面漆 | G38: 18、全检 | I38: 19、包装
A39: 责任人 | B39: 完成时间 | C39: 责任人 | D39: 完成时间 | E39: 责任人 | F39: 完成时间 | G39: 责任人 | H39: 完成时间 | I39: 责任人 | J39: 完成时间
A41: 预计交货日期： | C41: =N31 -> 0 | E41: 下单日期: | N41: 生产单号 | P41: =Q2 -> 0 | R41: =R2 -> -6
A42: 制表人： | C42: =C29 -> 陈昌容 | D42: 项目设计师： | F42: =F29 -> 0 | H42: 绘图员： | J42: =J29 -> 0 | L42: 拆单： | N42: =N29 -> 0

Sheet 7
A1: =+'1'!A1 -> 奢匠 | C1: 整装产品报价生产清单 | P1: 销售经理 | Q1: =+'1'!Q1 -> 0
C2: 经销商地址 | D2: =+'1'!D2 -> 0 | E2: 经销商名 | F2: =+'1'!F2 -> 0 | L2: 接单日期 | M2: ='1'!M2 -> 0 | P2: 订单编号 | Q2: =+'1'!Q2 -> 0 | R2: -7
C3: 终端客户及地址 | E3: ='1'!E3 -> 0
A4: =+A1 -> 奢匠 | C4: 整装作业单 | P4: 销售经理 | Q4: =+Q1 -> 0
C5: 省份 | D5: =+D2 -> 0 | E5: 姓名 | F5: =+F2 -> 0 | J5: 生产单号 | N5: =+'1'!N5 -> 0 | O5: =+R2 -> -7 | P5: 订单编号 | Q5: =+Q2 -> 0 | R5: =+R2 -> -7
C6: 终端客户及地址 | E6: =E3 -> 0
A7: 序号 | B7: 区域 | C7: 产品名称 | D7: 款式 | E7: 高 | F7: 宽 | G7: 厚 | H7: 数量 | I7: 米数 | J7: 平方 | K7: 单价（元） | L7: 小计（元） | M7: 工分 | N7: ='1'!N7 -> 颜色 | P7: 材质 | Q7: 备注
A8: 1 | J8: =E8/1000*F8/1000*H8 -> 0 | L8: =J8*K8 -> 0 | M8: =L8/100 -> 0 | N8: ='1'!N8 -> （请车间多配一瓶油漆，随货一起）
A9: 2 | M9: =L9/100 -> 0
A10: 3 | M10: =L10/100 -> 0
A11: 4 | M11: =L11/100 -> 0
A12: 5 | M12: =L12/100 -> 0
A13: 6 | M13: =L13/100 -> 0
A14: 7 | M14: =L14/100 -> 0
A15: 8 | M15: =L15/100 -> 0
A16: 9 | M16: =L16/100 -> 0
A17: 10 | M17: =L17/100 -> 0
A18: 11 | M18: =L18/100 -> 0
A19: 12 | M19: =L19/100 -> 0
A20: 13 | M20: =L20/100 -> 0
... A22: 15 | M22: =L22/100 -> 0
A23: 16 | C23: 木箱包装 | D23: 此单共打个木箱包装
A24: 合计 | H24: =SUM(H6:H22) -> 0 | I24: =SUM(I6:I22) -> 0 | J24: =SUM(J6:J22) -> 0 | M24: =SUM(M6:M22) -> 0
A25: ='1'!A27 -> 图文说明: | L25: =+SUM(L8:L23) -> 0 | N25: 元
D27: ='1'!D29 -> 0
L28: 经销商确认:
A29: 制表人： | C29: ='1'!C31 -> 陈昌容 | D29: 项目设计师： | F29: ='1'!F31 -> 0 | H29: 绘图员： | J29: ='1'!J31 -> 0 | L29: 拆单： | N29: ='1'!N31 -> 0
A30: =+A25 -> 图文说明: | I30: 木工预计交货日期： | P30: 木工实际交货日期：
I31: 包装预计交货日期： | N31: =+'1'!N33 -> 0 | P31: 包装实际交货日期：
A32: 1、开料 | C32: 2、实木备料 | E32: 3、柜体开料 | G32: 4、封边 | I32: 5、打孔 | N32: 6、门扇 | P32: 7、附件
A33: 责任人 | B33: 完成时间 | C33: 责任人 | D33: 完成时间 | E33: 责任人 | F33: 完成时间 | G33: 责任人 | H33: 完成时间 | I33: 责任人 | J33: 完成时间 | N33: 责任人 | O33: 完成时间 | P33: 责任人 | Q33: 完成时间
A35: 8、贴皮 | C35: 9、雕刻 | E35: 10、木工配套 | G35: 11、木磨 | I35: 12、灰工 | N35: 13、底漆 | P35: 14、油磨
A36: 责任人 | B36: 完成时间 | C36: 责任人 | D36: 完成时间 | E36: 责任人 | F36: 完成时间 | G36: 责任人 | H36: 完成时间 | I36: 责任人 | J36: 完成时间 | N36: 责任人 | O36: 完成时间 | P36: 责任人 | Q36: 完成时间
A38: 15、油磨检验 | C38: 16、擦色 | E38: 17、面漆 | G38: 18、全检 | I38: 19、包装
A39: 责任人 | B39: 完成时间 | C39: 责任人 | D39: 完成时间 | E39: 责任人 | F39: 完成时间 | G39: 责任人 | H39: 完成时间 | I39: 责任人 | J39: 完成时间
A41: 预计交货日期： | C41: =N31 -> 0 | E41: 下单日期: | N41: 生产单号 | P41: =Q2 -> 0 | R41: =R2 -> -7
A42: 制表人： | C42: =C29 -> 陈昌容 | D42: 项目设计师： | F42: =F29 -> 0 | H42: 绘图员： | J42: =J29 -> 0 | L42: 拆单： | N42: =N29 -> 0

Sheet 8
A1: =+'1'!A1 -> 奢匠 | C1: 整装产品报价生产清单 | P1: 销售经理 | Q1: =+'1'!Q1 -> 0
C2: 经销商地址 | D2: =+'1'!D2 -> 0 | E2: 经销商名 | F2: =+'1'!F2 -> 0 | L2: 接单日期 | M2: ='1'!M2 -> 0 | P2: 订单编号 | Q2: =+'1'!Q2 -> 0 | R2: -8
C3: 终端客户及地址 | E3: ='1'!E3 -> 0
A4: =+A1 -> 奢匠 | C4: 整装作业单 | P4: 销售经理 | Q4: =+Q1 -> 0
C5: 省份 | D5: =+D2 -> 0 | E5: 姓名 | F5: =+F2 -> 0 | J5: 生产单号 | N5: =+'1'!N5 -> 0 | O5: =+R2 -> -8 | P5: 订单编号 | Q5: =+Q2 -> 0 | R5: =+R2 -> -8
C6: 终端客户及地址 | E6: =E3 -> 0
A7: 序号 | B7: 区域 | C7: 产品名称 | D7: 款式 | E7: 高 | F7: 宽 | G7: 厚 | H7: 数量 | I7: 米数 | J7: 平方 | K7: 单价（元） | L7: 小计（元） | M7: 工分 | N7: 颜色 | P7: 材质 | Q7: 备注
A8: 1 | J8: =E8/1000*F8/1000*H8 -> 0 | L8: =J8*K8 -> 0 | M8: =L8/100 -> 0 | N8: ='1'!N8 -> （请车间多配一瓶油漆，随货一起）
A9: 2 | M9: =L9/100 -> 0
A10: 3 | M10: =L10/100 -> 0
A11: 4 | M11: =L11/100 -> 0
A12: 5 | J12: =E12/1000*F12/1000*H12 -> 0 | L12: =J12*K12 -> 0 | M12: =L12/100 -> 0
A13: 6 | M13: =L13/100 -> 0
A14: 7 | M14: =L14/100 -> 0
A15: 8 | M15: =L15/100 -> 0
A16: 9 | M16: =L16/100 -> 0
A17: 10 | M17: =L17/100 -> 0
A18: 11 | M18: =L18/100 -> 0
A19: 12 | M19: =L19/100 -> 0
A20: 13 | M20: =L20/100 -> 0
A21: 14 | M21: =L21/100 -> 0
A22: 15 | M22: =L22/100 -> 0
A23: 16 | C23: 木箱包装 | D23: 此单共打个木箱包装
A24: 合计 | H24: =SUM(H6:H22) -> 0 | I24: =SUM(I6:I22) -> 0 | J24: =SUM(J6:J22) -> 0 | M24: =SUM(M6:M22) -> 0
A25: ='1'!A27 -> 图文说明: | L25: =+SUM(L8:L23) -> 0 | N25: 元
D27: ='1'!D29 -> 0
L28: 经销商确认:
A29: 制表人： | C29: ='1'!C31 -> 陈昌容 | D29: 项目设计师： | F29: ='1'!F31 -> 0 | H29: 绘图员： | J29: ='1'!J31 -> 0 | L29: 拆单： | N29: ='1'!N31 -> 0
A30: =+A25 -> 图文说明: | I30: 木工预计交货日期： | P30: 木工实际交货日期：
I31: 包装预计交货日期： | N31: =+'1'!N33 -> 0 | P31: 包装实际交货日期：
A32: 1、开料 | C32: 2、实木备料 | E32: 3、柜体开料 | G32: 4、封边 | I32: 5、打孔 | N32: 6、门扇 | P32: 7、附件
A33: 责任人 | B33: 完成时间 | C33: 责任人 | D33: 完成时间 | E33: 责任人 | F33: 完成时间 | G33: 责任人 | H33: 完成时间 | I33: 责任人 | J33: 完成时间 | N33: 责任人 | O33: 完成时间 | P33: 责任人 | Q33: 完成时间
A35: 8、贴皮 | C35: 9、雕刻 | E35: 10、木工配套 | G35: 11、木磨 | I35: 12、灰工 | N35: 13、底漆 | P35: 14、油磨
A36: 责任人 | B36: 完成时间 | C36: 责任人 | D36: 完成时间 | E36: 责任人 | F36: 完成时间 | G36: 责任人 | H36: 完成时间 | I36: 责任人 | J36: 完成时间 | N36: 责任人 | O36: 完成时间 | P36: 责任人 | Q36: 完成时间
A38: 15、油磨检验 | C38: 16、擦色 | E38: 17、面漆 | G38: 18、全检 | I38: 19、包装
A39: 责任人 | B39: 完成时间 | C39: 责任人 | D39: 完成时间 | E39: 责任人 | F39: 完成时间 | G39: 责任人 | H39: 完成时间 | I39: 责任人 | J39: 完成时间
A41: 预计交货日期： | C41: =N31 -> 0 | E41: 下单日期: | N41: 生产单号 | P41: =Q2 -> 0 | R41: =R2 -> -8
A42: 制表人： | C42: =C29 -> 陈昌容 | D42: 项目设计师： | F42: =F29 -> 0 | H42: 绘图员： | J42: =J29 -> 0 | L42: 拆单： | N42: =N29 -> 0

Sheet 9
A1: =+'1'!A1 -> 奢匠 | C1: 整装产品报价生产清单 | P1: 销售经理 | Q1: =+'1'!Q1 -> 0
C2: 经销商地址 | D2: =+'1'!D2 -> 0 | E2: 经销商名 | F2: =+'1'!F2 -> 0 | L2: 接单日期 | M2: ='1'!M2 -> 0 | P2: 订单编号 | Q2: =+'1'!Q2 -> 0 | R2: -9
C3: 终端客户及地址 | E3: ='1'!E3 -> 0
A4: =+A1 -> 奢匠 | C4: 整装作业单 | P4: 销售经理 | Q4: =+Q1 -> 0
C5: 省份 | D5: =+D2 -> 0 | E5: 姓名 | F5: =+F2 -> 0 | J5: 生产单号 | N5: =+'1'!N5 -> 0 | O5: =+R2 -> -9 | P5: 订单编号 | Q5: =+Q2 -> 0 | R5: =+R2 -> -9
C6: 终端客户及地址 | E6: =E3 -> 0
A7: 序号 | B7: 区域 | C7: 产品名称 | D7: 款式 | E7: 高 | F7: 宽 | G7: 厚 | H7: 数量 | I7: 米数 | J7: 平方 | K7: 单价（元） | L7: 小计（元） | M7: 工分 | N7: 颜色 | P7: 材质 | Q7: 备注
A8: 1 | J8: =E8/1000*F8/1000*H8 -> 0 | L8: =J8*K8 -> 0 | M8: =L8/100 -> 0 | N8: ='1'!N8 -> （请车间多配一瓶油漆，随货一起）
A9: 2 | M9: =L9/100 -> 0
A10: 3 | M10: =L10/100 -> 0
A11: 4 | M11: =L11/100 -> 0
A12: 5 | M12: =L12/100 -> 0
A13: 6 | M13: =L13/100 -> 0
A14: 7 | M14: =L14/100 -> 0
A15: 8 | M15: =L15/100 -> 0
A16: 9 | M16: =L16/100 -> 0
A17: 10 | M17: =L17/100 -> 0
A18: 11 | M18: =L18/100 -> 0
A19: 12 | M19: =L19/100 -> 0
A20: 13 | M20: =L20/100 -> 0
... A22: 15 | M22: =L22/100 -> 0
A23: 16 | C23: 木箱包装 | D23: 此单共打个木箱包装
A24: 合计 | H24: =SUM(H6:H22) -> 0 | I24: =SUM(I6:I22) -> 0 | J24: =SUM(J6:J22) -> 0 | M24: =SUM(M6:M22) -> 0
A25: ='1'!A27 -> 图文说明: | L25: =+SUM(L8:L23) -> 0 | N25: 元
D27: ='1'!D29 -> 0
L28: 经销商确认:
A29: 制表人： | C29: ='1'!C31 -> 陈昌容 | D29: 项目设计师： | F29: ='1'!F31 -> 0 | H29: 绘图员： | J29: ='1'!J31 -> 0 | L29: 拆单： | N29: ='1'!N31 -> 0
A30: =+A25 -> 图文说明: | I30: 木工预计交货日期： | P30: 木工实际交货日期：
I31: 包装预计交货日期： | N31: =+'1'!N33 -> 0 | P31: 包装实际交货日期：
A32: 1、开料 | C32: 2、实木备料 | E32: 3、柜体开料 | G32: 4、封边 | I32: 5、打孔 | N32: 6、门扇 | P32: 7、附件
A33: 责任人 | B33: 完成时间 | C33: 责任人 | D33: 完成时间 | E33: 责任人 | F33: 完成时间 | G33: 责任人 | H33: 完成时间 | I33: 责任人 | J33: 完成时间 | N33: 责任人 | O33: 完成时间 | P33: 责任人 | Q33: 完成时间
A35: 8、贴皮 | C35: 9、雕刻 | E35: 10、木工配套 | G35: 11、木磨 | I35: 12、灰工 | N35: 13、底漆 | P35: 14、油磨
A36: 责任人 | B36: 完成时间 | C36: 责任人 | D36: 完成时间 | E36: 责任人 | F36: 完成时间 | G36: 责任人 | H36: 完成时间 | I36: 责任人 | J36: 完成时间 | N36: 责任人 | O36: 完成时间 | P36: 责任人 | Q36: 完成时间
A38: 15、油磨检验 | C38: 16、擦色 | E38: 17、面漆 | G38: 18、全检 | I38: 19、包装
A39: 责任人 | B39: 完成时间 | C39: 责任人 | D39: 完成时间 | E39: 责任人 | F39: 完成时间 | G39: 责任人 | H39: 完成时间 | I39: 责任人 | J39: 完成时间
A41: 预计交货日期： | C41: =N31 -> 0 | E41: 下单日期: | N41: 生产单号 | P41: =Q2 -> 0 | R41: =R2 -> -9
A42: 制表人： | C42: =C29 -> 陈昌容 | D42: 项目设计师： | F42: =F29 -> 0 | H42: 绘图员： | J42: =J29 -> 0 | L42: 拆单： | N42: =N29 -> 0

Sheet 10
A1: =+'1'!A1 -> 奢匠 | C1: 整装产品报价生产清单 | P1: 销售经理 | Q1: =+'1'!Q1 -> 0
C2: 经销商地址 | D2: =+'1'!D2 -> 0 | E2: 经销商名 | F2: =+'1'!F2 -> 0 | L2: 接单日期 | M2: ='1'!M2 -> 0 | P2: 订单编号 | Q2: =+'1'!Q2 -> 0 | R2: -10
C3: 终端客户及地址 | E3: ='1'!E3 -> 0
A4: =+A1 -> 奢匠 | C4: 整装作业单 | P4: 销售经理 | Q4: =+Q1 -> 0
C5: 省份 | D5: =+D2 -> 0 | E5: 姓名 | F5: =+F2 -> 0 | J5: 生产单号 | N5: =+'1'!N5 -> 0 | O5: =+R2 -> -10 | P5: 订单编号 | Q5: =+Q2 -> 0 | R5: =+R2 -> -10
C6: 终端客户及地址 | E6: =E3 -> 0
A7: 序号 | B7: 区域 | C7: 产品名称 | D7: 款式 | E7: 高 | F7: 宽 | G7: 厚 | H7: 数量 | I7: 米数 | J7: 平方 | K7: 单价（元） | L7: 小计（元） | M7: 工分 | N7: 颜色 | P7: 材质 | Q7: 备注
A8: 1 | J8: =E8/1000*F8/1000*H8 -> 0 | L8: =J8*K8 -> 0 | M8: =L8/100 -> 0 | N8: ='1'!N8 -> （请车间多配一瓶油漆，随货一起）
A9: 2 | M9: =L9/100 -> 0
A10: 3 | M10: =L10/100 -> 0
A11: 4 | M11: =L11/100 -> 0
A12: 5 | M12: =L12/100 -> 0
A13: 6 | M13: =L13/100 -> 0
A14: 7 | M14: =L14/100 -> 0
A15: 8 | M15: =L15/100 -> 0
A16: 9 | M16: =L16/100 -> 0
A17: 10 | M17: =L17/100 -> 0
A18: 11 | M18: =L18/100 -> 0
A19: 12 | M19: =L19/100 -> 0
A20: 13 | M20: =L20/100 -> 0
... A22: 15 | M22: =L22/100 -> 0
A23: 16 | C23: 木箱包装 | D23: 此单共打个木箱包装
A24: 合计 | H24: =SUM(H6:H22) -> 0 | I24: =SUM(I6:I22) -> 0 | J24: =SUM(J6:J22) -> 0 | M24: =SUM(M6:M22) -> 0
A25: ='1'!A27 -> 图文说明: | L25: =+SUM(L8:L23) -> 0 | N25: 元
D27: ='1'!D29 -> 0
L28: 经销商确认:
A29: 制表人： | C29: ='1'!C31 -> 陈昌容 | D29: 项目设计师： | F29: ='1'!F31 -> 0 | H29: 绘图员： | J29: ='1'!J31 -> 0 | L29: 拆单： | N29: ='1'!N31 -> 0
A30: =+A25 -> 图文说明: | I30: 木工预计交货日期： | P30: 木工实际交货日期：
I31: 包装预计交货日期： | N31: =+'1'!N33 -> 0 | P31: 包装实际交货日期：
A32: 1、开料 | C32: 2、实木备料 | E32: 3、柜体开料 | G32: 4、封边 | I32: 5、打孔 | N32: 6、门扇 | P32: 7、附件
A33: 责任人 | B33: 完成时间 | C33: 责任人 | D33: 完成时间 | E33: 责任人 | F33: 完成时间 | G33: 责任人 | H33: 完成时间 | I33: 责任人 | J33: 完成时间 | N33: 责任人 | O33: 完成时间 | P33: 责任人 | Q33: 完成时间
A35: 8、贴皮 | C35: 9、雕刻 | E35: 10、木工配套 | G35: 11、木磨 | I35: 12、灰工 | N35: 13、底漆 | P35: 14、油磨
A36: 责任人 | B36: 完成时间 | C36: 责任人 | D36: 完成时间 | E36: 责任人 | F36: 完成时间 | G36: 责任人 | H36: 完成时间 | I36: 责任人 | J36: 完成时间 | N36: 责任人 | O36: 完成时间 | P36: 责任人 | Q36: 完成时间
A38: 15、油磨检验 | C38: 16、擦色 | E38: 17、面漆 | G38: 18、全检 | I38: 19、包装
A39: 责任人 | B39: 完成时间 | C39: 责任人 | D39: 完成时间 | E39: 责任人 | F39: 完成时间 | G39: 责任人 | H39: 完成时间 | I39: 责任人 | J39: 完成时间
A41: 预计交货日期： | C41: =N31 -> 0 | E41: 下单日期: | N41: 生产单号 | P41: =Q2 -> 0 | R41: =R2 -> -10
A42: 制表人： | C42: =C29 -> 陈昌容 | D42: 项目设计师： | F42: =F29 -> 0 | H42: 绘图员： | J42: =J29 -> 0 | L42: 拆单： | N42: =N29 -> 0

Sheet 11
A1: =+'1'!A1 -> 奢匠 | C1: 整装产品报价生产清单 | P1: 销售经理 | Q1: =+'1'!Q1 -> 0
C2: 经销商地址 | D2: =+'1'!D2 -> 0 | E2: 经销商名 | F2: =+'1'!F2 -> 0 | L2: 接单日期 | M2: ='1'!M2 -> 0 | P2: 订单编号 | Q2: =+'1'!Q2 -> 0 | R2: -11
C3: 终端客户及地址 | E3: ='1'!E3 -> 0
A4: =+A1 -> 奢匠 | C4: 整装作业单 | P4: 销售经理 | Q4: =+Q1 -> 0
C5: 省份 | D5: =+D2 -> 0 | E5: 姓名 | F5: =+F2 -> 0 | J5: 生产单号 | N5: =+'1'!N5 -> 0 | O5: =+R2 -> -11 | P5: 订单编号 | Q5: =+Q2 -> 0 | R5: =+R2 -> -11
C6: 终端客户及地址 | E6: =E3 -> 0
A7: 序号 | B7: 区域 | C7: 产品名称 | D7: 款式 | E7: 高 | F7: 宽 | G7: 厚 | H7: 数量 | I7: 米数 | J7: 平方 | K7: 单价（元） | L7: 小计（元） | M7: 工分 | N7: 颜色 | P7: 材质 | Q7: 备注
A8: 1 | J8: =E8/1000*F8/1000*H8 -> 0 | L8: =J8*K8 -> 0 | M8: =L8/100 -> 0 | N8: ='1'!N8 -> （请车间多配一瓶油漆，随货一起）
A9: 2 | M9: =L9/100 -> 0
A10: 3 | M10: =L10/100 -> 0
A11: 4 | M11: =L11/100 -> 0
A12: 5 | M12: =L12/100 -> 0
A13: 6 | M13: =L13/100 -> 0
A14: 7 | M14: =L14/100 -> 0
A15: 8 | M15: =L15/100 -> 0
A16: 9 | M16: =L16/100 -> 0
A17: 10 | M17: =L17/100 -> 0
A18: 11 | M18: =L18/100 -> 0
A19: 12 | M19: =L19/100 -> 0
A20: 13 | M20: =L20/100 -> 0
... A22: 15 | M22: =L22/100 -> 0
A23: 16 | C23: 木箱包装 | D23: 此单共打个木箱包装
A24: 合计 | H24: =SUM(H6:H22) -> 0 | I24: =SUM(I6:I22) -> 0 | J24: =SUM(J6:J22) -> 0 | M24: =SUM(M6:M22) -> 0
A25: ='1'!A27 -> 图文说明: | L25: =+SUM(L8:L23) -> 0 | N25: 元
D27: ='1'!D29 -> 0
L28: 经销商确认:
A29: 制表人： | C29: ='1'!C31 -> 陈昌容 | D29: 项目设计师： | F29: ='1'!F31 -> 0 | H29: 绘图员： | J29: ='1'!J31 -> 0 | L29: 拆单： | N29: ='1'!N31 -> 0
A30: =+A25 -> 图文说明: | I30: 木工预计交货日期： | P30: 木工实际交货日期：
I31: 包装预计交货日期： | N31: =+'1'!N33 -> 0 | P31: 包装实际交货日期：
A32: 1、开料 | C32: 2、实木备料 | E32: 3、柜体开料 | G32: 4、封边 | I32: 5、打孔 | N32: 6、门扇 | P32: 7、附件
A33: 责任人 | B33: 完成时间 | C33: 责任人 | D33: 完成时间 | E33: 责任人 | F33: 完成时间 | G33: 责任人 | H33: 完成时间 | I33: 责任人 | J33: 完成时间 | N33: 责任人 | O33: 完成时间 | P33: 责任人 | Q33: 完成时间
A35: 8、贴皮 | C35: 9、雕刻 | E35: 10、木工配套 | G35: 11、木磨 | I35: 12、灰工 | N35: 13、底漆 | P35: 14、油磨
A36: 责任人 | B36: 完成时间 | C36: 责任人 | D36: 完成时间 | E36: 责任人 | F36: 完成时间 | G36: 责任人 | H36: 完成时间 | I36: 责任人 | J36: 完成时间 | N36: 责任人 | O36: 完成时间 | P36: 责任人 | Q36: 完成时间
A38: 15、油磨检验 | C38: 16、擦色 | E38: 17、面漆 | G38: 18、全检 | I38: 19、包装
A39: 责任人 | B39: 完成时间 | C39: 责任人 | D39: 完成时间 | E39: 责任人 | F39: 完成时间 | G39: 责任人 | H39: 完成时间 | I39: 责任人 | J39: 完成时间
A41: 预计交货日期： | C41: =N31 -> 0 | E41: 下单日期: | N41: 生产单号 | P41: =Q2 -> 0 | R41: =R2 -> -11
A42: 制表人： | C42: =C29 -> 陈昌容 | D42: 项目设计师： | F42: =F29 -> 0 | H42: 绘图员： | J42: =J29 -> 0 | L42: 拆单： | N42: =N29 -> 0

Sheet 12
A1: =+'1'!A1 -> 奢匠 | C1: 整装产品报价生产清单 | P1: 销售经理 | Q1: =+'1'!Q1 -> 0
C2: 经销商地址 | D2: =+'1'!D2 -> 0 | E2: 经销商名 | F2: =+'1'!F2 -> 0 | L2: 接单日期 | M2: ='1'!M2 -> 0 | P2: 订单编号 | Q2: =+'1'!Q2 -> 0 | R2: -12
C3: 终端客户及地址 | E3: ='1'!E3 -> 0
A4: =+A1 -> 奢匠 | C4: 整装作业单 | P4: 销售经理 | Q4: =+Q1 -> 0
C5: 省份 | D5: =+D2 -> 0 | E5: 姓名 | F5: =+F2 -> 0 | J5: 生产单号 | N5: =+'1'!N5 -> 0 | O5: =+R2 -> -12 | P5: 订单编号 | Q5: =+Q2 -> 0 | R5: =+R2 -> -12
C6: 终端客户及地址 | E6: =E3 -> 0
A7: 序号 | B7: 区域 | C7: 产品名称 | D7: 款式 | E7: 高 | F7: 宽 | G7: 厚 | H7: 数量 | I7: 米数 | J7: 平方 | K7: 单价（元） | L7: 小计（元） | M7: 工分 | N7: 颜色 | P7: 材质 | Q7: 备注
A8: 1 | J8: =E8/1000*F8/1000*H8 -> 0 | L8: =J8*K8 -> 0 | M8: =L8/100 -> 0 | N8: ='1'!N8 -> （请车间多配一瓶油漆，随货一起）
A9: 2 | M9: =L9/100 -> 0
A10: 3 | M10: =L10/100 -> 0
A11: 4 | M11: =L11/100 -> 0
A12: 5 | M12: =L12/100 -> 0
A13: 6 | M13: =L13/100 -> 0
A14: 7 | M14: =L14/100 -> 0
A15: 8 | M15: =L15/100 -> 0
A16: 9 | M16: =L16/100 -> 0
A17: 10 | M17: =L17/100 -> 0
A18: 11 | M18: =L18/100 -> 0
A19: 12 | M19: =L19/100 -> 0
A20: 13 | M20: =L20/100 -> 0
... A22: 15 | M22: =L22/100 -> 0
A23: 16 | C23: 木箱包装 | D23: 此单共打个木箱包装
A24: 合计 | H24: =SUM(H6:H22) -> 0 | I24: =SUM(I6:I22) -> 0 | J24: =SUM(J6:J22) -> 0 | M24: =SUM(M6:M22) -> 0
A25: ='1'!A27 -> 图文说明: | L25: =+SUM(L8:L23) -> 0 | N25: 元
D27: ='1'!D29 -> 0
L28: 经销商确认:
A29: 制表人： | C29: ='1'!C31 -> 陈昌容 | D29: 项目设计师： | F29: ='1'!F31 -> 0 | H29: 绘图员： | J29: ='1'!J31 -> 0 | L29: 拆单： | N29: ='1'!N31 -> 0
A30: =+A25 -> 图文说明: | I30: 木工预计交货日期： | P30: 木工实际交货日期：
I31: 包装预计交货日期： | N31: =+'1'!N33 -> 0 | P31: 包装实际交货日期：
A32: 1、开料 | C32: 2、实木备料 | E32: 3、柜体开料 | G32: 4、封边 | I32: 5、打孔 | N32: 6、门扇 | P32: 7、附件
A33: 责任人 | B33: 完成时间 | C33: 责任人 | D33: 完成时间 | E33: 责任人 | F33: 完成时间 | G33: 责任人 | H33: 完成时间 | I33: 责任人 | J33: 完成时间 | N33: 责任人 | O33: 完成时间 | P33: 责任人 | Q33: 完成时间
A35: 8、贴皮 | C35: 9、雕刻 | E35: 10、木工配套 | G35: 11、木磨 | I35: 12、灰工 | N35: 13、底漆 | P35: 14、油磨
A36: 责任人 | B36: 完成时间 | C36: 责任人 | D36: 完成时间 | E36: 责任人 | F36: 完成时间 | G36: 责任人 | H36: 完成时间 | I36: 责任人 | J36: 完成时间 | N36: 责任人 | O36: 完成时间 | P36: 责任人 | Q36: 完成时间
A38: 15、油磨检验 | C38: 16、擦色 | E38: 17、面漆 | G38: 18、全检 | I38: 19、包装
A39: 责任人 | B39: 完成时间 | C39: 责任人 | D39: 完成时间 | E39: 责任人 | F39: 完成时间 | G39: 责任人 | H39: 完成时间 | I39: 责任人 | J39: 完成时间
A41: 预计交货日期： | C41: =N31 -> 0 | E41: 下单日期: | N41: 生产单号 | P41: =Q2 -> 0 | R41: =R2 -> -12
A42: 制表人： | C42: =C29 -> 陈昌容 | D42: 项目设计师： | F42: =F29 -> 0 | H42: 绘图员： | J42: =J29 -> 0 | L42: 拆单： | N42: =N29 -> 0

Sheet 13
A1: =+'1'!A1 -> 奢匠 | C1: 整装产品报价生产清单 | P1: 销售经理 | Q1: =+'1'!Q1 -> 0
C2: 经销商地址 | D2: =+'1'!D2 -> 0 | E2: 经销商名 | F2: =+'1'!F2 -> 0 | L2: 接单日期 | M2: ='1'!M2 -> 0 | P2: 订单编号 | Q2: =+'1'!Q2 -> 0 | R2: -13
C3: 终端客户及地址 | E3: ='1'!E3 -> 0
A4: =+A1 -> 奢匠 | C4: 整装作业单 | P4: 销售经理 | Q4: =+Q1 -> 0
C5: 省份 | D5: =+D2 -> 0 | E5: 姓名 | F5: =+F2 -> 0 | J5: 生产单号 | N5: =+'1'!N5 -> 0 | O5: =+R2 -> -13 | P5: 订单编号 | Q5: =+Q2 -> 0 | R5: =+R2 -> -13
C6: 终端客户及地址 | E6: =E3 -> 0
A7: 序号 | B7: 区域 | C7: 产品名称 | D7: 款式 | E7: 高 | F7: 宽 | G7: 厚 | H7: 数量 | I7: 米数 | J7: 平方 | K7: 单价（元） | L7: 小计（元） | M7: 工分 | N7: 颜色 | P7: 材质 | Q7: 备注
A8: 1 | J8: =E8/1000*F8/1000*H8 -> 0 | L8: =J8*K8 -> 0 | M8: =L8/100 -> 0 | N8: ='1'!N8 -> （请车间多配一瓶油漆，随货一起）
A9: 2 | M9: =L9/100 -> 0
A10: 3 | M10: =L10/100 -> 0
A11: 4 | M11: =L11/100 -> 0
A12: 5 | M12: =L12/100 -> 0
A13: 6 | M13: =L13/100 -> 0
A14: 7 | M14: =L14/100 -> 0
A15: 8 | M15: =L15/100 -> 0
A16: 9 | M16: =L16/100 -> 0
A17: 10 | M17: =L17/100 -> 0
A18: 11 | M18: =L18/100 -> 0
A19: 12 | M19: =L19/100 -> 0
A20: 13 | M20: =L20/100 -> 0
... A22: 15 | M22: =L22/100 -> 0
A23: 16 | C23: 木箱包装 | D23: 此单共打个木箱包装
A24: 合计 | H24: =SUM(H6:H22) -> 0 | I24: =SUM(I6:I22) -> 0 | J24: =SUM(J6:J22) -> 0 | M24: =SUM(M6:M22) -> 0
A25: ='1'!A27 -> 图文说明: | L25: =+SUM(L8:L23) -> 0 | N25: 元
D27: ='1'!D29 -> 0
L28: 经销商确认:
A29: 制表人： | C29: ='1'!C31 -> 陈昌容 | D29: 项目设计师： | F29: ='1'!F31 -> 0 | H29: 绘图员： | J29: ='1'!J31 -> 0 | L29: 拆单： | N29: ='1'!N31 -> 0
A30: =+A25 -> 图文说明: | I30: 木工预计交货日期： | P30: 木工实际交货日期：
I31: 包装预计交货日期： | N31: =+'1'!N33 -> 0 | P31: 包装实际交货日期：
A32: 1、开料 | C32: 2、实木备料 | E32: 3、柜体开料 | G32: 4、封边 | I32: 5、打孔 | N32: 6、门扇 | P32: 7、附件
A33: 责任人 | B33: 完成时间 | C33: 责任人 | D33: 完成时间 | E33: 责任人 | F33: 完成时间 | G33: 责任人 | H33: 完成时间 | I33: 责任人 | J33: 完成时间 | N33: 责任人 | O33: 完成时间 | P33: 责任人 | Q33: 完成时间
A35: 8、贴皮 | C35: 9、雕刻 | E35: 10、木工配套 | G35: 11、木磨 | I35: 12、灰工 | N35: 13、底漆 | P35: 14、油磨
A36: 责任人 | B36: 完成时间 | C36: 责任人 | D36: 完成时间 | E36: 责任人 | F36: 完成时间 | G36: 责任人 | H36: 完成时间 | I36: 责任人 | J36: 完成时间 | N36: 责任人 | O36: 完成时间 | P36: 责任人 | Q36: 完成时间
A38: 15、油磨检验 | C38: 16、擦色 | E38: 17、面漆 | G38: 18、全检 | I38: 19、包装
A39: 责任人 | B39: 完成时间 | C39: 责任人 | D39: 完成时间 | E39: 责任人 | F39: 完成时间 | G39: 责任人 | H39: 完成时间 | I39: 责任人 | J39: 完成时间
A41: 预计交货日期： | C41: =N31 -> 0 | E41: 下单日期: | N41: 生产单号 | P41: =Q2 -> 0 | R41: =R2 -> -13
A42: 制表人： | C42: =C29 -> 陈昌容 | D42: 项目设计师： | F42: =F29 -> 0 | H42: 绘图员： | J42: =J29 -> 0 | L42: 拆单： | N42: =N29 -> 0

Sheet 14
A1: =+'1'!A1 -> 奢匠 | C1: 整装产品报价生产清单 | P1: 销售经理 | Q1: =+'1'!Q1 -> 0
C2: 经销商地址 | D2: =+'1'!D2 -> 0 | E2: 经销商名 | F2: =+'1'!F2 -> 0 | L2: 接单日期 | M2: ='1'!M2 -> 0 | P2: 订单编号 | Q2: =+'1'!Q2 -> 0 | R2: -14
C3: 终端客户及地址 | E3: ='1'!E3 -> 0
A4: =+A1 -> 奢匠 | C4: 整装作业单 | P4: 销售经理 | Q4: =+Q1 -> 0
C5: 省份 | D5: =+D2 -> 0 | E5: 姓名 | F5: =+F2 -> 0 | J5: 生产单号 | N5: =+'1'!N5 -> 0 | O5: =+R2 -> -14 | P5: 订单编号 | Q5: =+Q2 -> 0 | R5: =+R2 -> -14
C6: 终端客户及地址 | E6: =E3 -> 0
A7: 序号 | B7: 区域 | C7: 产品名称 | D7: 款式 | E7: 高 | F7: 宽 | G7: 厚 | H7: 数量 | I7: 米数 | J7: 平方 | K7: 单价（元） | L7: 小计（元） | M7: 工分 | N7: 颜色 | P7: 材质 | Q7: 备注
A8: 1 | J8: =E8/1000*F8/1000*H8 -> 0 | L8: =J8*K8 -> 0 | M8: =L8/100 -> 0 | N8: ='1'!N8 -> （请车间多配一瓶油漆，随货一起）
A9: 2 | M9: =L9/100 -> 0
A10: 3 | M10: =L10/100 -> 0
A11: 4 | M11: =L11/100 -> 0
A12: 5 | M12: =L12/100 -> 0
A13: 6 | M13: =L13/100 -> 0
A14: 7 | M14: =L14/100 -> 0
A15: 8 | M15: =L15/100 -> 0
A16: 9 | M16: =L16/100 -> 0
A17: 10 | M17: =L17/100 -> 0
A18: 11 | M18: =L18/100 -> 0
A19: 12 | M19: =L19/100 -> 0
A20: 13 | M20: =L20/100 -> 0
... A22: 15 | M22: =L22/100 -> 0
A23: 16 | C23: 木箱包装 | D23: 此单共打个木箱包装
A24: 合计 | H24: =SUM(H6:H22) -> 0 | I24: =SUM(I6:I22) -> 0 | J24: =SUM(J6:J22) -> 0 | M24: =SUM(M6:M22) -> 0
A25: ='1'!A27 -> 图文说明: | L25: =+SUM(L8:L23) -> 0 | N25: 元
D27: ='1'!D29 -> 0
L28: 经销商确认:
A29: 制表人： | C29: ='1'!C31 -> 陈昌容 | D29: 项目设计师： | F29: ='1'!F31 -> 0 | H29: 绘图员： | J29: ='1'!J31 -> 0 | L29: 拆单： | N29: ='1'!N31 -> 0
A30: =+A25 -> 图文说明: | I30: 木工预计交货日期： | P30: 木工实际交货日期：
I31: 包装预计交货日期： | N31: =+'1'!N33 -> 0 | P31: 包装实际交货日期：
A32: 1、开料 | C32: 2、实木备料 | E32: 3、柜体开料 | G32: 4、封边 | I32: 5、打孔 | N32: 6、门扇 | P32: 7、附件
A33: 责任人 | B33: 完成时间 | C33: 责任人 | D33: 完成时间 | E33: 责任人 | F33: 完成时间 | G33: 责任人 | H33: 完成时间 | I33: 责任人 | J33: 完成时间 | N33: 责任人 | O33: 完成时间 | P33: 责任人 | Q33: 完成时间
A35: 8、贴皮 | C35: 9、雕刻 | E35: 10、木工配套 | G35: 11、木磨 | I35: 12、灰工 | N35: 13、底漆 | P35: 14、油磨
A36: 责任人 | B36: 完成时间 | C36: 责任人 | D36: 完成时间 | E36: 责任人 | F36: 完成时间 | G36: 责任人 | H36: 完成时间 | I36: 责任人 | J36: 完成时间 | N36: 责任人 | O36: 完成时间 | P36: 责任人 | Q36: 完成时间
A38: 15、油磨检验 | C38: 16、擦色 | E38: 17、面漆 | G38: 18、全检 | I38: 19、包装
A39: 责任人 | B39: 完成时间 | C39: 责任人 | D39: 完成时间 | E39: 责任人 | F39: 完成时间 | G39: 责任人 | H39: 完成时间 | I39: 责任人 | J39: 完成时间
A41: 预计交货日期： | C41: =N31 -> 0 | E41: 下单日期: | N41: 生产单号 | P41: =Q2 -> 0 | R41: =R2 -> -14
A42: 制表人： | C42: =C29 -> 陈昌容 | D42: 项目设计师： | F42: =F29 -> 0 | H42: 绘图员： | J42: =J29 -> 0 | L42: 拆单： | N42: =N29 -> 0

Sheet 15
A1: =+'1'!A1 -> 奢匠 | C1: 整装产品报价生产清单 | P1: 销售经理 | Q1: =+'1'!Q1 -> 0
C2: 经销商地址 | D2: =+'1'!D2 -> 0 | E2: 经销商名 | F2: =+'1'!F2 -> 0 | L2: 接单日期 | M2: ='1'!M2 -> 0 | P2: 订单编号 | Q2: =+'1'!Q2 -> 0 | R2: -15
C3: 终端客户及地址 | E3: ='1'!E3 -> 0
A4: =+A1 -> 奢匠 | C4: 整装作业单 | P4: 销售经理 | Q4: =+Q1 -> 0
C5: 省份 | D5: =+D2 -> 0 | E5: 姓名 | F5: =+F2 -> 0 | J5: 生产单号 | N5: =+'1'!N5 -> 0 | O5: =+R2 -> -15 | P5: 订单编号 | Q5: =+Q2 -> 0 | R5: =+R2 -> -15
C6: 终端客户及地址 | E6: =E3 -> 0
A7: 序号 | B7: 区域 | C7: 产品名称 | D7: 款式 | E7: 高 | F7: 宽 | G7: 厚 | H7: 数量 | I7: 米数 | J7: 平方 | K7: 单价（元） | L7: 小计（元） | M7: 工分 | N7: 颜色 | P7: 材质 | Q7: 备注
A8: 1 | J8: =E8/1000*F8/1000*H8 -> 0 | L8: =J8*K8 -> 0 | M8: =L8/100 -> 0 | N8: ='1'!N8 -> （请车间多配一瓶油漆，随货一起）
A9: 2 | M9: =L9/100 -> 0
A10: 3 | M10: =L10/100 -> 0
A11: 4 | M11: =L11/100 -> 0
A12: 5 | M12: =L12/100 -> 0
A13: 6 | M13: =L13/100 -> 0
A14: 7 | M14: =L14/100 -> 0
A15: 8 | M15: =L15/100 -> 0
A16: 9 | M16: =L16/100 -> 0
A17: 10 | M17: =L17/100 -> 0
A18: 11 | M18: =L18/100 -> 0
A19: 12 | M19: =L19/100 -> 0
A20: 13 | M20: =L20/100 -> 0
... A22: 15 | M22: =L22/100 -> 0
A23: 16 | C23: 木箱包装 | D23: 此单共打个木箱包装
A24: 合计 | H24: =SUM(H6:H22) -> 0 | I24: =SUM(I6:I22) -> 0 | J24: =SUM(J6:J22) -> 0 | M24: =SUM(M6:M22) -> 0
A25: ='1'!A27 -> 图文说明: | L25: =+SUM(L8:L23) -> 0 | N25: 元
D27: ='1'!D29 -> 0
L28: 经销商确认:
A29: 制表人： | C29: ='1'!C31 -> 陈昌容 | D29: 项目设计师： | F29: ='1'!F31 -> 0 | H29: 绘图员： | J29: ='1'!J31 -> 0 | L29: 拆单： | N29: ='1'!N31 -> 0
A30: =+A25 -> 图文说明: | I30: 木工预计交货日期： | P30: 木工实际交货日期：
I31: 包装预计交货日期： | N31: =+'1'!N33 -> 0 | P31: 包装实际交货日期：
A32: 1、开料 | C32: 2、实木备料 | E32: 3、柜体开料 | G32: 4、封边 | I32: 5、打孔 | N32: 6、门扇 | P32: 7、附件
A33: 责任人 | B33: 完成时间 | C33: 责任人 | D33: 完成时间 | E33: 责任人 | F33: 完成时间 | G33: 责任人 | H33: 完成时间 | I33: 责任人 | J33: 完成时间 | N33: 责任人 | O33: 完成时间 | P33: 责任人 | Q33: 完成时间
A35: 8、贴皮 | C35: 9、雕刻 | E35: 10、木工配套 | G35: 11、木磨 | I35: 12、灰工 | N35: 13、底漆 | P35: 14、油磨
A36: 责任人 | B36: 完成时间 | C36: 责任人 | D36: 完成时间 | E36: 责任人 | F36: 完成时间 | G36: 责任人 | H36: 完成时间 | I36: 责任人 | J36: 完成时间 | N36: 责任人 | O36: 完成时间 | P36: 责任人 | Q36: 完成时间
A38: 15、油磨检验 | C38: 16、擦色 | E38: 17、面漆 | G38: 18、全检 | I38: 19、包装
A39: 责任人 | B39: 完成时间 | C39: 责任人 | D39: 完成时间 | E39: 责任人 | F39: 完成时间 | G39: 责任人 | H39: 完成时间 | I39: 责任人 | J39: 完成时间
A41: 预计交货日期： | C41: =N31 -> 0 | E41: 下单日期: | N41: 生产单号 | P41: =Q2 -> 0 | R41: =R2 -> -15
A42: 制表人： | C42: =C29 -> 陈昌容 | D42: 项目设计师： | F42: =F29 -> 0 | H42: 绘图员： | J42: =J29 -> 0 | L42: 拆单： | N42: =N29 -> 0

Sheet 16
A1: =+'1'!A1 -> 奢匠 | C1: 整装产品报价生产清单 | P1: 销售经理 | Q1: =+'1'!Q1 -> 0
C2: 经销商地址 | D2: =+'1'!D2 -> 0 | E2: 经销商名 | F2: =+'1'!F2 -> 0 | L2: 接单日期 | M2: ='1'!M2 -> 0 | P2: 订单编号 | Q2: =+'1'!Q2 -> 0 | R2: -16
C3: 终端客户及地址 | E3: ='1'!E3 -> 0
A4: =+A1 -> 奢匠 | C4: 整装作业单 | P4: 销售经理 | Q4: =+Q1 -> 0
C5: 省份 | D5: =+D2 -> 0 | E5: 姓名 | F5: =+F2 -> 0 | J5: 生产单号 | N5: =+'1'!N5 -> 0 | O5: =+R2 -> -16 | P5: 订单编号 | Q5: =+Q2 -> 0 | R5: =+R2 -> -16
C6: 终端客户及地址 | E6: =E3 -> 0
A7: 序号 | B7: 区域 | C7: 产品名称 | D7: 款式 | E7: 高 | F7: 宽 | G7: 厚 | H7: 数量 | I7: 米数 | J7: 平方 | K7: 单价（元） | L7: 小计（元） | M7: 工分 | N7: 颜色 | P7: 材质 | Q7: 备注
A8: 1 | J8: =E8/1000*F8/1000*H8 -> 0 | L8: =J8*K8 -> 0 | M8: =L8/100 -> 0 | N8: ='1'!N8 -> （请车间多配一瓶油漆，随货一起）
A9: 2 | M9: =L9/100 -> 0
A10: 3 | M10: =L10/100 -> 0
A11: 4 | M11: =L11/100 -> 0
A12: 5 | M12: =L12/100 -> 0
A13: 6 | M13: =L13/100 -> 0
A14: 7 | M14: =L14/100 -> 0
A15: 8 | M15: =L15/100 -> 0
A16: 9 | M16: =L16/100 -> 0
A17: 10 | M17: =L17/100 -> 0
A18: 11 | M18: =L18/100 -> 0
A19: 12 | M19: =L19/100 -> 0
A20: 13 | M20: =L20/100 -> 0
... A22: 15 | M22: =L22/100 -> 0
A23: 16 | C23: 木箱包装 | D23: 此单共打个木箱包装
A24: 合计 | H24: =SUM(H6:H22) -> 0 | I24: =SUM(I6:I22) -> 0 | J24: =SUM(J6:J22) -> 0 | M24: =SUM(M6:M22) -> 0
A25: ='1'!A27 -> 图文说明: | L25: =+SUM(L8:L23) -> 0 | N25: 元
D27: ='1'!D29 -> 0
L28: 经销商确认:
A29: 制表人： | C29: ='1'!C31 -> 陈昌容 | D29: 项目设计师： | F29: ='1'!F31 -> 0 | H29: 绘图员： | J29: ='1'!J31 -> 0 | L29: 拆单： | N29: ='1'!N31 -> 0
A30: =+A25 -> 图文说明: | I30: 木工预计交货日期： | P30: 木工实际交货日期：
I31: 包装预计交货日期： | N31: =+'1'!N33 -> 0 | P31: 包装实际交货日期：
A32: 1、开料 | C32: 2、实木备料 | E32: 3、柜体开料 | G32: 4、封边 | I32: 5、打孔 | N32: 6、门扇 | P32: 7、附件
A33: 责任人 | B33: 完成时间 | C33: 责任人 | D33: 完成时间 | E33: 责任人 | F33: 完成时间 | G33: 责任人 | H33: 完成时间 | I33: 责任人 | J33: 完成时间 | N33: 责任人 | O33: 完成时间 | P33: 责任人 | Q33: 完成时间
A35: 8、贴皮 | C35: 9、雕刻 | E35: 10、木工配套 | G35: 11、木磨 | I35: 12、灰工 | N35: 13、底漆 | P35: 14、油磨
A36: 责任人 | B36: 完成时间 | C36: 责任人 | D36: 完成时间 | E36: 责任人 | F36: 完成时间 | G36: 责任人 | H36: 完成时间 | I36: 责任人 | J36: 完成时间 | N36: 责任人 | O36: 完成时间 | P36: 责任人 | Q36: 完成时间
A38: 15、油磨检验 | C38: 16、擦色 | E38: 17、面漆 | G38: 18、全检 | I38: 19、包装
A39: 责任人 | B39: 完成时间 | C39: 责任人 | D39: 完成时间 | E39: 责任人 | F39: 完成时间 | G39: 责任人 | H39: 完成时间 | I39: 责任人 | J39: 完成时间
A41: 预计交货日期： | C41: =N31 -> 0 | E41: 下单日期: | N41: 生产单号 | P41: =Q2 -> 0 | R41: =R2 -> -16
A42: 制表人： | C42: =C29 -> 陈昌容 | D42: 项目设计师： | F42: =F29 -> 0 | H42: 绘图员： | J42: =J29 -> 0 | L42: 拆单： | N42: =N29 -> 0

Sheet 17
A1: =+'1'!A1 -> 奢匠 | C1: 整装产品报价生产清单 | P1: 销售经理 | Q1: =+'1'!Q1 -> 0
C2: 经销商地址 | D2: =+'1'!D2 -> 0 | E2: 经销商名 | F2: =+'1'!F2 -> 0 | L2: 接单日期 | M2: ='1'!M2 -> 0 | P2: 订单编号 | Q2: =+'1'!Q2 -> 0 | R2: -17
C3: 终端客户及地址 | E3: ='1'!E3 -> 0
A4: =+A1 -> 奢匠 | C4: 整装作业单 | P4: 销售经理 | Q4: =+Q1 -> 0
C5: 省份 | D5: =+D2 -> 0 | E5: 姓名 | F5: =+F2 -> 0 | J5: 生产单号 | N5: =+'1'!N5 -> 0 | O5: =+R2 -> -17 | P5: 订单编号 | Q5: =+Q2 -> 0 | R5: =+R2 -> -17
C6: 终端客户及地址 | E6: =E3 -> 0
A7: 序号 | B7: 区域 | C7: 产品名称 | D7: 款式 | E7: 高 | F7: 宽 | G7: 厚 | H7: 数量 | I7: 米数 | J7: 平方 | K7: 单价（元） | L7: 小计（元） | M7: 工分 | N7: 颜色 | P7: 材质 | Q7: 备注
A8: 1 | J8: =E8/1000*F8/1000*H8 -> 0 | L8: =J8*K8 -> 0 | M8: =L8/100 -> 0 | N8: ='1'!N8 -> （请车间多配一瓶油漆，随货一起）
A9: 2 | M9: =L9/100 -> 0
A10: 3 | M10: =L10/100 -> 0
A11: 4 | M11: =L11/100 -> 0
A12: 5 | M12: =L12/100 -> 0
A13: 6 | M13: =L13/100 -> 0
A14: 7 | M14: =L14/100 -> 0
A15: 8 | M15: =L15/100 -> 0
A16: 9 | M16: =L16/100 -> 0
A17: 10 | M17: =L17/100 -> 0
A18: 11 | M18: =L18/100 -> 0
A19: 12 | M19: =L19/100 -> 0
A20: 13 | M20: =L20/100 -> 0
... A22: 15 | M22: =L22/100 -> 0
A23: 16 | C23: 木箱包装 | D23: 此单共打个木箱包装
A24: 合计 | H24: =SUM(H6:H22) -> 0 | I24: =SUM(I6:I22) -> 0 | J24: =SUM(J6:J22) -> 0 | M24: =SUM(M6:M22) -> 0
A25: ='1'!A27 -> 图文说明: | L25: =+SUM(L8:L23) -> 0 | N25: 元
D27: ='1'!D29 -> 0
L28: 经销商确认:
A29: 制表人： | C29: ='1'!C31 -> 陈昌容 | D29: 项目设计师： | F29: ='1'!F31 -> 0 | H29: 绘图员： | J29: ='1'!J31 -> 0 | L29: 拆单： | N29: ='1'!N31 -> 0
A30: =+A25 -> 图文说明: | I30: 木工预计交货日期： | P30: 木工实际交货日期：
I31: 包装预计交货日期： | N31: =+'1'!N33 -> 0 | P31: 包装实际交货日期：
A32: 1、开料 | C32: 2、实木备料 | E32: 3、柜体开料 | G32: 4、封边 | I32: 5、打孔 | N32: 6、门扇 | P32: 7、附件
A33: 责任人 | B33: 完成时间 | C33: 责任人 | D33: 完成时间 | E33: 责任人 | F33: 完成时间 | G33: 责任人 | H33: 完成时间 | I33: 责任人 | J33: 完成时间 | N33: 责任人 | O33: 完成时间 | P33: 责任人 | Q33: 完成时间
A35: 8、贴皮 | C35: 9、雕刻 | E35: 10、木工配套 | G35: 11、木磨 | I35: 12、灰工 | N35: 13、底漆 | P35: 14、油磨
A36: 责任人 | B36: 完成时间 | C36: 责任人 | D36: 完成时间 | E36: 责任人 | F36: 完成时间 | G36: 责任人 | H36: 完成时间 | I36: 责任人 | J36: 完成时间 | N36: 责任人 | O36: 完成时间 | P36: 责任人 | Q36: 完成时间
A38: 15、油磨检验 | C38: 16、擦色 | E38: 17、面漆 | G38: 18、全检 | I38: 19、包装
A39: 责任人 | B39: 完成时间 | C39: 责任人 | D39: 完成时间 | E39: 责任人 | F39: 完成时间 | G39: 责任人 | H39: 完成时间 | I39: 责任人 | J39: 完成时间
A41: 预计交货日期： | C41: =N31 -> 0 | E41: 下单日期: | N41: 生产单号 | P41: =Q2 -> 0 | R41: =R2 -> -17
A42: 制表人： | C42: =C29 -> 陈昌容 | D42: 项目设计师： | F42: =F29 -> 0 | H42: 绘图员： | J42: =J29 -> 0 | L42: 拆单： | N42: =N29 -> 0

Sheet 18
A1: =+'1'!A1 -> 奢匠 | C1: 整装产品报价生产清单 | P1: 销售经理 | Q1: =+'1'!Q1 -> 0
C2: 经销商地址 | D2: =+'1'!D2 -> 0 | E2: 经销商名 | F2: =+'1'!F2 -> 0 | L2: 接单日期 | M2: ='1'!M2 -> 0 | P2: 订单编号 | Q2: =+'1'!Q2 -> 0 | R2: -18
C3: 终端客户及地址 | E3: ='1'!E3 -> 0
A4: =+A1 -> 奢匠 | C4: 整装作业单 | P4: 销售经理 | Q4: =+Q1 -> 0
C5: 省份 | D5: =+D2 -> 0 | E5: 姓名 | F5: =+F2 -> 0 | J5: 生产单号 | N5: =+'1'!N5 -> 0 | O5: =+R2 -> -18 | P5: 订单编号 | Q5: =+Q2 -> 0 | R5: =+R2 -> -18
C6: 终端客户及地址 | E6: =E3 -> 0
A7: 序号 | B7: 区域 | C7: 产品名称 | D7: 款式 | E7: 高 | F7: 宽 | G7: 厚 | H7: 数量 | I7: 米数 | J7: 平方 | K7: 单价（元） | L7: 小计（元） | M7: 工分 | N7: 颜色 | P7: 材质 | Q7: 备注
A8: 1 | J8: =E8/1000*F8/1000*H8 -> 0 | L8: =J8*K8 -> 0 | M8: =L8/100 -> 0 | N8: ='1'!N8 -> （请车间多配一瓶油漆，随货一起）
A9: 2 | M9: =L9/100 -> 0
A10: 3 | M10: =L10/100 -> 0
A11: 4 | M11: =L11/100 -> 0
A12: 5 | M12: =L12/100 -> 0
A13: 6 | M13: =L13/100 -> 0
A14: 7 | M14: =L14/100 -> 0
A15: 8 | M15: =L15/100 -> 0
A16: 9 | M16: =L16/100 -> 0
A17: 10 | M17: =L17/100 -> 0
A18: 11 | M18: =L18/100 -> 0
A19: 12 | M19: =L19/100 -> 0
A20: 13 | M20: =L20/100 -> 0
... A22: 15 | M22: =L22/100 -> 0
A23: 16 | C23: 木箱包装 | D23: 此单共打个木箱包装
A24: 合计 | H24: =SUM(H6:H22) -> 0 | I24: =SUM(I6:I22) -> 0 | J24: =SUM(J6:J22) -> 0 | M24: =SUM(M6:M22) -> 0
A25: ='1'!A27 -> 图文说明: | L25: =+SUM(L8:L23) -> 0 | N25: 元
D27: ='1'!D29 -> 0
L28: 经销商确认:
A29: 制表人： | C29: ='1'!C31 -> 陈昌容 | D29: 项目设计师： | F29: ='1'!F31 -> 0 | H29: 绘图员： | J29: ='1'!J31 -> 0 | L29: 拆单： | N29: ='1'!N31 -> 0
A30: =+A25 -> 图文说明: | I30: 木工预计交货日期： | P30: 木工实际交货日期：
I31: 包装预计交货日期： | N31: =+'1'!N33 -> 0 | P31: 包装实际交货日期：
A32: 1、开料 | C32: 2、实木备料 | E32: 3、柜体开料 | G32: 4、封边 | I32: 5、打孔 | N32: 6、门扇 | P32: 7、附件
A33: 责任人 | B33: 完成时间 | C33: 责任人 | D33: 完成时间 | E33: 责任人 | F33: 完成时间 | G33: 责任人 | H33: 完成时间 | I33: 责任人 | J33: 完成时间 | N33: 责任人 | O33: 完成时间 | P33: 责任人 | Q33: 完成时间
A35: 8、贴皮 | C35: 9、雕刻 | E35: 10、木工配套 | G35: 11、木磨 | I35: 12、灰工 | N35: 13、底漆 | P35: 14、油磨
A36: 责任人 | B36: 完成时间 | C36: 责任人 | D36: 完成时间 | E36: 责任人 | F36: 完成时间 | G36: 责任人 | H36: 完成时间 | I36: 责任人 | J36: 完成时间 | N36: 责任人 | O36: 完成时间 | P36: 责任人 | Q36: 完成时间
A38: 15、油磨检验 | C38: 16、擦色 | E38: 17、面漆 | G38: 18、全检 | I38: 19、包装
A39: 责任人 | B39: 完成时间 | C39: 责任人 | D39: 完成时间 | E39: 责任人 | F39: 完成时间 | G39: 责任人 | H39: 完成时间 | I39: 责任人 | J39: 完成时间
A41: 预计交货日期： | C41: =N31 -> 0 | E41: 下单日期: | N41: 生产单号 | P41: =Q2 -> 0 | R41: =R2 -> -18
A42: 制表人： | C42: =C29 -> 陈昌容 | D42: 项目设计师： | F42: =F29 -> 0 | H42: 绘图员： | J42: =J29 -> 0 | L42: 拆单： | N42: =N29 -> 0

Sheet 19
A1: =+'1'!A1 -> 奢匠 | C1: 整装产品报价生产清单 | P1: 销售经理 | Q1: =+'1'!Q1 -> 0
C2: 经销商地址 | D2: =+'1'!D2 -> 0 | E2: 经销商名 | F2: =+'1'!F2 -> 0 | L2: 接单日期 | M2: ='1'!M2 -> 0 | P2: 订单编号 | Q2: =+'1'!Q2 -> 0 | R2: -19
C3: 终端客户及地址 | E3: ='1'!E3 -> 0
A4: =+A1 -> 奢匠 | C4: 整装作业单 | P4: 销售经理 | Q4: =+Q1 -> 0
C5: 省份 | D5: =+D2 -> 0 | E5: 姓名 | F5: =+F2 -> 0 | J5: 生产单号 | N5: =+'1'!N5 -> 0 | O5: =+R2 -> -19 | P5: 订单编号 | Q5: =+Q2 -> 0 | R5: =+R2 -> -19
C6: 终端客户及地址 | E6: =E3 -> 0
A7: 序号 | B7: 区域 | C7: 产品名称 | D7: 款式 | E7: 高 | F7: 宽 | G7: 厚 | H7: 数量 | I7: 米数 | J7: 平方 | K7: 单价（元） | L7: 小计（元） | M7: 工分 | N7: 颜色 | P7: 材质 | Q7: 备注
A8: 1 | J8: =E8/1000*F8/1000*H8 -> 0 | L8: =J8*K8 -> 0 | M8: =L8/100 -> 0 | N8: ='1'!N8 -> （请车间多配一瓶油漆，随货一起）
A9: 2 | M9: =L9/100 -> 0
A10: 3 | M10: =L10/100 -> 0
A11: 4 | M11: =L11/100 -> 0
A12: 5 | M12: =L12/100 -> 0
A13: 6 | M13: =L13/100 -> 0
A14: 7 | M14: =L14/100 -> 0
A15: 8 | M15: =L15/100 -> 0
A16: 9 | M16: =L16/100 -> 0
A17: 10 | M17: =L17/100 -> 0
A18: 11 | M18: =L18/100 -> 0
A19: 12 | M19: =L19/100 -> 0
A20: 13 | M20: =L20/100 -> 0
... A22: 15 | M22: =L22/100 -> 0
A23: 16 | C23: 木箱包装 | D23: 此单共打个木箱包装
A24: 合计 | H24: =SUM(H6:H22) -> 0 | I24: =SUM(I6:I22) -> 0 | J24: =SUM(J6:J22) -> 0 | M24: =SUM(M6:M22) -> 0
A25: ='1'!A27 -> 图文说明: | L25: =+SUM(L8:L23) -> 0 | N25: 元
D27: ='1'!D29 -> 0
L28: 经销商确认:
A29: 制表人： | C29: ='1'!C31 -> 陈昌容 | D29: 项目设计师： | F29: ='1'!F31 -> 0 | H29: 绘图员： | J29: ='1'!J31 -> 0 | L29: 拆单： | N29: ='1'!N31 -> 0
A30: =+A25 -> 图文说明: | I30: 木工预计交货日期： | P30: 木工实际交货日期：
I31: 包装预计交货日期： | N31: =+'1'!N33 -> 0 | P31: 包装实际交货日期：
A32: 1、开料 | C32: 2、实木备料 | E32: 3、柜体开料 | G32: 4、封边 | I32: 5、打孔 | N32: 6、门扇 | P32: 7、附件
A33: 责任人 | B33: 完成时间 | C33: 责任人 | D33: 完成时间 | E33: 责任人 | F33: 完成时间 | G33: 责任人 | H33: 完成时间 | I33: 责任人 | J33: 完成时间 | N33: 责任人 | O33: 完成时间 | P33: 责任人 | Q33: 完成时间
A35: 8、贴皮 | C35: 9、雕刻 | E35: 10、木工配套 | G35: 11、木磨 | I35: 12、灰工 | N35: 13、底漆 | P35: 14、油磨
A36: 责任人 | B36: 完成时间 | C36: 责任人 | D36: 完成时间 | E36: 责任人 | F36: 完成时间 | G36: 责任人 | H36: 完成时间 | I36: 责任人 | J36: 完成时间 | N36: 责任人 | O36: 完成时间 | P36: 责任人 | Q36: 完成时间
A38: 15、油磨检验 | C38: 16、擦色 | E38: 17、面漆 | G38: 18、全检 | I38: 19、包装
A39: 责任人 | B39: 完成时间 | C39: 责任人 | D39: 完成时间 | E39: 责任人 | F39: 完成时间 | G39: 责任人 | H39: 完成时间 | I39: 责任人 | J39: 完成时间
A41: 预计交货日期： | C41: =N31 -> 0 | E41: 下单日期: | N41: 生产单号 | P41: =Q2 -> 0 | R41: =R2 -> -19
A42: 制表人： | C42: =C29 -> 陈昌容 | D42: 项目设计师： | F42: =F29 -> 0 | H42: 绘图员： | J42: =J29 -> 0 | L42: 拆单： | N42: =N29 -> 0

Sheet 20
A1: =+'1'!A1 -> 奢匠 | C1: 整装产品报价生产清单 | P1: 销售经理 | Q1: =+'1'!Q1 -> 0
C2: 经销商地址 | D2: =+'1'!D2 -> 0 | E2: 经销商名 | F2: =+'1'!F2 -> 0 | L2: 接单日期 | M2: ='1'!M2 -> 0 | P2: 订单编号 | Q2: =+'1'!Q2 -> 0 | R2: -20
C3: 终端客户及地址 | E3: ='1'!E3 -> 0
A4: =+A1 -> 奢匠 | C4: 整装作业单 | P4: 销售经理 | Q4: =+Q1 -> 0
C5: 省份 | D5: =+D2 -> 0 | E5: 姓名 | F5: =+F2 -> 0 | J5: 生产单号 | N5: =+'1'!N5 -> 0 | O5: =+R2 -> -20 | P5: 订单编号 | Q5: =+Q2 -> 0 | R5: =+R2 -> -20
C6: 终端客户及地址 | E6: =E3 -> 0
A7: 序号 | B7: 区域 | C7: 产品名称 | D7: 款式 | E7: 高 | F7: 宽 | G7: 厚 | H7: 数量 | I7: 米数 | J7: 平方 | K7: 单价（元） | L7: 小计（元） | M7: 工分 | N7: 颜色 | P7: 材质 | Q7: 备注
A8: 1 | J8: =E8/1000*F8/1000*H8 -> 0 | L8: =J8*K8 -> 0 | M8: =L8/100 -> 0 | N8: ='1'!N8 -> （请车间多配一瓶油漆，随货一起）
A9: 2 | M9: =L9/100 -> 0
A10: 3 | M10: =L10/100 -> 0
A11: 4 | M11: =L11/100 -> 0
A12: 5 | M12: =L12/100 -> 0
A13: 6 | M13: =L13/100 -> 0
A14: 7 | M14: =L14/100 -> 0
A15: 8 | M15: =L15/100 -> 0
A16: 9 | M16: =L16/100 -> 0
A17: 10 | M17: =L17/100 -> 0
A18: 11 | M18: =L18/100 -> 0
A19: 12 | M19: =L19/100 -> 0
A20: 13 | M20: =L20/100 -> 0
... A22: 15 | M22: =L22/100 -> 0
A23: 16 | C23: 木箱包装 | D23: 此单共打个木箱包装
A24: 合计 | H24: =SUM(H6:H22) -> 0 | I24: =SUM(I6:I22) -> 0 | J24: =SUM(J6:J22) -> 0 | M24: =SUM(M6:M22) -> 0
A25: ='1'!A27 -> 图文说明: | L25: =+SUM(L8:L23) -> 0 | N25: 元
D27: ='1'!D29 -> 0
L28: 经销商确认:
A29: 制表人： | C29: ='1'!C31 -> 陈昌容 | D29: 项目设计师： | F29: ='1'!F31 -> 0 | H29: 绘图员： | J29: ='1'!J31 -> 0 | L29: 拆单： | N29: ='1'!N31 -> 0
A30: =+A25 -> 图文说明: | I30: 木工预计交货日期： | P30: 木工实际交货日期：
I31: 包装预计交货日期： | N31: =+'1'!N33 -> 0 | P31: 包装实际交货日期：
A32: 1、开料 | C32: 2、实木备料 | E32: 3、柜体开料 | G32: 4、封边 | I32: 5、打孔 | N32: 6、门扇 | P32: 7、附件
A33: 责任人 | B33: 完成时间 | C33: 责任人 | D33: 完成时间 | E33: 责任人 | F33: 完成时间 | G33: 责任人 | H33: 完成时间 | I33: 责任人 | J33: 完成时间 | N33: 责任人 | O33: 完成时间 | P33: 责任人 | Q33: 完成时间
A35: 8、贴皮 | C35: 9、雕刻 | E35: 10、木工配套 | G35: 11、木磨 | I35: 12、灰工 | N35: 13、底漆 | P35: 14、油磨
A36: 责任人 | B36: 完成时间 | C36: 责任人 | D36: 完成时间 | E36: 责任人 | F36: 完成时间 | G36: 责任人 | H36: 完成时间 | I36: 责任人 | J36: 完成时间 | N36: 责任人 | O36: 完成时间 | P36: 责任人 | Q36: 完成时间
A38: 15、油磨检验 | C38: 16、擦色 | E38: 17、面漆 | G38: 18、全检 | I38: 19、包装
A39: 责任人 | B39: 完成时间 | C39: 责任人 | D39: 完成时间 | E39: 责任人 | F39: 完成时间 | G39: 责任人 | H39: 完成时间 | I39: 责任人 | J39: 完成时间
A41: 预计交货日期： | C41: =N31 -> 0 | E41: 下单日期: | N41: 生产单号 | P41: =Q2 -> 0 | R41: =R2 -> -20
A42: 制表人： | C42: =C29 -> 陈昌容 | D42: 项目设计师： | F42: =F29 -> 0 | H42: 绘图员： | J42: =J29 -> 0 | L42: 拆单： | N42: =N29 -> 0

Sheet 21
A1: =+'1'!A1 -> 奢匠 | C1: 整装产品报价生产清单 | P1: 销售经理 | Q1: =+'1'!Q1 -> 0
C2: 经销商地址 | D2: =+'1'!D2 -> 0 | E2: 经销商名 | F2: =+'1'!F2 -> 0 | L2: 接单日期 | M2: ='1'!M2 -> 0 | P2: 订单编号 | Q2: =+'1'!Q2 -> 0 | R2: -21
C3: 终端客户及地址 | E3: ='1'!E3 -> 0
A4: =+A1 -> 奢匠 | C4: 整装作业单 | P4: 销售经理 | Q4: =+Q1 -> 0
C5: 省份 | D5: =+D2 -> 0 | E5: 姓名 | F5: =+F2 -> 0 | J5: 生产单号 | N5: =+'1'!N5 -> 0 | O5: =+R2 -> -21 | P5: 订单编号 | Q5: =+Q2 -> 0 | R5: =+R2 -> -21
C6: 终端客户及地址 | E6: =E3 -> 0
A7: 序号 | B7: 区域 | C7: 产品名称 | D7: 款式 | E7: 高 | F7: 宽 | G7: 厚 | H7: 数量 | I7: 米数 | J7: 平方 | K7: 单价（元） | L7: 小计（元） | M7: 工分 | N7: 颜色 | P7: 材质 | Q7: 备注
A8: 1 | J8: =E8/1000*F8/1000*H8 -> 0 | L8: =J8*K8 -> 0 | M8: =L8/100 -> 0 | N8: ='1'!N8 -> （请车间多配一瓶油漆，随货一起）
A9: 2 | M9: =L9/100 -> 0
A10: 3 | M10: =L10/100 -> 0
A11: 4 | M11: =L11/100 -> 0
A12: 5 | M12: =L12/100 -> 0
A13: 6 | M13: =L13/100 -> 0
A14: 7 | M14: =L14/100 -> 0
A15: 8 | M15: =L15/100 -> 0
A16: 9 | M16: =L16/100 -> 0
A17: 10 | M17: =L17/100 -> 0
A18: 11 | M18: =L18/100 -> 0
A19: 12 | M19: =L19/100 -> 0
A20: 13 | M20: =L20/100 -> 0
... A22: 15 | M22: =L22/100 -> 0
A23: 16 | C23: 木箱包装 | D23: 此单共打个木箱包装
A24: 合计 | H24: =SUM(H6:H22) -> 0 | I24: =SUM(I6:I22) -> 0 | J24: =SUM(J6:J22) -> 0 | M24: =SUM(M6:M22) -> 0
A25: ='1'!A27 -> 图文说明: | L25: =+SUM(L8:L23) -> 0 | N25: 元
L28: 经销商确认:
A29: 制表人： | C29: ='1'!C31 -> 陈昌容 | D29: 项目设计师： | F29: ='1'!F31 -> 0 | H29: 绘图员： | J29: ='1'!J31 -> 0 | L29: 拆单： | N29: ='1'!N31 -> 0
A30: =+A25 -> 图文说明: | I30: 木工预计交货日期： | P30: 木工实际交货日期：
I31: 包装预计交货日期： | N31: =+'1'!N33 -> 0 | P31: 包装实际交货日期：
A32: 1、开料 | C32: 2、实木备料 | E32: 3、柜体开料 | G32: 4、封边 | I32: 5、打孔 | N32: 6、门扇 | P32: 7、附件
A33: 责任人 | B33: 完成时间 | C33: 责任人 | D33: 完成时间 | E33: 责任人 | F33: 完成时间 | G33: 责任人 | H33: 完成时间 | I33: 责任人 | J33: 完成时间 | N33: 责任人 | O33: 完成时间 | P33: 责任人 | Q33: 完成时间
A35: 8、贴皮 | C35: 9、雕刻 | E35: 10、木工配套 | G35: 11、木磨 | I35: 12、灰工 | N35: 13、底漆 | P35: 14、油磨
A36: 责任人 | B36: 完成时间 | C36: 责任人 | D36: 完成时间 | E36: 责任人 | F36: 完成时间 | G36: 责任人 | H36: 完成时间 | I36: 责任人 | J36: 完成时间 | N36: 责任人 | O36: 完成时间 | P36: 责任人 | Q36: 完成时间
A38: 15、油磨检验 | C38: 16、擦色 | E38: 17、面漆 | G38: 18、全检 | I38: 19、包装
A39: 责任人 | B39: 完成时间 | C39: 责任人 | D39: 完成时间 | E39: 责任人 | F39: 完成时间 | G39: 责任人 | H39: 完成时间 | I39: 责任人 | J39: 完成时间
A41: 预计交货日期： | C41: =N31 -> 0 | E41: 下单日期: | N41: 生产单号 | P41: =Q2 -> 0 | R41: =R2 -> -21
A42: 制表人： | C42: =C29 -> 陈昌容 | D42: 项目设计师： | F42: =F29 -> 0 | H42: 绘图员： | J42: =J29 -> 0 | L42: 拆单： | N42: =N29 -> 0

Sheet 22
A1: =+'1'!A1 -> 奢匠 | C1: 整装产品报价生产清单 | P1: 销售经理 | Q1: =+'1'!Q1 -> 0
C2: 经销商地址 | D2: =+'1'!D2 -> 0 | E2: 经销商名 | F2: =+'1'!F2 -> 0 | L2: 接单日期 | M2: ='1'!M2 -> 0 | P2: 订单编号 | Q2: =+'1'!Q2 -> 0 | R2: -22
C3: 终端客户及地址 | E3: ='1'!E3 -> 0
A4: =+A1 -> 奢匠 | C4: 整装作业单 | P4: 销售经理 | Q4: =+Q1 -> 0
C5: 省份 | D5: =+D2 -> 0 | E5: 姓名 | F5: =+F2 -> 0 | J5: 生产单号 | N5: =+'1'!N5 -> 0 | O5: =+R2 -> -22 | P5: 订单编号 | Q5: =+Q2 -> 0 | R5: =+R2 -> -22
C6: 终端客户及地址 | E6: =E3 -> 0
A7: 序号 | B7: 区域 | C7: 产品名称 | D7: 款式 | E7: 高 | F7: 宽 | G7: 厚 | H7: 数量 | I7: 米数 | J7: 平方 | K7: 单价（元） | L7: 小计（元） | M7: 工分 | N7: 颜色 | P7: 材质 | Q7: 备注
A8: 1 | J8: =E8/1000*F8/1000*H8 -> 0 | L8: =J8*K8 -> 0 | M8: =L8/100 -> 0 | N8: ='1'!N8 -> （请车间多配一瓶油漆，随货一起）
A9: 2 | M9: =L9/100 -> 0
A10: 3 | M10: =L10/100 -> 0
A11: 4 | M11: =L11/100 -> 0
A12: 5 | M12: =L12/100 -> 0
A13: 6 | M13: =L13/100 -> 0
A14: 7 | M14: =L14/100 -> 0
A15: 8 | M15: =L15/100 -> 0
A16: 9 | M16: =L16/100 -> 0
A17: 10 | M17: =L17/100 -> 0
A18: 11 | M18: =L18/100 -> 0
A19: 12 | M19: =L19/100 -> 0
A20: 13 | M20: =L20/100 -> 0
... A22: 15 | M22: =L22/100 -> 0
A23: 16 | C23: 木箱包装 | D23: 此单共打个木箱包装
A24: 合计 | H24: =SUM(H6:H22) -> 0 | I24: =SUM(I6:I22) -> 0 | J24: =SUM(J6:J22) -> 0 | M24: =SUM(M6:M22) -> 0
A25: ='1'!A27 -> 图文说明: | L25: =+SUM(L8:L23) -> 0 | N25: 元
L28: 经销商确认:
A29: 制表人： | C29: ='1'!C31 -> 陈昌容 | D29: 项目设计师： | F29: ='1'!F31 -> 0 | H29: 绘图员： | J29: ='1'!J31 -> 0 | L29: 拆单： | N29: ='1'!N31 -> 0
A30: =+A25 -> 图文说明: | I30: 木工预计交货日期： | P30: 木工实际交货日期：
I31: 包装预计交货日期： | N31: =+'1'!N33 -> 0 | P31: 包装实际交货日期：
A32: 1、开料 | C32: 2、实木备料 | E32: 3、柜体开料 | G32: 4、封边 | I32: 5、打孔 | N32: 6、门扇 | P32: 7、附件
A33: 责任人 | B33: 完成时间 | C33: 责任人 | D33: 完成时间 | E33: 责任人 | F33: 完成时间 | G33: 责任人 | H33: 完成时间 | I33: 责任人 | J33: 完成时间 | N33: 责任人 | O33: 完成时间 | P33: 责任人 | Q33: 完成时间
A35: 8、贴皮 | C35: 9、雕刻 | E35: 10、木工配套 | G35: 11、木磨 | I35: 12、灰工 | N35: 13、底漆 | P35: 14、油磨
A36: 责任人 | B36: 完成时间 | C36: 责任人 | D36: 完成时间 | E36: 责任人 | F36: 完成时间 | G36: 责任人 | H36: 完成时间 | I36: 责任人 | J36: 完成时间 | N36: 责任人 | O36: 完成时间 | P36: 责任人 | Q36: 完成时间
A38: 15、油磨检验 | C38: 16、擦色 | E38: 17、面漆 | G38: 18、全检 | I38: 19、包装
A39: 责任人 | B39: 完成时间 | C39: 责任人 | D39: 完成时间 | E39: 责任人 | F39: 完成时间 | G39: 责任人 | H39: 完成时间 | I39: 责任人 | J39: 完成时间
A41: 预计交货日期： | C41: =N31 -> 0 | E41: 下单日期: | N41: 生产单号 | P41: =Q2 -> 0 | R41: =R2 -> -22
A42: 制表人： | C42: =C29 -> 陈昌容 | D42: 项目设计师： | F42: =F29 -> 0 | H42: 绘图员： | J42: =J29 -> 0 | L42: 拆单： | N42: =N29 -> 0

Sheet 23
A1: =+'1'!A1 -> 奢匠 | C1: 整装产品报价生产清单 | P1: 销售经理 | Q1: =+'1'!Q1 -> 0
C2: 经销商地址 | D2: =+'1'!D2 -> 0 | E2: 经销商名 | F2: =+'1'!F2 -> 0 | L2: 接单日期 | M2: ='1'!M2 -> 0 | P2: 订单编号 | Q2: =+'1'!Q2 -> 0 | R2: -23
C3: 终端客户及地址 | E3: ='1'!E3 -> 0
A4: =+A1 -> 奢匠 | C4: 整装作业单 | P4: 销售经理 | Q4: =+Q1 -> 0
C5: 省份 | D5: =+D2 -> 0 | E5: 姓名 | F5: =+F2 -> 0 | J5: 生产单号 | N5: =+'1'!N5 -> 0 | O5: =+R2 -> -23 | P5: 订单编号 | Q5: =+Q2 -> 0 | R5: =+R2 -> -23
C6: 终端客户及地址 | E6: =E3 -> 0
A7: 序号 | B7: 区域 | C7: 产品名称 | D7: 款式 | E7: 高 | F7: 宽 | G7: 厚 | H7: 数量 | I7: 米数 | J7: 平方 | K7: 单价（元） | L7: 小计（元） | M7: 工分 | N7: 颜色 | P7: 材质 | Q7: 备注
A8: 1 | J8: =E8/1000*F8/1000*H8 -> 0 | L8: =J8*K8 -> 0 | M8: =L8/100 -> 0 | N8: ='1'!N8 -> （请车间多配一瓶油漆，随货一起）
A9: 2 | M9: =L9/100 -> 0
A10: 3 | M10: =L10/100 -> 0
A11: 4 | M11: =L11/100 -> 0
A12: 5 | M12: =L12/100 -> 0
A13: 6 | M13: =L13/100 -> 0
A14: 7 | M14: =L14/100 -> 0
A15: 8 | M15: =L15/100 -> 0
A16: 9 | M16: =L16/100 -> 0
A17: 10 | M17: =L17/100 -> 0
A18: 11 | M18: =L18/100 -> 0
A19: 12 | M19: =L19/100 -> 0
A20: 13 | M20: =L20/100 -> 0
... A22: 15 | M22: =L22/100 -> 0
A23: 16 | C23: 木箱包装 | D23: 此单共打个木箱包装
A24: 合计 | H24: =SUM(H6:H22) -> 0 | I24: =SUM(I6:I22) -> 0 | J24: =SUM(J6:J22) -> 0 | M24: =SUM(M6:M22) -> 0
A25: ='1'!A27 -> 图文说明: | L25: =+SUM(L8:L23) -> 0 | N25: 元
L28: 经销商确认:
A29: 制表人： | C29: ='1'!C31 -> 陈昌容 | D29: 项目设计师： | F29: ='1'!F31 -> 0 | H29: 绘图员： | J29: ='1'!J31 -> 0 | L29: 拆单： | N29: ='1'!N31 -> 0
A30: =+A25 -> 图文说明: | I30: 木工预计交货日期： | P30: 木工实际交货日期：
I31: 包装预计交货日期： | N31: =+'1'!N33 -> 0 | P31: 包装实际交货日期：
A32: 1、开料 | C32: 2、实木备料 | E32: 3、柜体开料 | G32: 4、封边 | I32: 5、打孔 | N32: 6、门扇 | P32: 7、附件
A33: 责任人 | B33: 完成时间 | C33: 责任人 | D33: 完成时间 | E33: 责任人 | F33: 完成时间 | G33: 责任人 | H33: 完成时间 | I33: 责任人 | J33: 完成时间 | N33: 责任人 | O33: 完成时间 | P33: 责任人 | Q33: 完成时间
A35: 8、贴皮 | C35: 9、雕刻 | E35: 10、木工配套 | G35: 11、木磨 | I35: 12、灰工 | N35: 13、底漆 | P35: 14、油磨
A36: 责任人 | B36: 完成时间 | C36: 责任人 | D36: 完成时间 | E36: 责任人 | F36: 完成时间 | G36: 责任人 | H36: 完成时间 | I36: 责任人 | J36: 完成时间 | N36: 责任人 | O36: 完成时间 | P36: 责任人 | Q36: 完成时间
A38: 15、油磨检验 | C38: 16、擦色 | E38: 17、面漆 | G38: 18、全检 | I38: 19、包装
A39: 责任人 | B39: 完成时间 | C39: 责任人 | D39: 完成时间 | E39: 责任人 | F39: 完成时间 | G39: 责任人 | H39: 完成时间 | I39: 责任人 | J39: 完成时间
A41: 预计交货日期： | C41: =N31 -> 0 | E41: 下单日期: | N41: 生产单号 | P41: =Q2 -> 0 | R41: =R2 -> -23
A42: 制表人： | C42: =C29 -> 陈昌容 | D42: 项目设计师： | F42: =F29 -> 0 | H42: 绘图员： | J42: =J29 -> 0 | L42: 拆单： | N42: =N29 -> 0

Sheet 24
A1: =+'1'!A1 -> 奢匠 | C1: 整装产品报价生产清单 | P1: 销售经理 | Q1: =+'1'!Q1 -> 0
C2: 经销商地址 | D2: =+'1'!D2 -> 0 | E2: 经销商名 | F2: =+'1'!F2 -> 0 | L2: 接单日期 | M2: ='1'!M2 -> 0 | P2: 订单编号 | Q2: =+'1'!Q2 -> 0 | R2: -24
C3: 终端客户及地址 | E3: ='1'!E3 -> 0
A4: =+A1 -> 奢匠 | C4: 整装作业单 | P4: 销售经理 | Q4: =+Q1 -> 0
C5: 省份 | D5: =+D2 -> 0 | E5: 姓名 | F5: =+F2 -> 0 | J5: 生产单号 | N5: =+'1'!N5 -> 0 | O5: =+R2 -> -24 | P5: 订单编号 | Q5: =+Q2 -> 0 | R5: =+R2 -> -24
C6: 终端客户及地址 | E6: =E3 -> 0
A7: 序号 | B7: 区域 | C7: 产品名称 | D7: 款式 | E7: 高 | F7: 宽 | G7: 厚 | H7: 数量 | I7: 米数 | J7: 平方 | K7: 单价（元） | L7: 小计（元） | M7: 工分 | N7: 颜色 | P7: 材质 | Q7: 备注
A8: 1 | J8: =E8/1000*F8/1000*H8 -> 0 | L8: =J8*K8 -> 0 | M8: =L8/100 -> 0 | N8: ='1'!N8 -> （请车间多配一瓶油漆，随货一起）
A9: 2 | M9: =L9/100 -> 0
A10: 3 | M10: =L10/100 -> 0
A11: 4 | M11: =L11/100 -> 0
A12: 5 | M12: =L12/100 -> 0
A13: 6 | M13: =L13/100 -> 0
A14: 7 | M14: =L14/100 -> 0
A15: 8 | M15: =L15/100 -> 0
A16: 9 | M16: =L16/100 -> 0
A17: 10 | M17: =L17/100 -> 0
A18: 11 | M18: =L18/100 -> 0
A19: 12 | M19: =L19/100 -> 0
A20: 13 | M20: =L20/100 -> 0
... A22: 15 | M22: =L22/100 -> 0
A23: 16 | C23: 木箱包装 | D23: 此单共打个木箱包装
A24: 合计 | H24: =SUM(H6:H22) -> 0 | I24: =SUM(I6:I22) -> 0 | J24: =SUM(J6:J22) -> 0 | M24: =SUM(M6:M22) -> 0
A25: ='1'!A27 -> 图文说明: | L25: =+SUM(L8:L23) -> 0 | N25: 元
L28: 经销商确认:
A29: 制表人： | C29: ='1'!C31 -> 陈昌容 | D29: 项目设计师： | F29: ='1'!F31 -> 0 | H29: 绘图员： | J29: ='1'!J31 -> 0 | L29: 拆单： | N29: ='1'!N31 -> 0
A30: =+A25 -> 图文说明: | I30: 木工预计交货日期： | P30: 木工实际交货日期：
I31: 包装预计交货日期： | N31: =+'1'!N33 -> 0 | P31: 包装实际交货日期：
A32: 1、开料 | C32: 2、实木备料 | E32: 3、柜体开料 | G32: 4、封边 | I32: 5、打孔 | N32: 6、门扇 | P32: 7、附件
A33: 责任人 | B33: 完成时间 | C33: 责任人 | D33: 完成时间 | E33: 责任人 | F33: 完成时间 | G33: 责任人 | H33: 完成时间 | I33: 责任人 | J33: 完成时间 | N33: 责任人 | O33: 完成时间 | P33: 责任人 | Q33: 完成时间
A35: 8、贴皮 | C35: 9、雕刻 | E35: 10、木工配套 | G35: 11、木磨 | I35: 12、灰工 | N35: 13、底漆 | P35: 14、油磨
A36: 责任人 | B36: 完成时间 | C36: 责任人 | D36: 完成时间 | E36: 责任人 | F36: 完成时间 | G36: 责任人 | H36: 完成时间 | I36: 责任人 | J36: 完成时间 | N36: 责任人 | O36: 完成时间 | P36: 责任人 | Q36: 完成时间
A38: 15、油磨检验 | C38: 16、擦色 | E38: 17、面漆 | G38: 18、全检 | I38: 19、包装
