Workbook

Sheet 3月部门分发
A1: 打卡地点 | B1: 姓名 | C1: 工号 | D1: 一级部门 | E1: 二级部门 | F1: 46082 | H1: 小时数 | I1: 天数 | J1: 46083 | L1: 小时数 | M1: 天数 | N1: 46084 | P1: 小时数 | Q1: 天数 | R1: 46085 | T1: 小时数 | U1: 天数 | V1: 46086 | X1: 小时数 | Y1: 天数 | Z1: 46087 | AB1: 小时数 | AC1: 天数 | AD1: 46088 | AF1: 小时数 | AG1: 天数 | AH1: 46089 | AJ1: 小时数 | AK1: 天数 | AL1: 46090 | AN1: 小时数 | AO1: 天数 | AP1: 46091 | AR1: 小时数 | AS1: 天数 | AT1: 46092 | AV1: 小时数 | AW1: 天数 | AX1: 46093 | AZ1: 小时数 | BA1: 天数 | BB1: 46094 | BD1: 小时数 | BE1: 天数 | BF1: 46095 | BH1: 小时数 | BI1: 天数 | BJ1: 46096 | BL1: 小时数 | BM1: 天数 | BN1: 46097 | BP1: 小时数 | BQ1: 天数 | BR1: 46098 | BT1: 小时数 | BU1: 天数 | BV1: 46099 | BX1: 小时数 | BY1: 天数 | BZ1: 46100 | CB1: 小时数 | CC1: 天数 | CD1: 46101 | CF1: 小时数 | CG1: 天数 | CH1: 46102 | CJ1: 小时数 | CK1: 天数 | CL1: 46103 | CN1: 小时数 | CO1: 天数 | CP1: 46104 | CR1: 小时数 | CS1: 天数 | CT1: 46105 | CV1: 小时数 | CW1: 天数 | CX1: 46106 | CZ1: 小时数 | DA1: 天数 | DB1: 46107 | DD1: 小时数 | DE1: 天数 | DF1: 46108 | DH1: 小时数 | DI1: 天数 | DJ1: 46109 | DL1: 小时数 | DM1: 天数 | DN1: 46110 | DP1: 小时数 | DQ1: 天数 | DR1: 46111 | DT1: 小时数 | DU1: 天数 | DV1: 46112 | DX1: 小时数 | DY1: 天数 | DZ1: 总小时数 | EA1: 总天数
A2: 五楼 | B2: 张雪莲 | C2: 1 | F2: 0.34930556 | G2: 0.75555556 | H2: =MOD(G2-F2,1)*24 | I2: 1 | J2: 0.34305556 | K2: 0.73819444 | L2: =MOD(K2-J2,1)*24 | M2: 1 | N2: 0.35138889 | O2: 0.7375 | P2: =MOD(O2-N2,1)*24 | Q2: 1 | V2: 0.34722222 | W2: 0.7375 | X2: =MOD(W2-V2,1)*24 | Y2: 1 | Z2: 0.34513889 | AA2: 0.7375 | AB2: =MOD(AA2-Z2,1)*24 | AC2: 1 | AD2: 0.35 | AE2: 0.73958333 | AF2: =MOD(AE2-AD2,1)*24 | AG2: 1 | AL2: 0.35 | AM2: 0.7375 | AN2: =MOD(AM2-AL2,1)*24 | AO2: 1 | AP2: 0.34930556 | AQ2: 0.73819444 | AR2: =MOD(AQ2-AP2,1)*24 | AS2: 1 | AT2: 0.34722222 | AU2: 0.7375 | AV2: =MOD(AU2-AT2,1)*24 | AW2: 1 | AX2: 0.35 | AY2: 0.73888889 | AZ2: =MOD(AY2-AX2,1)*24 | BA2: 1 | BB2: 0.35 | BC2: 0.7375 | BD2: =MOD(BC2-BB2,1)*24 | BE2: 1 | BF2: 0.34444444 | BG2: 0.73819444 | BH2: =MOD(BG2-BF2,1)*24 | BI2: 1 | BN2: 0.35069444 | BO2: 0.73680556 | BP2: =MOD(BO2-BN2,1)*24 | BQ2: 1 | BR2: 0.35138889 | BS2: 0.7375 | BT2: =MOD(BS2-BR2,1)*24 | BU2: 1 | BV2: 0.34722222 | BW2: 0.7375 | BX2: =MOD(BW2-BV2,1)*24 | BY2: 1 | BZ2: 0.35208333 | CA2: 0.73819444 | CB2: =MOD(CA2-BZ2,1)*24 | CC2: 1 | CD2: 0.34930556 | CE2: 0.73680556 | CF2: =MOD(CE2-CD2,1)*24 | CG2: 1 | CH2: 0.35069444 | CI2: 0.7375 | CJ2: =MOD(CI2-CH2,1)*24 | CK2: 1 | CP2: 0.35138889 | CQ2: 0.73888889 | CR2: =MOD(CQ2-CP2,1)*24 | CS2: 1 | CT2: 0.35 | CU2: 0.74166667 | CV2: =MOD(CU2-CT2,1)*24 | CW2: 1 | CX2: 0.35 | CY2: 0.73888889 | CZ2: =MOD(CY2-CX2,1)*24 | DA2: 1 | DB2: 0.35069444 | DC2: 0.74236111 | DD2: =MOD(DC2-DB2,1)*24 | DE2: 1 | DF2: 0.35208333 | DG2: 0.74444444 | DH2: =MOD(DG2-DF2,1)*24 | DI2: 1 | DJ2: 0.34930556 | DK2: 0.74166667 | DL2: =MOD(DK2-DJ2,1)*24 | DM2: 1 | DR2: 0.35138889 | DS2: 0.73888889 | DT2: =MOD(DS2-DR2,1)*24 | DU2: 1 | DV2: 0.35208333 | DW2: 0.7375 | DX2: =MOD(DW2-DV2,1)*24 | DY2: 1
A3: 五楼 | B3: 高淑文 | C3: 2 | F3: 0.35069444 | G3: 0.75625 | H3: =MOD(G3-F3,1)*24 | I3: 1 | J3: 0.35069444 | K3: 0.73680556 | L3: =MOD(K3-J3,1)*24 | M3: 1 | R3: 0.35277778 | S3: 0.73611111 | T3: =MOD(S3-R3,1)*24 | U3: 1 | V3: 0.34791667 | W3: 0.73888889 | X3: =MOD(W3-V3,1)*24 | Y3: 1 | Z3: 0.34791667 | AA3: 0.73680556 | AB3: =MOD(AA3-Z3,1)*24 | AC3: 1 | AD3: 0.35486111 | AE3: 0.73819444 | AF3: =MOD(AE3-AD3,1)*24 | AG3: 1 | AL3: 0.35277778 | AM3: 0.73611111 | AN3: =MOD(AM3-AL3,1)*24 | AO3: 1 | AP3: 0.34722222 | AQ3: 0.73611111 | AR3: =MOD(AQ3-AP3,1)*24 | AS3: 1 | AT3: 0.34791667 | AU3: 0.73680556 | AV3: =MOD(AU3-AT3,1)*24 | AW3: 1 | AX3: 0.34513889 | AY3: 0.73611111 | AZ3: =MOD(AY3-AX3,1)*24 | BA3: 1 | BB3: 0.34791667 | BC3: 0.73611111 | BD3: =MOD(BC3-BB3,1)*24 | BE3: 1 | BF3: 0.35208333 | BG3: 0.73611111 | BH3: =MOD(BG3-BF3,1)*24 | BI3: 1 | BN3: 0.34930556 | BO3: 0.73611111 | BP3: =MOD(BO3-BN3,1)*24 | BQ3: 1 | BR3: 0.34652778 | BS3: 0.73680556 | BT3: =MOD(BS3-BR3,1)*24 | BU3: 1 | BV3: 0.34930556 | BW3: 0.73611111 | BX3: =MOD(BW3-BV3,1)*24 | BY3: 1 | BZ3: 0.34722222 | CA3: 0.73611111 | CB3: =MOD(CA3-BZ3,1)*24 | CC3: 1 | CD3: 0.34930556 | CE3: 0.73611111 | CF3: =MOD(CE3-CD3,1)*24 | CG3: 1 | CH3: 0.34305556 | CI3: 0.73680556 | CJ3: =MOD(CI3-CH3,1)*24 | CK3: 1 | CP3: 0.34722222 | CQ3: 0.73611111 | CR3: =MOD(CQ3-CP3,1)*24 | CS3: 1 | CT3: 0.34583333 | CU3: 0.73680556 | CV3: =MOD(CU3-CT3,1)*24 | CW3: 1 | CX3: 0.35416667 | CY3: 0.73611111 | CZ3: =MOD(CY3-CX3,1)*24 | DA3: 1 | DB3: 0.34722222 | DC3: 0.73611111 | DD3: =MOD(DC3-DB3,1)*24 | DE3: 1 | DF3: 0.34583333 | DG3: 0.73611111 | DH3: =MOD(DG3-DF3,1)*24 | DI3: 1 | DJ3: 0.35416667 | DK3: 0.73680556 | DL3: =MOD(DK3-DJ3,1)*24 | DM3: 1 | DR3: 0.35138889 | DS3: 0.73680556 | DT3: =MOD(DS3-DR3,1)*24 | DU3: 1 | DV3: 0.34722222 | DW3: 0.73680556 | DX3: =MOD(DW3-DV3,1)*24 | DY3: 1
A4: 五楼 | B4: 高淑文 | C4: 2 | AD4: 0.73680556 | AF4: =MOD(AE4-AD4,1)*24 | AG4: 1
A5: 五楼 | B5: 伍小雪 | C5: 3 | F5: 0.35138889 | G5: 0.75763889 | H5: =MOD(G5-F5,1)*24 | I5: 1 | J5: 0.35138889 | K5: 0.74583333 | L5: =MOD(K5-J5,1)*24 | M5: 1 | N5: 0.35069444 | O5: 0.73611111 | P5: =MOD(O5-N5,1)*24 | Q5: 1 | R5: 0.35347222 | S5: 0.73958333 | T5: =MOD(S5-R5,1)*24 | U5: 1 | V5: 0.35277778 | W5: 0.74930556 | X5: =MOD(W5-V5,1)*24 | Y5: 1 | Z5: 0.35208333 | AA5: 0.73958333 | AB5: =MOD(AA5-Z5,1)*24 | AC5: 1 | AD5: 0.35277778 | AE5: 0.73819444 | AF5: =MOD(AE5-AD5,1)*24 | AG5: 1 | AL5: 0.35138889 | AM5: 0.75277778 | AN5: =MOD(AM5-AL5,1)*24 | AO5: 1 | AP5: 0.35069444 | AQ5: 0.74027778 | AR5: =MOD(AQ5-AP5,1)*24 | AS5: 1 | AT5: 0.35208333 | AU5: 0.73819444 | AV5: =MOD(AU5-AT5,1)*24 | AW5: 1 | AX5: 0.34930556 | AY5: 0.73958333 | AZ5: =MOD(AY5-AX5,1)*24 | BA5: 1 | BB5: 0.35 | BC5: 0.75 | BD5: =MOD(BC5-BB5,1)*24 | BE5: 1 | BF5: 0.35277778 | BG5: 0.74097222 | BH5: =MOD(BG5-BF5,1)*24 | BI5: 1 | BN5: 0.35347222 | BO5: 0.74930556 | BP5: =MOD(BO5-BN5,1)*24 | BQ5: 1 | BR5: 0.35138889 | BS5: 0.75208333 | BT5: =MOD(BS5-BR5,1)*24 | BU5: 1 | BV5: 0.34930556 | BW5: 0.74236111 | BX5: =MOD(BW5-BV5,1)*24 | BY5: 1 | BZ5: 0.35347222 | CA5: 0.73819444 | CB5: =MOD(CA5-BZ5,1)*24 | CC5: 1 | CD5: 0.35208333 | CE5: 0.73819444 | CF5: =MOD(CE5-CD5,1)*24 | CG5: 1 | CH5: 0.34861111 | CI5: 0.73819444 | CJ5: =MOD(CI5-CH5,1)*24 | CK5: 1 | CP5: 0.35277778 | CQ5: 0.73958333 | CR5: =MOD(CQ5-CP5,1)*24 | CS5: 1 | CT5: 0.35208333 | CU5: 0.87847222 | CV5: =MOD(CU5-CT5,1)*24 | CW5: 1 | CX5: 0.35277778 | CY5: 0.74097222 | CZ5: =MOD(CY5-CX5,1)*24 | DA5: 1 | DB5: 0.35138889 | DC5: 0.73819444 | DD5: =MOD(DC5-DB5,1)*24 | DE5: 1 | DF5: 0.35069444 | DG5: 0.73819444 | DH5: =MOD(DG5-DF5,1)*24 | DI5: 1 | DJ5: 0.35277778 | DK5: 0.74027778 | DL5: =MOD(DK5-DJ5,1)*24 | DM5: 1 | DR5: 0.35277778 | DS5: 0.75416667 | DT5: =MOD(DS5-DR5,1)*24 | DU5: 1 | DV5: 0.35208333 | DW5: 0.74166667 | DX5: =MOD(DW5-DV5,1)*24 | DY5: 1
A6: 五楼 | B6: 邱霞 | C6: 4 | F6: 0.34861111 | G6: 0.75555556 | H6: =MOD(G6-F6,1)*24 | I6: 1 | J6: 0.35138889 | K6: 0.73819444 | L6: =MOD(K6-J6,1)*24 | M6: 1 | N6: 0.35069444 | O6: 0.74097222 | P6: =MOD(O6-N6,1)*24 | Q6: 1 | V6: 0.35208333 | W6: 0.73819444 | X6: =MOD(W6-V6,1)*24 | Y6: 1 | AD6: 0.35277778 | AE6: 0.73819444 | AF6: =MOD(AE6-AD6,1)*24 | AG6: 1 | AL6: 0.35208333 | AM6: 0.74583333 | AN6: =MOD(AM6-AL6,1)*24 | AO6: 1 | AT6: 0.35347222 | AU6: 0.73819444 | AV6: =MOD(AU6-AT6,1)*24 | AW6: 1 | AX6: 0.35277778 | AY6: 0.73888889 | AZ6: =MOD(AY6-AX6,1)*24 | BA6: 1 | BF6: 0.35277778 | BG6: 0.74097222 | BH6: =MOD(BG6-BF6,1)*24 | BI6: 1 | BN6: 0.35277778 | BO6: 0.74861111 | BP6: =MOD(BO6-BN6,1)*24 | BQ6: 1 | BR6: 0.35069444 | BS6: 0.74513889 | BT6: =MOD(BS6-BR6,1)*24 | BU6: 1 | BV6: 0.34930556 | BW6: 0.73958333 | BX6: =MOD(BW6-BV6,1)*24 | BY6: 1 | BZ6: 0.35347222 | CA6: 0.73819444 | CB6: =MOD(CA6-BZ6,1)*24 | CC6: 1 | CD6: 0.35277778 | CE6: 0.74027778 | CF6: =MOD(CE6-CD6,1)*24 | CG6: 1 | CH6: 0.34722222 | CI6: 0.73819444 | CJ6: =MOD(CI6-CH6,1)*24 | CK6: 1 | CP6: 0.35416667 | CQ6: 0.74027778 | CR6: =MOD(CQ6-CP6,1)*24 | CS6: 1 | CT6: 0.35347222 | CU6: 0.7375 | CV6: =MOD(CU6-CT6,1)*24 | CW6: 1 | CX6: 0.35277778 | CY6: 0.74097222 | CZ6: =MOD(CY6-CX6,1)*24 | DA6: 1 | DB6: 0.35138889 | DC6: 0.73958333 | DD6: =MOD(DC6-DB6,1)*24 | DE6: 1 | DF6: 0.35 | DG6: 0.73819444 | DH6: =MOD(DG6-DF6,1)*24 | DI6: 1 | DJ6: 0.35208333 | DK6: 0.74166667 | DL6: =MOD(DK6-DJ6,1)*24 | DM6: 1 | DR6: 0.35138889 | DS6: 0.75555556 | DT6: =MOD(DS6-DR6,1)*24 | DU6: 1 | DV6: 0.35208333 | DW6: 0.74097222 | DX6: =MOD(DW6-DV6,1)*24 | DY6: 1
A7: 五楼 | B7: 苏春梅 | C7: 5 | F7: 0.35347222 | G7: 0.75555556 | H7: =MOD(G7-F7,1)*24 | I7: 1 | R7: 0.35208333 | S7: 0.73819444 | T7: =MOD(S7-R7,1)*24 | U7: 1 | Z7: 0.35208333 | AA7: 0.73819444 | AB7: =MOD(AA7-Z7,1)*24 | AC7: 1 | AD7: 0.35347222 | AE7: 0.73680556 | AF7: =MOD(AE7-AD7,1)*24 | AG7: 1
A8: 五楼 | B8: 黄晓云 | C8: 6 | F8: 0.35347222 | G8: 0.77430556 | H8: =MOD(G8-F8,1)*24 | I8: 1 | J8: 0.35347222 | K8: 0.7375 | L8: =MOD(K8-J8,1)*24 | M8: 1 | N8: 0.35347222 | O8: 0.78194444 | P8: =MOD(O8-N8,1)*24 | Q8: 1 | R8: 0.35347222 | S8: 0.77638889 | T8: =MOD(S8-R8,1)*24 | U8: 1 | V8: 0.35486111 | X8: =MOD(W8-V8,1)*24 | Y8: 1 | Z8: 0.35277778 | AA8: 0.74305556 | AB8: =MOD(AA8-Z8,1)*24 | AC8: 1 | AD8: 0.35347222 | AE8: 0.73888889 | AF8: =MOD(AE8-AD8,1)*24 | AG8: 1 | AL8: 0.35347222 | AM8: 0.73680556 | AN8: =MOD(AM8-AL8,1)*24 | AO8: 1 | AP8: 0.35277778 | AQ8: 0.73680556 | AR8: =MOD(AQ8-AP8,1)*24 | AS8: 1 | AT8: 0.35347222 | AU8: 0.73680556 | AV8: =MOD(AU8-AT8,1)*24 | AW8: 1 | AX8: 0.35277778 | AY8: 0.73680556 | AZ8: =MOD(AY8-AX8,1)*24 | BA8: 1 | BB8: 0.35277778 | BC8: 0.7375 | BD8: =MOD(BC8-BB8,1)*24 | BE8: 1 | BF8: 0.35277778 | BG8: 0.73819444 | BH8: =MOD(BG8-BF8,1)*24 | BI8: 1 | BN8: 0.35416667 | BO8: 0.73611111 | BP8: =MOD(BO8-BN8,1)*24 | BQ8: 1 | BR8: 0.35208333 | BS8: 0.73680556 | BT8: =MOD(BS8-BR8,1)*24 | BU8: 1 | BV8: 0.7375 | BX8: =MOD(BW8-BV8,1)*24 | BY8: 1 | BZ8: 0.35277778 | CA8: 0.73680556 | CB8: =MOD(CA8-BZ8,1)*24 | CC8: 1 | CD8: 0.35416667 | CE8: 0.73611111 | CF8: =MOD(CE8-CD8,1)*24 | CG8: 1 | CT8: 0.35486111 | CU8: 0.74513889 | CV8: =MOD(CU8-CT8,1)*24 | CW8: 1 | CX8: 0.35347222 | CY8: 0.73680556 | CZ8: =MOD(CY8-CX8,1)*24 | DA8: 1 | DB8: 0.34930556 | DC8: 0.73611111 | DD8: =MOD(DC8-DB8,1)*24 | DE8: 1 | DF8: 0.35416667 | DG8: 0.75208333 | DH8: =MOD(DG8-DF8,1)*24 | DI8: 1 | DJ8: 0.35625 | DK8: 0.75486111 | DL8: =MOD(DK8-DJ8,1)*24 | DM8: 1 | DN8: 0.35277778 | DO8: 0.73819444 | DP8: =MOD(DO8-DN8,1)*24 | DQ8: 1 | DR8: 0.35347222 | DS8: 0.75555556 | DT8: =MOD(DS8-DR8,1)*24 | DU8: 1 | DV8: 0.35347222 | DW8: 0.73819444 | DX8: =MOD(DW8-DV8,1)*24 | DY8: 1
A9: 五楼 | B9: 陈小红 | C9: 7 | F9: 0.35277778 | G9: 0.75625 | H9: =MOD(G9-F9,1)*24 | I9: 1 | J9: 0.35416667 | K9: 0.74513889 | L9: =MOD(K9-J9,1)*24 | M9: 1 | N9: 0.35138889 | O9: 0.73819444 | P9: =MOD(O9-N9,1)*24 | Q9: 1 | R9: 0.35416667 | S9: 0.73611111 | T9: =MOD(S9-R9,1)*24 | U9: 1 | V9: 0.33472222 | W9: 0.73611111 | X9: =MOD(W9-V9,1)*24 | Y9: 1 | Z9: 0.75069444 | AB9: =MOD(AA9-Z9,1)*24 | AC9: 1 | AD9: 0.35138889 | AE9: 0.76875 | AF9: =MOD(AE9-AD9,1)*24 | AG9: 1 | AL9: 0.34444444 | AM9: 0.75138889 | AN9: =MOD(AM9-AL9,1)*24 | AO9: 1 | AP9: 0.35277778 | AQ9: 0.75069444 | AR9: =MOD(AQ9-AP9,1)*24 | AS9: 1 | AT9: 0.34791667 | AU9: 0.75347222 | AV9: =MOD(AU9-AT9,1)*24 | AW9: 1 | AX9: 0.35277778 | AZ9: =MOD(AY9-AX9,1)*24 | BA9: 1 | BB9: 0.34513889 | BC9: 0.83333333 | BD9: =MOD(BC9-BB9,1)*24 | BE9: 1 | BF9: 0.34722222 | BG9: 0.73888889 | BH9: =MOD(BG9-BF9,1)*24 | BI9: 1 | BN9: 0.35347222 | BO9: 0.74583333 | BP9: =MOD(BO9-BN9,1)*24 | BQ9: 1 | BR9: 0.35 | BS9: 0.74305556 | BT9: =MOD(BS9-BR9,1)*24 | BU9: 1 | BV9: 0.74861111 | BX9: =MOD(BW9-BV9,1)*24 | BY9: 1 | BZ9: 0.34652778 | CA9: 0.75625 | CB9: =MOD(CA9-BZ9,1)*24 | CC9: 1 | CD9: 0.35208333 | CE9: 0.74027778 | CF9: =MOD(CE9-CD9,1)*24 | CG9: 1 | CH9: 0.35416667 | CI9: 0.74166667 | CJ9: =MOD(CI9-CH9,1)*24 | CK9: 1 | CL9: 0.33611111 | CM9: 0.74097222 | CN9: =MOD(CM9-CL9,1)*24 | CO9: 1 | CP9: 0.35138889 | CQ9: 0.73611111 | CR9: =MOD(CQ9-CP9,1)*24 | CS9: 1 | CT9: 0.34583333 | CU9: 0.73888889 | CV9: =MOD(CU9-CT9,1)*24 | CW9: 1 | CX9: 0.35 | CY9: 0.75138889 | CZ9: =MOD(CY9-CX9,1)*24 | DA9: 1 | DB9: 0.35347222 | DC9: 0.74791667 | DD9: =MOD(DC9-DB9,1)*24 | DE9: 1 | DF9: 0.35138889 | DG9: 0.84444444 | DH9: =MOD(DG9-DF9,1)*24 | DI9: 1 | DJ9: 0.34652778 | DK9: 0.74097222 | DL9: =MOD(DK9-DJ9,1)*24 | DM9: 1 | DN9: 0.35486111 | DO9: 0.75 | DP9: =MOD(DO9-DN9,1)*24 | DQ9: 1 | DR9: 0.34930556 | DS9: 0.83888889 | DT9: =MOD(DS9-DR9,1)*24 | DU9: 1 | DV9: 0.34652778 | DW9: 0.77430556 | DX9: =MOD(DW9-DV9,1)*24 | DY9: 1
A10: 五楼 | B10: 罗丽 | C10: 8
A11: 五楼 | B11: 胡娅 | C11: 9 | F11: 0.35 | G11: 0.75555556 | H11: =MOD(G11-F11,1)*24 | I11: 1 | N11: 0.34791667 | O11: 0.73611111 | P11: =MOD(O11-N11,1)*24 | Q11: 1 | R11: 0.34444444 | S11: 0.73611111 | T11: =MOD(S11-R11,1)*24 | U11: 1 | Z11: 0.34652778 | AA11: 0.73819444 | AB11: =MOD(AA11-Z11,1)*24 | AC11: 1 | AH11: 0.34652778 | AI11: 0.73611111 | AJ11: =MOD(AI11-AH11,1)*24 | AK11: 1 | AP11: 0.34930556 | AQ11: 0.73680556 | AR11: =MOD(AQ11-AP11,1)*24 | AS11: 1 | AX11: 0.34861111 | AY11: 0.73680556 | AZ11: =MOD(AY11-AX11,1)*24 | BA11: 1 | BB11: 0.34722222 | BC11: 0.74930556 | BD11: =MOD(BC11-BB11,1)*24 | BE11: 1 | BF11: 0.33055556 | BG11: 0.5125 | BH11: =MOD(BG11-BF11,1)*24 | BI11: 1 | BN11: 0.35069444 | BP11: =MOD(BO11-BN11,1)*24 | BQ11: 1 | BR11: 0.34930556 | BS11: 0.74722222 | BT11: =MOD(BS11-BR11,1)*24 | BU11: 1 | BV11: 0.33194444 | BW11: 0.73819444 | BX11: =MOD(BW11-BV11,1)*24 | BY11: 1 | BZ11: 0.32708333 | CA11: 0.73819444 | CB11: =MOD(CA11-BZ11,1)*24 | CC11: 1 | CD11: 0.33194444 | CE11: 0.7375 | CF11: =MOD(CE11-CD11,1)*24 | CG11: 1 | CH11: 0.34444444 | CI11: 0.425 | CJ11: =MOD(CI11-CH11,1)*24 | CK11: 1 | CP11: 0.33888889 | CQ11: 0.7375 | CR11: =MOD(CQ11-CP11,1)*24 | CS11: 1 | CT11: 0.34027778 | CU11: 0.7375 | CV11: =MOD(CU11-CT11,1)*24 | CW11: 1 | CX11: 0.34722222 | CY11: 0.50277778 | CZ11: =MOD(CY11-CX11,1)*24 | DA11: 1 | DB11: 0.3375 | DC11: 0.73680556 | DD11: =MOD(DC11-DB11,1)*24 | DE11: 1 | DF11: 0.34097222 | DG11: 0.73819444 | DH11: =MOD(DG11-DF11,1)*24 | DI11: 1 | DN11: 0.34652778 | DO11: 0.73611111 | DP11: =MOD(DO11-DN11,1)*24 | DQ11: 1 | DR11: 0.34097222 | DS11: 0.74305556 | DT11: =MOD(DS11-DR11,1)*24 | DU11: 1 | DV11: 0.34027778 | DW11: 0.73958333 | DX11: =MOD(DW11-DV11,1)*24 | DY11: 1
A12: 五楼 | B12: 杨青青 | C12: 10 | F12: 0.35069444 | G12: 0.75694444 | H12: =MOD(G12-F12,1)*24 | I12: 1 | J12: 0.35416667 | K12: 0.74097222 | L12: =MOD(K12-J12,1)*24 | M12: 1 | V12: 0.35347222 | W12: 0.74861111 | X12: =MOD(W12-V12,1)*24 | Y12: 1 | Z12: 0.5375 | AA12: 0.73958333 | AB12: =MOD(AA12-Z12,1)*24 | AC12: 1 | AD12: 0.34236111 | AE12: 0.73958333 | AF12: =MOD(AE12-AD12,1)*24 | AG12: 1 | AL12: 0.35347222 | AM12: 0.75277778 | AN12: =MOD(AM12-AL12,1)*24 | AO12: 1 | AP12: 0.35347222 | AQ12: 0.7375 | AR12: =MOD(AQ12-AP12,1)*24 | AS12: 1 | AT12: 0.35347222 | AU12: 0.73819444 | AV12: =MOD(AU12-AT12,1)*24 | AW12: 1 | BB12: 0.35416667 | BC12: 0.50902778 | BD12: =MOD(BC12-BB12,1)*24 | BE12: 1 | BF12: 0.5125 | BG12: 0.73888889 | BH12: =MOD(BG12-BF12,1)*24 | BI12: 1 | BJ12: 0.33958333 | BK12: 0.7375 | BL12: =MOD(BK12-BJ12,1)*24 | BM12: 1 | BN12: 0.54861111 | BO12: 0.75347222 | BP12: =MOD(BO12-BN12,1)*24 | BQ12: 1 | BR12: 0.54166667 | BS12: 0.7625 | BT12: =MOD(BS12-BR12,1)*24 | BU12: 1 | BZ12: 0.53333333 | CA12: 0.7375 | CB12: =MOD(CA12-BZ12,1)*24 | CC12: 1 | CD12: 0.33194444 | CE12: 0.73819444 | CF12: =MOD(CE12-CD12,1)*24 | CG12: 1 | CH12: 0.35347222 | CI12: 0.74097222 | CJ12: =MOD(CI12-CH12,1)*24 | CK12: 1 | CL12: 0.34722222 | CM12: 0.73819444 | CN12: =MOD(CM12-CL12,1)*24 | CO12: 1 | CP12: 0.33888889 | CQ12: 0.7375 | CR12: =MOD(CQ12-CP12,1)*24 | CS12: 1 | CT12: 0.34027778 | CU12: 0.73680556 | CV12: =MOD(CU12-CT12,1)*24 | CW12: 1 | CX12: 0.35208333 | CY12: 0.74097222 | CZ12: =MOD(CY12-CX12,1)*24 | DA12: 1 | DB12: 0.3375 | DC12: 0.7375 | DD12: =MOD(DC12-DB12,1)*24 | DE12: 1 | DF12: 0.34097222 | DG12: 0.74305556 | DH12: =MOD(DG12-DF12,1)*24 | DI12: 1 | DJ12: 0.33194444 | DK12: 0.73819444 | DL12: =MOD(DK12-DJ12,1)*24 | DM12: 1 | DR12: 0.34097222 | DS12: 0.74375 | DT12: =MOD(DS12-DR12,1)*24 | DU12: 1 | DV12: 0.34027778 | DW12: 0.74027778 | DX12: =MOD(DW12-DV12,1)*24 | DY12: 1
A13: 五楼 | B13: 杨青青 | C13: 10 | CH13: 0.73888889 | CJ13: =MOD(CI13-CH13,1)*24 | CK13: 1
A14: 五楼 | B14: 代白高 | C14: 11 | J14: 0.34375 | K14: 0.75208333 | L14: =MOD(K14-J14,1)*24 | M14: 1 | N14: 0.34375 | O14: 0.74513889 | P14: =MOD(O14-N14,1)*24 | Q14: 1 | R14: 0.33958333 | T14: =MOD(S14-R14,1)*24 | U14: 1
A15: 五楼 | B15: 向锋 | C15: 12 | F15: 0.35138889 | G15: 0.8125 | H15: =MOD(G15-F15,1)*24 | I15: 1 | J15: 0.34791667 | K15: 0.74930556 | L15: =MOD(K15-J15,1)*24 | M15: 1 | N15: 0.34861111 | O15: 0.74097222 | P15: =MOD(O15-N15,1)*24 | Q15: 1 | R15: 0.34791667 | S15: 0.74375 | T15: =MOD(S15-R15,1)*24 | U15: 1 | V15: 0.35069444 | W15: 0.74861111 | X15: =MOD(W15-V15,1)*24 | Y15: 1 | Z15: 0.34930556 | AA15: 0.73680556 | AB15: =MOD(AA15-Z15,1)*24 | AC15: 1 | AT15: 0.34861111 | AU15: 0.75208333 | AV15: =MOD(AU15-AT15,1)*24 | AW15: 1 | AX15: 0.34930556 | AY15: 0.80694444 | AZ15: =MOD(AY15-AX15,1)*24 | BA15: 1 | BB15: 0.35069444 | BC15: 0.8375 | BD15: =MOD(BC15-BB15,1)*24 | BE15: 1 | BF15: 0.35138889 | BG15: 0.75347222 | BH15: =MOD(BG15-BF15,1)*24 | BI15: 1 | BJ15: 0.25069444 | BK15: 0.96319444 | BL15: =MOD(BK15-BJ15,1)*24 | BM15: 1 | BN15: 0.35138889 | BO15: 0.82291667 | BP15: =MOD(BO15-BN15,1)*24 | BQ15: 1 | BR15: 0.35277778 | BS15: 0.82430556 | BT15: =MOD(BS15-BR15,1)*24 | BU15: 1 | BV15: 0.35277778 | BW15: 0.74444444 | BX15: =MOD(BW15-BV15,1)*24 | BY15: 1 | BZ15: 0.35208333 | CA15: 0.90694444 | CB15: =MOD(CA15-BZ15,1)*24 | CC15: 1 | CD15: 0.34930556 | CE15: 0.91458333 | CF15: =MOD(CE15-CD15,1)*24 | CG15: 1 | CH15: 0.35069444 | CJ15: =MOD(CI15-CH15,1)*24 | CK15: 1 | DF15: 0.35208333 | DG15: 0.81666667 | DH15: =MOD(DG15-DF15,1)*24 | DI15: 1 | DJ15: 0.35277778 | DL15: =MOD(DK15-DJ15,1)*24 | DM15: 1 | DN15: 0.975 | DP15: =MOD(DO15-DN15,1)*24 | DQ15: 1 | DR15: 0.35138889 | DS15: 0.90833333 | DT15: =MOD(DS15-DR15,1)*24 | DU15: 1 | DV15: 0.35208333 | DW15: 0.82986111 | DX15: =MOD(DW15-DV15,1)*24 | DY15: 1
A16: 五楼 | B16: 向锋 | C16: 12 | CD16: 0.85555556 | CF16: =MOD(CE16-CD16,1)*24 | CG16: 1
A17: 五楼 | B17: 雷松儒 | C17: 13 | F17: 0.34930556 | G17: 0.75972222 | H17: =MOD(G17-F17,1)*24 | I17: 1 | J17: 0.35277778 | K17: 0.89861111 | L17: =MOD(K17-J17,1)*24 | M17: 1 | N17: 0.35069444 | O17: 0.74444444 | P17: =MOD(O17-N17,1)*24 | Q17: 1 | R17: 0.35138889 | S17: 0.74652778 | T17: =MOD(S17-R17,1)*24 | U17: 1 | V17: 0.35277778 | W17: 0.74861111 | X17: =MOD(W17-V17,1)*24 | Y17: 1 | Z17: 0.35069444 | AA17: 0.74166667 | AB17: =MOD(AA17-Z17,1)*24 | AC17: 1 | AL17: 0.76666667 | AN17: =MOD(AM17-AL17,1)*24 | AO17: 1 | AP17: 0.35138889 | AQ17: 0.79236111 | AR17: =MOD(AQ17-AP17,1)*24 | AS17: 1 | AT17: 0.34861111 | AU17: 0.75208333 | AV17: =MOD(AU17-AT17,1)*24 | AW17: 1 | AX17: 0.35 | AY17: 0.73958333 | AZ17: =MOD(AY17-AX17,1)*24 | BA17: 1 | BB17: 0.35 | BC17: 0.76180556 | BD17: =MOD(BC17-BB17,1)*24 | BE17: 1 | BF17: 0.35069444 | BG17: 0.73680556 | BH17: =MOD(BG17-BF17,1)*24 | BI17: 1 | BJ17: 0.96319444 | BL17: =MOD(BK17-BJ17,1)*24 | BM17: 1 | BN17: 0.34930556 | BO17: 0.82430556 | BP17: =MOD(BO17-BN17,1)*24 | BQ17: 1 | BR17: 0.35 | BS17: 0.75486111 | BT17: =MOD(BS17-BR17,1)*24 | BU17: 1 | BV17: 0.35486111 | BW17: 0.80763889 | BX17: =MOD(BW17-BV17,1)*24 | BY17: 1 | BZ17: 0.35277778 | CA17: 0.74513889 | CB17: =MOD(CA17-BZ17,1)*24 | CC17: 1 | CD17: 0.35069444 | CE17: 0.82777778 | CF17: =MOD(CE17-CD17,1)*24 | CG17: 1 | CH17: 0.35069444 | CI17: 0.82708333 | CJ17: =MOD(CI17-CH17,1)*24 | CK17: 1 | CL17: 0.34930556 | CM17: 0.75833333 | CN17: =MOD(CM17-CL17,1)*24 | CO17: 1 | CP17: 0.37013889 | CR17: =MOD(CQ17-CP17,1)*24 | CS17: 1 | DF17: 0.35138889 | DG17: 0.75069444 | DH17: =MOD(DG17-DF17,1)*24 | DI17: 1 | DJ17: 0.34097222 | DL17: =MOD(DK17-DJ17,1)*24 | DM17: 1 | DN17: 0.975 | DP17: =MOD(DO17-DN17,1)*24 | DQ17: 1 | DR17: 0.35138889 | DS17: 0.74722222 | DT17: =MOD(DS17-DR17,1)*24 | DU17: 1 | DV17: 0.35208333 | DW17: 0.79930556 | DX17: =MOD(DW17-DV17,1)*24 | DY17: 1
A18: 五楼 | B18: 杨首琴 | C18: 14 | F18: 0.35138889 | G18: 0.75694444 | H18: =MOD(G18-F18,1)*24 | I18: 1 | N18: 0.34930556 | O18: 0.73680556 | P18: =MOD(O18-N18,1)*24 | Q18: 1 | V18: 0.34791667 | W18: 0.74027778 | X18: =MOD(W18-V18,1)*24 | Y18: 1 | AD18: 0.35138889 | AE18: 0.73819444 | AF18: =MOD(AE18-AD18,1)*24 | AG18: 1 | AL18: 0.35 | AM18: 0.74027778 | AN18: =MOD(AM18-AL18,1)*24 | AO18: 1 | AP18: 0.35069444 | AQ18: 0.73958333 | AR18: =MOD(AQ18-AP18,1)*24 | AS18: 1 | AT18: 0.35069444 | AU18: 0.74236111 | AV18: =MOD(AU18-AT18,1)*24 | AW18: 1 | AX18: 0.34027778 | AY18: 0.74305556 | AZ18: =MOD(AY18-AX18,1)*24 | BA18: 1 | BB18: 0.35069444 | BC18: 0.74861111 | BD18: =MOD(BC18-BB18,1)*24 | BE18: 1 | BF18: 0.35069444 | BG18: 0.73819444 | BH18: =MOD(BG18-BF18,1)*24 | BI18: 1 | BR18: 0.34930556 | BS18: 0.74166667 | BT18: =MOD(BS18-BR18,1)*24 | BU18: 1 | BV18: 0.35138889 | BW18: 0.7375 | BX18: =MOD(BW18-BV18,1)*24 | BY18: 1 | BZ18: 0.35208333 | CA18: 0.73611111 | CB18: =MOD(CA18-BZ18,1)*24 | CC18: 1 | CD18: 0.35138889 | CE18: 0.73611111 | CF18: =MOD(CE18-CD18,1)*24 | CG18: 1 | CH18: 0.35138889 | CI18: 0.73888889 | CJ18: =MOD(CI18-CH18,1)*24 | CK18: 1 | CP18: 0.35277778 | CQ18: 0.73819444 | CR18: =MOD(CQ18-CP18,1)*24 | CS18: 1 | CT18: 0.35277778 | CU18: 0.74444444 | CV18: =MOD(CU18-CT18,1)*24 | CW18: 1 | CX18: 0.35069444 | CY18: 0.74027778 | CZ18: =MOD(CY18-CX18,1)*24 | DA18: 1 | DB18: 0.35138889 | DC18: 0.74097222 | DD18: =MOD(DC18-DB18,1)*24 | DE18: 1 | DF18: 0.35347222 | DG18: 0.74583333 | DH18: =MOD(DG18-DF18,1)*24 | DI18: 1 | DJ18: 0.35208333 | DK18: 0.74722222 | DL18: =MOD(DK18-DJ18,1)*24 | DM18: 1 | DR18: 0.35277778 | DS18: 0.75486111 | DT18: =MOD(DS18-DR18,1)*24 | DU18: 1 | DV18: 0.34861111 | DW18: 0.75763889 | DX18: =MOD(DW18-DV18,1)*24 | DY18: 1
A19: 五楼 | B19: 杨首琴 | C19: 14 | BF19: 0.73680556 | BH19: =MOD(BG19-BF19,1)*24 | BI19: 1 | CP19: 0.7375 | CR19: =MOD(CQ19-CP19,1)*24 | CS19: 1 | DF19: 0.74513889 | DH19: =MOD(DG19-DF19,1)*24 | DI19: 1
A20: 五楼 | B20: 王晓兰 | C20: 15 | F20: 0.35347222 | G20: 0.77013889 | H20: =MOD(G20-F20,1)*24 | I20: 1 | J20: 0.35347222 | K20: 0.73819444 | L20: =MOD(K20-J20,1)*24 | M20: 1 | N20: 0.35208333 | O20: 0.50833333 | P20: =MOD(O20-N20,1)*24 | Q20: 1 | R20: 0.35208333 | S20: 0.73888889 | T20: =MOD(S20-R20,1)*24 | U20: 1 | V20: 0.34861111 | W20: 0.74722222 | X20: =MOD(W20-V20,1)*24 | Y20: 1 | Z20: 0.34375 | AA20: 0.7375 | AB20: =MOD(AA20-Z20,1)*24 | AC20: 1 | AD20: 0.35208333 | AE20: 0.74027778 | AF20: =MOD(AE20-AD20,1)*24 | AG20: 1 | AH20: 0.35208333 | AI20: 0.74444444 | AJ20: =MOD(AI20-AH20,1)*24 | AK20: 1 | AL20: 0.35 | AM20: 0.7375 | AN20: =MOD(AM20-AL20,1)*24 | AO20: 1 | AP20: 0.34583333 | AQ20: 0.74097222 | AR20: =MOD(AQ20-AP20,1)*24 | AS20: 1 | AT20: 0.3375 | AU20: 0.74166667 | AV20: =MOD(AU20-AT20,1)*24 | AW20: 1 | BB20: 0.33680556 | BC20: 0.7375 | BD20: =MOD(BC20-BB20,1)*24 | BE20: 1 | BF20: 0.35416667 | BG20: 0.74027778 | BH20: =MOD(BG20-BF20,1)*24 | BI20: 1 | BJ20: 0.35347222 | BK20: 0.52361111 | BL20: =MOD(BK20-BJ20,1)*24 | BM20: 1 | BN20: 0.34097222 | BO20: 0.73819444 | BP20: =MOD(BO20-BN20,1)*24 | BQ20: 1 | BR20: 0.35138889 | BS20: 0.73819444 | BT20: =MOD(BS20-BR20,1)*24 | BU20: 1 | BV20: 0.34722222 | BW20: 0.73888889 | BX20: =MOD(BW20-BV20,1)*24 | BY20: 1 | BZ20: 0.34097222 | CA20: 0.73888889 | CB20: =MOD(CA20-BZ20,1)*24 | CC20: 1 | CD20: 0.34166667 | CE20: 0.73888889 | CF20: =MOD(CE20-CD20,1)*24 | CG20: 1 | CH20: 0.54444444 | CI20: 0.73680556 | CJ20: =MOD(CI20-CH20,1)*24 | CK20: 1 | CP20: 0.34305556 | CQ20: 0.73680556 | CR20: =MOD(CQ20-CP20,1)*24 | CS20: 1 | CT20: 0.34097222 | CU20: 0.73888889 | CV20: =MOD(CU20-CT20,1)*24 | CW20: 1 | CX20: 0.34375 | CY20: 0.74444444 | CZ20: =MOD(CY20-CX20,1)*24 | DA20: 1 | DB20: 0.34097222 | DC20: 0.74097222 | DD20: =MOD(DC20-DB20,1)*24 | DE20: 1 | DF20: 0.33958333 | DG20: 0.74027778 | DH20: =MOD(DG20-DF20,1)*24 | DI20: 1 | DJ20: 0.54027778 | DK20: 0.74166667 | DL20: =MOD(DK20-DJ20,1)*24 | DM20: 1 | DR20: 0.34236111 | DS20: 0.74097222 | DT20: =MOD(DS20-DR20,1)*24 | DU20: 1 | DV20: 0.34583333 | DW20: 0.7375 | DX20: =MOD(DW20-DV20,1)*24 | DY20: 1
A21: 五楼 | B21: 王晓兰 | C21: 15 | DB21: 0.73958333 | DD21: =MOD(DC21-DB21,1)*24 | DE21: 1
A22: 五楼 | B22: 杨益琴 | C22: 16 | F22: 0.34444444 | G22: 0.75694444 | H22: =MOD(G22-F22,1)*24 | I22: 1 | J22: 0.34583333 | K22: 0.7375 | L22: =MOD(K22-J22,1)*24 | M22: 1 | R22: 0.34652778 | S22: 0.73819444 | T22: =MOD(S22-R22,1)*24 | U22: 1 | Z22: 0.34722222 | AA22: 0.73819444 | AB22: =MOD(AA22-Z22,1)*24 | AC22: 1 | AH22: 0.34791667 | AI22: 0.7375 | AJ22: =MOD(AI22-AH22,1)*24 | AK22: 1 | AX22: 0.34652778 | AY22: 0.74722222 | AZ22: =MOD(AY22-AX22,1)*24 | BA22: 1 | BB22: 0.34722222 | BC22: 0.73680556 | BD22: =MOD(BC22-BB22,1)*24 | BE22: 1 | BF22: 0.34930556 | BG22: 0.7375 | BH22: =MOD(BG22-BF22,1)*24 | BI22: 1 | BN22: 0.34722222 | BO22: 0.73680556 | BP22: =MOD(BO22-BN22,1)*24 | BQ22: 1 | BR22: 0.35138889 | BS22: 0.73680556 | BT22: =MOD(BS22-BR22,1)*24 | BU22: 1 | BV22: 0.34305556 | BW22: 0.7375 | BX22: =MOD(BW22-BV22,1)*24 | BY22: 1 | BZ22: 0.34930556 | CA22: 0.7375 | CB22: =MOD(CA22-BZ22,1)*24 | CC22: 1 | CD22: 0.35 | CE22: 0.7375 | CF22: =MOD(CE22-CD22,1)*24 | CG22: 1 | CH22: 0.35069444 | CI22: 0.7375 | CJ22: =MOD(CI22-CH22,1)*24 | CK22: 1 | CP22: 0.34583333 | CQ22: 0.7375 | CR22: =MOD(CQ22-CP22,1)*24 | CS22: 1 | CT22: 0.34930556 | CU22: 0.7375 | CV22: =MOD(CU22-CT22,1)*24 | CW22: 1 | CX22: 0.34375 | CY22: 0.7375 | CZ22: =MOD(CY22-CX22,1)*24 | DA22: 1 | DB22: 0.34305556 | DC22: 0.7375 | DD22: =MOD(DC22-DB22,1)*24 | DE22: 1 | DF22: 0.34513889 | DG22: 0.78194444 | DH22: =MOD(DG22-DF22,1)*24 | DI22: 1 | DJ22: 0.35 | DK22: 0.73819444 | DL22: =MOD(DK22-DJ22,1)*24 | DM22: 1 | DR22: 0.35069444 | DS22: 0.74236111 | DT22: =MOD(DS22-DR22,1)*24 | DU22: 1 | DV22: 0.34444444 | DW22: 0.93402778 | DX22: =MOD(DW22-DV22,1)*24 | DY22: 1
A23: 五楼 | B23: 刘琴 | C23: 17 | F23: 0.34930556 | G23: 0.75555556 | H23: =MOD(G23-F23,1)*24 | I23: 1 | J23: 0.34791667 | K23: 0.7375 | L23: =MOD(K23-J23,1)*24 | M23: 1 | R23: 0.35138889 | S23: 0.7375 | T23: =MOD(S23-R23,1)*24 | U23: 1 | Z23: 0.35138889 | AB23: =MOD(AA23-Z23,1)*24 | AC23: 1 | AD23: 0.34791667 | AE23: 0.74027778 | AF23: =MOD(AE23-AD23,1)*24 | AG23: 1 | AL23: 0.35208333 | AM23: 0.7375 | AN23: =MOD(AM23-AL23,1)*24 | AO23: 1 | AP23: 0.34930556 | AQ23: 0.85694444 | AR23: =MOD(AQ23-AP23,1)*24 | AS23: 1 | AT23: 0.35138889 | AU23: 0.74027778 | AV23: =MOD(AU23-AT23,1)*24 | AW23: 1 | AX23: 0.35069444 | AY23: 0.74236111 | AZ23: =MOD(AY23-AX23,1)*24 | BA23: 1 | BB23: 0.35138889 | BC23: 0.75972222 | BD23: =MOD(BC23-BB23,1)*24 | BE23: 1 | BF23: 0.35208333 | BG23: 0.50208333 | BH23: =MOD(BG23-BF23,1)*24 | BI23: 1 | BN23: 0.35208333 | BO23: 0.7375 | BP23: =MOD(BO23-BN23,1)*24 | BQ23: 1 | BR23: 0.35277778 | BS23: 0.73888889 | BT23: =MOD(BS23-BR23,1)*24 | BU23: 1 | BV23: 0.35069444 | BW23: 0.75069444 | BX23: =MOD(BW23-BV23,1)*24 | BY23: 1 | BZ23: 0.35416667 | CA23: 0.74027778 | CB23: =MOD(CA23-BZ23,1)*24 | CC23: 1 | CD23: 0.35138889 | CE23: 0.73888889 | CF23: =MOD(CE23-CD23,1)*24 | CG23: 1 | CH23: 0.35208333 | CI23: 0.73611111 | CJ23: =MOD(CI23-CH23,1)*24 | CK23: 1 | CP23: 0.35416667 | CQ23: 0.73819444 | CR23: =MOD(CQ23-CP23,1)*24 | CS23: 1 | CT23: 0.35069444 | CU23: 0.77361111 | CV23: =MOD(CU23-CT23,1)*24 | CW23: 1 | CX23: 0.35138889 | CY23: 0.74375 | CZ23: =MOD(CY23-CX23,1)*24 | DA23: 1 | DB23: 0.34791667 | DC23: 0.74027778 | DD23: =MOD(DC23-DB23,1)*24 | DE23: 1 | DF23: 0.35138889 | DG23: 0.74027778 | DH23: =MOD(DG23-DF23,1)*24 | DI23: 1 | DJ23: 0.35347222 | DK23: 0.7375 | DL23: =MOD(DK23-DJ23,1)*24 | DM23: 1
A24: 五楼 | B24: 刘琴 | C24: 17 | BV24: 0.75 | BX24: =MOD(BW24-BV24,1)*24 | BY24: 1 | BZ24: 0.73958333 | CB24: =MOD(CA24-BZ24,1)*24 | CC24: 1 | DF24: 0.73958333 | DH24: =MOD(DG24-DF24,1)*24 | DI24: 1
A25: 五楼 | B25: 刘文旦 | C25: 18 | F25: 0.33194444 | G25: 0.75694444 | H25: =MOD(G25-F25,1)*24 | I25: 1 | N25: 0.35416667 | O25: 0.73819444 | P25: =MOD(O25-N25,1)*24 | Q25: 1 | R25: 0.35 | S25: 0.7375 | T25: =MOD(S25-R25,1)*24 | U25: 1 | AL25: 0.53680556 | AM25: 0.78125 | AN25: =MOD(AM25-AL25,1)*24 | AO25: 1 | AP25: 0.35069444 | AQ25: 0.80486111 | AR25: =MOD(AQ25-AP25,1)*24 | AS25: 1 | AT25: 0.35347222 | AU25: 0.75902778 | AV25: =MOD(AU25-AT25,1)*24 | AW25: 1 | AX25: 0.35208333 | AY25: 0.74652778 | AZ25: =MOD(AY25-AX25,1)*24 | BA25: 1 | BB25: 0.31875 | BC25: 0.77222222 | BD25: =MOD(BC25-BB25,1)*24 | BE25: 1 | BF25: 0.35555556 | BG25: 0.76041667 | BH25: =MOD(BG25-BF25,1)*24 | BI25: 1 | BJ25: 0.34722222 | BK25: 0.775 | BL25: =MOD(BK25-BJ25,1)*24 | BM25: 1 | BN25: 0.35138889 | BO25: 0.73819444 | BP25: =MOD(BO25-BN25,1)*24 | BQ25: 1 | BR25: 0.35625 | BS25: 0.77361111 | BT25: =MOD(BS25-BR25,1)*24 | BU25: 1 | BV25: 0.35763889 | BW25: 0.7875 | BX25: =MOD(BW25-BV25,1)*24 | BY25: 1 | BZ25: 0.35416667 | CA25: 0.73958333 | CB25: =MOD(CA25-BZ25,1)*24 | CC25: 1 | CD25: 0.35555556 | CE25: 0.75972222 | CF25: =MOD(CE25-CD25,1)*24 | CG25: 1 | CH25: 0.35416667 | CI25: 0.78819444 | CJ25: =MOD(CI25-CH25,1)*24 | CK25: 1 | CL25: 0.76319444 | CN25: =MOD(CM25-CL25,1)*24 | CO25: 1 | CP25: 0.35902778 | CQ25: 0.76041667 | CR25: =MOD(CQ25-CP25,1)*24 | CS25: 1 | CT25: 0.35486111 | CU25: 0.89236111 | CV25: =MOD(CU25-CT25,1)*24 | CW25: 1 | CX25: 0.35763889 | CY25: 0.74375 | CZ25: =MOD(CY25-CX25,1)*24 | DA25: 1 | DB25: 0.35555556 | DC25: 0.74375 | DD25: =MOD(DC25-DB25,1)*24 | DE25: 1 | DF25: 0.35763889 | DG25: 0.77569444 | DH25: =MOD(DG25-DF25,1)*24 | DI25: 1 | DJ25: 0.55069444 | DK25: 0.75208333 | DL25: =MOD(DK25-DJ25,1)*24 | DM25: 1 | DN25: 0.35486111 | DO25: 0.78888889 | DP25: =MOD(DO25-DN25,1)*24 | DQ25: 1 | DR25: 0.79305556 | DT25: =MOD(DS25-DR25,1)*24 | DU25: 1 | DV25: 0.35416667 | DW25: 0.78472222 | DX25: =MOD(DW25-DV25,1)*24 | DY25: 1
A26: 五楼 | B26: 王一程 | C26: 19 | F26: 0.35138889 | G26: 0.75694444 | H26: =MOD(G26-F26,1)*24 | I26: 1 | J26: 0.35138889 | K26: 0.74930556 | L26: =MOD(K26-J26,1)*24 | M26: 1 | R26: 0.35347222 | S26: 0.73819444 | T26: =MOD(S26-R26,1)*24 | U26: 1 | V26: 0.35277778 | W26: 0.73819444 | X26: =MOD(W26-V26,1)*24 | Y26: 1 | Z26: 0.35208333 | AA26: 0.73888889 | AB26: =MOD(AA26-Z26,1)*24 | AC26: 1 | AD26: 0.35277778 | AE26: 0.73958333 | AF26: =MOD(AE26-AD26,1)*24 | AG26: 1 | AL26: 0.35208333 | AM26: 0.74444444 | AN26: =MOD(AM26-AL26,1)*24 | AO26: 1 | AP26: 0.35069444 | AQ26: 0.73958333 | AR26: =MOD(AQ26-AP26,1)*24 | AS26: 1 | AT26: 0.35208333 | AU26: 0.74027778 | AV26: =MOD(AU26-AT26,1)*24 | AW26: 1 | AX26: 0.34930556 | AY26: 0.73888889 | AZ26: =MOD(AY26-AX26,1)*24 | BA26: 1 | BB26: 0.35 | BC26: 0.74027778 | BD26: =MOD(BC26-BB26,1)*24 | BE26: 1 | BF26: 0.35277778 | BG26: 0.73611111 | BH26: =MOD(BG26-BF26,1)*24 | BI26: 1 | BN26: 0.35347222 | BO26: 0.73958333 | BP26: =MOD(BO26-BN26,1)*24 | BQ26: 1 | BR26: 0.35138889 | BS26: 0.73819444 | BT26: =MOD(BS26-BR26,1)*24 | BU26: 1 | BV26: 0.34930556 | BW26: 0.7375 | BX26: =MOD(BW26-BV26,1)*24 | BY26: 1 | BZ26: 0.35347222 | CA26: 0.7375 | CB26: =MOD(CA26-BZ26,1)*24 | CC26: 1 | CD26: 0.35208333 | CE26: 0.73819444 | CF26: =MOD(CE26-CD26,1)*24 | CG26: 1 | CH26: 0.34930556 | CI26: 0.73958333 | CJ26: =MOD(CI26-CH26,1)*24 | CK26: 1 | CP26: 0.35277778 | CQ26: 0.73819444 | CR26: =MOD(CQ26-CP26,1)*24 | CS26: 1 | CT26: 0.35208333 | CU26: 0.7375 | CV26: =MOD(CU26-CT26,1)*24 | CW26: 1 | CX26: 0.35277778 | CY26: 0.82916667 | CZ26: =MOD(CY26-CX26,1)*24 | DA26: 1 | DB26: 0.35138889 | DC26: 0.825 | DD26: =MOD(DC26-DB26,1)*24 | DE26: 1 | DF26: 0.35069444 | DG26: 0.85416667 | DH26: =MOD(DG26-DF26,1)*24 | DI26: 1 | DJ26: 0.35277778 | DK26: 0.85416667 | DL26: =MOD(DK26-DJ26,1)*24 | DM26: 1 | DN26: 0.73888889 | DO26: 0.74027778 | DP26: =MOD(DO26-DN26,1)*24 | DQ26: 1 | DV26: 0.011805556 | DW26: 0.94375 | DX26: =MOD(DW26-DV26,1)*24 | DY26: 1
A27: 五楼 | B27: 王一程 | C27: 19 | J27: 0.74513889 | L27: =MOD(K27-J27,1)*24 | M27: 1 | DV27: 0.35208333 | DW27: 0.83333333 | DX27: =MOD(DW27-DV27,1)*24 | DY27: 1
A28: 五楼 | B28: 段绍红 | C28: 20 | F28: 0.34861111 | G28: 0.75416667 | H28: =MOD(G28-F28,1)*24 | I28: 1 | J28: 0.34861111 | K28: 0.73819444 | L28: =MOD(K28-J28,1)*24 | M28: 1 | N28: 0.35 | O28: 0.73680556 | P28: =MOD(O28-N28,1)*24 | Q28: 1 | R28: 0.34583333 | T28: =MOD(S28-R28,1)*24 | U28: 1 | V28: 0.35069444 | W28: 0.7375 | X28: =MOD(W28-V28,1)*24 | Y28: 1 | Z28: 0.35069444 | AA28: 0.74097222 | AB28: =MOD(AA28-Z28,1)*24 | AC28: 1 | AH28: 0.34444444 | AI28: 0.73680556 | AJ28: =MOD(AI28-AH28,1)*24 | AK28: 1 | AL28: 0.33888889 | AM28: 0.73680556 | AN28: =MOD(AM28-AL28,1)*24 | AO28: 1 | AP28: 0.34930556 | AQ28: 0.73611111 | AR28: =MOD(AQ28-AP28,1)*24 | AS28: 1 | AT28: 0.34861111 | AU28: 0.74027778 | AV28: =MOD(AU28-AT28,1)*24 | AW28: 1 | AX28: 0.33888889 | AY28: 0.50069444 | AZ28: =MOD(AY28-AX28,1)*24 | BA28: 1 | BB28: 0.34166667 | BC28: 0.7375 | BD28: =MOD(BC28-BB28,1)*24 | BE28: 1 | BF28: 0.34791667 | BG28: 0.74166667 | BH28: =MOD(BG28-BF28,1)*24 | BI28: 1 | BN28: 0.34791667 | BO28: 0.7375 | BP28: =MOD(BO28-BN28,1)*24 | BQ28: 1 | BR28: 0.34583333 | BS28: 0.73888889 | BT28: =MOD(BS28-BR28,1)*24 | BU28: 1 | BZ28: 0.34722222 | CA28: 0.73680556 | CB28: =MOD(CA28-BZ28,1)*24 | CC28: 1 | CD28: 0.34305556 | CE28: 0.73958333 | CF28: =MOD(CE28-CD28,1)*24 | CG28: 1 | CH28: 0.35 | CJ28: =MOD(CI28-CH28,1)*24 | CK28: 1 | CP28: 0.34652778 | CQ28: 0.73958333 | CR28: =MOD(CQ28-CP28,1)*24 | CS28: 1 | CT28: 0.34305556 | CU28: 0.7375 | CV28: =MOD(CU28-CT28,1)*24 | CW28: 1 | CX28: 0.34027778 | CY28: 0.73680556 | CZ28: =MOD(CY28-CX28,1)*24 | DA28: 1 | DB28: 0.34236111 | DC28: 0.5 | DD28: =MOD(DC28-DB28,1)*24 | DE28: 1 | DF28: 0.35277778 | DG28: 0.73680556 | DH28: =MOD(DG28-DF28,1)*24 | DI28: 1 | DJ28: 0.34791667 | DK28: 0.73680556 | DL28: =MOD(DK28-DJ28,1)*24 | DM28: 1 | DN28: 0.34513889 | DO28: 0.74375 | DP28: =MOD(DO28-DN28,1)*24 | DQ28: 1 | DR28: 0.34444444 | DS28: 0.7375 | DT28: =MOD(DS28-DR28,1)*24 | DU28: 1 | DV28: 0.35 | DW28: 0.74166667 | DX28: =MOD(DW28-DV28,1)*24 | DY28: 1
A29: 五楼 | B29: 段绍红 | C29: 20 | Z29: 0.73819444 | AB29: =MOD(AA29-Z29,1)*24 | AC29: 1 | AT29: 0.73680556 | AV29: =MOD(AU29-AT29,1)*24 | AW29: 1 | BF29: 0.73680556 | BH29: =MOD(BG29-BF29,1)*24 | BI29: 1 | CP29: 0.73680556 | CR29: =MOD(CQ29-CP29,1)*24 | CS29: 1 | DV29: 0.35138889 | DX29: =MOD(DW29-DV29,1)*24 | DY29: 1
A30: 五楼 | B30: 龙训东 | C30: 21 | F30: 0.34791667 | G30: 0.75486111 | H30: =MOD(G30-F30,1)*24 | I30: 1 | J30: 0.34791667 | K30: 0.74236111 | L30: =MOD(K30-J30,1)*24 | M30: 1 | R30: 0.34166667 | S30: 0.74027778 | T30: =MOD(S30-R30,1)*24 | U30: 1 | Z30: 0.34305556 | AA30: 0.74375 | AB30: =MOD(AA30-Z30,1)*24 | AC30: 1 | AH30: 0.34583333 | AI30: 0.74027778 | AJ30: =MOD(AI30-AH30,1)*24 | AK30: 1 | AP30: 0.34652778 | AQ30: 0.73958333 | AR30: =MOD(AQ30-AP30,1)*24 | AS30: 1 | AX30: 0.34722222 | AY30: 0.74583333 | AZ30: =MOD(AY30-AX30,1)*24 | BA30: 1 | BF30: 0.34930556 | BG30: 0.73888889 | BH30: =MOD(BG30-BF30,1)*24 | BI30: 1 | BN30: 0.34236111 | BO30: 0.73819444 | BP30: =MOD(BO30-BN30,1)*24 | BQ30: 1 | BV30: 0.33819444 | BW30: 0.74583333 | BX30: =MOD(BW30-BV30,1)*24 | BY30: 1 | CD30: 0.34375 | CE30: 0.78541667 | CF30: =MOD(CE30-CD30,1)*24 | CG30: 1 | CL30: 0.33958333 | CM30: 0.73680556 | CN30: =MOD(CM30-CL30,1)*24 | CO30: 1 | CP30: 0.33055556 | CQ30: 0.74236111 | CR30: =MOD(CQ30-CP30,1)*24 | CS30: 1 | CT30: 0.34305556 | CU30: 0.75 | CV30: =MOD(CU30-CT30,1)*24 | CW30: 1 | CX30: 0.34305556 | CY30: 0.73888889 | CZ30: =MOD(CY30-CX30,1)*24 | DA30: 1 | DB30: 0.34375 | DC30: 0.73958333 | DD30: =MOD(DC30-DB30,1)*24 | DE30: 1 | DJ30: 0.35138889 | DK30: 0.73888889 | DL30: =MOD(DK30-DJ30,1)*24 | DM30: 1 | DN30: 0.33958333 | DO30: 0.75972222 | DP30: =MOD(DO30-DN30,1)*24 | DQ30: 1 | DR30: 0.34444444 | DS30: 0.75 | DT30: =MOD(DS30-DR30,1)*24 | DU30: 1 | DV30: 0.34375 | DW30: 0.75694444 | DX30: =MOD(DW30-DV30,1)*24 | DY30: 1
A31: 五楼 | B31: 龙训东 | C31: 21 | J31: 0.74097222 | L31: =MOD(K31-J31,1)*24 | M31: 1
A32: 五楼 | B32: 李荧 | C32: 22 | F32: 0.34652778 | G32: 0.75555556 | H32: =MOD(G32-F32,1)*24 | I32: 1 | J32: 0.35069444 | K32: 0.7375 | L32: =MOD(K32-J32,1)*24 | M32: 1 | R32: 0.34722222 | S32: 0.74375 | T32: =MOD(S32-R32,1)*24 | U32: 1 | Z32: 0.35208333 | AA32: 0.76041667 | AB32: =MOD(AA32-Z32,1)*24 | AC32: 1 | AH32: 0.34652778 | AI32: 0.74791667 | AJ32: =MOD(AI32-AH32,1)*24 | AK32: 1 | AL32: 0.34861111 | AM32: 0.80625 | AN32: =MOD(AM32-AL32,1)*24 | AO32: 1 | AX32: 0.34930556 | AY32: 0.75347222 | AZ32: =MOD(AY32-AX32,1)*24 | BA32: 1 | BF32: 0.35 | BG32: 0.73819444 | BH32: =MOD(BG32-BF32,1)*24 | BI32: 1 | BN32: 0.35208333 | BO32: 0.73888889 | BP32: =MOD(BO32-BN32,1)*24 | BQ32: 1 | BV32: 0.35 | BW32: 0.74722222 | BX32: =MOD(BW32-BV32,1)*24 | BY32: 1 | CD32: 0.35208333 | CE32: 0.74236111 | CF32: =MOD(CE32-CD32,1)*24 | CG32: 1 | CH32: 0.35 | CI32: 0.76944444 | CJ32: =MOD(CI32-CH32,1)*24 | CK32: 1 | CL32: 0.34722222 | CM32: 0.73888889 | CN32: =MOD(CM32-CL32,1)*24 | CO32: 1 | CP32: 0.34930556 | CQ32: 0.74097222 | CR32: =MOD(CQ32-CP32,1)*24 | CS32: 1 | CT32: 0.34722222 | CU32: 0.7375 | CV32: =MOD(CU32-CT32,1)*24 | CW32: 1 | CX32: 0.34652778 | CY32: 0.75208333 | CZ32: =MOD(CY32-CX32,1)*24 | DA32: 1 | DB32: 0.34791667 | DC32: 0.74027778 | DD32: =MOD(DC32-DB32,1)*24 | DE32: 1 | DF32: 0.34652778 | DG32: 0.74513889 | DH32: =MOD(DG32-DF32,1)*24 | DI32: 1 | DJ32: 0.34930556 | DK32: 0.74652778 | DL32: =MOD(DK32-DJ32,1)*24 | DM32: 1 | DN32: 0.34930556 | DO32: 0.74166667 | DP32: =MOD(DO32-DN32,1)*24 | DQ32: 1 | DR32: 0.35069444 | DS32: 0.74027778 | DT32: =MOD(DS32-DR32,1)*24 | DU32: 1 | DV32: 0.34930556 | DW32: 0.92291667 | DX32: =MOD(DW32-DV32,1)*24 | DY32: 1
A33: 五楼 | B33: 李荧 | C33: 22 | AL33: 0.78472222 | AN33: =MOD(AM33-AL33,1)*24 | AO33: 1 | DB33: 0.35138889 | DD33: =MOD(DC33-DB33,1)*24 | DE33: 1
A34: 五楼 | B34: 贺悦 | C34: 23 | F34: 0.34861111 | G34: 0.75694444 | H34: =MOD(G34-F34,1)*24 | I34: 1 | J34: 0.34583333 | K34: 0.73680556 | L34: =MOD(K34-J34,1)*24 | M34: 1 | N34: 0.35 | O34: 0.73958333 | P34: =MOD(O34-N34,1)*24 | Q34: 1 | R34: 0.35138889 | S34: 0.7375 | T34: =MOD(S34-R34,1)*24 | U34: 1 | V34: 0.35 | W34: 0.73680556 | X34: =MOD(W34-V34,1)*24 | Y34: 1 | Z34: 0.35277778 | AA34: 0.73958333 | AB34: =MOD(AA34-Z34,1)*24 | AC34: 1 | AH34: 0.34930556 | AI34: 0.73819444 | AJ34: =MOD(AI34-AH34,1)*24 | AK34: 1 | AL34: 0.35208333 | AM34: 0.74166667 | AN34: =MOD(AM34-AL34,1)*24 | AO34: 1 | AP34: 0.35069444 | AQ34: 0.73958333 | AR34: =MOD(AQ34-AP34,1)*24 | AS34: 1 | AT34: 0.35208333 | AU34: 0.75 | AV34: =MOD(AU34-AT34,1)*24 | AW34: 1 | AX34: 0.35208333 | AY34: 0.73958333 | AZ34: =MOD(AY34-AX34,1)*24 | BA34: 1 | BB34: 0.35069444 | BC34: 0.74305556 | BD34: =MOD(BC34-BB34,1)*24 | BE34: 1 | BF34: 0.35208333 | BG34: 0.77291667 | BH34: =MOD(BG34-BF34,1)*24 | BI34: 1 | BN34: 0.34861111 | BO34: 0.74305556 | BP34: =MOD(BO34-BN34,1)*24 | BQ34: 1 | BR34: 0.35138889 | BS34: 0.74305556 | BT34: =MOD(BS34-BR34,1)*24 | BU34: 1 | BV34: 0.35069444 | BW34: 0.7375 | BX34: =MOD(BW34-BV34,1)*24 | BY34: 1 | BZ34: 0.35416667 | CA34: 0.75625 | CB34: =MOD(CA34-BZ34,1)*24 | CC34: 1 | CD34: 0.35208333 | CE34: 0.73819444 | CF34: =MOD(CE34-CD34,1)*24 | CG34: 1 | CH34: 0.35208333 | CI34: 0.73819444 | CJ34: =MOD(CI34-CH34,1)*24 | CK34: 1 | CP34: 0.35277778 | CQ34: 0.74027778 | CR34: =MOD(CQ34-CP34,1)*24 | CS34: 1 | CT34: 0.35138889 | CU34: 0.7375 | CV34: =MOD(CU34-CT34,1)*24 | CW34: 1 | CX34: 0.35069444 | CY34: 0.7375 | CZ34: =MOD(CY34-CX34,1)*24 | DA34: 1 | DB34: 0.35069444 | DC34: 0.7375 | DD34: =MOD(DC34-DB34,1)*24 | DE34: 1 | DJ34: 0.35277778 | DK34: 0.74583333 | DL34: =MOD(DK34-DJ34,1)*24 | DM34: 1 | DN34: 0.35277778 | DO34: 0.73819444 | DP34: =MOD(DO34-DN34,1)*24 | DQ34: 1 | DR34: 0.34930556 | DS34: 0.7375 | DT34: =MOD(DS34-DR34,1)*24 | DU34: 1 | DV34: 0.35347222 | DW34: 0.74652778 | DX34: =MOD(DW34-DV34,1)*24 | DY34: 1
A35: 五楼 | B35: 贺悦 | C35: 23 | Z35: 0.73819444 | AB35: =MOD(AA35-Z35,1)*24 | AC35: 1 | BB35: 0.74236111 | BD35: =MOD(BC35-BB35,1)*24 | BE35: 1
A36: 五楼 | B36: 莫娇 | C36: 24 | F36: 0.35138889 | G36: 0.75625 | H36: =MOD(G36-F36,1)*24 | I36: 1 | J36: 0.35138889 | K36: 0.73680556 | L36: =MOD(K36-J36,1)*24 | M36: 1 | R36: 0.35138889 | S36: 0.7375 | T36: =MOD(S36-R36,1)*24 | U36: 1 | Z36: 0.34722222 | AA36: 0.7375 | AB36: =MOD(AA36-Z36,1)*24 | AC36: 1 | AD36: 0.34722222 | AE36: 0.73680556 | AF36: =MOD(AE36-AD36,1)*24 | AG36: 1 | AL36: 0.35069444 | AM36: 0.73680556 | AN36: =MOD(AM36-AL36,1)*24 | AO36: 1 | AP36: 0.34930556 | AQ36: 0.7375 | AR36: =MOD(AQ36-AP36,1)*24 | AS36: 1 | AT36: 0.35138889 | AU36: 0.73680556 | AV36: =MOD(AU36-AT36,1)*24 | AW36: 1 | AX36: 0.34930556 | AY36: 0.73680556 | AZ36: =MOD(AY36-AX36,1)*24 | BA36: 1 | BB36: 0.35069444 | BC36: 0.73680556 | BD36: =MOD(BC36-BB36,1)*24 | BE36: 1 | BF36: 0.35 | BG36: 0.7375 | BH36: =MOD(BG36-BF36,1)*24 | BI36: 1 | BN36: 0.35 | BO36: 0.7375 | BP36: =MOD(BO36-BN36,1)*24 | BQ36: 1 | BR36: 0.35 | BS36: 0.73680556 | BT36: =MOD(BS36-BR36,1)*24 | BU36: 1 | BV36: 0.35069444 | BW36: 0.7375 | BX36: =MOD(BW36-BV36,1)*24 | BY36: 1 | BZ36: 0.34930556 | CA36: 0.7375 | CB36: =MOD(CA36-BZ36,1)*24 | CC36: 1 | CD36: 0.35069444 | CE36: 0.73819444 | CF36: =MOD(CE36-CD36,1)*24 | CG36: 1 | CH36: 0.35 | CI36: 0.73680556 | CJ36: =MOD(CI36-CH36,1)*24 | CK36: 1 | CP36: 0.34930556 | CQ36: 0.73819444 | CR36: =MOD(CQ36-CP36,1)*24 | CS36: 1 | CT36: 0.34930556 | CU36: 0.7375 | CV36: =MOD(CU36-CT36,1)*24 | CW36: 1 | CX36: 0.34930556 | CY36: 0.7375 | CZ36: =MOD(CY36-CX36,1)*24 | DA36: 1 | DB36: 0.35 | DC36: 0.73819444 | DD36: =MOD(DC36-DB36,1)*24 | DE36: 1 | DF36: 0.35 | DG36: 0.7375 | DH36: =MOD(DG36-DF36,1)*24 | DI36: 1 | DJ36: 0.34722222 | DK36: 0.73680556 | DL36: =MOD(DK36-DJ36,1)*24 | DM36: 1 | DN36: 0.34583333 | DO36: 0.73680556 | DP36: =MOD(DO36-DN36,1)*24 | DQ36: 1 | DR36: 0.34930556 | DS36: 0.73819444 | DT36: =MOD(DS36-DR36,1)*24 | DU36: 1 | DV36: 0.34861111 | DW36: 0.76111111 | DX36: =MOD(DW36-DV36,1)*24 | DY36: 1
A37: 五楼 | B37: 蒋年冬 | C37: 25 | Z37: 0.35555556 | AA37: 0.7375 | AB37: =MOD(AA37-Z37,1)*24 | AC37: 1 | AD37: 0.35138889 | AE37: 0.7375 | AF37: =MOD(AE37-AD37,1)*24 | AG37: 1 | AH37: 0.35069444 | AI37: 0.35416667 | AJ37: =MOD(AI37-AH37,1)*24 | AK37: 1 | AL37: 0.35208333 | AM37: 0.75277778 | AN37: =MOD(AM37-AL37,1)*24 | AO37: 1 | AP37: 0.34444444 | AQ37: 0.73680556 | AR37: =MOD(AQ37-AP37,1)*24 | AS37: 1 | AT37: 0.35208333 | AU37: 0.73680556 | AV37: =MOD(AU37-AT37,1)*24 | AW37: 1 | AX37: 0.35277778 | AY37: 0.7375 | AZ37: =MOD(AY37-AX37,1)*24 | BA37: 1 | BB37: 0.34375 | BC37: 0.74166667 | BD37: =MOD(BC37-BB37,1)*24 | BE37: 1 | BF37: 0.35208333 | BG37: 0.7375 | BH37: =MOD(BG37-BF37,1)*24 | BI37: 1 | BN37: 0.35138889 | BO37: 0.73680556 | BP37: =MOD(BO37-BN37,1)*24 | BQ37: 1 | BR37: 0.35138889 | BS37: 0.73680556 | BT37: =MOD(BS37-BR37,1)*24 | BU37: 1 | BV37: 0.34513889 | BW37: 0.73680556 | BX37: =MOD(BW37-BV37,1)*24 | BY37: 1 | BZ37: 0.34722222 | CA37: 0.73680556 | CB37: =MOD(CA37-BZ37,1)*24 | CC37: 1 | CD37: 0.34861111 | CE37: 0.73680556 | CF37: =MOD(CE37-CD37,1)*24 | CG37: 1 | CH37: 0.35277778 | CI37: 0.73680556 | CJ37: =MOD(CI37-CH37,1)*24 | CK37: 1 | CP37: 0.34305556 | CQ37: 0.73680556 | CR37: =MOD(CQ37-CP37,1)*24 | CS37: 1 | CT37: 0.34583333 | CU37: 0.73680556 | CV37: =MOD(CU37-CT37,1)*24 | CW37: 1 | CX37: 0.35 | CY37: 0.73680556 | CZ37: =MOD(CY37-CX37,1)*24 | DA37: 1 | DB37: 0.35069444 | DC37: 0.73680556 | DD37: =MOD(DC37-DB37,1)*24 | DE37: 1 | DF37: 0.35277778 | DG37: 0.73680556 | DH37: =MOD(DG37-DF37,1)*24 | DI37: 1 | DJ37: 0.35069444 | DK37: 0.73680556 | DL37: =MOD(DK37-DJ37,1)*24 | DM37: 1 | DR37: 0.34166667 | DS37: 0.73680556 | DT37: =MOD(DS37-DR37,1)*24 | DU37: 1 | DV37: 0.34375 | DW37: 0.73680556 | DX37: =MOD(DW37-DV37,1)*24 | DY37: 1
A38: 五楼 | B38: 田建锋 | C38: 26 | F38: 0.34305556 | G38: 0.75555556 | H38: =MOD(G38-F38,1)*24 | I38: 1 | N38: 0.34444444 | O38: 0.81319444 | P38: =MOD(O38-N38,1)*24 | Q38: 1 | V38: 0.34791667 | W38: 0.73680556 | X38: =MOD(W38-V38,1)*24 | Y38: 1 | AD38: 0.34513889 | AE38: 0.74652778 | AF38: =MOD(AE38-AD38,1)*24 | AG38: 1 | AP38: 0.34583333 | AQ38: 0.78472222 | AR38: =MOD(AQ38-AP38,1)*24 | AS38: 1 | AT38: 0.34375 | AU38: 0.75347222 | AV38: =MOD(AU38-AT38,1)*24 | AW38: 1 | BB38: 0.34583333 | BC38: 0.7375 | BD38: =MOD(BC38-BB38,1)*24 | BE38: 1 | BJ38: 0.34444444 | BK38: 0.73680556 | BL38: =MOD(BK38-BJ38,1)*24 | BM38: 1 | BR38: 0.34444444 | BS38: 0.75138889 | BT38: =MOD(BS38-BR38,1)*24 | BU38: 1 | BZ38: 0.34791667 | CA38: 0.76458333 | CB38: =MOD(CA38-BZ38,1)*24 | CC38: 1 | CD38: 0.34583333 | CE38: 0.73680556 | CF38: =MOD(CE38-CD38,1)*24 | CG38: 1 | CH38: 0.33819444 | CI38: 0.74097222 | CJ38: =MOD(CI38-CH38,1)*24 | CK38: 1 | CL38: 0.34791667 | CM38: 0.73680556 | CN38: =MOD(CM38-CL38,1)*24 | CO38: 1 | CP38: 0.34722222 | CQ38: 0.74305556 | CR38: =MOD(CQ38-CP38,1)*24 | CS38: 1 | CT38: 0.34305556 | CU38: 0.73958333 | CV38: =MOD(CU38-CT38,1)*24 | CW38: 1 | CX38: 0.34375 | CY38: 0.7375 | CZ38: =MOD(CY38-CX38,1)*24 | DA38: 1 | DB38: 0.34444444 | DC38: 0.74097222 | DD38: =MOD(DC38-DB38,1)*24 | DE38: 1 | DF38: 0.34791667 | DG38: 0.74652778 | DH38: =MOD(DG38-DF38,1)*24 | DI38: 1 | DJ38: 0.34513889 | DK38: 0.74027778 | DL38: =MOD(DK38-DJ38,1)*24 | DM38: 1 | DN38: 0.35 | DO38: 0.74236111 | DP38: =MOD(DO38-DN38,1)*24 | DQ38: 1 | DR38: 0.34444444 | DS38: 0.74166667 | DT38: =MOD(DS38-DR38,1)*24 | DU38: 1 | DV38: 0.34583333 | DW38: 0.86388889 | DX38: =MOD(DW38-DV38,1)*24 | DY38: 1
A39: 五楼 | B39: 田建锋 | C39: 26 | DV39: 0.74722222 | DX39: =MOD(DW39-DV39,1)*24 | DY39: 1
A40: 五楼 | B40: 李红波 | C40: 27 | F40: 0.34791667 | G40: 0.75555556 | H40: =MOD(G40-F40,1)*24 | I40: 1 | N40: 0.34722222 | O40: 0.7375 | P40: =MOD(O40-N40,1)*24 | Q40: 1 | V40: 0.34791667 | W40: 0.73680556 | X40: =MOD(W40-V40,1)*24 | Y40: 1 | AD40: 0.35 | AE40: 0.74027778 | AF40: =MOD(AE40-AD40,1)*24 | AG40: 1 | AL40: 0.35 | AM40: 0.74027778 | AN40: =MOD(AM40-AL40,1)*24 | AO40: 1 | AT40: 0.34652778 | AU40: 0.7375 | AV40: =MOD(AU40-AT40,1)*24 | AW40: 1 | BB40: 0.35 | BC40: 0.7375 | BD40: =MOD(BC40-BB40,1)*24 | BE40: 1 | BJ40: 0.34444444 | BK40: 0.73680556 | BL40: =MOD(BK40-BJ40,1)*24 | BM40: 1 | BR40: 0.34583333 | BS40: 0.73680556 | BT40: =MOD(BS40-BR40,1)*24 | BU40: 1 | BZ40: 0.34930556 | CA40: 0.73680556 | CB40: =MOD(CA40-BZ40,1)*24 | CC40: 1 | CH40: 0.34791667 | CI40: 0.74513889 | CJ40: =MOD(CI40-CH40,1)*24 | CK40: 1 | CL40: 0.34791667 | CM40: 0.73680556 | CN40: =MOD(CM40-CL40,1)*24 | CO40: 1 | CP40: 0.34652778 | CQ40: 0.7375 | CR40: =MOD(CQ40-CP40,1)*24 | CS40: 1 | CT40: 0.34652778 | CU40: 0.73680556 | CV40: =MOD(CU40-CT40,1)*24 | CW40: 1 | CX40: 0.34861111 | CY40: 0.7375 | CZ40: =MOD(CY40-CX40,1)*24 | DA40: 1 | DB40: 0.34652778 | DC40: 0.73819444 | DD40: =MOD(DC40-DB40,1)*24 | DE40: 1 | DF40: 0.34861111 | DG40: 0.74444444 | DH40: =MOD(DG40-DF40,1)*24 | DI40: 1 | DJ40: 0.34583333 | DK40: 0.73819444 | DL40: =MOD(DK40-DJ40,1)*24 | DM40: 1 | DN40: 0.34930556 | DO40: 0.73888889 | DP40: =MOD(DO40-DN40,1)*24 | DQ40: 1 | DR40: 0.34652778 | DS40: 0.73680556 | DT40: =MOD(DS40-DR40,1)*24 | DU40: 1 | DV40: 0.34861111 | DW40: 0.73680556 | DX40: =MOD(DW40-DV40,1)*24 | DY40: 1
...

Sheet 汇总
A1: 姓名 | B1: 打卡地点 | C1: 一级部门 | D1: 二级部门 | E1: 岗位 | F1: 上班日期 | G1: 身份证号 | H1: 上班小时数 | I1: 上班分钟数 | J1: 当月打卡天数 | K1: 正常休假天数 | L1: 调休天数 | M1: 出差天数 | N1: 补卡天数 | O1: 异常打卡 | P1: 漏卡次数 | Q1: 请假天数 | R1: 出勤合计 | S1: 补卡时间 | T1: 出差时间 | U1: 请假时间 | V1: 未打卡时间 | W1: 备注
A2: 张雪莲 | H2: =SUMIF('3月部门分发'!B:B,A2,'3月部门分发'!DX:DX) | I2: =H2*60 | J2: =SUMIF('3月部门分发'!B:B,A2,'3月部门分发'!DY:DY) | R2: =J2+K2+L2+M2+N2+O2+P2+Q2
A3: 高淑文 | H3: =SUMIF('3月部门分发'!B:B,A3,'3月部门分发'!DX:DX) | I3: =H3*60 | J3: =SUMIF('3月部门分发'!B:B,A3,'3月部门分发'!DY:DY) | R3: =J3+K3+L3+M3+N3+O3+P3+Q3
A4: 伍小雪 | H4: =SUMIF('3月部门分发'!B:B,A4,'3月部门分发'!DX:DX) | I4: =H4*60 | J4: =SUMIF('3月部门分发'!B:B,A4,'3月部门分发'!DY:DY) | R4: =J4+K4+L4+M4+N4+O4+P4+Q4
A5: 邱霞 | H5: =SUMIF('3月部门分发'!B:B,A5,'3月部门分发'!DX:DX) | I5: =H5*60 | J5: =SUMIF('3月部门分发'!B:B,A5,'3月部门分发'!DY:DY) | R5: =J5+K5+L5+M5+N5+O5+P5+Q5
A6: 苏春梅 | H6: =SUMIF('3月部门分发'!B:B,A6,'3月部门分发'!DX:DX) | I6: =H6*60 | J6: =SUMIF('3月部门分发'!B:B,A6,'3月部门分发'!DY:DY) | R6: =J6+K6+L6+M6+N6+O6+P6+Q6
A7: 黄晓云 | H7: =SUMIF('3月部门分发'!B:B,A7,'3月部门分发'!DX:DX) | I7: =H7*60 | J7: =SUMIF('3月部门分发'!B:B,A7,'3月部门分发'!DY:DY) | R7: =J7+K7+L7+M7+N7+O7+P7+Q7
A8: 陈小红 | H8: =SUMIF('3月部门分发'!B:B,A8,'3月部门分发'!DX:DX) | I8: =H8*60 | J8: =SUMIF('3月部门分发'!B:B,A8,'3月部门分发'!DY:DY) | R8: =J8+K8+L8+M8+N8+O8+P8+Q8
A9: 罗丽 | H9: =SUMIF('3月部门分发'!B:B,A9,'3月部门分发'!DX:DX) | I9: =H9*60 | J9: =SUMIF('3月部门分发'!B:B,A9,'3月部门分发'!DY:DY) | R9: =J9+K9+L9+M9+N9+O9+P9+Q9
A10: 胡娅 | H10: =SUMIF('3月部门分发'!B:B,A10,'3月部门分发'!DX:DX) | I10: =H10*60 | J10: =SUMIF('3月部门分发'!B:B,A10,'3月部门分发'!DY:DY) | R10: =J10+K10+L10+M10+N10+O10+P10+Q10
A11: 杨青青 | H11: =SUMIF('3月部门分发'!B:B,A11,'3月部门分发'!DX:DX) | I11: =H11*60 | J11: =SUMIF('3月部门分发'!B:B,A11,'3月部门分发'!DY:DY) | R11: =J11+K11+L11+M11+N11+O11+P11+Q11
A12: 代白高 | H12: =SUMIF('3月部门分发'!B:B,A12,'3月部门分发'!DX:DX) | I12: =H12*60 | J12: =SUMIF('3月部门分发'!B:B,A12,'3月部门分发'!DY:DY) | R12: =J12+K12+L12+M12+N12+O12+P12+Q12
A13: 向锋 | H13: =SUMIF('3月部门分发'!B:B,A13,'3月部门分发'!DX:DX) | I13: =H13*60 | J13: =SUMIF('3月部门分发'!B:B,A13,'3月部门分发'!DY:DY) | R13: =J13+K13+L13+M13+N13+O13+P13+Q13
... A85: 毛玉玲 | H85: =SUMIF('3月部门分发'!B:B,A85,'3月部门分发'!DX:DX) | I85: =H85*60 | J85: =SUMIF('3月部门分发'!B:B,A85,'3月部门分发'!DY:DY) | R85: =J85+K85+L85+M85+N85+O85+P85+Q85

Sheet 花名册
A1: 姓名 | B1: 部门 | C1: 二级部门 | D1: 岗位 | E1: 合同签订日期 | F1: 身份证号码
A2: 郑强 | B2: 生产制造中心 | C2: 生产制造中心 | D2: 生产总监 | E2: 2022-02-07 | F2: 511521198402115393
A3: 康波 | B3: 设计部 | C3: 设计组 | D3: 方案设计师 | E3: 2023-02-22 | F3: 500225199303293814
A4: 贺悦 | B4: 信息部 | C4: 信息部 | D4: 酷家乐建模工程师 | E4: 2025-03-03 | F4: 500111199702150016
A5: 匡启素 | B5: 综合部 | C5: 综合部 | D5: 经理 | E5: 2014-02-07 | F5: 512322197310221860
A6: 陈静 | B6: 品质部 | C6: 品质部 | D6: 全检 | E6: 2024-03-14 | F6: 500234199107196327
A7: 杨为 | B7: 板式车间 | C7: 柜体线-排孔组 | D7: 排孔 | E7: 2022-02-11 | F7: 500225199009093838
A8: 李荧 | B8: 订单部 | C8: 审单组 | D8: 手工拆单员 | E8: 2021-02-19 | F8: 513021199504011068
A9: 章新灯 | B9: 设计部 | C9: 设计组 | D9: 工艺经理 | E9: 2024-09-04 | F9: 500237199310047879
A10: 刘文旦 | B10: 设计部 | C10: 设计组 | D10: 深化拆单设计师 | E10: 2024-10-21 | F10: 362421199210302911
A11: 谭勇 | B11: 设计部 | C11: 设计组 | D11: 方案设计师 | E11: 2025-06-30 | F11: 500225198602072312
A12: 莫永兵 | B12: 板式车间 | C12: 板式车间 | D12: 厂长 | E12: 2022-03-28 | F12: 510225197703015437
... A155: 王晓兰 | B155: 财务部 | C155: 财务部 | D155: 会计 | E155: 2019-04-17 | F155: 500225199107248442
A156: 张冰 | B156: 压贴厂 | D156: 压板厂长 | E156: 2021-06-09 | F156: 510184199101272173
A157: 覃树科 | B157: 压贴厂 | D157: 压贴工 | E157: 2026-03-09 | F157: 500225199402021451
A158: 刘俊杰 | B158: 压贴厂 | D158: 压贴工 | E158: 2023-06-21 | F158: 513623198004109713
A159: 黄贞才 | B159: 压贴厂 | D159: 叉车工 | E159: 2026-03-23 | F159: 510230197505267191
A160: 杨宗碧 | B160: 综合部 | D160: 车间清洁工 | E160: 2023-05-06 | F160: 512322196609231284
A161: 肖祖鞅 | B161: 销售一部 | D161: 销售经理 | E161: 2026-03-05 | F161: 500225200410311112
A162: 李文儒 | B162: 销售一部 | D162: 销售经理 | E162: 2026-03-05 | F162: 500225200405054473
A163: 曹连民 | B163: 久派商贸公司 | D163: 展辰油漆工 | E163: 2026-03-06 | F163: 371428198301092519
A164: 杨玲 | B164: 综合部 | D164: 叉车工 | E164: 2024-03-17 | F164: 500225199407141188
A165: 张成彪 | B165: 压贴厂 | D165: 压贴工 | E165: 2025-06-24 | F165: 500225198710111171
A166: 罗万川 | B166: 线条厂 | D166: 包覆 | E166: 2021-12-30 | F166: 51023019830406435X
A167: 陈建 | B167: 销售一部 | D167: 销售经理 | E167: 2022-09-12 | F167: 510230198205071116
... A270: 肖俊泽 | B270: 压贴厂 | D270: 压贴工 | E270: 2026-03-16 | F270: 510230197505138437
